Workbook

Sheet Figurer
B2: Ratioer
B3: Kapital-output-ratio (K/Y) | C3: 1993 | D3: 1994 | E3: 1995 | F3: 1996 | G3: 1997 | H3: 1998 | I3: 1999 | J3: 2000 | K3: 2001 | L3: 2002 | M3: 2003 | N3: 2004 | O3: 2005 | P3: 2006 | Q3: 2007 | R3: 2008 | S3: 2009 | T3: 2010 | U3: 2011 | V3: 2012 | W3: 2013 | X3: 2014 | Y3: 2015 | Z3: 2016 | AA3: 2017 | AB3: 2018 | AC3: 2019 | AD3: 2020 | AE3: 2021 | AF3: 2022
B4: Landbrug | C4: =K!AC2/Y!AB2 -> 3.8077253 | D4: =K!AD2/Y!AC2 -> 3.7963422 | E4: =K!AE2/Y!AD2 -> 3.7117405 | F4: =K!AF2/Y!AE2 -> 3.6385806 | G4: =K!AG2/Y!AF2 -> 3.5119004 | H4: =K!AH2/Y!AG2 -> 3.4295951 | I4: =K!AI2/Y!AH2 -> 3.3311872 | J4: =K!AJ2/Y!AI2 -> 3.2511995 | ... AF4: =K!BF2/Y!BE2 -> 2.3398088
B5: Føde- drikke og tobaksvareindustri | C5: =K!AC3/Y!AB3 -> 0.52835922 | D5: =K!AD3/Y!AC3 -> 0.5281621 | E5: =K!AE3/Y!AD3 -> 0.53503635 | F5: =K!AF3/Y!AE3 -> 0.57693307 | G5: =K!AG3/Y!AF3 -> 0.57365674 | H5: =K!AH3/Y!AG3 -> 0.56357497 | I5: =K!AI3/Y!AH3 -> 0.56419763 | J5: =K!AJ3/Y!AI3 -> 0.57922845 | ... AF5: =K!BF3/Y!BE3 -> 0.60815323
B6: Resten af økonomien | C6: =K!AC4/Y!AB4 -> 2.4616773 | D6: =K!AD4/Y!AC4 -> 2.3515402 | E6: =K!AE4/Y!AD4 -> 2.2948131 | F6: =K!AF4/Y!AE4 -> 2.2584458 | G6: =K!AG4/Y!AF4 -> 2.214041 | H6: =K!AH4/Y!AG4 -> 2.1876465 | I6: =K!AI4/Y!AH4 -> 2.1233423 | J6: =K!AJ4/Y!AI4 -> 2.0526324 | ... AF6: =K!BF4/Y!BE4 -> 1.8182721
B8: Arbejdskraft-output-ratio (L/Y) | C8: 1993 | D8: 1994 | E8: 1995 | F8: 1996 | G8: 1997 | H8: 1998 | I8: 1999 | J8: 2000 | K8: 2001 | L8: 2002 | M8: 2003 | N8: 2004 | O8: 2005 | P8: 2006 | Q8: 2007 | R8: 2008 | S8: 2009 | T8: 2010 | U8: 2011 | V8: 2012 | W8: 2013 | X8: 2014 | Y8: 2015 | Z8: 2016 | AA8: 2017 | AB8: 2018 | AC8: 2019 | AD8: 2020 | AE8: 2021 | AF8: 2022
B9: Landbrug | C9: =L!AC2/Y!AB2 -> 0.0029571062 | D9: =L!AD2/Y!AC2 -> 0.0027202249 | E9: =L!AE2/Y!AD2 -> 0.0025938706 | F9: =L!AF2/Y!AE2 -> 0.0024622549 | G9: =L!AG2/Y!AF2 -> 0.0022490593 | H9: =L!AH2/Y!AG2 -> 0.0021981132 | I9: =L!AI2/Y!AH2 -> 0.0020810781 | J9: =L!AJ2/Y!AI2 -> 0.0020012299 | ... AF9: =L!BF2/Y!BE2 -> 0.0010369286
B10: Føde- drikke og tobaksvareindustri | C10: =L!AC3/Y!AB3 -> 0.00082931062 | D10: =L!AD3/Y!AC3 -> 0.00080005675 | E10: =L!AE3/Y!AD3 -> 0.0008201487 | F10: =L!AF3/Y!AE3 -> 0.00083500121 | G10: =L!AG3/Y!AF3 -> 0.00080733325 | H10: =L!AH3/Y!AG3 -> 0.00076728456 | I10: =L!AI3/Y!AH3 -> 0.0007769908 | J10: =L!AJ3/Y!AI3 -> 0.00078217112 | ... AF10: =L!BF3/Y!BE3 -> 0.00041439251
B11: Resten af økonomien | C11: =L!AC4/Y!AB4 -> 0.0013646966 | D11: =L!AD4/Y!AC4 -> 0.0012804717 | E11: =L!AE4/Y!AD4 -> 0.0012620348 | F11: =L!AF4/Y!AE4 -> 0.001237055 | G11: =L!AG4/Y!AF4 -> 0.0012205198 | H11: =L!AH4/Y!AG4 -> 0.0012120392 | I11: =L!AI4/Y!AH4 -> 0.0011887711 | J11: =L!AJ4/Y!AI4 -> 0.0011558209 | ... AF11: =L!BF4/Y!BE4 -> 0.00081986545
B13: Materiale-output-ratio (Mtot/Y) | C13: 1993 | D13: 1994 | E13: 1995 | F13: 1996 | G13: 1997 | H13: 1998 | I13: 1999 | J13: 2000 | K13: 2001 | L13: 2002 | M13: 2003 | N13: 2004 | O13: 2005 | P13: 2006 | Q13: 2007 | R13: 2008 | S13: 2009 | T13: 2010 | U13: 2011 | V13: 2012 | W13: 2013 | X13: 2014 | Y13: 2015 | Z13: 2016 | AA13: 2017 | AB13: 2018 | AC13: 2019 | AD13: 2020 | AE13: 2021 | AF13: 2022
B14: Landbrug | C14: =Mtot!AB2/Y!AB2 -> 0.76620736 | D14: =Mtot!AC2/Y!AC2 -> 0.74528358 | E14: =Mtot!AD2/Y!AD2 -> 0.71846463 | F14: =Mtot!AE2/Y!AE2 -> 0.70156608 | G14: =Mtot!AF2/Y!AF2 -> 0.70675842 | H14: =Mtot!AG2/Y!AG2 -> 0.71425458 | I14: =Mtot!AH2/Y!AH2 -> 0.72524137 | J14: =Mtot!AI2/Y!AI2 -> 0.6898744 | ... AF14: =Mtot!BE2/Y!BE2 -> 0.66658913
B15: Føde- drikke og tobaksvareindustri | C15: =Mtot!AB3/Y!AB3 -> 0.77039685 | D15: =Mtot!AC3/Y!AC3 -> 0.77248456 | E15: =Mtot!AD3/Y!AD3 -> 0.75953472 | F15: =Mtot!AE3/Y!AE3 -> 0.76295332 | G15: =Mtot!AF3/Y!AF3 -> 0.74730071 | H15: =Mtot!AG3/Y!AG3 -> 0.75383101 | I15: =Mtot!AH3/Y!AH3 -> 0.74330711 | J15: =Mtot!AI3/Y!AI3 -> 0.7513189 | ... AF15: =Mtot!BE3/Y!BE3 -> 0.76577921
B16: Resten af økonomien | C16: =Mtot!AB4/Y!AB4 -> 0.46238202 | D16: =Mtot!AC4/Y!AC4 -> 0.46011318 | E16: =Mtot!AD4/Y!AD4 -> 0.46179801 | F16: =Mtot!AE4/Y!AE4 -> 0.46160346 | G16: =Mtot!AF4/Y!AF4 -> 0.45895152 | H16: =Mtot!AG4/Y!AG4 -> 0.4621365 | I16: =Mtot!AH4/Y!AH4 -> 0.46563593 | J16: =Mtot!AI4/Y!AI4 -> 0.46040943 | ... AF16: =Mtot!BE4/Y!BE4 -> 0.48647562
B18: Kapital pr arbejdstime (K/L) | C18: 1993 | D18: 1994 | E18: 1995 | F18: 1996 | G18: 1997 | H18: 1998 | I18: 1999 | J18: 2000 | K18: 2001 | L18: 2002 | M18: 2003 | N18: 2004 | O18: 2005 | P18: 2006 | Q18: 2007 | R18: 2008 | S18: 2009 | T18: 2010 | U18: 2011 | V18: 2012 | W18: 2013 | X18: 2014 | Y18: 2015 | Z18: 2016 | AA18: 2017 | AB18: 2018 | AC18: 2019 | AD18: 2020 | AE18: 2021 | AF18: 2022
B19: Landbrug | C19: =K!AC2/L!AC2 -> 1287.6525 | D19: =K!AD2/L!AD2 -> 1395.5986 | E19: =K!AE2/L!AE2 -> 1430.966 | F19: =K!AF2/L!AF2 -> 1477.7433 | G19: =K!AG2/L!AG2 -> 1561.4974 | H19: =K!AH2/L!AH2 -> 1560.245 | I19: =K!AI2/L!AI2 -> 1600.7027 | J19: =K!AJ2/L!AJ2 -> 1624.6007 | ... AF19: =K!BF2/L!BF2 -> 2256.4801
B20: Føde- drikke og tobaksvareindustri | C20: =K!AC3/L!AC3 -> 637.10654 | D20: =K!AD3/L!AD3 -> 660.1558 | E20: =K!AE3/L!AE3 -> 652.36505 | F20: =K!AF3/L!AF3 -> 690.93681 | G20: =K!AG3/L!AG3 -> 710.55756 | H20: =K!AH3/L!AH3 -> 734.50582 | I20: =K!AI3/L!AI3 -> 726.13167 | J20: =K!AJ3/L!AJ3 -> 740.5393 | ... AF20: =K!BF3/L!BF3 -> 1467.5778
B21: Resten af økonomien | C21: =K!AC4/L!AC4 -> 1803.8276 | D21: =K!AD4/L!AD4 -> 1836.464 | E21: =K!AE4/L!AE4 -> 1818.3437 | F21: =K!AF4/L!AF4 -> 1825.6632 | G21: =K!AG4/L!AG4 -> 1814.0148 | H21: =K!AH4/L!AH4 -> 1804.9304 | I21: =K!AI4/L!AI4 -> 1786.1658 | J21: =K!AJ4/L!AJ4 -> 1775.9088 | ... AF21: =K!BF4/L!BF4 -> 2217.7689
B23: Produktionsværdi (mio.kr.) | C23: 1993 | D23: 1994 | E23: 1995 | F23: 1996 | G23: 1997 | H23: 1998 | I23: 1999 | J23: 2000 | K23: 2001 | L23: 2002 | M23: 2003 | N23: 2004 | O23: 2005 | P23: 2006 | Q23: 2007 | R23: 2008 | S23: 2009 | T23: 2010 | U23: 2011 | V23: 2012 | W23: 2013 | X23: 2014 | Y23: 2015 | Z23: 2016 | AA23: 2017 | AB23: 2018 | AC23: 2019 | AD23: 2020 | AE23: 2021 | AF23: 2022
B24: Landbrug | C24: =Y!AB2*P!AB2 -> 55728.664 | D24: =Y!AC2*P!AC2 -> 55147.064 | E24: =Y!AD2*P!AD2 -> 58275.627 | F24: =Y!AE2*P!AE2 -> 59527.836 | G24: =Y!AF2*P!AF2 -> 61114.082 | H24: =Y!AG2*P!AG2 -> 55009.011 | I24: =Y!AH2*P!AH2 -> 53791.911 | J24: =Y!AI2*P!AI2 -> 59756.001 | ... AF24: =Y!BE2*P!BE2 -> 95782.8
B25: Føde- drikke og tobaksvareindustri | C25: =Y!AB3*P!AB3 -> 113491.54 | D25: =Y!AC3*P!AC3 -> 115531.56 | E25: =Y!AD3*P!AD3 -> 116174.18 | F25: =Y!AE3*P!AE3 -> 113564.13 | G25: =Y!AF3*P!AF3 -> 116548.17 | H25: =Y!AG3*P!AG3 -> 113149.85 | I25: =Y!AH3*P!AH3 -> 109463.88 | J25: =Y!AI3*P!AI3 -> 117014.81 | ... AF25: =Y!BE3*P!BE3 -> 193667.23
B26: Resten af økonomien | C26: =Y!AB4*P!AB4 -> 1248607.7 | D26: =Y!AC4*P!AC4 -> 1339359.2 | E26: =Y!AD4*P!AD4 -> 1413633.7 | F26: =Y!AE4*P!AE4 -> 1474891.7 | G26: =Y!AF4*P!AF4 -> 1558557.7 | H26: =Y!AG4*P!AG4 -> 1600889.3 | I26: =Y!AH4*P!AH4 -> 1683627.2 | J26: =Y!AI4*P!AI4 -> 1859433.3 | ... AF26: =Y!BE4*P!BE4 -> 4563032.4

Sheet Ark1
A1: ANVENDELSE | B1: 1993 | C1: 1994 | D1: 1995 | E1: 1996 | F1: 1997 | G1: 1998 | H1: 1999 | I1: 2000 | J1: 2001 | K1: 2002 | L1: 2003 | M1: 2004 | N1: 2005 | O1: 2006 | P1: 2007 | Q1: 2008 | R1: 2009 | S1: 2010 | T1: 2011 | U1: 2012 | V1: 2013 | W1: 2014 | X1: 2015 | Y1: 2016 | Z1: 2017 | AA1: 2018 | AB1: 2019 | AC1: 2020 | AD1: 2021 | AE1: 2022
A2: L | B2: 205.929 | C2: 187.306 | D2: 180.889 | E2: 173.049 | F2: 162.332 | G2: 160.81 | H2: 152.28 | I2: 149.02 | J2: 145.343 | K2: 145.637 | L2: 134.391 | M2: 133.301 | N2: 125.588 | O2: 117.953 | P2: 114.771 | Q2: 109.397 | R2: 101.938 | S2: 98.594 | T2: 97.135 | U2: 95.702 | V2: 94.814 | W2: 95.678 | X2: 97.467 | Y2: 91.694 | Z2: 92.464 | AA2: 89.982 | AB2: 85.014 | AC2: 85.49 | AD2: 86.997 | AE2: 84.49
A3: KL | C3: 52117.794 | D3: 50900.442 | E3: 49681.538 | F3: 48143.426 | G3: 47708.981 | H3: 46314.405 | I3: 45117.473 | J3: 44432.633 | K3: 44480.111 | L3: 42600.847 | M3: 42241.35 | N3: 40925.503 | O3: 39424.938 | P3: 39026.41 | Q3: 38328.713 | R3: 37355.83 | S3: 36543.067 | T3: 35879.711 | U3: 35222.069 | V3: 34756.946 | W3: 34683.366 | X3: 34775.854 | Y3: 33362.229 | Z3: 33300.801 | AA3: 32593.134 | AB3: 31418.74 | AC3: 31265.505 | AD3: 31288.388 | AE3: 30691.04
A4: w | B4: 70.472785 | C4: 72.401971 | D4: 73.668419 | E4: 77.602928 | F4: 82.112148 | G4: 85.654427 | H4: 87.363624 | I4: 90.147712 | J4: 91.297341 | K4: 97.14543 | L4: 103.01562 | M4: 108.39572 | N4: 109.31073 | O4: 113.52155 | P4: 120.93852 | Q4: 127.13193 | R4: 132.90639 | S4: 140.4119 | T4: 143.61532 | U4: 146.408 | V4: 150.45915 | W4: 156.52284 | X4: 175.97839 | Y4: 179.46352 | Z4: 182.14425 | AA4: 189.6717 | AB4: 197.71026 | AC4: 205.68694 | AD4: 203.39064 | AE4: 217.89115
A5: P_KL | C5: 0.5694121 | D5: 0.62035501 | E5: 0.71346775 | F5: 0.65078662 | G5: 0.64940884 | H5: 0.76888134 | I5: 0.63509005 | J5: 0.60434501 | K5: 0.64413311 | L5: 0.68386032 | M5: 0.74184557 | N5: 0.59880691 | O5: 0.7204948 | P5: 0.67093704 | Q5: 0.77635834 | R5: 0.83598365 | S5: 0.86793431 | T5: 0.87398331 | U5: 0.76017118 | V5: 0.80984611 | W5: 0.80380746 | X5: 0.84621455 | Y5: 0.79660741 | Z5: 0.90949967 | AA5: 1.1242478 | AB5: 0.98676346 | AC5: 1 | AD5: 1.1984003 | AE5: 1.0173887
A7: EKL | B7: 0
B8: =(B2/B3)*(B4/B5)^$B$7 -> #DIV/0! | C8: =(C2/C3)*(C4/C5)^$B$7 -> 0.0035938973 | D8: =(D2/D3)*(D4/D5)^$B$7 -> 0.0035537805 | E8: =(E2/E3)*(E4/E5)^$B$7 -> 0.0034831651 | F8: =(F2/F3)*(F4/F5)^$B$7 -> 0.0033718415 | G8: =(G2/G3)*(G4/G5)^$B$7 -> 0.0033706442 | H8: =(H2/H3)*(H4/H5)^$B$7 -> 0.0032879619 | I8: =(I2/I3)*(I4/I5)^$B$7 -> 0.0033029332 | ... AE8: =(AE2/AE3)*(AE4/AE5)^$B$7 -> 0.0027529208
A11: lon lob | B11: =B2*B4 -> 14512.39 | C11: =C2*C4 -> 13561.324 | D11: =D2*D4 -> 13325.807 | E11: =E2*E4 -> 13429.109 | F11: =F2*F4 -> 13329.429 | G11: =G2*G4 -> 13774.088 | H11: =H2*H4 -> 13303.733 | I11: =I2*I4 -> 13433.812 | ... AF11: =AF2*AF4 -> 0
A12: lon for | B12: =B2*A4 -> #VALUE! | C12: =C2*B4 -> 13199.975 | D12: =D2*C4 -> 13096.72 | E12: =E2*D4 -> 12748.246 | F12: =F2*E4 -> 12597.438 | G12: =G2*F4 -> 13204.455 | H12: =H2*G4 -> 13043.456 | I12: =I2*H4 -> 13018.927 | ... AE12: =AE2*AD4 -> 17184.475
A13: Pt | B13: =C13/(C11/C12) -> 0.34262158 | C13: =D13/(D11/D12) -> 0.35200082 | D13: =E13/(E11/E12) -> 0.35815798 | E13: =F13/(F11/F12) -> 0.37728661 | F13: =G13/(G11/G12) -> 0.39920935 | G13: =H13/(H11/H12) -> 0.41643105 | H13: =I13/(I11/I12) -> 0.42474075 | I13: =J13/(J11/J12) -> 0.43827631 | ... AB13: =AC13/(AC11/AC12) -> 0.96121931 | AC13: =1 -> 1 | AD13: =AC13*AD11/AD12 -> 0.98883595 | AE13: =AD13*AE11/AE12 -> 1.0593339
A14: Xt | B14: =B11/B13 -> 42356.906 | C14: =C11/C13 -> 38526.398 | D14: =D11/D13 -> 37206.505 | E14: =E11/E13 -> 35593.919 | F14: =F11/F13 -> 33389.572 | G14: =G11/G13 -> 33076.517 | H14: =H11/H13 -> 31322.007 | I14: =I11/I13 -> 30651.468 | ... AE14: =AE11/AE13 -> 17378.489
B16: =(B14/B3)*(B13/B5)^$B$7 -> #DIV/0! | C16: =(C14/C3)*(C13/C5)^$B$7 -> 0.73921773 | D16: =(D14/D3)*(D13/D5)^$B$7 -> 0.73096624 | E16: =(E14/E3)*(E13/E5)^$B$7 -> 0.71644157 | F16: =(F14/F3)*(F13/F5)^$B$7 -> 0.69354375 | G16: =(G14/G3)*(G13/G5)^$B$7 -> 0.69329749 | H16: =(H14/H3)*(H13/H5)^$B$7 -> 0.67629082 | I16: =(I14/I3)*(I13/I5)^$B$7 -> 0.67937022 | ... AE16: =(AE14/AE3)*(AE13/AE5)^$B$7 -> 0.56623984

Sheet 10120
A2: Mængder | B2: 1993 | C2: 1994 | D2: 1995 | E2: 1996 | F2: 1997 | G2: 1998 | H2: 1999 | I2: 2000 | J2: 2001 | K2: 2002 | L2: 2003 | M2: 2004 | N2: 2005 | O2: 2006 | P2: 2007 | Q2: 2008 | R2: 2009 | S2: 2010 | T2: 2011 | U2: 2012 | V2: 2013 | W2: 2014 | X2: 2015 | Y2: 2016 | Z2: 2017 | AA2: 2018 | AB2: 2019 | AC2: 2020 | AD2: 2021 | AE2: 2022
A3: Y | B3: =Y!AB3 -> 150359.82 | C3: =Y!AC3 -> 151786.73 | D3: =Y!AD3 -> 151157.95 | E3: =Y!AE3 -> 144547.1 | F3: =Y!AF3 -> 146043.78 | G3: =Y!AG3 -> 150061.67 | H3: =Y!AH3 -> 149807.44 | I3: =Y!AI3 -> 149968.46 | ... AE3: =Y!BE3 -> 168806.14
A4: K | B4: =K!AC3 -> 79444 | C4: =K!AD3 -> 80168 | D4: =K!AE3 -> 80875 | E4: =K!AF3 -> 83394 | F4: =K!AG3 -> 83779 | G4: =K!AH3 -> 84571 | H4: =K!AI3 -> 84521 | I4: =K!AJ3 -> 86866 | ... AE4: =K!BF3 -> 102660
A5: L | B5: =L!AC3 -> 124.695 | C5: =L!AD3 -> 121.438 | D5: =L!AE3 -> 123.972 | E5: =L!AF3 -> 120.697 | F5: =L!AG3 -> 117.906 | G5: =L!AH3 -> 115.14 | H5: =L!AI3 -> 116.399 | I5: =L!AJ3 -> 117.301 | ... AE5: =L!BF3 -> 69.952
A6: Mtot | B6: =Mtot!AB3 -> 115836.74 | C6: =Mtot!AC3 -> 117252.91 | D6: =Mtot!AD3 -> 114809.72 | E6: =Mtot!AE3 -> 110282.69 | F6: =Mtot!AF3 -> 109138.62 | G6: =Mtot!AG3 -> 113121.14 | H6: =Mtot!AH3 -> 111352.93 | I6: =Mtot!AI3 -> 112674.14 | ... AE6: =Mtot!BE3 -> 129268.23
A7: J | B7: =J!M3 -> 0 | C7: =J!N3 -> 0 | D7: =J!O3 -> 0 | E7: =J!P3 -> 0 | F7: =J!Q3 -> 0 | G7: =J!R3 -> 0 | H7: =J!S3 -> 0 | I7: =J!T3 -> 0 | ... AE7: =J!AP3 -> 0
A8: I | B8: =I!B3 -> 6200 | C8: =I!C3 -> 6403 | D8: =I!D3 -> 6422 | E8: =I!E3 -> 8467 | F8: =I!F3 -> 6945 | G8: =I!G3 -> 7452 | H8: =I!H3 -> 6764 | I8: =I!I3 -> 9085 | ... AE8: =I!AE3 -> 7507
A10: Priser
A11: p_Y | B11: =P!AB3 -> 0.75479964 | C11: =P!AC3 -> 0.76114401 | D11: =P!AD3 -> 0.76856146 | E11: =P!AE3 -> 0.78565486 | F11: =P!AF3 -> 0.79803586 | G11: =P!AG3 -> 0.75402237 | H11: =P!AH3 -> 0.73069725 | I11: =P!AI3 -> 0.78026275 | ... AE11: =P!BE3 -> 1.1472759
A12: P_K | B12: =P_K!AC3 -> 0 | C12: =P_K!AD3 -> 0.10203538 | D12: =P_K!AE3 -> 0.10777479 | E12: =P_K!AF3 -> 0.11877328 | F12: =P_K!AG3 -> 0.11164507 | G12: =P_K!AH3 -> 0.10658308 | H12: =P_K!AI3 -> 0.0963468 | I12: =P_K!AJ3 -> 0.11085744 | ... AE12: =P_K!BF3 -> 0.082330124
A13: w | B13: =w!AC3 -> 142.0781 | C13: =w!AD3 -> 146.61712 | D13: =w!AE3 -> 147.38063 | E13: =w!AF3 -> 152.68933 | F13: =w!AG3 -> 157.86554 | G13: =w!AH3 -> 168.62299 | H13: =w!AI3 -> 166.71729 | I13: =w!AJ3 -> 171.25747 | ... AE13: =w!BF3 -> 333.34154
A14: P_Mtot | B14: =P_Mtot!AB3 -> 0.7487871 | C14: =P_Mtot!AC3 -> 0.76162629 | D14: =P_Mtot!AD3 -> 0.77195901 | E14: =P_Mtot!AE3 -> 0.78289225 | F14: =P_Mtot!AF3 -> 0.79729797 | G14: =P_Mtot!AG3 -> 0.7485308 | H14: =P_Mtot!AH3 -> 0.71806287 | I14: =P_Mtot!AI3 -> 0.76666594 | ... AE14: =P_Mtot!BE3 -> 1.2453425
A15: P_J | B15: =P_J!AC3 -> 0 | C15: =P_J!AD3 -> 0 | D15: =P_J!AE3 -> 0 | E15: =P_J!AF3 -> 0 | F15: =P_J!AG3 -> 0 | G15: =P_J!AH3 -> 0 | H15: =P_J!AI3 -> 0 | I15: =P_J!AJ3 -> 0 | ... AE15: =P_J!BF3 -> 0
A16: P_I | B16: =P_I!C3 -> 0.70532258 | C16: =P_I!D3 -> 0.72013119 | D16: =P_I!E3 -> 0.72734351 | E16: =P_I!F3 -> 0.7146569 | F16: =P_I!G3 -> 0.7362131 | G16: =P_I!H3 -> 0.74597424 | H16: =P_I!I3 -> 0.75458309 | I16: =P_I!J3 -> 0.76224546 | ... AE16: =P_I!AF3 -> 1.0655388
A17: P_Jord | B17: =P_Jord!M3 -> 0 | C17: =P_Jord!N3 -> 0 | D17: =P_Jord!O3 -> 0 | E17: =P_Jord!P3 -> 0 | F17: =P_Jord!Q3 -> 0 | G17: =P_Jord!R3 -> 0 | H17: =P_Jord!S3 -> 0 | I17: =P_Jord!T3 -> 0 | ... AE17: =P_Jord!AP3 -> 0
A19: Andet
A20: Subsidiesats | B20: =tau_Y!AC3 -> -0.0052241545 | C20: =tau_Y!AD3 -> -0.0062216068 | D20: =tau_Y!AE3 -> -0.0041188069 | E20: =tau_Y!AF3 -> -0.0046475991 | F20: =tau_Y!AG3 -> -0.0029108785 | G20: =tau_Y!AH3 -> -0.0012037651 | H20: =tau_Y!AI3 -> -0.00039389257 | I20: =tau_Y!AJ3 -> 4.4346782e-05 | ... AE20: =tau_Y!BF3 -> 0.0028560706
A21: Afgift indenlandsk | B21: =tau_MD!AB3 -> -0.0031050841 | C21: =tau_MD!AC3 -> -0.00027029362 | D21: =tau_MD!AD3 -> -0.0023572128 | E21: =tau_MD!AE3 -> -0.0027298842 | F21: =tau_MD!AF3 -> -0.0025350968 | G21: =tau_MD!AG3 -> -0.00043101845 | H21: =tau_MD!AH3 -> 0.0028970078 | I21: =tau_MD!AI3 -> 0.0044174752 | ... AE21: =tau_MD!BE3 -> 0.0061585633
A22: Markup | B22: =markup!AC3 -> 0 | C22: =markup!AD3 -> 0.0090350964 | D22: =markup!AE3 -> 0.0096512526 | E22: =markup!AF3 -> -0.0024480986 | F22: =markup!AG3 -> 0.016953187 | G22: =markup!AH3 -> 0.0023614807 | H22: =markup!AI3 -> 0.018553578 | I22: =markup!AJ3 -> 0.010080435 | ... AE22: =markup!BF3 -> 0.0022215309

Sheet Y
A1: ANVENDELSE | B1: 1967 | C1: 1968 | D1: 1969 | E1: 1970 | F1: 1971 | G1: 1972 | H1: 1973 | I1: 1974 | J1: 1975 | K1: 1976 | L1: 1977 | M1: 1978 | N1: 1979 | O1: 1980 | P1: 1981 | Q1: 1982 | R1: 1983 | S1: 1984 | T1: 1985 | U1: 1986 | V1: 1987 | W1: 1988 | X1: 1989 | Y1: 1990 | Z1: 1991 | AA1: 1992 | AB1: 1993 | AC1: 1994 | AD1: 1995 | AE1: 1996 | AF1: 1997 | AG1: 1998 | AH1: 1999 | AI1: 2000 | AJ1: 2001 | AK1: 2002 | AL1: 2003 | AM1: 2004 | AN1: 2005 | AO1: 2006 | AP1: 2007 | AQ1: 2008 | AR1: 2009 | AS1: 2010 | AT1: 2011 | AU1: 2012 | AV1: 2013 | AW1: 2014 | AX1: 2015 | AY1: 2016 | AZ1: 2017 | BA1: 2018 | BB1: 2019 | BC1: 2020 | BD1: 2021 | BE1: 2022
A2: 01000 | B2: 44352.253 | C2: 44088.474 | D2: 44065.485 | E2: 41076.955 | F2: 44428.588 | G2: 45125.516 | H2: 45687.594 | I2: 47792.366 | J2: 45353.08 | K2: 45360.614 | L2: 48300.748 | M2: 50462.618 | N2: 51681.032 | O2: 51506.404 | P2: 52624.818 | Q2: 55228.202 | R2: 53482.361 | S2: 58750.744 | T2: 58588.026 | U2: 58742.299 | V2: 56961.097 | W2: 56075.446 | X2: 58852.663 | Y2: 62263.479 | Z2: 60786.475 | AA2: 60399.718 | AB2: 69638.69 | AC2: 68856.807 | AD2: 69737.096 | AE2: 70280.702 | AF2: 72177.731 | AG2: 73158.199 | AH2: 73173.611 | AI2: 74464.21 | AJ2: 73547.402 | AK2: 74587.448 | AL2: 74719.005 | AM2: 75618.655 | AN2: 74196.06 | AO2: 75618.96 | AP2: 79159.854 | AQ2: 73126.391 | AR2: 73444.22 | AS2: 77334.77 | AT2: 75869.896 | AU2: 77617.493 | AV2: 76593.51 | AW2: 80374.732 | AX2: 79210.579 | AY2: 76984.41 | AZ2: 80708.048 | BA2: 79724.539 | BB2: 78394.569 | BC2: 80503.511 | BD2: 82678.533 | BE2: 81481.018
A3: 10120 | B3: 83186.189 | C3: 86476.234 | D3: 85557.501 | E3: 89270.716 | F3: 92244.747 | G3: 94861.982 | H3: 96469.273 | I3: 98731.17 | J3: 96574.474 | K3: 100366.04 | L3: 105550.69 | M3: 108622.24 | N3: 118817.66 | O3: 124261.63 | P3: 125155.28 | Q3: 121655.97 | R3: 119434.54 | S3: 120350.92 | T3: 126590.8 | U3: 133131.09 | V3: 131489.29 | W3: 131466.32 | X3: 131914.27 | Y3: 138076.58 | Z3: 139256.11 | AA3: 142823.72 | AB3: 150359.82 | AC3: 151786.73 | AD3: 151157.95 | AE3: 144547.1 | AF3: 146043.78 | AG3: 150061.67 | AH3: 149807.44 | AI3: 149968.46 | AJ3: 152904.38 | AK3: 155839.87 | AL3: 157377.12 | AM3: 159879.98 | AN3: 163810.69 | AO3: 162171.86 | AP3: 160069.3 | AQ3: 158120.91 | AR3: 150853.33 | AS3: 144714.15 | AT3: 145739.45 | AU3: 142580.88 | AV3: 144480.44 | AW3: 145446.79 | AX3: 146833.77 | AY3: 148098.44 | AZ3: 153499.94 | BA3: 153657.79 | BB3: 155602.57 | BC3: 161377.86 | BD3: 165261.18 | BE3: 168806.14
A4: Privat | B4: 1026759.8 | C4: 1060228 | D4: 1128335.3 | E4: 1163036.9 | F4: 1190367.5 | G4: 1245135.5 | H4: 1301826.3 | I4: 1283839.6 | J4: 1247791.5 | K4: 1341368.2 | L4: 1369531.2 | M4: 1399200.8 | N4: 1458076.4 | O4: 1444205 | P4: 1413996.2 | Q4: 1442953.8 | R4: 1470393.7 | S4: 1563352.9 | T4: 1649454.8 | U4: 1767725.2 | V4: 1790231.4 | W4: 1812075.4 | X4: 1823885.1 | Y4: 1869398.4 | Z4: 1883903.1 | AA4: 1910380.1 | AB4: 1925612.6 | AC4: 2029748.8 | AD4: 2102984.8 | AE4: 2163214.2 | AF4: 2238321.7 | AG4: 2303787.6 | AH4: 2405520.3 | AI4: 2534870.3 | AJ4: 2597762.6 | AK4: 2626560.7 | AL4: 2633042.8 | AM4: 2696370 | AN4: 2860107.9 | AO4: 3027807.4 | AP4: 3135857.7 | AQ4: 3148473.7 | AR4: 2893995.6 | AS4: 2888940.4 | AT4: 2982891.5 | AU4: 3003146.7 | AV4: 3008539.6 | AW4: 3070703.6 | AX4: 3147783.9 | AY4: 3280295.1 | AZ4: 3379204.8 | BA4: 3448242.6 | BB4: 3504899.4 | BC4: 3423589 | BD4: 3653418.8 | BE4: 3780880.1
A5: REST | B5: 1109665.2 | C5: 1150467.2 | D5: 1244272.4 | E5: 1296967.3 | F5: 1323255.2 | G5: 1389078.8 | H5: 1455464.8 | I5: 1429114.2 | J5: 1395556.7 | K5: 1504518.1 | L5: 1524849.3 | M5: 1565128.5 | N5: 1624837 | O5: 1610111.2 | P5: 1578283.4 | Q5: 1618114.6 | R5: 1656904 | S5: 1747167.8 | T5: 1838273 | U5: 1959928.8 | V5: 1995809.2 | W5: 2024259.3 | X5: 2032213.7 | Y5: 2061376.4 | Z5: 2081193.2 | AA5: 2112919.2 | AB5: 2121405.3 | AC5: 2237038.4 | AD5: 2322092.6 | AE5: 2404762 | AF5: 2483498.2 | AG5: 2556756.6 | AH5: 2672884.8 | AI5: 2814342.7 | AJ5: 2887124.9 | AK5: 2919063.6 | AL5: 2924155.7 | AM5: 2993388 | AN5: 3163125.6 | AO5: 3345591.2 | AP5: 3450061.6 | AQ5: 3489091 | AR5: 3255992.7 | AS5: 3260982 | AT5: 3349605.6 | AU5: 3379079.5 | AV5: 3383461.5 | AW5: 3454296 | AX5: 3545031.5 | AY5: 3681621.6 | AZ5: 3775390.8 | BA5: 3850118.5 | BB5: 3911961.7 | BC5: 3813550.3 | BD5: 4064668.8 | BE5: 4180703.9

Sheet Mtot
A1: ANVENDELSE | B1: 1967 | C1: 1968 | D1: 1969 | E1: 1970 | F1: 1971 | G1: 1972 | H1: 1973 | I1: 1974 | J1: 1975 | K1: 1976 | L1: 1977 | M1: 1978 | N1: 1979 | O1: 1980 | P1: 1981 | Q1: 1982 | R1: 1983 | S1: 1984 | T1: 1985 | U1: 1986 | V1: 1987 | W1: 1988 | X1: 1989 | Y1: 1990 | Z1: 1991 | AA1: 1992 | AB1: 1993 | AC1: 1994 | AD1: 1995 | AE1: 1996 | AF1: 1997 | AG1: 1998 | AH1: 1999 | AI1: 2000 | AJ1: 2001 | AK1: 2002 | AL1: 2003 | AM1: 2004 | AN1: 2005 | AO1: 2006 | AP1: 2007 | AQ1: 2008 | AR1: 2009 | AS1: 2010 | AT1: 2011 | AU1: 2012 | AV1: 2013 | AW1: 2014 | AX1: 2015 | AY1: 2016 | AZ1: 2017 | BA1: 2018 | BB1: 2019 | BC1: 2020 | BD1: 2021 | BE1: 2022
A2: 01000 | B2: 39158.518 | C2: 38650.312 | D2: 37599.57 | E2: 39477.463 | F2: 39989.894 | G2: 39968.78 | H2: 43203.207 | I2: 40624.801 | J2: 41184.028 | K2: 45049.756 | L2: 44518.695 | M2: 47531.524 | N2: 49980.482 | O2: 48731.852 | P2: 47712.43 | Q2: 48749.416 | R2: 49280.812 | S2: 49178.903 | T2: 50055.651 | U2: 48856.276 | V2: 51127.725 | W2: 47936.374 | X2: 46717.146 | Y2: 48397.555 | Z2: 46713.689 | AA2: 48453.715 | AB2: 53357.677 | AC2: 51317.848 | AD2: 50103.637 | AE2: 49306.557 | AF2: 51012.219 | AG2: 52253.578 | AH2: 53068.53 | AI2: 51370.952 | AJ2: 49577.561 | AK2: 51738.253 | AL2: 50336.364 | AM2: 50593.936 | AN2: 49993.304 | AO2: 50482.307 | AP2: 50622.981 | AQ2: 51288.072 | AR2: 52138.985 | AS2: 51115.381 | AT2: 51939.369 | AU2: 51132.975 | AV2: 51962.32 | AW2: 51260.314 | AX2: 53815.232 | AY2: 54109.514 | AZ2: 54622.469 | BA2: 54318.847 | BB2: 51561.033 | BC2: 53402.835 | BD2: 53643.955 | BE2: 54314.361
A3: 10120 | B3: 61168.908 | C3: 63366.112 | D3: 62908.687 | E3: 66315.865 | F3: 69522.091 | G3: 70582.374 | H3: 71085.547 | I3: 72967.32 | J3: 72152.64 | K3: 75759.772 | L3: 77865.086 | M3: 81362 | N3: 89053.188 | O3: 93553.418 | P3: 94169.026 | Q3: 90833.077 | R3: 87704.507 | S3: 89727.186 | T3: 94513.239 | U3: 100591.64 | V3: 100836.82 | W3: 98946.674 | X3: 98253.018 | Y3: 103669.6 | Z3: 104457.9 | AA3: 109206.93 | AB3: 115836.74 | AC3: 117252.91 | AD3: 114809.72 | AE3: 110282.69 | AF3: 109138.62 | AG3: 113121.14 | AH3: 111352.93 | AI3: 112674.14 | AJ3: 114029.63 | AK3: 120528.93 | AL3: 124582.68 | AM3: 125432.27 | AN3: 128358.35 | AO3: 129842.14 | AP3: 128854.42 | AQ3: 128455.78 | AR3: 121554.51 | AS3: 115038.18 | AT3: 116451.86 | AU3: 114000.84 | AV3: 115688.26 | AW3: 116298.81 | AX3: 120274.32 | AY3: 120429.91 | AZ3: 123525.11 | BA3: 125198.66 | BB3: 124712.78 | BC3: 130185.31 | BD3: 130242.37 | BE3: 129268.23
A4: Privat | B4: 489183.39 | C4: 497803.42 | D4: 531106.12 | E4: 560532.26 | F4: 566577.19 | G4: 592048.13 | H4: 622281.6 | I4: 608316.33 | J4: 588619.41 | K4: 640041.42 | L4: 650211.49 | M4: 669190.43 | N4: 699957.72 | O4: 694794.77 | P4: 673091.66 | Q4: 670003.85 | R4: 680531.57 | S4: 734884.47 | T4: 782277.13 | U4: 846029.52 | V4: 857565.27 | W4: 861698.99 | X4: 855473.9 | Y4: 870566.77 | Z4: 867837.43 | AA4: 880672.57 | AB4: 890368.65 | AC4: 933914.2 | AD4: 971154.19 | AE4: 998547.18 | AF4: 1027281.1 | AG4: 1064664.4 | AH4: 1120096.7 | AI4: 1167078.2 | AJ4: 1212130.2 | AK4: 1239178.1 | AL4: 1226530.9 | AM4: 1253237.9 | AN4: 1365647 | AO4: 1456220.4 | AP4: 1516413.1 | AQ4: 1526217.8 | AR4: 1376908.8 | AS4: 1356348.3 | AT4: 1400960 | AU4: 1418591.1 | AV4: 1411060.2 | AW4: 1453357.9 | AX4: 1510304.9 | AY4: 1569023 | AZ4: 1605494.4 | BA4: 1637654.6 | BB4: 1666063 | BC4: 1642472.1 | BD4: 1742584.3 | BE4: 1839306
A5: REST | B5: 429425.77 | C5: 438104.29 | D5: 481460.68 | E5: 508854.09 | F5: 510244.46 | G5: 540634.97 | H5: 570883.72 | I5: 556252.43 | J5: 535578.38 | K5: 583106.24 | L5: 591924.48 | M5: 608211.11 | N5: 628418.8 | O5: 618325.33 | P5: 593573.52 | Q5: 593445.7 | R5: 609143.43 | S5: 667096.98 | T5: 710926.28 | U5: 775663.24 | V5: 789733.13 | W5: 796441.78 | X5: 793487.58 | Y5: 800866.82 | Z5: 801200.15 | AA5: 809276.4 | AB5: 814819.29 | AC5: 864082.93 | AD5: 912068.8 | AE5: 951107.78 | AF5: 981114.47 | AG5: 1017067.6 | AH5: 1081882.8 | AI5: 1133494 | AJ5: 1185092.3 | AK5: 1205063.8 | AL5: 1191577.4 | AM5: 1223673.4 | AN5: 1342970 | AO5: 1437216.6 | AP5: 1499775.9 | AQ5: 1517743.2 | AR5: 1379351.6 | AS5: 1364739.9 | AT5: 1400676.1 | AU5: 1427973.9 | AV5: 1417020.8 | AW5: 1463315.3 | AX5: 1517724.4 | AY5: 1581461.1 | AZ5: 1617080.5 | BA5: 1650726.9 | BB5: 1681786.2 | BC5: 1658028.6 | BD5: 1767698.2 | BE5: 1864350.3

Sheet K
A1: ANVENDELSE | B1: 1966 | C1: 1967 | D1: 1968 | E1: 1969 | F1: 1970 | G1: 1971 | H1: 1972 | I1: 1973 | J1: 1974 | K1: 1975 | L1: 1976 | M1: 1977 | N1: 1978 | O1: 1979 | P1: 1980 | Q1: 1981 | R1: 1982 | S1: 1983 | T1: 1984 | U1: 1985 | V1: 1986 | W1: 1987 | X1: 1988 | Y1: 1989 | Z1: 1990 | AA1: 1991 | AB1: 1992 | AC1: 1993 | AD1: 1994 | AE1: 1995 | AF1: 1996 | AG1: 1997 | AH1: 1998 | AI1: 1999 | AJ1: 2000 | AK1: 2001 | AL1: 2002 | AM1: 2003 | AN1: 2004 | AO1: 2005 | AP1: 2006 | AQ1: 2007 | AR1: 2008 | AS1: 2009 | AT1: 2010 | AU1: 2011 | AV1: 2012 | AW1: 2013 | AX1: 2014 | AY1: 2015 | AZ1: 2016 | BA1: 2017 | BB1: 2018 | BC1: 2019 | BD1: 2020 | BE1: 2021 | BF1: 2022 | BG1: 2023 | BH1: 2024
A2: 01000 | B2: 222779 | C2: 224430 | D2: 224282 | E2: 225092 | F2: 225532 | G2: 226385 | H2: 229269 | I2: 235171 | J2: 240479 | K2: 244016 | L2: 249923 | M2: 257543 | N2: 265709 | O2: 273950 | P2: 274839 | Q2: 271574 | R2: 269172 | S2: 265387 | T2: 264710 | U2: 266226 | V2: 266885 | W2: 266110 | X2: 264303 | Y2: 267224 | Z2: 270771 | AA2: 270977 | AB2: 269956 | AC2: 265165 | AD2: 261404 | AE2: 258846 | AF2: 255722 | AG2: 253481 | AH2: 250903 | AI2: 243755 | AJ2: 242098 | AK2: 242131 | AL2: 240161 | AM2: 238063 | AN2: 236088 | AO2: 234687 | AP2: 235845 | AQ2: 239330 | AR2: 242244 | AS2: 239024 | AT2: 234064 | AU2: 229103 | AV2: 225090 | AW2: 222016 | AX2: 218477 | AY2: 215268 | AZ2: 211288 | BA2: 208278 | BB2: 204256 | BC2: 200726 | BD2: 196514 | BE2: 194470 | BF2: 190650 | BG2: 187393 | BH2: 184590
A3: 10120 | B3: 34654 | C3: 36904 | D3: 38025 | E3: 39447 | F3: 40346 | G3: 41710 | H3: 42921 | I3: 44127 | J3: 46869 | K3: 48514 | L3: 50580 | M3: 52444 | N3: 54643 | O3: 57092 | P3: 58318 | Q3: 59085 | R3: 59216 | S3: 59268 | T3: 60351 | U3: 61829 | V3: 63940 | W3: 66178 | X3: 68823 | Y3: 71028 | Z3: 72698 | AA3: 75678 | AB3: 78426 | AC3: 79444 | AD3: 80168 | AE3: 80875 | AF3: 83394 | AG3: 83779 | AH3: 84571 | AI3: 84521 | AJ3: 86866 | AK3: 88848 | AL3: 90559 | AM3: 93051 | AN3: 95676 | AO3: 95904 | AP3: 95868 | AQ3: 96614 | AR3: 99622 | AS3: 102062 | AT3: 99903 | AU3: 98584 | AV3: 99448 | AW3: 99126 | AX3: 98817 | AY3: 98167 | AZ3: 97863 | BA3: 98143 | BB3: 100338 | BC3: 101517 | BD3: 101385 | BE3: 101864 | BF3: 102660 | BG3: 103486 | BH3: 104607
A4: Privat | B4: 2328289 | C4: 2420953 | D4: 2512851 | E4: 2625053 | F4: 2731578 | G4: 2833885 | H4: 2968039 | I4: 3113691 | J4: 3216009 | K4: 3292020 | L4: 3408556 | M4: 3511869 | N4: 3615136 | O4: 3713343 | P4: 3780940 | Q4: 3807718 | R4: 3850841 | S4: 3900678 | T4: 3969100 | U4: 4059681 | V4: 4195239 | W4: 4321877 | X4: 4413324 | Y4: 4504518 | Z4: 4595977 | AA4: 4658767 | AB4: 4707856 | AC4: 4740237 | AD4: 4773036 | AE4: 4825957 | AF4: 4885502 | AG4: 4955736 | AH4: 5039873 | AI4: 5107743 | AJ4: 5203157 | AK4: 5285017 | AL4: 5356277 | AM4: 5425441 | AN4: 5498539 | AO4: 5587189 | AP4: 5723562 | AQ4: 5850835 | AR4: 5942911 | AS4: 5987917 | AT4: 5990758 | AU4: 5995379 | AV4: 6010959 | AW4: 6036155 | AX4: 6077431 | AY4: 6133100 | AZ4: 6213595 | BA4: 6311588 | BB4: 6417049 | BC4: 6501720 | BD4: 6591703 | BE4: 6734739 | BF4: 6874669 | BG4: 6992400 | BH4: 7114398
A5: REST | B5: 2618163 | C5: 2738303 | D5: 2867006 | E5: 3015495 | F5: 3161059 | G5: 3302298 | H5: 3467494 | I5: 3631240 | J5: 3755637 | K5: 3856260 | L5: 3992820 | M5: 4114787 | N5: 4233512 | O5: 4350333 | P5: 4435830 | Q5: 4471498 | R5: 4517509 | S5: 4564886 | T5: 4625448 | U5: 4710206 | V5: 4837386 | W5: 4962141 | X5: 5055391 | Y5: 5137935 | Z5: 5217291 | AA5: 5264800 | AB5: 5305384 | AC5: 5328639 | AD5: 5354683 | AE5: 5403081 | AF5: 5462484 | AG5: 5531111 | AH5: 5612542 | AI5: 5682056 | AJ5: 5773271 | AK5: 5852073 | AL5: 5918328 | AM5: 5980902 | AN5: 6046439 | AO5: 6132550 | AP5: 6270696 | AQ5: 6395005 | AR5: 6486901 | AS5: 6533631 | AT5: 6550770 | AU5: 6568622 | AV5: 6599838 | AW5: 6638025 | AX5: 6696875 | AY5: 6769376 | AZ5: 6870825 | BA5: 6985059 | BB5: 7107156 | BC5: 7209258 | BD5: 7324959 | BE5: 7488001 | BF5: 7648052 | BG5: 7786450 | BH5: 7930718

Sheet L
A1: ANVENDELSE | B1: 1966 | C1: 1967 | D1: 1968 | E1: 1969 | F1: 1970 | G1: 1971 | H1: 1972 | I1: 1973 | J1: 1974 | K1: 1975 | L1: 1976 | M1: 1977 | N1: 1978 | O1: 1979 | P1: 1980 | Q1: 1981 | R1: 1982 | S1: 1983 | T1: 1984 | U1: 1985 | V1: 1986 | W1: 1987 | X1: 1988 | Y1: 1989 | Z1: 1990 | AA1: 1991 | AB1: 1992 | AC1: 1993 | AD1: 1994 | AE1: 1995 | AF1: 1996 | AG1: 1997 | AH1: 1998 | AI1: 1999 | AJ1: 2000 | AK1: 2001 | AL1: 2002 | AM1: 2003 | AN1: 2004 | AO1: 2005 | AP1: 2006 | AQ1: 2007 | AR1: 2008 | AS1: 2009 | AT1: 2010 | AU1: 2011 | AV1: 2012 | AW1: 2013 | AX1: 2014 | AY1: 2015 | AZ1: 2016 | BA1: 2017 | BB1: 2018 | BC1: 2019 | BD1: 2020 | BE1: 2021 | BF1: 2022
A2: 01000 | B2: 630.077 | C2: 595.974 | D2: 561.953 | E2: 532.92 | F2: 505.492 | G2: 472.538 | H2: 463.15 | I2: 454.509 | J2: 433.263 | K2: 415.44 | L2: 408.086 | M2: 393.844 | N2: 380.021 | O2: 361.6 | P2: 342.439 | Q2: 325.525 | R2: 314.708 | S2: 305.717 | T2: 297.005 | U2: 286.292 | V2: 277.373 | W2: 272.733 | X2: 247.527 | Y2: 239.832 | Z2: 229.64 | AA2: 224.577 | AB2: 216.746 | AC2: 205.929 | AD2: 187.306 | AE2: 180.889 | AF2: 173.049 | AG2: 162.332 | AH2: 160.81 | AI2: 152.28 | AJ2: 149.02 | AK2: 145.343 | AL2: 145.637 | AM2: 134.391 | AN2: 133.301 | AO2: 125.588 | AP2: 117.953 | AQ2: 114.771 | AR2: 109.397 | AS2: 101.938 | AT2: 98.594 | AU2: 97.135 | AV2: 95.702 | AW2: 94.814 | AX2: 95.678 | AY2: 97.467 | AZ2: 91.694 | BA2: 92.464 | BB2: 89.982 | BC2: 85.014 | BD2: 85.49 | BE2: 86.997 | BF2: 84.49
A3: 10120 | B3: 232.125 | C3: 220.326 | D3: 210.205 | E3: 204.42 | F3: 202.642 | G3: 194.114 | H3: 187.292 | I3: 179.902 | J3: 174.334 | K3: 156.33 | L3: 155.216 | M3: 152.588 | N3: 149.102 | O3: 150.151 | P3: 147.911 | Q3: 145.985 | R3: 146.121 | S3: 147.457 | T3: 147.552 | U3: 145.082 | V3: 148.494 | W3: 140.336 | X3: 138.844 | Y3: 133.495 | Z3: 129.957 | AA3: 129.1 | AB3: 127.466 | AC3: 124.695 | AD3: 121.438 | AE3: 123.972 | AF3: 120.697 | AG3: 117.906 | AH3: 115.14 | AI3: 116.399 | AJ3: 117.301 | AK3: 117.036 | AL3: 116.729 | AM3: 110.661 | AN3: 106.601 | AO3: 99.25 | AP3: 95.156 | AQ3: 90.557 | AR3: 89.332 | AS3: 83.22 | AT3: 79.289 | AU3: 76.719 | AV3: 73.253 | AW3: 70.479 | AX3: 66.267 | AY3: 64.949 | AZ3: 65.699 | BA3: 67.126 | BB3: 65.335 | BC3: 65.519 | BD3: 70.152 | BE3: 70.24 | BF3: 69.952
A4: Privat | B4: 4005.275 | C4: 3893.867 | D4: 3812.789 | E4: 3762.969 | F4: 3723.123 | G4: 3604.532 | H4: 3514.151 | I4: 3435.632 | J4: 3343.361 | K4: 3118.256 | L4: 3174.012 | M4: 3109.71 | N4: 3055.256 | O4: 3029.475 | P4: 2953.509 | Q4: 2789.238 | R4: 2784.644 | S4: 2764.548 | T4: 2820.456 | U4: 2867.423 | V4: 2957.498 | W4: 2898.773 | X4: 2814.231 | Y4: 2765.429 | Z4: 2727.54 | AA4: 2699.07 | AB4: 2699.99 | AC4: 2627.877 | AD4: 2599.036 | AE4: 2654.04 | AF4: 2676.015 | AG4: 2731.916 | AH4: 2792.281 | AI4: 2859.613 | AJ4: 2929.856 | AK4: 2953.905 | AL4: 2933.736 | AM4: 2869.431 | AN4: 2852.465 | AO4: 2866.743 | AP4: 2937.49 | AQ4: 2976.606 | AR4: 3006.822 | AS4: 2803.28 | AT4: 2719.164 | AU4: 2768.068 | AV4: 2722.961 | AW4: 2725.009 | AX4: 2724.198 | AY4: 2766.634 | AZ4: 2847.098 | BA4: 2885.301 | BB4: 2877.876 | BC4: 2901.013 | BD4: 2776.337 | BE4: 2946.767 | BF4: 3099.813
A5: REST | B5: 3742.182 | C5: 3720.867 | D5: 3695.254 | E5: 3716.009 | F5: 3741.101 | G5: 3694.889 | H5: 3653.882 | I5: 3614.336 | J5: 3566.698 | K5: 3379.346 | L5: 3472.797 | M5: 3418.194 | N5: 3410.781 | O5: 3444.395 | P5: 3477.283 | Q5: 3356.998 | R5: 3400.968 | S5: 3394.252 | T5: 3445.565 | U5: 3514.7 | V5: 3625.889 | W5: 3568.13 | X5: 3517.672 | Y5: 3475.337 | Z5: 3434.81 | AA5: 3395.609 | AB5: 3413.744 | AC5: 3357.281 | AD5: 3342.697 | AE5: 3401.971 | AF5: 3431.762 | AG5: 3539.072 | AH5: 3632.582 | AI5: 3714.509 | AJ5: 3772.557 | AK5: 3824.171 | AL5: 3809.762 | AM5: 3776.588 | AN5: 3761.275 | AO5: 3814.54 | AP5: 3929.729 | AQ5: 3967.488 | AR5: 4018.058 | AS5: 3861.885 | AT5: 3790.107 | AU5: 3830.075 | AV5: 3769.454 | AW5: 3781.533 | AX5: 3776.795 | AY5: 3815.08 | AZ5: 3899.913 | BA5: 3935.591 | BB5: 3934.302 | BC5: 3972.38 | BD5: 3827.066 | BE5: 4062.261 | BF5: 4225.398

Sheet P
A1: ANVENDELSE | B1: 1967 | C1: 1968 | D1: 1969 | E1: 1970 | F1: 1971 | G1: 1972 | H1: 1973 | I1: 1974 | J1: 1975 | K1: 1976 | L1: 1977 | M1: 1978 | N1: 1979 | O1: 1980 | P1: 1981 | Q1: 1982 | R1: 1983 | S1: 1984 | T1: 1985 | U1: 1986 | V1: 1987 | W1: 1988 | X1: 1989 | Y1: 1990 | Z1: 1991 | AA1: 1992 | AB1: 1993 | AC1: 1994 | AD1: 1995 | AE1: 1996 | AF1: 1997 | AG1: 1998 | AH1: 1999 | AI1: 2000 | AJ1: 2001 | AK1: 2002 | AL1: 2003 | AM1: 2004 | AN1: 2005 | AO1: 2006 | AP1: 2007 | AQ1: 2008 | AR1: 2009 | AS1: 2010 | AT1: 2011 | AU1: 2012 | AV1: 2013 | AW1: 2014 | AX1: 2015 | AY1: 2016 | AZ1: 2017 | BA1: 2018 | BB1: 2019 | BC1: 2020 | BD1: 2021 | BE1: 2022
A2: 01000 | B2: 0.25607391 | C2: 0.25834004 | D2: 0.28105258 | E2: 0.30430121 | F2: 0.29811967 | G2: 0.3339359 | H2: 0.43052799 | I2: 0.44414889 | J2: 0.48715192 | K2: 0.5640882 | L2: 0.59514356 | M2: 0.6345172 | N2: 0.65096351 | O2: 0.72318177 | P2: 0.81190981 | Q2: 0.91041812 | R2: 0.95466565 | S2: 0.99197673 | T2: 0.98749151 | U2: 0.95475842 | V2: 0.95360648 | W2: 0.93289799 | X2: 0.97239892 | Y2: 0.90614873 | Z2: 0.89339057 | AA2: 0.9027064 | AB2: 0.80025435 | AC2: 0.80089488 | AD2: 0.83564746 | AE2: 0.84700116 | AF2: 0.84671658 | AG2: 0.75191861 | AH2: 0.73512719 | AI2: 0.80247949 | AJ2: 0.85718239 | AK2: 0.78091773 | AL2: 0.75515379 | AM2: 0.77755657 | AN2: 0.71833855 | AO2: 0.73132553 | AP2: 0.76268103 | AQ2: 0.83607121 | AR2: 0.79607803 | AS2: 0.84462464 | AT2: 0.94835462 | AU2: 1.0293523 | AV2: 0.9779207 | AW2: 0.93853411 | AX2: 0.86804807 | AY2: 0.8813666 | AZ2: 0.9560939 | BA2: 0.91154158 | BB2: 0.98517616 | BC2: 1 | BD2: 0.97836787 | BE2: 1.1755229
A3: 10120 | B3: 0.21736726 | C3: 0.21710019 | D3: 0.23343467 | E3: 0.25019141 | F3: 0.25792979 | G3: 0.27667241 | H3: 0.35413554 | I3: 0.38365037 | J3: 0.41428954 | K3: 0.45273991 | L3: 0.48772052 | M3: 0.51748751 | N3: 0.52452863 | O3: 0.57813656 | P3: 0.65156258 | Q3: 0.72420846 | R3: 0.74937649 | S3: 0.8071227 | T3: 0.80627525 | U3: 0.76773198 | V3: 0.75546495 | W3: 0.7647754 | X3: 0.81507702 | Y3: 0.7943401 | Z3: 0.79175995 | AA3: 0.8113854 | AB3: 0.75479964 | AC3: 0.76114401 | AD3: 0.76856146 | AE3: 0.78565486 | AF3: 0.79803586 | AG3: 0.75402237 | AH3: 0.73069725 | AI3: 0.78026275 | AJ3: 0.81970009 | AK3: 0.82018067 | AL3: 0.80459867 | AM3: 0.81073778 | AN3: 0.81833701 | AO3: 0.83200361 | AP3: 0.86051449 | AQ3: 0.92183343 | AR3: 0.88637583 | AS3: 0.91582157 | AT3: 0.95976415 | AU3: 0.99275846 | AV3: 1.0090947 | AW3: 0.98179215 | AX3: 0.96693149 | AY3: 0.97212259 | AZ3: 0.98167364 | BA3: 0.9721503 | BB3: 0.9972466 | BC3: 1 | BD3: 0.99145651 | BE3: 1.1472759
A4: Privat | B4: 0.13385216 | C4: 0.13861823 | D4: 0.14731478 | E4: 0.1590853 | F4: 0.1679589 | G4: 0.18036533 | H4: 0.20500282 | I4: 0.24010783 | J4: 0.26491165 | K4: 0.2875602 | L4: 0.31038809 | M4: 0.33191039 | N4: 0.35422797 | O4: 0.39293269 | P4: 0.44186123 | Q4: 0.48892587 | R4: 0.52199306 | S4: 0.55185749 | T4: 0.57285028 | U4: 0.56338293 | V4: 0.57271612 | W4: 0.58460042 | X4: 0.62083014 | Y4: 0.63107736 | Z4: 0.64476656 | AA4: 0.65310671 | AB4: 0.64842101 | AC4: 0.65986452 | AD4: 0.6722035 | AE4: 0.68180568 | AF4: 0.69630638 | AG4: 0.69489446 | AH4: 0.69990148 | AI4: 0.73354179 | AJ4: 0.75226471 | AK4: 0.75724342 | AL4: 0.76103765 | AM4: 0.77517331 | AN4: 0.79725781 | AO4: 0.81982154 | AP4: 0.84299682 | AQ4: 0.88342793 | AR4: 0.8611562 | AS4: 0.89703601 | AT4: 0.91765698 | AU4: 0.94171381 | AV4: 0.94899262 | AW4: 0.9512778 | AX4: 0.95218359 | AY4: 0.94081603 | AZ4: 0.96222829 | BA4: 0.97624078 | BB4: 0.99192193 | BC4: 1 | BD4: 1.051389 | BE4: 1.2068704
A5: REST | B5: 0.11367524 | C5: 0.11970203 | D5: 0.12712092 | E5: 0.1379434 | F5: 0.14817806 | G5: 0.15925596 | H5: 0.17599834 | I5: 0.21077905 | J5: 0.23578933 | K5: 0.2547441 | L5: 0.27537931 | M5: 0.29513295 | N5: 0.31843116 | O5: 0.35329295 | P5: 0.39662562 | Q5: 0.43949182 | R5: 0.47188153 | S5: 0.49739374 | T5: 0.51982296 | U5: 0.51672073 | V5: 0.53285898 | W5: 0.54884824 | X5: 0.58187566 | Y5: 0.59855472 | Z5: 0.61564213 | AA5: 0.62424257 | AB5: 0.62877082 | AC5: 0.64020326 | AD5: 0.65076452 | AE5: 0.66043461 | AF5: 0.67617658 | AG5: 0.68328877 | AH5: 0.69275442 | AI5: 0.72089398 | AJ5: 0.73839614 | AK5: 0.74851574 | AL5: 0.75647841 | AM5: 0.77184925 | AN5: 0.79589363 | AO5: 0.81825641 | AP5: 0.84085023 | AQ5: 0.87822555 | AR5: 0.86662997 | AS5: 0.89841806 | AT5: 0.91182114 | AU5: 0.93274208 | AV5: 0.94063557 | AW5: 0.94452562 | AX5: 0.94667601 | AY5: 0.93774849 | AZ5: 0.95693456 | BA5: 0.97344332 | BB5: 0.98632641 | BC5: 1 | BD5: 1.0496921 | BE5: 1.1875979

Sheet w
A1: ANVENDELSE | B1: 1966 | C1: 1967 | D1: 1968 | E1: 1969 | F1: 1970 | G1: 1971 | H1: 1972 | I1: 1973 | J1: 1974 | K1: 1975 | L1: 1976 | M1: 1977 | N1: 1978 | O1: 1979 | P1: 1980 | Q1: 1981 | R1: 1982 | S1: 1983 | T1: 1984 | U1: 1985 | V1: 1986 | W1: 1987 | X1: 1988 | Y1: 1989 | Z1: 1990 | AA1: 1991 | AB1: 1992 | AC1: 1993 | AD1: 1994 | AE1: 1995 | AF1: 1996 | AG1: 1997 | AH1: 1998 | AI1: 1999 | AJ1: 2000 | AK1: 2001 | AL1: 2002 | AM1: 2003 | AN1: 2004 | AO1: 2005 | AP1: 2006 | AQ1: 2007 | AR1: 2008 | AS1: 2009 | AT1: 2010 | AU1: 2011 | AV1: 2012 | AW1: 2013 | AX1: 2014 | AY1: 2015 | AZ1: 2016 | BA1: 2017 | BB1: 2018 | BC1: 2019 | BD1: 2020 | BE1: 2021 | BF1: 2022
A2: 01000 | B2: 4.9614659 | C2: 5.3261863 | D2: 5.6442061 | E2: 6.0123327 | F2: 5.8437461 | G2: 6.86028 | H2: 7.0786711 | I2: 7.9727202 | J2: 9.6403693 | K2: 11.505817 | L2: 12.853657 | M2: 14.346346 | N2: 16.749786 | O2: 19.344179 | P2: 22.662031 | Q2: 25.412391 | R2: 28.234244 | S2: 32.004413 | T2: 35.982725 | U2: 39.726702 | V2: 43.975964 | W2: 49.244809 | X2: 54.206254 | Y2: 57.809751 | Z2: 61.150908 | AA2: 62.964672 | AB2: 68.243047 | AC2: 70.472785 | AD2: 72.401971 | AE2: 73.668419 | AF2: 77.602928 | AG2: 82.112148 | AH2: 85.654427 | AI2: 87.363624 | AJ2: 90.147712 | AK2: 91.297341 | AL2: 97.14543 | AM2: 103.01562 | AN2: 108.39572 | AO2: 109.31073 | AP2: 113.52155 | AQ2: 120.93852 | AR2: 127.13193 | AS2: 132.90639 | AT2: 140.4119 | AU2: 143.61532 | AV2: 146.408 | AW2: 150.45915 | AX2: 156.52284 | AY2: 175.97839 | AZ2: 179.46352 | BA2: 182.14425 | BB2: 189.6717 | BC2: 197.71026 | BD2: 205.68694 | BE2: 203.39064 | BF2: 217.89115
A3: 10120 | B3: 10.642166 | C3: 11.953693 | D3: 13.270209 | E3: 14.817641 | F3: 16.770804 | G3: 19.7178 | H3: 22.357043 | I3: 26.961596 | J3: 32.740298 | K3: 40.098082 | L3: 44.334284 | M3: 49.171518 | N3: 54.381386 | O3: 60.086146 | P3: 65.502649 | Q3: 72.561179 | R3: 78.850417 | S3: 85.204956 | T3: 90.681675 | U3: 95.726497 | V3: 100.14818 | W3: 113.00424 | X3: 118.64512 | Y3: 124.33357 | Z3: 131.58692 | AA3: 136.4622 | AB3: 140.12418 | AC3: 142.0781 | AD3: 146.61712 | AE3: 147.38063 | AF3: 152.68933 | AG3: 157.86554 | AH3: 168.62299 | AI3: 166.71729 | AJ3: 171.25747 | AK3: 177.91464 | AL3: 186.38922 | AM3: 198.10179 | AN3: 204.59416 | AO3: 215.89704 | AP3: 225.25355 | AQ3: 239.9327 | AR3: 247.39118 | AS3: 252.65251 | AT3: 262.04289 | AU3: 260.51514 | AV3: 266.62836 | AW3: 271.5241 | AX3: 276.05941 | AY3: 277.41873 | AZ3: 294.32353 | BA3: 299.88461 | BB3: 309.84822 | BC3: 316.77175 | BD3: 314.17493 | BE3: 326.18735 | BF3: 333.34154
A4: Privat | B4: 10.312987 | C4: 11.600269 | D4: 12.969816 | E4: 14.721626 | F4: 16.4194 | G4: 18.753253 | H4: 21.059298 | I4: 24.725791 | J4: 29.597821 | K4: 35.416866 | L4: 39.478798 | M4: 44.582485 | N4: 49.837362 | O4: 55.340124 | P4: 61.534723 | Q4: 68.695138 | R4: 76.378325 | S4: 84.173787 | T4: 90.062285 | U4: 96.206133 | V4: 101.58234 | W4: 112.58822 | X4: 120.23263 | Y4: 127.26408 | Z4: 134.59333 | AA4: 139.67843 | AB4: 143.46638 | AC4: 146.42297 | AD4: 152.02628 | AE4: 155.80511 | AF4: 162.84915 | AG4: 166.34018 | AH4: 171.86196 | AI4: 175.10932 | AJ4: 178.99855 | AK4: 186.12955 | AL4: 194.66273 | AM4: 203.37372 | AN4: 209.0886 | AO4: 218.6608 | AP4: 226.92328 | AQ4: 240.6112 | AR4: 248.03532 | AS4: 256.06107 | AT4: 262.59157 | AU4: 264.19393 | AV4: 270.42136 | AW4: 272.95611 | AX4: 278.91267 | AY4: 286.52096 | AZ4: 287.36456 | BA4: 293.97478 | BB4: 305.19848 | BC4: 311.10504 | BD4: 327.95566 | BE4: 328.0687 | BF4: 336.69936
A5: REST | B5: 11.57843 | C5: 12.994332 | D5: 14.604469 | E5: 16.579907 | F5: 18.656783 | G5: 21.379339 | H5: 23.970374 | I5: 27.734018 | J5: 33.053165 | K5: 39.41599 | L5: 43.800474 | M5: 49.329405 | N5: 54.723886 | O5: 60.128075 | P5: 65.23713 | Q5: 72.806233 | R5: 81.366639 | S5: 88.756504 | T5: 94.018266 | U5: 99.506818 | V5: 103.77431 | W5: 114.86774 | X5: 123.04579 | Y5: 129.6554 | Z5: 136.01277 | AA5: 142.22567 | AB5: 146.13481 | AC5: 149.70152 | AD5: 155.14169 | AE5: 159.2887 | AF5: 166.92529 | AG5: 169.26072 | AH5: 174.44241 | AI5: 179.20911 | AJ5: 184.59864 | AK5: 191.2066 | AL5: 199.7988 | AM5: 207.22356 | AN5: 213.51149 | AO5: 220.49602 | AP5: 227.05593 | AQ5: 238.42066 | AR5: 247.31225 | AS5: 256.32685 | AT5: 263.39882 | AU5: 264.63435 | AV5: 271.6613 | AW5: 275.58602 | AX5: 281.98289 | AY5: 288.79274 | AZ5: 290.27159 | BA5: 296.43418 | BB5: 306.32276 | BC5: 311.95188 | BD5: 327.73115 | BE5: 327.71366 | BF5: 336.59787

Sheet P_K
A1: ANVENDELSE | B1: 1966 | C1: 1967 | D1: 1968 | E1: 1969 | F1: 1970 | G1: 1971 | H1: 1972 | I1: 1973 | J1: 1974 | K1: 1975 | L1: 1976 | M1: 1977 | N1: 1978 | O1: 1979 | P1: 1980 | Q1: 1981 | R1: 1982 | S1: 1983 | T1: 1984 | U1: 1985 | V1: 1986 | W1: 1987 | X1: 1988 | Y1: 1989 | Z1: 1990 | AA1: 1991 | AB1: 1992 | AC1: 1993 | AD1: 1994 | AE1: 1995 | AF1: 1996 | AG1: 1997 | AH1: 1998 | AI1: 1999 | AJ1: 2000 | AK1: 2001 | AL1: 2002 | AM1: 2003 | AN1: 2004 | AO1: 2005 | AP1: 2006 | AQ1: 2007 | AR1: 2008 | AS1: 2009 | AT1: 2010 | AU1: 2011 | AV1: 2012 | AW1: 2013 | AX1: 2014 | AY1: 2015 | AZ1: 2016 | BA1: 2017 | BB1: 2018 | BC1: 2019 | BD1: 2020 | BE1: 2021 | BF1: 2022 | BG1: 2023 | BH1: 2024
A2: 01000 | AD2: 0.060751278 | AE2: 0.069791081 | AF2: 0.085026536 | AG2: 0.070368963 | AH2: 0.067863342 | AI2: 0.088871606 | AJ2: 0.062415609 | AK2: 0.056085129 | AL2: 0.059875374 | AM2: 0.063636068 | AN2: 0.070909567 | AO2: 0.045636799 | AP2: 0.063955834 | AQ2: 0.052150347 | AR2: 0.066197293 | AS2: 0.072959482 | AT2: 0.074747652 | AU2: 0.074345659 | AV2: 0.055688748 | AW2: 0.06165053 | AX2: 0.058095357 | AY2: 0.056166675 | AZ2: 0.046997512 | BA2: 0.063610903 | BB2: 0.093953035 | BC2: 0.069468615 | BD2: 0.068133568 | BE2: 0.10072659 | BF2: 0.065872729
A3: 10120 | AD3: 0.10203538 | AE3: 0.10777479 | AF3: 0.11877328 | AG3: 0.11164507 | AH3: 0.10658308 | AI3: 0.0963468 | AJ3: 0.11085744 | AK3: 0.086690043 | AL3: 0.093857836 | AM3: 0.09654273 | AN3: 0.10400685 | AO3: 0.083365909 | AP3: 0.10278033 | AQ3: 0.074265195 | AR3: 0.098188281 | AS3: 0.10325658 | AT3: 0.10760116 | AU3: 0.10489538 | AV3: 0.095932698 | AW3: 0.095640066 | AX3: 0.078553793 | AY3: 0.07951904 | AZ3: 0.077908112 | BA3: 0.094663324 | BB3: 0.095160056 | BC3: 0.083019975 | BD3: 0.083904178 | BE3: 0.086398922 | BF3: 0.082330124
A4: Privat | AD4: 0.086433793 | AE4: 0.094132987 | AF4: 0.094800995 | AG4: 0.097947835 | AH4: 0.093258046 | AI4: 0.090793286 | AJ4: 0.085624726 | AK4: 0.075434044 | AL4: 0.080025935 | AM4: 0.082903004 | AN4: 0.086110743 | AO4: 0.072018317 | AP4: 0.081504575 | AQ4: 0.066056071 | AR4: 0.080667379 | AS4: 0.099280284 | AT4: 0.097714354 | AU4: 0.088841726 | AV4: 0.078334472 | AW4: 0.082724478 | AX4: 0.083205545 | AY4: 0.078723432 | AZ4: 0.072903316 | BA4: 0.080126154 | BB4: 0.082995408 | BC4: 0.081217804 | BD4: 0.083883584 | BE4: 0.082905144 | BF4: 0.063548345
A5: REST | AD5: 0.089550877 | AE5: 0.095563278 | AF5: 0.093422145 | AG5: 0.094739862 | AH5: 0.091017427 | AI5: 0.087634851 | AJ5: 0.083132466 | AK5: 0.073182359 | AL5: 0.07897033 | AM5: 0.082359985 | AN5: 0.085365409 | AO5: 0.071647686 | AP5: 0.08076912 | AQ5: 0.066085404 | AR5: 0.081532434 | AS5: 0.098867346 | AT5: 0.098193075 | AU5: 0.090370048 | AV5: 0.080607895 | AW5: 0.085510326 | AX5: 0.08566152 | AY5: 0.081148775 | AZ5: 0.075072538 | BA5: 0.080983122 | BB5: 0.082669874 | BC5: 0.080932536 | BD5: 0.084380497 | BE5: 0.082775737 | BF5: 0.063257686

Sheet KL
A1: ANVENDELSE | B1: 1994 | C1: 1995 | D1: 1996 | E1: 1997 | F1: 1998 | G1: 1999 | H1: 2000 | I1: 2001 | J1: 2002 | K1: 2003 | L1: 2004 | M1: 2005 | N1: 2006 | O1: 2007 | P1: 2008 | Q1: 2009 | R1: 2010 | S1: 2011 | T1: 2012 | U1: 2013 | V1: 2014 | W1: 2015 | X1: 2016 | Y1: 2017 | Z1: 2018 | AA1: 2019 | AB1: 2020 | AC1: 2021 | AD1: 2022
A2: 01000 | B2: 52117.794 | C2: 50900.442 | D2: 49681.538 | E2: 48143.426 | F2: 47708.981 | G2: 46314.405 | H2: 45117.473 | I2: 44432.633 | J2: 44480.111 | K2: 42600.847 | L2: 42241.35 | M2: 40925.503 | N2: 39424.938 | O2: 39026.41 | P2: 38328.713 | Q2: 37355.83 | R2: 36543.067 | S2: 35879.711 | T2: 35222.069 | U2: 34756.946 | V2: 34683.366 | W2: 34775.854 | X2: 33362.229 | Y2: 33300.801 | Z2: 32593.134 | AA2: 31418.74 | AB2: 31265.505 | AC2: 31288.388 | AD2: 30691.04
A3: 10120 | B3: 41053.802 | C3: 41759.501 | D3: 41128.759 | E3: 40942.503 | F3: 40365.296 | G3: 40787.837 | H3: 41003.31 | I3: 41301.986 | J3: 41472.717 | K3: 40135.482 | L3: 39397.689 | M3: 37857.534 | N3: 36744.013 | O3: 35523.214 | P3: 35229.502 | Q3: 33872.477 | R3: 33070.653 | S3: 32127.489 | T3: 31029.396 | U3: 30326.43 | V3: 29083.172 | W3: 28650.367 | X3: 28823.509 | Y3: 29246.826 | Z3: 28738.801 | AA3: 28997.102 | AB3: 30557.868 | AC3: 30574.44 | AD3: 30523.704
A4: Privat | B4: 1225407.7 | C4: 1242795.7 | D4: 1255462.1 | E4: 1277006.2 | F4: 1301906 | G4: 1330330.8 | H4: 1356944.2 | I4: 1375790.7 | J4: 1380125.2 | K4: 1371087.4 | L4: 1374650.5 | M4: 1386943.9 | N4: 1416927.3 | O4: 1442726.8 | P4: 1463823.9 | Q4: 1412634.3 | R4: 1394308 | S4: 1408259.2 | T4: 1395263.5 | U4: 1397199.9 | V4: 1399261.9 | W4: 1416234.5 | X4: 1446856.2 | Y4: 1466272.9 | Z4: 1472584.5 | AA4: 1489320.8 | AB4: 1455978.1 | AC4: 1519428.8 | AD4: 1581749.9
A5: REST | B5: 1527969.9 | C5: 1546477.3 | D5: 1561291.6 | E5: 1596610.2 | F5: 1630908.7 | G5: 1664171.9 | H5: 1689272.5 | I5: 1715552.3 | J5: 1720985.9 | K5: 1719611.2 | L5: 1722950.2 | M5: 1745689.9 | N5: 1789467.5 | O5: 1815573.7 | P5: 1843060 | Q5: 1805786.2 | R5: 1790700.5 | S5: 1804084.2 | T5: 1787836.6 | U5: 1794529.7 | V5: 1796799.1 | W5: 1814378.2 | X5: 1848027 | Y5: 1868512.6 | Z5: 1878314 | AA5: 1901400.2 | AB5: 1862622.6 | AC5: 1949504.5 | AD5: 2016873.8

Sheet JKL
A1: ANVENDELSE | B1: 1994 | C1: 1995 | D1: 1996 | E1: 1997 | F1: 1998 | G1: 1999 | H1: 2000 | I1: 2001 | J1: 2002 | K1: 2003 | L1: 2004 | M1: 2005 | N1: 2006 | O1: 2007 | P1: 2008 | Q1: 2009 | R1: 2010 | S1: 2011 | T1: 2012 | U1: 2013 | V1: 2014 | W1: 2015 | X1: 2016 | Y1: 2017 | Z1: 2018 | AA1: 2019 | AB1: 2020 | AC1: 2021 | AD1: 2022
A2: 01000 | B2: 39615.423 | C2: 38703.353 | D2: 37843.795 | E2: 36756.849 | F2: 36466.9 | G2: 35429.093 | H2: 34504.781 | I2: 34006.56 | J2: 34046.776 | K2: 32626.197 | L2: 32344.644 | M2: 31282.764 | N2: 29799.95 | O2: 29463.372 | P2: 28938.182 | Q2: 28443.2 | R2: 27834.982 | S2: 27251.991 | T2: 26664.953 | U2: 26233.149 | V2: 26206.615 | W2: 26195.87 | X2: 25089.115 | Y2: 24975.354 | Z2: 24306.916 | AA2: 23237.553 | AB2: 23089.686 | AC2: 23204.748 | AD2: 22673.607
A3: 10120 | B3: 0 | C3: 0 | D3: 0 | E3: 0 | F3: 0 | G3: 0 | H3: 0 | I3: 0 | J3: 0 | K3: 0 | L3: 0 | M3: 0 | N3: 0 | O3: 0 | P3: 0 | Q3: 0 | R3: 0 | S3: 0 | T3: 0 | U3: 0 | V3: 0 | W3: 0 | X3: 0 | Y3: 0 | Z3: 0 | AA3: 0 | AB3: 0 | AC3: 0 | AD3: 0
A4: REST | B4: 0 | C4: 0 | D4: 0 | E4: 0 | F4: 0 | G4: 0 | H4: 0 | I4: 0 | J4: 0 | K4: 0 | L4: 0 | M4: 0 | N4: 0 | O4: 0 | P4: 0 | Q4: 0 | R4: 0 | S4: 0 | T4: 0 | U4: 0 | V4: 0 | W4: 0 | X4: 0 | Y4: 0 | Z4: 0 | AA4: 0 | AB4: 0 | AC4: 0 | AD4: 0

Sheet P_KL
A1: ANVENDELSE | B1: 1994 | C1: 1995 | D1: 1996 | E1: 1997 | F1: 1998 | G1: 1999 | H1: 2000 | I1: 2001 | J1: 2002 | K1: 2003 | L1: 2004 | M1: 2005 | N1: 2006 | O1: 2007 | P1: 2008 | Q1: 2009 | R1: 2010 | S1: 2011 | T1: 2012 | U1: 2013 | V1: 2014 | W1: 2015 | X1: 2016 | Y1: 2017 | Z1: 2018 | AA1: 2019 | AB1: 2020 | AC1: 2021 | AD1: 2022
A2: 01000 | B2: 0.5694121 | C2: 0.62035501 | D2: 0.71346775 | E2: 0.65078662 | F2: 0.64940884 | G2: 0.76888134 | H2: 0.63509005 | I2: 0.60434501 | J2: 0.64413311 | K2: 0.68386032 | L2: 0.74184557 | M2: 0.59880691 | N2: 0.7204948 | O2: 0.67093704 | P2: 0.77635834 | Q2: 0.83598365 | R2: 0.86793431 | S2: 0.87398331 | T2: 0.76017118 | U2: 0.80984611 | V2: 0.80380746 | W2: 0.84621455 | X2: 0.79660741 | Y2: 0.90949967 | Z2: 1.1242478 | AA2: 0.98676346 | AB2: 1 | AC2: 1.1984003 | AD2: 1.0173887
A3: 10120 | B3: 0.63115103 | C3: 0.64443612 | D3: 0.6816428 | E3: 0.68202981 | F3: 0.70220843 | G3: 0.67554531 | H3: 0.7184454 | I3: 0.68647991 | J3: 0.72568847 | K3: 0.76404035 | L3: 0.79923661 | M3: 0.77670287 | N3: 0.8516072 | O3: 0.81207128 | P3: 0.89659224 | Q3: 0.92442524 | R3: 0.96034766 | S3: 0.94828548 | T3: 0.93424129 | U3: 0.94465941 | V3: 0.8967559 | W3: 0.90316668 | X3: 0.93621212 | Y3: 1.0050415 | Z3: 1.0293892 | AA3: 1.0030241 | AB3: 1 | AC3: 1.0358694 | AD3: 1.0386862
A4: Privat | B4: 0.65065849 | C4: 0.68776721 | D4: 0.70530553 | E4: 0.72462162 | F4: 0.71885117 | G4: 0.71659641 | H4: 0.70572373 | I4: 0.68278241 | J4: 0.71839964 | K4: 0.74781135 | L4: 0.77227612 | M4: 0.73640233 | N4: 0.79081995 | O4: 0.75790761 | P4: 0.83148031 | Q4: 0.92568895 | R4: 0.93170036 | S4: 0.89711719 | T4: 0.86414799 | U4: 0.88796288 | V4: 0.90163304 | W4: 0.8972773 | X4: 0.87428376 | Y4: 0.91788668 | Z4: 0.95211704 | AA4: 0.95596257 | AB4: 1 | AC4: 0.99597384 | AD4: 0.93045813
A5: REST | B5: 0.64426937 | C5: 0.67373434 | D5: 0.68326909 | E5: 0.69286435 | F5: 0.69199508 | G5: 0.69138756 | H5: 0.68846437 | I5: 0.67004359 | J5: 0.708581 | K5: 0.73646721 | L5: 0.76056082 | M5: 0.72857669 | N5: 0.77409188 | O5: 0.74840172 | P5: 0.82122482 | Q5: 0.90265454 | R5: 0.91516668 | S5: 0.88942961 | T5: 0.86843753 | U5: 0.89470878 | V5: 0.90871245 | W5: 0.90639536 | X5: 0.88728105 | Y5: 0.92198246 | Z5: 0.94896591 | AA5: 0.95423242 | AB5: 1 | AC5: 0.99393303 | AD5: 0.94007068

Sheet P_JKL
A1: ANVENDELSE | B1: 1994 | C1: 1995 | D1: 1996 | E1: 1997 | F1: 1998 | G1: 1999 | H1: 2000 | I1: 2001 | J1: 2002 | K1: 2003 | L1: 2004 | M1: 2005 | N1: 2006 | O1: 2007 | P1: 2008 | Q1: 2009 | R1: 2010 | S1: 2011 | T1: 2012 | U1: 2013 | V1: 2014 | W1: 2015 | X1: 2016 | Y1: 2017 | Z1: 2018 | AA1: 2019 | AB1: 2020 | AC1: 2021 | AD1: 2022
A2: 01000 | B2: 0.78955065 | C2: 0.86603523 | D2: 0.98633788 | E2: 0.89070213 | F2: 0.87230866 | G2: 1.0602147 | H2: 0.89728176 | I2: 0.81573364 | J2: 0.85435782 | K2: 0.85378233 | L2: 0.9207597 | M2: 0.6713107 | N2: 0.89180965 | O2: 0.92796618 | P2: 1.1712725 | Q2: 1.1292171 | R2: 1.0266244 | S2: 1.0203331 | T2: 0.76705998 | U2: 0.81458429 | V2: 0.82163463 | W2: 0.86560481 | X2: 0.78623653 | Y2: 0.93580081 | Z2: 1.1852182 | AA2: 0.99639826 | AB2: 1 | AC2: 1.2943497 | AD2: 1.1943897
A3: 10120 | B3: 0.91204468 | C3: 0.94214976 | D3: 0.99038459 | E3: 0.97438183 | F3: 0.98142971 | G3: 0.98264568 | H3: 1.0548166 | I3: 0.96482557 | J3: 1.0033153 | K3: 0.99748008 | L3: 1.035665 | M3: 0.93453306 | N3: 1.1041385 | O3: 1.1661255 | P3: 1.4004694 | Q3: 1.3002981 | R3: 1.1830881 | S3: 1.1499318 | T3: 1.0084345 | U3: 1.0009334 | V3: 0.95270531 | W3: 0.94581899 | X3: 0.97567968 | Y3: 1.0703929 | Z3: 1.0588539 | AA3: 1.0189032 | AB3: 1 | AC3: 1.0764477 | AD3: 1.2266574
A4: Privat | B4: 0.65589992 | C4: 0.69353212 | D4: 0.71111879 | E4: 0.73016093 | F4: 0.72388762 | G4: 0.72246915 | H4: 0.71183593 | I4: 0.6877213 | J4: 0.72323068 | K4: 0.75157125 | L4: 0.77598231 | M4: 0.73846947 | N4: 0.79448832 | O4: 0.7634618 | P4: 0.8395602 | Q4: 0.93189817 | R4: 0.93504293 | S4: 0.89997427 | T4: 0.86482615 | U4: 0.88843922 | V4: 0.90247473 | W4: 0.89786349 | X4: 0.87450514 | Y4: 0.91833838 | Z4: 0.95212152 | AA4: 0.9559423 | AB4: 1 | AC4: 0.99636431 | AD4: 0.93260223
A5: REST | B5: 0.64831935 | C5: 0.67816131 | D5: 0.68769376 | E5: 0.69702119 | F5: 0.69577508 | G5: 0.69584333 | H5: 0.69315252 | I5: 0.67381809 | J5: 0.71227713 | K5: 0.73929888 | L5: 0.76334433 | M5: 0.73008331 | N5: 0.77681478 | O5: 0.75266041 | P5: 0.8274733 | Q5: 0.90737988 | R5: 0.91769339 | S5: 0.89161937 | T5: 0.86898565 | U5: 0.89511152 | V5: 0.9094009 | W5: 0.90689417 | X5: 0.8875119 | Y5: 0.92235433 | Z5: 0.94895569 | AA5: 0.95420896 | AB5: 1 | AC5: 0.9942285 | AD5: 0.94178693

Sheet P_O
A1: ANVENDELSE | B1: 1967 | C1: 1968 | D1: 1969 | E1: 1970 | F1: 1971 | G1: 1972 | H1: 1973 | I1: 1974 | J1: 1975 | K1: 1976 | L1: 1977 | M1: 1978 | N1: 1979 | O1: 1980 | P1: 1981 | Q1: 1982 | R1: 1983 | S1: 1984 | T1: 1985 | U1: 1986 | V1: 1987 | W1: 1988 | X1: 1989 | Y1: 1990 | Z1: 1991 | AA1: 1992 | AB1: 1993 | AC1: 1994 | AD1: 1995 | AE1: 1996 | AF1: 1997 | AG1: 1998 | AH1: 1999 | AI1: 2000 | AJ1: 2001 | AK1: 2002 | AL1: 2003 | AM1: 2004 | AN1: 2005 | AO1: 2006 | AP1: 2007 | AQ1: 2008 | AR1: 2009 | AS1: 2010 | AT1: 2011 | AU1: 2012 | AV1: 2013 | AW1: 2014 | AX1: 2015 | AY1: 2016 | AZ1: 2017 | BA1: 2018 | BB1: 2019 | BC1: 2020 | BD1: 2021 | BE1: 2022
A2: 01000 | AC2: 0.92524062 | AD2: 0.93772332 | AE2: 0.98915716 | AF2: 0.92829362 | AG2: 0.88676803 | AH2: 0.96471811 | AI2: 0.87678264 | AJ2: 0.84788308 | AK2: 0.88567324 | AL2: 0.85774934 | AM2: 0.88385955 | AN2: 0.79290526 | AO2: 0.86489302 | AP2: 0.88708999 | AQ2: 1.1287624 | AR2: 1.0705243 | AS2: 0.97383911 | AT2: 1.0399151 | AU2: 0.93485053 | AV2: 0.98230049 | AW2: 0.91504954 | AX2: 0.96403101 | AY2: 0.93123881 | AZ2: 0.94549997 | BA2: 1.0401406 | BB2: 0.95888405 | BC2: 0.95011224 | BD2: 1.0617468 | BE2: 1.206521
A3: 10120 | AC3: 0.7590511 | AD3: 0.76436305 | AE3: 0.7912604 | AF3: 0.78702307 | AG3: 0.75315257 | AH3: 0.71766984 | AI3: 0.77244161 | AJ3: 0.793133 | AK3: 0.7874137 | AL3: 0.7827383 | AM3: 0.79172534 | AN3: 0.78806174 | AO3: 0.82780204 | AP3: 0.84472724 | AQ3: 0.92554372 | AR3: 0.88718743 | AS3: 0.93000776 | AT3: 0.9767265 | AU3: 1.0080666 | AV3: 1.0135364 | AW3: 0.96639152 | AX3: 0.93782514 | AY3: 0.93949328 | AZ3: 0.9821566 | BA3: 0.96966514 | BB3: 0.97890271 | BC3: 0.99606609 | BD3: 0.99767844 | BE3: 1.1414728
A4: Privat | AC4: 0.71094284 | AD4: 0.73427929 | AE4: 0.7407833 | AF4: 0.75042651 | AG4: 0.74374692 | AH4: 0.73628051 | AI4: 0.72733982 | AJ4: 0.72521752 | AK4: 0.74520905 | AL4: 0.75454441 | AM4: 0.76330345 | AN4: 0.74743943 | AO4: 0.77369027 | AP4: 0.76861228 | AQ4: 0.82967868 | AR4: 0.87808036 | AS4: 0.8836848 | AT4: 0.87468872 | AU4: 0.86521771 | AV4: 0.87318059 | AW4: 0.8737278 | AX4: 0.86610098 | AY4: 0.84180978 | AZ4: 0.86318278 | BA4: 0.87924676 | BB4: 0.88438824 | BC4: 0.90500792 | BD4: 0.9160714 | BE4: 0.96720873
A5: REST | AC5: 0.7057984 | AD5: 0.72574698 | AE5: 0.72504734 | AF5: 0.7327866 | AG5: 0.73262498 | AH5: 0.72823588 | AI5: 0.71969739 | AJ5: 0.71728543 | AK5: 0.74161575 | AL5: 0.75578295 | AM5: 0.76583913 | AN5: 0.75151286 | AO5: 0.77685084 | AP5: 0.77171361 | AQ5: 0.8296781 | AR5: 0.882758 | AS5: 0.89049336 | AT5: 0.87885849 | AU5: 0.87111062 | AV5: 0.88248225 | AW5: 0.88525134 | AX5: 0.87666938 | AY5: 0.85561958 | AZ5: 0.87477421 | BA5: 0.89001986 | BB5: 0.89564472 | BC5: 0.92318125 | BD5: 0.93329443 | BE5: 0.97364624

Sheet mu_Y_Mtot
A1: ANVENDELSE | B1: 1967 | C1: 1968 | D1: 1969 | E1: 1970 | F1: 1971 | G1: 1972 | H1: 1973 | I1: 1974 | J1: 1975 | K1: 1976 | L1: 1977 | M1: 1978 | N1: 1979 | O1: 1980 | P1: 1981 | Q1: 1982 | R1: 1983 | S1: 1984 | T1: 1985 | U1: 1986 | V1: 1987 | W1: 1988 | X1: 1989 | Y1: 1990 | Z1: 1991 | AA1: 1992 | AB1: 1993 | AC1: 1994 | AD1: 1995 | AE1: 1996 | AF1: 1997 | AG1: 1998 | AH1: 1999 | AI1: 2000 | AJ1: 2001 | AK1: 2002 | AL1: 2003 | AM1: 2004 | AN1: 2005 | AO1: 2006 | AP1: 2007 | AQ1: 2008 | AR1: 2009 | AS1: 2010 | AT1: 2011 | AU1: 2012 | AV1: 2013 | AW1: 2014 | AX1: 2015 | AY1: 2016 | AZ1: 2017 | BA1: 2018 | BB1: 2019 | BC1: 2020 | BD1: 2021 | BE1: 2022
A2: 01000 | AC2: 0.45414116 | AD2: 0.43400665 | AE2: 0.40894357 | AF2: 0.46417701 | AG2: 0.46070302 | AH2: 0.41038295 | AI2: 0.48475435 | AJ2: 0.52385073 | AK2: 0.5248715 | AL2: 0.53651836 | AM2: 0.52412548 | AN2: 0.63416985 | AO2: 0.57322389 | AP2: 0.60233316 | AQ2: 0.55948612 | AR2: 0.56008225 | AS2: 0.60904474 | AT2: 0.63696714 | AU2: 0.73702743 | AV2: 0.72774015 | AW2: 0.72959801 | AX2: 0.71038997 | AY2: 0.73164458 | AZ2: 0.6989695 | BA2: 0.64431851 | BB2: 0.70270546 | BC2: 0.70899326 | BD2: 0.66069438 | BE2: 0.74293967
A3: 10120 | AC3: 0.77589329 | AD3: 0.76936169 | AE3: 0.75248058 | AF3: 0.76000868 | AG3: 0.74782283 | AH3: 0.74383635 | AI3: 0.74402406 | AJ3: 0.77245109 | AK3: 0.74922433 | AL3: 0.73931027 | AM3: 0.74153255 | AN3: 0.76885392 | AO3: 0.75707102 | AP3: 0.78123768 | AQ3: 0.77589629 | AR3: 0.75450205 | AS3: 0.75498555 | AT3: 0.78209796 | AU3: 0.79794094 | AV3: 0.8054627 | AW3: 0.81896214 | AX3: 0.80999433 | AY3: 0.80393362 | AZ3: 0.80511985 | BA3: 0.7974915 | BB3: 0.81134123 | BC3: 0.81085545 | BD3: 0.8139524 | BE3: 0.85757837
A4: Privat | AC4: 0.4370405 | AD4: 0.4352628 | AE4: 0.43699385 | AF4: 0.44034543 | AG4: 0.44667757 | AH4: 0.45692101 | AI4: 0.48385541 | AJ4: 0.5102425 | AK4: 0.49843252 | AL4: 0.48796497 | AM4: 0.48889324 | AN4: 0.5355288 | AO4: 0.53372851 | AP4: 0.56624203 | AQ4: 0.54948607 | AR4: 0.48824954 | AS4: 0.49779459 | AT4: 0.53039756 | AU4: 0.55653184 | AV4: 0.54652732 | AW4: 0.54776663 | AX4: 0.55108943 | AY4: 0.5624336 | AZ4: 0.55914485 | BA4: 0.55786796 | BB4: 0.56199852 | BC4: 0.54622088 | BD4: 0.57110938 | BE4: 0.6355895
A5: REST | AC5: 0.36438664 | AD5: 0.36957826 | AE5: 0.37797029 | AF5: 0.3839362 | AG5: 0.3914995 | AH5: 0.40549476 | AI5: 0.42922165 | AJ5: 0.45310905 | AK5: 0.44175933 | AL5: 0.43083422 | AM5: 0.43258349 | AN5: 0.47643655 | AO5: 0.47766379 | AP5: 0.50666573 | AQ5: 0.48985628 | AR5: 0.43514616 | AS5: 0.44044834 | AT5: 0.46613933 | AU5: 0.488238 | AV5: 0.47575799 | AW5: 0.47922175 | AX5: 0.48417518 | AY5: 0.4953228 | AZ5: 0.49436442 | BA5: 0.4962463 | BB5: 0.49903226 | BC5: 0.4823802 | BD5: 0.50683068 | BE5: 0.56397803

Sheet mu_Y_KL
A1: ANVENDELSE | B1: 1967 | C1: 1968 | D1: 1969 | E1: 1970 | F1: 1971 | G1: 1972 | H1: 1973 | I1: 1974 | J1: 1975 | K1: 1976 | L1: 1977 | M1: 1978 | N1: 1979 | O1: 1980 | P1: 1981 | Q1: 1982 | R1: 1983 | S1: 1984 | T1: 1985 | U1: 1986 | V1: 1987 | W1: 1988 | X1: 1989 | Y1: 1990 | Z1: 1991 | AA1: 1992 | AB1: 1993 | AC1: 1994 | AD1: 1995 | AE1: 1996 | AF1: 1997 | AG1: 1998 | AH1: 1999 | AI1: 2000 | AJ1: 2001 | AK1: 2002 | AL1: 2003 | AM1: 2004 | AN1: 2005 | AO1: 2006 | AP1: 2007 | AQ1: 2008 | AR1: 2009 | AS1: 2010 | AT1: 2011 | AU1: 2012 | AV1: 2013 | AW1: 2014 | AX1: 2015 | AY1: 2016 | AZ1: 2017 | BA1: 2018 | BB1: 2019 | BC1: 2020 | BD1: 2021 | BE1: 2022
A2: 01000 | AC2: 0.40268249 | AD2: 0.42657259 | AE2: 0.46227532 | AF2: 0.42035188 | AG2: 0.43496845 | AH2: 0.47125737 | AI2: 0.39840387 | AJ2: 0.38901682 | AK2: 0.39419658 | AL2: 0.42469414 | AM2: 0.44485468 | AN2: 0.38291143 | AO2: 0.41115854 | AP2: 0.34291141 | AQ2: 0.32221644 | AR2: 0.36879275 | AS2: 0.4068457 | AT2: 0.37725609 | AU2: 0.34679693 | AV2: 0.35306544 | AW2: 0.36460394 | AX2: 0.37059619 | AY2: 0.35374517 | AZ2: 0.39230259 | BA2: 0.45230886 | BB2: 0.41599091 | BC2: 0.41509092 | BD2: 0.44294077 | BE2: 0.3017816
