Workbook

Sheet Figurer
B2: Ratioer
B3: Kapital-output-ratio (K/Y) | C3: 1993 | D3: 1994 | E3: 1995 | F3: 1996 | G3: 1997 | H3: 1998 | I3: 1999 | J3: 2000 | K3: 2001 | L3: 2002 | M3: 2003 | N3: 2004 | O3: 2005 | P3: 2006 | Q3: 2007 | R3: 2008 | S3: 2009 | T3: 2010 | U3: 2011 | V3: 2012 | W3: 2013 | X3: 2014 | Y3: 2015 | Z3: 2016 | AA3: 2017 | AB3: 2018 | AC3: 2019 | AD3: 2020 | AE3: 2021 | AF3: 2022
B4: Landbrug | C4: =K!AC2/Y!AB2 | D4: =K!AD2/Y!AC2 | E4: =K!AE2/Y!AD2 | F4: =K!AF2/Y!AE2 | G4: =K!AG2/Y!AF2 | H4: =K!AH2/Y!AG2 | I4: =K!AI2/Y!AH2 | J4: =K!AJ2/Y!AI2 | ... AF4: =K!BF2/Y!BE2
B5: Føde- drikke og tobaksvareindustri | C5: =K!AC3/Y!AB3 | D5: =K!AD3/Y!AC3 | E5: =K!AE3/Y!AD3 | F5: =K!AF3/Y!AE3 | G5: =K!AG3/Y!AF3 | H5: =K!AH3/Y!AG3 | I5: =K!AI3/Y!AH3 | J5: =K!AJ3/Y!AI3 | ... AF5: =K!BF3/Y!BE3
B6: Resten af økonomien | C6: =K!AC4/Y!AB4 | D6: =K!AD4/Y!AC4 | E6: =K!AE4/Y!AD4 | F6: =K!AF4/Y!AE4 | G6: =K!AG4/Y!AF4 | H6: =K!AH4/Y!AG4 | I6: =K!AI4/Y!AH4 | J6: =K!AJ4/Y!AI4 | ... AF6: =K!BF4/Y!BE4
B8: Arbejdskraft-output-ratio (L/Y) | C8: 1993 | D8: 1994 | E8: 1995 | F8: 1996 | G8: 1997 | H8: 1998 | I8: 1999 | J8: 2000 | K8: 2001 | L8: 2002 | M8: 2003 | N8: 2004 | O8: 2005 | P8: 2006 | Q8: 2007 | R8: 2008 | S8: 2009 | T8: 2010 | U8: 2011 | V8: 2012 | W8: 2013 | X8: 2014 | Y8: 2015 | Z8: 2016 | AA8: 2017 | AB8: 2018 | AC8: 2019 | AD8: 2020 | AE8: 2021 | AF8: 2022
B9: Landbrug | C9: =L!AC2/Y!AB2 | D9: =L!AD2/Y!AC2 | E9: =L!AE2/Y!AD2 | F9: =L!AF2/Y!AE2 | G9: =L!AG2/Y!AF2 | H9: =L!AH2/Y!AG2 | I9: =L!AI2/Y!AH2 | J9: =L!AJ2/Y!AI2 | ... AF9: =L!BF2/Y!BE2
B10: Føde- drikke og tobaksvareindustri | C10: =L!AC3/Y!AB3 | D10: =L!AD3/Y!AC3 | E10: =L!AE3/Y!AD3 | F10: =L!AF3/Y!AE3 | G10: =L!AG3/Y!AF3 | H10: =L!AH3/Y!AG3 | I10: =L!AI3/Y!AH3 | J10: =L!AJ3/Y!AI3 | ... AF10: =L!BF3/Y!BE3
B11: Resten af økonomien | C11: =L!AC4/Y!AB4 | D11: =L!AD4/Y!AC4 | E11: =L!AE4/Y!AD4 | F11: =L!AF4/Y!AE4 | G11: =L!AG4/Y!AF4 | H11: =L!AH4/Y!AG4 | I11: =L!AI4/Y!AH4 | J11: =L!AJ4/Y!AI4 | ... AF11: =L!BF4/Y!BE4
B13: Materiale-output-ratio (Mtot/Y) | C13: 1993 | D13: 1994 | E13: 1995 | F13: 1996 | G13: 1997 | H13: 1998 | I13: 1999 | J13: 2000 | K13: 2001 | L13: 2002 | M13: 2003 | N13: 2004 | O13: 2005 | P13: 2006 | Q13: 2007 | R13: 2008 | S13: 2009 | T13: 2010 | U13: 2011 | V13: 2012 | W13: 2013 | X13: 2014 | Y13: 2015 | Z13: 2016 | AA13: 2017 | AB13: 2018 | AC13: 2019 | AD13: 2020 | AE13: 2021 | AF13: 2022
B14: Landbrug | C14: =Mtot!AB2/Y!AB2 | D14: =Mtot!AC2/Y!AC2 | E14: =Mtot!AD2/Y!AD2 | F14: =Mtot!AE2/Y!AE2 | G14: =Mtot!AF2/Y!AF2 | H14: =Mtot!AG2/Y!AG2 | I14: =Mtot!AH2/Y!AH2 | J14: =Mtot!AI2/Y!AI2 | ... AF14: =Mtot!BE2/Y!BE2
B15: Føde- drikke og tobaksvareindustri | C15: =Mtot!AB3/Y!AB3 | D15: =Mtot!AC3/Y!AC3 | E15: =Mtot!AD3/Y!AD3 | F15: =Mtot!AE3/Y!AE3 | G15: =Mtot!AF3/Y!AF3 | H15: =Mtot!AG3/Y!AG3 | I15: =Mtot!AH3/Y!AH3 | J15: =Mtot!AI3/Y!AI3 | ... AF15: =Mtot!BE3/Y!BE3
B16: Resten af økonomien | C16: =Mtot!AB4/Y!AB4 | D16: =Mtot!AC4/Y!AC4 | E16: =Mtot!AD4/Y!AD4 | F16: =Mtot!AE4/Y!AE4 | G16: =Mtot!AF4/Y!AF4 | H16: =Mtot!AG4/Y!AG4 | I16: =Mtot!AH4/Y!AH4 | J16: =Mtot!AI4/Y!AI4 | ... AF16: =Mtot!BE4/Y!BE4
B18: Kapital pr arbejdstime (K/L) | C18: 1993 | D18: 1994 | E18: 1995 | F18: 1996 | G18: 1997 | H18: 1998 | I18: 1999 | J18: 2000 | K18: 2001 | L18: 2002 | M18: 2003 | N18: 2004 | O18: 2005 | P18: 2006 | Q18: 2007 | R18: 2008 | S18: 2009 | T18: 2010 | U18: 2011 | V18: 2012 | W18: 2013 | X18: 2014 | Y18: 2015 | Z18: 2016 | AA18: 2017 | AB18: 2018 | AC18: 2019 | AD18: 2020 | AE18: 2021 | AF18: 2022
B19: Landbrug | C19: =K!AC2/L!AC2 | D19: =K!AD2/L!AD2 | E19: =K!AE2/L!AE2 | F19: =K!AF2/L!AF2 | G19: =K!AG2/L!AG2 | H19: =K!AH2/L!AH2 | I19: =K!AI2/L!AI2 | J19: =K!AJ2/L!AJ2 | ... AF19: =K!BF2/L!BF2
B20: Føde- drikke og tobaksvareindustri | C20: =K!AC3/L!AC3 | D20: =K!AD3/L!AD3 | E20: =K!AE3/L!AE3 | F20: =K!AF3/L!AF3 | G20: =K!AG3/L!AG3 | H20: =K!AH3/L!AH3 | I20: =K!AI3/L!AI3 | J20: =K!AJ3/L!AJ3 | ... AF20: =K!BF3/L!BF3
B21: Resten af økonomien | C21: =K!AC4/L!AC4 | D21: =K!AD4/L!AD4 | E21: =K!AE4/L!AE4 | F21: =K!AF4/L!AF4 | G21: =K!AG4/L!AG4 | H21: =K!AH4/L!AH4 | I21: =K!AI4/L!AI4 | J21: =K!AJ4/L!AJ4 | ... AF21: =K!BF4/L!BF4
B23: Produktionsværdi (mio.kr.) | C23: 1993 | D23: 1994 | E23: 1995 | F23: 1996 | G23: 1997 | H23: 1998 | I23: 1999 | J23: 2000 | K23: 2001 | L23: 2002 | M23: 2003 | N23: 2004 | O23: 2005 | P23: 2006 | Q23: 2007 | R23: 2008 | S23: 2009 | T23: 2010 | U23: 2011 | V23: 2012 | W23: 2013 | X23: 2014 | Y23: 2015 | Z23: 2016 | AA23: 2017 | AB23: 2018 | AC23: 2019 | AD23: 2020 | AE23: 2021 | AF23: 2022
B24: Landbrug | C24: =Y!AB2*P!AB2 | D24: =Y!AC2*P!AC2 | E24: =Y!AD2*P!AD2 | F24: =Y!AE2*P!AE2 | G24: =Y!AF2*P!AF2 | H24: =Y!AG2*P!AG2 | I24: =Y!AH2*P!AH2 | J24: =Y!AI2*P!AI2 | ... AF24: =Y!BE2*P!BE2
B25: Føde- drikke og tobaksvareindustri | C25: =Y!AB3*P!AB3 | D25: =Y!AC3*P!AC3 | E25: =Y!AD3*P!AD3 | F25: =Y!AE3*P!AE3 | G25: =Y!AF3*P!AF3 | H25: =Y!AG3*P!AG3 | I25: =Y!AH3*P!AH3 | J25: =Y!AI3*P!AI3 | ... AF25: =Y!BE3*P!BE3
B26: Resten af økonomien | C26: =Y!AB4*P!AB4 | D26: =Y!AC4*P!AC4 | E26: =Y!AD4*P!AD4 | F26: =Y!AE4*P!AE4 | G26: =Y!AF4*P!AF4 | H26: =Y!AG4*P!AG4 | I26: =Y!AH4*P!AH4 | J26: =Y!AI4*P!AI4 | ... AF26: =Y!BE4*P!BE4

Sheet Ark1
A1: ANVENDELSE | B1: 1993 | C1: 1994 | D1: 1995 | E1: 1996 | F1: 1997 | G1: 1998 | H1: 1999 | I1: 2000 | J1: 2001 | K1: 2002 | L1: 2003 | M1: 2004 | N1: 2005 | O1: 2006 | P1: 2007 | Q1: 2008 | R1: 2009 | S1: 2010 | T1: 2011 | U1: 2012 | V1: 2013 | W1: 2014 | X1: 2015 | Y1: 2016 | Z1: 2017 | AA1: 2018 | AB1: 2019 | AC1: 2020 | AD1: 2021 | AE1: 2022
A2: L | B2: 205.929 | C2: 187.306 | D2: 180.889 | E2: 173.049 | F2: 162.332 | G2: 160.81 | H2: 152.28 | I2: 149.02 | J2: 145.343 | K2: 145.637 | L2: 134.391 | M2: 133.301 | N2: 125.588 | O2: 117.953 | P2: 114.771 | Q2: 109.397 | R2: 101.938 | S2: 98.594 | T2: 97.135 | U2: 95.702 | V2: 94.814 | W2: 95.678 | X2: 97.467 | Y2: 91.694 | Z2: 92.464 | AA2: 89.982 | AB2: 85.014 | AC2: 85.49 | AD2: 86.997 | AE2: 84.49
A3: KL | C3: 52117.794 | D3: 50900.442 | E3: 49681.538 | F3: 48143.426 | G3: 47708.981 | H3: 46314.405 | I3: 45117.473 | J3: 44432.633 | K3: 44480.111 | L3: 42600.847 | M3: 42241.35 | N3: 40925.503 | O3: 39424.938 | P3: 39026.41 | Q3: 38328.713 | R3: 37355.83 | S3: 36543.067 | T3: 35879.711 | U3: 35222.069 | V3: 34756.946 | W3: 34683.366 | X3: 34775.854 | Y3: 33362.229 | Z3: 33300.801 | AA3: 32593.134 | AB3: 31418.74 | AC3: 31265.505 | AD3: 31288.388 | AE3: 30691.04
A4: w | B4: 70.472785 | C4: 72.401971 | D4: 73.668419 | E4: 77.602928 | F4: 82.112148 | G4: 85.654427 | H4: 87.363624 | I4: 90.147712 | J4: 91.297341 | K4: 97.14543 | L4: 103.01562 | M4: 108.39572 | N4: 109.31073 | O4: 113.52155 | P4: 120.93852 | Q4: 127.13193 | R4: 132.90639 | S4: 140.4119 | T4: 143.61532 | U4: 146.408 | V4: 150.45915 | W4: 156.52284 | X4: 175.97839 | Y4: 179.46352 | Z4: 182.14425 | AA4: 189.6717 | AB4: 197.71026 | AC4: 205.68694 | AD4: 203.39064 | AE4: 217.89115
A5: P_KL | C5: 0.5694121 | D5: 0.62035501 | E5: 0.71346775 | F5: 0.65078662 | G5: 0.64940884 | H5: 0.76888134 | I5: 0.63509005 | J5: 0.60434501 | K5: 0.64413311 | L5: 0.68386032 | M5: 0.74184557 | N5: 0.59880691 | O5: 0.7204948 | P5: 0.67093704 | Q5: 0.77635834 | R5: 0.83598365 | S5: 0.86793431 | T5: 0.87398331 | U5: 0.76017118 | V5: 0.80984611 | W5: 0.80380746 | X5: 0.84621455 | Y5: 0.79660741 | Z5: 0.90949967 | AA5: 1.1242478 | AB5: 0.98676346 | AC5: 1 | AD5: 1.1984003 | AE5: 1.0173887
A7: EKL | B7: 0
B8: =(B2/B3)*(B4/B5)^$B$7 | C8: =(C2/C3)*(C4/C5)^$B$7 | D8: =(D2/D3)*(D4/D5)^$B$7 | E8: =(E2/E3)*(E4/E5)^$B$7 | F8: =(F2/F3)*(F4/F5)^$B$7 | G8: =(G2/G3)*(G4/G5)^$B$7 | H8: =(H2/H3)*(H4/H5)^$B$7 | I8: =(I2/I3)*(I4/I5)^$B$7 | ... AE8: =(AE2/AE3)*(AE4/AE5)^$B$7
A11: lon lob | B11: =B2*B4 | C11: =C2*C4 | D11: =D2*D4 | E11: =E2*E4 | F11: =F2*F4 | G11: =G2*G4 | H11: =H2*H4 | I11: =I2*I4 | ... AF11: =AF2*AF4
A12: lon for | B12: =B2*A4 | C12: =C2*B4 | D12: =D2*C4 | E12: =E2*D4 | F12: =F2*E4 | G12: =G2*F4 | H12: =H2*G4 | I12: =I2*H4 | ... AE12: =AE2*AD4
A13: Pt | B13: =C13/(C11/C12) | C13: =D13/(D11/D12) | D13: =E13/(E11/E12) | E13: =F13/(F11/F12) | F13: =G13/(G11/G12) | G13: =H13/(H11/H12) | H13: =I13/(I11/I12) | I13: =J13/(J11/J12) | ... AB13: =AC13/(AC11/AC12) | AC13: =1 | AD13: =AC13*AD11/AD12 | AE13: =AD13*AE11/AE12
A14: Xt | B14: =B11/B13 | C14: =C11/C13 | D14: =D11/D13 | E14: =E11/E13 | F14: =F11/F13 | G14: =G11/G13 | H14: =H11/H13 | I14: =I11/I13 | ... AE14: =AE11/AE13
B16: =(B14/B3)*(B13/B5)^$B$7 | C16: =(C14/C3)*(C13/C5)^$B$7 | D16: =(D14/D3)*(D13/D5)^$B$7 | E16: =(E14/E3)*(E13/E5)^$B$7 | F16: =(F14/F3)*(F13/F5)^$B$7 | G16: =(G14/G3)*(G13/G5)^$B$7 | H16: =(H14/H3)*(H13/H5)^$B$7 | I16: =(I14/I3)*(I13/I5)^$B$7 | ... AE16: =(AE14/AE3)*(AE13/AE5)^$B$7

Sheet Y
A1: ANVENDELSE | B1: 1967 | C1: 1968 | D1: 1969 | E1: 1970 | F1: 1971 | G1: 1972 | H1: 1973 | I1: 1974 | J1: 1975 | K1: 1976 | L1: 1977 | M1: 1978 | N1: 1979 | O1: 1980 | P1: 1981 | Q1: 1982 | R1: 1983 | S1: 1984 | T1: 1985 | U1: 1986 | V1: 1987 | W1: 1988 | X1: 1989 | Y1: 1990 | Z1: 1991 | AA1: 1992 | AB1: 1993 | AC1: 1994 | AD1: 1995 | AE1: 1996 | AF1: 1997 | AG1: 1998 | AH1: 1999 | AI1: 2000 | AJ1: 2001 | AK1: 2002 | AL1: 2003 | AM1: 2004 | AN1: 2005 | AO1: 2006 | AP1: 2007 | AQ1: 2008 | AR1: 2009 | AS1: 2010 | AT1: 2011 | AU1: 2012 | AV1: 2013 | AW1: 2014 | AX1: 2015 | AY1: 2016 | AZ1: 2017 | BA1: 2018 | BB1: 2019 | BC1: 2020 | BD1: 2021 | BE1: 2022
A2: 01000 | B2: 44352.253 | C2: 44088.474 | D2: 44065.485 | E2: 41076.955 | F2: 44428.588 | G2: 45125.516 | H2: 45687.594 | I2: 47792.366 | J2: 45353.08 | K2: 45360.614 | L2: 48300.748 | M2: 50462.618 | N2: 51681.032 | O2: 51506.404 | P2: 52624.818 | Q2: 55228.202 | R2: 53482.361 | S2: 58750.744 | T2: 58588.026 | U2: 58742.299 | V2: 56961.097 | W2: 56075.446 | X2: 58852.663 | Y2: 62263.479 | Z2: 60786.475 | AA2: 60399.718 | AB2: 69638.69 | AC2: 68856.807 | AD2: 69737.096 | AE2: 70280.702 | AF2: 72177.731 | AG2: 73158.199 | AH2: 73173.611 | AI2: 74464.21 | AJ2: 73547.402 | AK2: 74587.448 | AL2: 74719.005 | AM2: 75618.655 | AN2: 74196.06 | AO2: 75618.96 | AP2: 79159.854 | AQ2: 73126.391 | AR2: 73444.22 | AS2: 77334.77 | AT2: 75869.896 | AU2: 77617.493 | AV2: 76593.51 | AW2: 80374.732 | AX2: 79210.579 | AY2: 76984.41 | AZ2: 80708.048 | BA2: 79724.539 | BB2: 78394.569 | BC2: 80503.511 | BD2: 82678.533 | BE2: 81481.018
A3: 10120 | B3: 83186.189 | C3: 86476.234 | D3: 85557.501 | E3: 89270.716 | F3: 92244.747 | G3: 94861.982 | H3: 96469.273 | I3: 98731.17 | J3: 96574.474 | K3: 100366.04 | L3: 105550.69 | M3: 108622.24 | N3: 118817.66 | O3: 124261.63 | P3: 125155.28 | Q3: 121655.97 | R3: 119434.54 | S3: 120350.92 | T3: 126590.8 | U3: 133131.09 | V3: 131489.29 | W3: 131466.32 | X3: 131914.27 | Y3: 138076.58 | Z3: 139256.11 | AA3: 142823.72 | AB3: 150359.82 | AC3: 151786.73 | AD3: 151157.95 | AE3: 144547.1 | AF3: 146043.78 | AG3: 150061.67 | AH3: 149807.44 | AI3: 149968.46 | AJ3: 152904.38 | AK3: 155839.87 | AL3: 157377.12 | AM3: 159879.98 | AN3: 163810.69 | AO3: 162171.86 | AP3: 160069.3 | AQ3: 158120.91 | AR3: 150853.33 | AS3: 144714.15 | AT3: 145739.45 | AU3: 142580.88 | AV3: 144480.44 | AW3: 145446.79 | AX3: 146833.77 | AY3: 148098.44 | AZ3: 153499.94 | BA3: 153657.79 | BB3: 155602.57 | BC3: 161377.86 | BD3: 165261.18 | BE3: 168806.14
A4: Privat | B4: -145266.93 | C4: -163957.03 | D4: -191310.48 | E4: -230670.18 | F4: -230989.18 | G4: -245238.53 | H4: -253725.62 | I4: -252109.58 | J4: -258278.76 | K4: -274864.66 | L4: -271206.89 | M4: -291009.47 | N4: -309191.34 | O4: -324252.26 | P4: -329311.32 | Q4: -332188.01 | R4: -339354.86 | S4: -322217 | T4: -331051.41 | U4: -333287.23 | V4: -346166.61 | W4: -352791.91 | X4: -347702.97 | Y4: -333890.87 | Z4: -341320.92 | AA4: -351521.1 | AB4: -354269.74 | AC4: -365426.75 | AD4: -375332.95 | AE4: -389791.23 | AF4: -393171.49 | AG4: -405031.99 | AH4: -418254.63 | AI4: -429681.31 | AJ4: -442620 | AK4: -448939.78 | AL4: -449166.98 | AM4: -457473.31 | AN4: -466982.39 | AO4: -479788.08 | AP4: -473827.51 | AQ4: -498412.84 | AR4: -513999.13 | AS4: -517589.03 | AT4: -513501.89 | AU4: -519409.87 | AV4: -520408.5 | AW4: -529876.61 | AX4: -544906.17 | AY4: -549644.94 | AZ4: -549781.75 | BA4: -555403.32 | BB4: -562496.56 | BC4: -551339.13 | BD4: -576511.2 | BE4: -568004.8
A5: REST | B5: 1109665.2 | C5: 1150467.2 | D5: 1244272.4 | E5: 1296967.3 | F5: 1323255.2 | G5: 1389078.8 | H5: 1455464.8 | I5: 1429114.2 | J5: 1395556.7 | K5: 1504518.1 | L5: 1524849.3 | M5: 1565128.5 | N5: 1624837 | O5: 1610111.2 | P5: 1578283.4 | Q5: 1618114.6 | R5: 1656904 | S5: 1747167.8 | T5: 1838273 | U5: 1959928.8 | V5: 1995809.2 | W5: 2024259.3 | X5: 2032213.7 | Y5: 2061376.4 | Z5: 2081193.2 | AA5: 2112919.2 | AB5: 2121405.3 | AC5: 2237038.4 | AD5: 2322092.6 | AE5: 2404762 | AF5: 2483498.2 | AG5: 2556756.6 | AH5: 2672884.8 | AI5: 2814342.7 | AJ5: 2887124.9 | AK5: 2919063.6 | AL5: 2924155.7 | AM5: 2993388 | AN5: 3163125.6 | AO5: 3345591.2 | AP5: 3450061.6 | AQ5: 3489091 | AR5: 3255992.7 | AS5: 3260982 | AT5: 3349605.6 | AU5: 3379079.5 | AV5: 3383461.5 | AW5: 3454296 | AX5: 3545031.5 | AY5: 3681621.6 | AZ5: 3775390.8 | BA5: 3850118.5 | BB5: 3911961.7 | BC5: 3813550.3 | BD5: 4064668.8 | BE5: 4180703.9

Sheet Mtot
A1: ANVENDELSE | B1: 1967 | C1: 1968 | D1: 1969 | E1: 1970 | F1: 1971 | G1: 1972 | H1: 1973 | I1: 1974 | J1: 1975 | K1: 1976 | L1: 1977 | M1: 1978 | N1: 1979 | O1: 1980 | P1: 1981 | Q1: 1982 | R1: 1983 | S1: 1984 | T1: 1985 | U1: 1986 | V1: 1987 | W1: 1988 | X1: 1989 | Y1: 1990 | Z1: 1991 | AA1: 1992 | AB1: 1993 | AC1: 1994 | AD1: 1995 | AE1: 1996 | AF1: 1997 | AG1: 1998 | AH1: 1999 | AI1: 2000 | AJ1: 2001 | AK1: 2002 | AL1: 2003 | AM1: 2004 | AN1: 2005 | AO1: 2006 | AP1: 2007 | AQ1: 2008 | AR1: 2009 | AS1: 2010 | AT1: 2011 | AU1: 2012 | AV1: 2013 | AW1: 2014 | AX1: 2015 | AY1: 2016 | AZ1: 2017 | BA1: 2018 | BB1: 2019 | BC1: 2020 | BD1: 2021 | BE1: 2022
A2: 01000 | B2: 48616.653 | C2: 47695.375 | D2: 45482.569 | E2: 48860.851 | F2: 49832.777 | G2: 48754.6 | H2: 53687.976 | I2: 50347.45 | J2: 50898.993 | K2: 55765.444 | L2: 54995.312 | M2: 57754.737 | N2: 61097.322 | O2: 60091.676 | P2: 59554.568 | Q2: 59448.351 | R2: 59821.157 | S2: 59231.536 | T2: 60601.419 | U2: 58326.362 | V2: 60860.17 | W2: 55537.804 | X2: 54018.156 | Y2: 55825.538 | Z2: 53599.121 | AA2: 56940.762 | AB2: 64170.631 | AC2: 61795.671 | AD2: 61275.313 | AE2: 61125.298 | AF2: 62786.832 | AG2: 64275.386 | AH2: 66399.929 | AI2: 64663.644 | AJ2: 62761.645 | AK2: 62054.263 | AL2: 60125.175 | AM2: 59973.973 | AN2: 58787.124 | AO2: 59166.383 | AP2: 59174.696 | AQ2: 59635.583 | AR2: 61402.531 | AS2: 59798.812 | AT2: 62118.604 | AU2: 61114.016 | AV2: 61542.817 | AW2: 60755.589 | AX2: 63763.304 | AY2: 64105.716 | AZ2: 65253.11 | BA2: 65253.852 | BB2: 61879.55 | BC2: 63033.213 | BD2: 64274.682 | BE2: 66780.017
A3: 10120 | B3: 92311.383 | C3: 92533.87 | D3: 91299.971 | E3: 95924.243 | F3: 99093.355 | G3: 99118.146 | H3: 101617.64 | I3: 102728.3 | J3: 102527.8 | K3: 106483.67 | L3: 108828.29 | M3: 114400.46 | N3: 122847.16 | O3: 127864.44 | P3: 128325.39 | Q3: 125682.81 | R3: 124749.22 | S3: 126286.06 | T3: 131100.16 | U3: 138841.89 | V3: 137759.32 | W3: 134679.1 | X3: 134094.7 | Y3: 140357.96 | Z3: 141931.46 | AA3: 148881.5 | AB3: 158789.29 | AC3: 161316.43 | AD3: 158309.75 | AE3: 154302.02 | AF3: 153769.02 | AG3: 159143.85 | AH3: 157659.76 | AI3: 158584.46 | AJ3: 160192.85 | AK3: 171400.99 | AL3: 177339.73 | AM3: 178628.39 | AN3: 179994.96 | AO3: 181228.9 | AP3: 181025.09 | AQ3: 179981.75 | AR3: 167624.78 | AS3: 161904.18 | AT3: 163129.32 | AU3: 159423.35 | AV3: 161629.7 | AW3: 163134.34 | AX3: 167857.96 | AY3: 166609.29 | AZ3: 169873.36 | BA3: 171898.68 | BB3: 171774.58 | BC3: 178572.88 | BD3: 179510.88 | BE3: 177435.19
A4: REST | B4: 411650.36 | C4: 419464.85 | D4: 460225.25 | E4: 485600.64 | F4: 490434.49 | G4: 519321.25 | H4: 548114.68 | I4: 532865.6 | J4: 513054.6 | K4: 559570.35 | L4: 570967.8 | M4: 585914.3 | N4: 605503.72 | O4: 595958.45 | P4: 571217.18 | Q4: 572900.06 | R4: 588340.19 | S4: 643087.69 | T4: 687835.5 | U4: 753013.47 | V4: 766533.06 | W4: 773759.88 | X4: 769874.7 | Y4: 778785.69 | Z4: 777506.62 | AA4: 783090.04 | AB4: 790669.53 | AC4: 840314.59 | AD4: 887658.39 | AE4: 927768.45 | AF4: 956336.25 | AG4: 994177.18 | AH4: 1058538.4 | AI4: 1111451.2 | AJ4: 1160801 | AK4: 1182038.6 | AL4: 1166308.7 | AM4: 1196504.3 | AN4: 1310626.1 | AO4: 1402762.5 | AP4: 1468177.6 | AQ4: 1486203.3 | AR4: 1347206 | AS4: 1331167.3 | AT4: 1367626.5 | AU4: 1394607.1 | AV4: 1384723.6 | AW4: 1429188.8 | AX4: 1482747.1 | AY4: 1546927.7 | AZ4: 1582576.5 | BA4: 1615911.8 | BB4: 1646520.7 | BC4: 1622919.9 | BD4: 1733667.3 | BE4: 1826995

Sheet K
A1: ANVENDELSE | B1: 1966 | C1: 1967 | D1: 1968 | E1: 1969 | F1: 1970 | G1: 1971 | H1: 1972 | I1: 1973 | J1: 1974 | K1: 1975 | L1: 1976 | M1: 1977 | N1: 1978 | O1: 1979 | P1: 1980 | Q1: 1981 | R1: 1982 | S1: 1983 | T1: 1984 | U1: 1985 | V1: 1986 | W1: 1987 | X1: 1988 | Y1: 1989 | Z1: 1990 | AA1: 1991 | AB1: 1992 | AC1: 1993 | AD1: 1994 | AE1: 1995 | AF1: 1996 | AG1: 1997 | AH1: 1998 | AI1: 1999 | AJ1: 2000 | AK1: 2001 | AL1: 2002 | AM1: 2003 | AN1: 2004 | AO1: 2005 | AP1: 2006 | AQ1: 2007 | AR1: 2008 | AS1: 2009 | AT1: 2010 | AU1: 2011 | AV1: 2012 | AW1: 2013 | AX1: 2014 | AY1: 2015 | AZ1: 2016 | BA1: 2017 | BB1: 2018 | BC1: 2019 | BD1: 2020 | BE1: 2021 | BF1: 2022 | BG1: 2023 | BH1: 2024
A2: 01000 | B2: 222779 | C2: 224430 | D2: 224282 | E2: 225092 | F2: 225532 | G2: 226385 | H2: 229269 | I2: 235171 | J2: 240479 | K2: 244016 | L2: 249923 | M2: 257543 | N2: 265709 | O2: 273950 | P2: 274839 | Q2: 271574 | R2: 269172 | S2: 265387 | T2: 264710 | U2: 266226 | V2: 266885 | W2: 266110 | X2: 264303 | Y2: 267224 | Z2: 270771 | AA2: 270977 | AB2: 269956 | AC2: 265165 | AD2: 261404 | AE2: 258846 | AF2: 255722 | AG2: 253481 | AH2: 250903 | AI2: 243755 | AJ2: 242098 | AK2: 242131 | AL2: 240161 | AM2: 238063 | AN2: 236088 | AO2: 234687 | AP2: 235845 | AQ2: 239330 | AR2: 242244 | AS2: 239024 | AT2: 234064 | AU2: 229103 | AV2: 225090 | AW2: 222016 | AX2: 218477 | AY2: 215268 | AZ2: 211288 | BA2: 208278 | BB2: 204256 | BC2: 200726 | BD2: 196514 | BE2: 194470 | BF2: 190650 | BG2: 187393 | BH2: 184590
A3: 10120 | B3: 34654 | C3: 36904 | D3: 38025 | E3: 39447 | F3: 40346 | G3: 41710 | H3: 42921 | I3: 44127 | J3: 46869 | K3: 48514 | L3: 50580 | M3: 52444 | N3: 54643 | O3: 57092 | P3: 58318 | Q3: 59085 | R3: 59216 | S3: 59268 | T3: 60351 | U3: 61829 | V3: 63940 | W3: 66178 | X3: 68823 | Y3: 71028 | Z3: 72698 | AA3: 75678 | AB3: 78426 | AC3: 79444 | AD3: 80168 | AE3: 80875 | AF3: 83394 | AG3: 83779 | AH3: 84571 | AI3: 84521 | AJ3: 86866 | AK3: 88848 | AL3: 90559 | AM3: 93051 | AN3: 95676 | AO3: 95904 | AP3: 95868 | AQ3: 96614 | AR3: 99622 | AS3: 102062 | AT3: 99903 | AU3: 98584 | AV3: 99448 | AW3: 99126 | AX3: 98817 | AY3: 98167 | AZ3: 97863 | BA3: 98143 | BB3: 100338 | BC3: 101517 | BD3: 101385 | BE3: 101864 | BF3: 102660 | BG3: 103486 | BH3: 104607
A4: Privat | B4: 2328289 | C4: 2420953 | D4: 2512851 | E4: 2625053 | F4: 2731578 | G4: 2833885 | H4: 2968039 | I4: 3113691 | J4: 3216009 | K4: 3292020 | L4: 3408556 | M4: 3511869 | N4: 3615136 | O4: 3713343 | P4: 3780940 | Q4: 3807718 | R4: 3850841 | S4: 3900678 | T4: 3969100 | U4: 4059681 | V4: 4195239 | W4: 4321877 | X4: 4413324 | Y4: 4504518 | Z4: 4595977 | AA4: 4658767 | AB4: 4707856 | AC4: 4740237 | AD4: 4773036 | AE4: 4825957 | AF4: 4885502 | AG4: 4955736 | AH4: 5039873 | AI4: 5107743 | AJ4: 5203157 | AK4: 5285017 | AL4: 5356277 | AM4: 5425441 | AN4: 5498539 | AO4: 5587189 | AP4: 5723562 | AQ4: 5850835 | AR4: 5942911 | AS4: 5987917 | AT4: 5990758 | AU4: 5995379 | AV4: 6010959 | AW4: 6036155 | AX4: 6077431 | AY4: 6133100 | AZ4: 6213595 | BA4: 6311588 | BB4: 6417049 | BC4: 6501720 | BD4: 6591703 | BE4: 6734739 | BF4: 6874669 | BG4: 6992400 | BH4: 7114398
A5: REST | B5: 2618163 | C5: 2738303 | D5: 2867006 | E5: 3015495 | F5: 3161059 | G5: 3302298 | H5: 3467494 | I5: 3631240 | J5: 3755637 | K5: 3856260 | L5: 3992820 | M5: 4114787 | N5: 4233512 | O5: 4350333 | P5: 4435830 | Q5: 4471498 | R5: 4517509 | S5: 4564886 | T5: 4625448 | U5: 4710206 | V5: 4837386 | W5: 4962141 | X5: 5055391 | Y5: 5137935 | Z5: 5217291 | AA5: 5264800 | AB5: 5305384 | AC5: 5328639 | AD5: 5354683 | AE5: 5403081 | AF5: 5462484 | AG5: 5531111 | AH5: 5612542 | AI5: 5682056 | AJ5: 5773271 | AK5: 5852073 | AL5: 5918328 | AM5: 5980902 | AN5: 6046439 | AO5: 6132550 | AP5: 6270696 | AQ5: 6395005 | AR5: 6486901 | AS5: 6533631 | AT5: 6550770 | AU5: 6568622 | AV5: 6599838 | AW5: 6638025 | AX5: 6696875 | AY5: 6769376 | AZ5: 6870825 | BA5: 6985059 | BB5: 7107156 | BC5: 7209258 | BD5: 7324959 | BE5: 7488001 | BF5: 7648052 | BG5: 7786450 | BH5: 7930718

Sheet L
A1: ANVENDELSE | B1: 1966 | C1: 1967 | D1: 1968 | E1: 1969 | F1: 1970 | G1: 1971 | H1: 1972 | I1: 1973 | J1: 1974 | K1: 1975 | L1: 1976 | M1: 1977 | N1: 1978 | O1: 1979 | P1: 1980 | Q1: 1981 | R1: 1982 | S1: 1983 | T1: 1984 | U1: 1985 | V1: 1986 | W1: 1987 | X1: 1988 | Y1: 1989 | Z1: 1990 | AA1: 1991 | AB1: 1992 | AC1: 1993 | AD1: 1994 | AE1: 1995 | AF1: 1996 | AG1: 1997 | AH1: 1998 | AI1: 1999 | AJ1: 2000 | AK1: 2001 | AL1: 2002 | AM1: 2003 | AN1: 2004 | AO1: 2005 | AP1: 2006 | AQ1: 2007 | AR1: 2008 | AS1: 2009 | AT1: 2010 | AU1: 2011 | AV1: 2012 | AW1: 2013 | AX1: 2014 | AY1: 2015 | AZ1: 2016 | BA1: 2017 | BB1: 2018 | BC1: 2019 | BD1: 2020 | BE1: 2021 | BF1: 2022
A2: 01000 | B2: 630.077 | C2: 595.974 | D2: 561.953 | E2: 532.92 | F2: 505.492 | G2: 472.538 | H2: 463.15 | I2: 454.509 | J2: 433.263 | K2: 415.44 | L2: 408.086 | M2: 393.844 | N2: 380.021 | O2: 361.6 | P2: 342.439 | Q2: 325.525 | R2: 314.708 | S2: 305.717 | T2: 297.005 | U2: 286.292 | V2: 277.373 | W2: 272.733 | X2: 247.527 | Y2: 239.832 | Z2: 229.64 | AA2: 224.577 | AB2: 216.746 | AC2: 205.929 | AD2: 187.306 | AE2: 180.889 | AF2: 173.049 | AG2: 162.332 | AH2: 160.81 | AI2: 152.28 | AJ2: 149.02 | AK2: 145.343 | AL2: 145.637 | AM2: 134.391 | AN2: 133.301 | AO2: 125.588 | AP2: 117.953 | AQ2: 114.771 | AR2: 109.397 | AS2: 101.938 | AT2: 98.594 | AU2: 97.135 | AV2: 95.702 | AW2: 94.814 | AX2: 95.678 | AY2: 97.467 | AZ2: 91.694 | BA2: 92.464 | BB2: 89.982 | BC2: 85.014 | BD2: 85.49 | BE2: 86.997 | BF2: 84.49
A3: 10120 | B3: 232.125 | C3: 220.326 | D3: 210.205 | E3: 204.42 | F3: 202.642 | G3: 194.114 | H3: 187.292 | I3: 179.902 | J3: 174.334 | K3: 156.33 | L3: 155.216 | M3: 152.588 | N3: 149.102 | O3: 150.151 | P3: 147.911 | Q3: 145.985 | R3: 146.121 | S3: 147.457 | T3: 147.552 | U3: 145.082 | V3: 148.494 | W3: 140.336 | X3: 138.844 | Y3: 133.495 | Z3: 129.957 | AA3: 129.1 | AB3: 127.466 | AC3: 124.695 | AD3: 121.438 | AE3: 123.972 | AF3: 120.697 | AG3: 117.906 | AH3: 115.14 | AI3: 116.399 | AJ3: 117.301 | AK3: 117.036 | AL3: 116.729 | AM3: 110.661 | AN3: 106.601 | AO3: 99.25 | AP3: 95.156 | AQ3: 90.557 | AR3: 89.332 | AS3: 83.22 | AT3: 79.289 | AU3: 76.719 | AV3: 73.253 | AW3: 70.479 | AX3: 66.267 | AY3: 64.949 | AZ3: 65.699 | BA3: 67.126 | BB3: 65.335 | BC3: 65.519 | BD3: 70.152 | BE3: 70.24 | BF3: 69.952
A4: Privat | B4: 3143.073 | C4: 3077.567 | D4: 3040.631 | E4: 3025.629 | F4: 3014.989 | G4: 2937.88 | H4: 2863.709 | I4: 2801.221 | J4: 2735.764 | K4: 2546.486 | L4: 2610.71 | M4: 2563.278 | N4: 2526.133 | O4: 2517.724 | P4: 2463.159 | Q4: 2317.728 | R4: 2323.815 | S4: 2311.374 | T4: 2375.899 | U4: 2436.049 | V4: 2531.631 | W4: 2485.704 | X4: 2427.86 | Y4: 2392.102 | Z4: 2367.943 | AA4: 2345.393 | AB4: 2355.778 | AC4: 2297.253 | AD4: 2290.292 | AE4: 2349.179 | AF4: 2382.269 | AG4: 2451.678 | AH4: 2516.331 | AI4: 2590.934 | AJ4: 2663.535 | AK4: 2691.526 | AL4: 2671.37 | AM4: 2624.379 | AN4: 2612.563 | AO4: 2641.905 | AP4: 2724.381 | AQ4: 2771.278 | AR4: 2808.093 | AS4: 2618.122 | AT4: 2541.281 | AU4: 2594.214 | AV4: 2554.006 | AW4: 2559.716 | AX4: 2562.253 | AY4: 2604.218 | AZ4: 2689.705 | BA4: 2725.711 | BB4: 2722.559 | BC4: 2750.48 | BD4: 2620.695 | BE4: 2789.53 | BF4: 2945.371
A5: REST | B5: 3742.182 | C5: 3720.867 | D5: 3695.254 | E5: 3716.009 | F5: 3741.101 | G5: 3694.889 | H5: 3653.882 | I5: 3614.336 | J5: 3566.698 | K5: 3379.346 | L5: 3472.797 | M5: 3418.194 | N5: 3410.781 | O5: 3444.395 | P5: 3477.283 | Q5: 3356.998 | R5: 3400.968 | S5: 3394.252 | T5: 3445.565 | U5: 3514.7 | V5: 3625.889 | W5: 3568.13 | X5: 3517.672 | Y5: 3475.337 | Z5: 3434.81 | AA5: 3395.609 | AB5: 3413.744 | AC5: 3357.281 | AD5: 3342.697 | AE5: 3401.971 | AF5: 3431.762 | AG5: 3539.072 | AH5: 3632.582 | AI5: 3714.509 | AJ5: 3772.557 | AK5: 3824.171 | AL5: 3809.762 | AM5: 3776.588 | AN5: 3761.275 | AO5: 3814.54 | AP5: 3929.729 | AQ5: 3967.488 | AR5: 4018.058 | AS5: 3861.885 | AT5: 3790.107 | AU5: 3830.075 | AV5: 3769.454 | AW5: 3781.533 | AX5: 3776.795 | AY5: 3815.08 | AZ5: 3899.913 | BA5: 3935.591 | BB5: 3934.302 | BC5: 3972.38 | BD5: 3827.066 | BE5: 4062.261 | BF5: 4225.398

Sheet P
A1: ANVENDELSE | B1: 1967 | C1: 1968 | D1: 1969 | E1: 1970 | F1: 1971 | G1: 1972 | H1: 1973 | I1: 1974 | J1: 1975 | K1: 1976 | L1: 1977 | M1: 1978 | N1: 1979 | O1: 1980 | P1: 1981 | Q1: 1982 | R1: 1983 | S1: 1984 | T1: 1985 | U1: 1986 | V1: 1987 | W1: 1988 | X1: 1989 | Y1: 1990 | Z1: 1991 | AA1: 1992 | AB1: 1993 | AC1: 1994 | AD1: 1995 | AE1: 1996 | AF1: 1997 | AG1: 1998 | AH1: 1999 | AI1: 2000 | AJ1: 2001 | AK1: 2002 | AL1: 2003 | AM1: 2004 | AN1: 2005 | AO1: 2006 | AP1: 2007 | AQ1: 2008 | AR1: 2009 | AS1: 2010 | AT1: 2011 | AU1: 2012 | AV1: 2013 | AW1: 2014 | AX1: 2015 | AY1: 2016 | AZ1: 2017 | BA1: 2018 | BB1: 2019 | BC1: 2020 | BD1: 2021 | BE1: 2022
A2: 01000 | B2: 0.25607391 | C2: 0.25834004 | D2: 0.28105258 | E2: 0.30430121 | F2: 0.29811967 | G2: 0.3339359 | H2: 0.43052799 | I2: 0.44414889 | J2: 0.48715192 | K2: 0.5640882 | L2: 0.59514356 | M2: 0.6345172 | N2: 0.65096351 | O2: 0.72318177 | P2: 0.81190981 | Q2: 0.91041812 | R2: 0.95466565 | S2: 0.99197673 | T2: 0.98749151 | U2: 0.95475842 | V2: 0.95360648 | W2: 0.93289799 | X2: 0.97239892 | Y2: 0.90614873 | Z2: 0.89339057 | AA2: 0.9027064 | AB2: 0.80025435 | AC2: 0.80089488 | AD2: 0.83564746 | AE2: 0.84700116 | AF2: 0.84671658 | AG2: 0.75191861 | AH2: 0.73512719 | AI2: 0.80247949 | AJ2: 0.85718239 | AK2: 0.78091773 | AL2: 0.75515379 | AM2: 0.77755657 | AN2: 0.71833855 | AO2: 0.73132553 | AP2: 0.76268103 | AQ2: 0.83607121 | AR2: 0.79607803 | AS2: 0.84462464 | AT2: 0.94835462 | AU2: 1.0293523 | AV2: 0.9779207 | AW2: 0.93853411 | AX2: 0.86804807 | AY2: 0.8813666 | AZ2: 0.9560939 | BA2: 0.91154158 | BB2: 0.98517616 | BC2: 1 | BD2: 0.97836787 | BE2: 1.1755229
A3: 10120 | B3: 0.21736726 | C3: 0.21710019 | D3: 0.23343467 | E3: 0.25019141 | F3: 0.25792979 | G3: 0.27667241 | H3: 0.35413554 | I3: 0.38365037 | J3: 0.41428954 | K3: 0.45273991 | L3: 0.48772052 | M3: 0.51748751 | N3: 0.52452863 | O3: 0.57813656 | P3: 0.65156258 | Q3: 0.72420846 | R3: 0.74937649 | S3: 0.8071227 | T3: 0.80627525 | U3: 0.76773198 | V3: 0.75546495 | W3: 0.7647754 | X3: 0.81507702 | Y3: 0.7943401 | Z3: 0.79175995 | AA3: 0.8113854 | AB3: 0.75479964 | AC3: 0.76114401 | AD3: 0.76856146 | AE3: 0.78565486 | AF3: 0.79803586 | AG3: 0.75402237 | AH3: 0.73069725 | AI3: 0.78026275 | AJ3: 0.81970009 | AK3: 0.82018067 | AL3: 0.80459867 | AM3: 0.81073778 | AN3: 0.81833701 | AO3: 0.83200361 | AP3: 0.86051449 | AQ3: 0.92183343 | AR3: 0.88637583 | AS3: 0.91582157 | AT3: 0.95976415 | AU3: 0.99275846 | AV3: 1.0090947 | AW3: 0.98179215 | AX3: 0.96693149 | AY3: 0.97212259 | AZ3: 0.98167364 | BA3: 0.9721503 | BB3: 0.9972466 | BC3: 1 | BD3: 0.99145651 | BE3: 1.1472759
A4: Privat | B4: 0.046737416 | C4: 0.058066092 | D4: 0.06233153 | E4: 0.07032017 | F4: 0.086312447 | G4: 0.093319335 | H4: 0.092401103 | I4: 0.12235016 | J4: 0.14911283 | K4: 0.15637767 | L4: 0.17073687 | M4: 0.18460699 | N4: 0.20450289 | O4: 0.22576788 | P4: 0.2512639 | Q4: 0.28223467 | R4: 0.30595846 | S4: 0.3209648 | T4: 0.34059039 | U4: 0.35716535 | V4: 0.39728275 | W4: 0.43145359 | X4: 0.45352823 | Y4: 0.4905535 | Z4: 0.51813391 | AA4: 0.53247772 | AB4: 0.561046 | AC4: 0.57010487 | AD4: 0.56929693 | AE4: 0.58200495 | AF4: 0.60348694 | AG4: 0.6401067 | AH4: 0.66344612 | AI4: 0.6665968 | AJ4: 0.68449787 | AK4: 0.72133524 | AL4: 0.74547203 | AM4: 0.7648774 | AN4: 0.79514876 | AO4: 0.81331183 | AP4: 0.8340776 | AQ4: 0.85977003 | AR4: 0.9013076 | AS4: 0.90955147 | AT4: 0.88966667 | AU4: 0.89573448 | AV4: 0.90951019 | AW4: 0.91413244 | AX4: 0.91888537 | AY4: 0.9283278 | AZ4: 0.93113726 | BA4: 0.95594607 | BB4: 0.95477694 | BC4: 1 | BD4: 1.0222449 | BE4: 1.0486358
A5: REST | B5: 0.11367524 | C5: 0.11970203 | D5: 0.12712092 | E5: 0.1379434 | F5: 0.14817806 | G5: 0.15925596 | H5: 0.17599834 | I5: 0.21077905 | J5: 0.23578933 | K5: 0.2547441 | L5: 0.27537931 | M5: 0.29513295 | N5: 0.31843116 | O5: 0.35329295 | P5: 0.39662562 | Q5: 0.43949182 | R5: 0.47188153 | S5: 0.49739374 | T5: 0.51982296 | U5: 0.51672073 | V5: 0.53285898 | W5: 0.54884824 | X5: 0.58187566 | Y5: 0.59855472 | Z5: 0.61564213 | AA5: 0.62424257 | AB5: 0.62877082 | AC5: 0.64020326 | AD5: 0.65076452 | AE5: 0.66043461 | AF5: 0.67617658 | AG5: 0.68328877 | AH5: 0.69275442 | AI5: 0.72089398 | AJ5: 0.73839614 | AK5: 0.74851574 | AL5: 0.75647841 | AM5: 0.77184925 | AN5: 0.79589363 | AO5: 0.81825641 | AP5: 0.84085023 | AQ5: 0.87822555 | AR5: 0.86662997 | AS5: 0.89841806 | AT5: 0.91182114 | AU5: 0.93274208 | AV5: 0.94063557 | AW5: 0.94452562 | AX5: 0.94667601 | AY5: 0.93774849 | AZ5: 0.95693456 | BA5: 0.97344332 | BB5: 0.98632641 | BC5: 1 | BD5: 1.0496921 | BE5: 1.1875979

Sheet w
A1: ANVENDELSE | B1: 1966 | C1: 1967 | D1: 1968 | E1: 1969 | F1: 1970 | G1: 1971 | H1: 1972 | I1: 1973 | J1: 1974 | K1: 1975 | L1: 1976 | M1: 1977 | N1: 1978 | O1: 1979 | P1: 1980 | Q1: 1981 | R1: 1982 | S1: 1983 | T1: 1984 | U1: 1985 | V1: 1986 | W1: 1987 | X1: 1988 | Y1: 1989 | Z1: 1990 | AA1: 1991 | AB1: 1992 | AC1: 1993 | AD1: 1994 | AE1: 1995 | AF1: 1996 | AG1: 1997 | AH1: 1998 | AI1: 1999 | AJ1: 2000 | AK1: 2001 | AL1: 2002 | AM1: 2003 | AN1: 2004 | AO1: 2005 | AP1: 2006 | AQ1: 2007 | AR1: 2008 | AS1: 2009 | AT1: 2010 | AU1: 2011 | AV1: 2012 | AW1: 2013 | AX1: 2014 | AY1: 2015 | AZ1: 2016 | BA1: 2017 | BB1: 2018 | BC1: 2019 | BD1: 2020 | BE1: 2021 | BF1: 2022
A2: 01000 | B2: 4.9614659 | C2: 5.3261863 | D2: 5.6442061 | E2: 6.0123327 | F2: 5.8437461 | G2: 6.86028 | H2: 7.0786711 | I2: 7.9727202 | J2: 9.6403693 | K2: 11.505817 | L2: 12.853657 | M2: 14.346346 | N2: 16.749786 | O2: 19.344179 | P2: 22.662031 | Q2: 25.412391 | R2: 28.234244 | S2: 32.004413 | T2: 35.982725 | U2: 39.726702 | V2: 43.975964 | W2: 49.244809 | X2: 54.206254 | Y2: 57.809751 | Z2: 61.150908 | AA2: 62.964672 | AB2: 68.243047 | AC2: 70.472785 | AD2: 72.401971 | AE2: 73.668419 | AF2: 77.602928 | AG2: 82.112148 | AH2: 85.654427 | AI2: 87.363624 | AJ2: 90.147712 | AK2: 91.297341 | AL2: 97.14543 | AM2: 103.01562 | AN2: 108.39572 | AO2: 109.31073 | AP2: 113.52155 | AQ2: 120.93852 | AR2: 127.13193 | AS2: 132.90639 | AT2: 140.4119 | AU2: 143.61532 | AV2: 146.408 | AW2: 150.45915 | AX2: 156.52284 | AY2: 175.97839 | AZ2: 179.46352 | BA2: 182.14425 | BB2: 189.6717 | BC2: 197.71026 | BD2: 205.68694 | BE2: 203.39064 | BF2: 217.89115
A3: 10120 | B3: 10.642166 | C3: 11.953693 | D3: 13.270209 | E3: 14.817641 | F3: 16.770804 | G3: 19.7178 | H3: 22.357043 | I3: 26.961596 | J3: 32.740298 | K3: 40.098082 | L3: 44.334284 | M3: 49.171518 | N3: 54.381386 | O3: 60.086146 | P3: 65.502649 | Q3: 72.561179 | R3: 78.850417 | S3: 85.204956 | T3: 90.681675 | U3: 95.726497 | V3: 100.14818 | W3: 113.00424 | X3: 118.64512 | Y3: 124.33357 | Z3: 131.58692 | AA3: 136.4622 | AB3: 140.12418 | AC3: 142.0781 | AD3: 146.61712 | AE3: 147.38063 | AF3: 152.68933 | AG3: 157.86554 | AH3: 168.62299 | AI3: 166.71729 | AJ3: 171.25747 | AK3: 177.91464 | AL3: 186.38922 | AM3: 198.10179 | AN3: 204.59416 | AO3: 215.89704 | AP3: 225.25355 | AQ3: 239.9327 | AR3: 247.39118 | AS3: 252.65251 | AT3: 262.04289 | AU3: 260.51514 | AV3: 266.62836 | AW3: 271.5241 | AX3: 276.05941 | AY3: 277.41873 | AZ3: 294.32353 | BA3: 299.88461 | BB3: 309.84822 | BC3: 316.77175 | BD3: 314.17493 | BE3: 326.18735 | BF3: 333.34154
A4: Privat | B4: 11.801679 | C4: 13.217943 | D4: 14.700577 | E4: 16.617022 | F4: 18.480593 | G4: 21.024484 | H4: 23.615631 | I4: 27.704198 | J4: 33.112811 | K4: 39.604852 | L4: 44.031643 | M4: 49.684575 | N4: 55.498536 | O4: 61.568814 | P4: 68.355427 | Q4: 76.601542 | R4: 85.073268 | S4: 93.851082 | T4: 100.01256 | U4: 106.42417 | V4: 111.98542 | W4: 123.8581 | X4: 131.95679 | Y4: 139.43383 | Z4: 147.05547 | AA4: 152.72429 | AB4: 156.44921 | AC4: 159.50368 | AD4: 165.15307 | AE4: 169.1089 | AF4: 176.23405 | AG4: 179.40036 | AH4: 184.69813 | AI4: 187.72142 | AJ4: 191.74804 | AK4: 199.21598 | AL4: 208.53061 | AM4: 217.61955 | AN4: 223.21401 | AO4: 232.53252 | AP4: 240.35409 | AQ4: 253.86248 | AR4: 261.64477 | AS4: 270.36987 | AT4: 277.34354 | AU4: 278.37003 | AV4: 284.67993 | AW4: 286.98474 | AX4: 292.92131 | AY4: 300.39259 | AZ4: 300.78671 | BA4: 307.93259 | BB4: 319.38823 | BC4: 325.19495 | BD4: 344.35599 | BE4: 343.33468 | BF4: 351.3681
A5: REST | B5: 11.57843 | C5: 12.994332 | D5: 14.604469 | E5: 16.579907 | F5: 18.656783 | G5: 21.379339 | H5: 23.970374 | I5: 27.734018 | J5: 33.053165 | K5: 39.41599 | L5: 43.800474 | M5: 49.329405 | N5: 54.723886 | O5: 60.128075 | P5: 65.23713 | Q5: 72.806233 | R5: 81.366639 | S5: 88.756504 | T5: 94.018266 | U5: 99.506818 | V5: 103.77431 | W5: 114.86774 | X5: 123.04579 | Y5: 129.6554 | Z5: 136.01277 | AA5: 142.22567 | AB5: 146.13481 | AC5: 149.70152 | AD5: 155.14169 | AE5: 159.2887 | AF5: 166.92529 | AG5: 169.26072 | AH5: 174.44241 | AI5: 179.20911 | AJ5: 184.59864 | AK5: 191.2066 | AL5: 199.7988 | AM5: 207.22356 | AN5: 213.51149 | AO5: 220.49602 | AP5: 227.05593 | AQ5: 238.42066 | AR5: 247.31225 | AS5: 256.32685 | AT5: 263.39882 | AU5: 264.63435 | AV5: 271.6613 | AW5: 275.58602 | AX5: 281.98289 | AY5: 288.79274 | AZ5: 290.27159 | BA5: 296.43418 | BB5: 306.32276 | BC5: 311.95188 | BD5: 327.73115 | BE5: 327.71366 | BF5: 336.59787

Sheet P_K
A1: ANVENDELSE | B1: 1966 | C1: 1967 | D1: 1968 | E1: 1969 | F1: 1970 | G1: 1971 | H1: 1972 | I1: 1973 | J1: 1974 | K1: 1975 | L1: 1976 | M1: 1977 | N1: 1978 | O1: 1979 | P1: 1980 | Q1: 1981 | R1: 1982 | S1: 1983 | T1: 1984 | U1: 1985 | V1: 1986 | W1: 1987 | X1: 1988 | Y1: 1989 | Z1: 1990 | AA1: 1991 | AB1: 1992 | AC1: 1993 | AD1: 1994 | AE1: 1995 | AF1: 1996 | AG1: 1997 | AH1: 1998 | AI1: 1999 | AJ1: 2000 | AK1: 2001 | AL1: 2002 | AM1: 2003 | AN1: 2004 | AO1: 2005 | AP1: 2006 | AQ1: 2007 | AR1: 2008 | AS1: 2009 | AT1: 2010 | AU1: 2011 | AV1: 2012 | AW1: 2013 | AX1: 2014 | AY1: 2015 | AZ1: 2016 | BA1: 2017 | BB1: 2018 | BC1: 2019 | BD1: 2020 | BE1: 2021 | BF1: 2022 | BG1: 2023 | BH1: 2024
A2: 01000 | AD2: 0.060751278 | AE2: 0.069791081 | AF2: 0.085026536 | AG2: 0.070368963 | AH2: 0.067863342 | AI2: 0.088871606 | AJ2: 0.062415609 | AK2: 0.056085129 | AL2: 0.059875374 | AM2: 0.063636068 | AN2: 0.070909567 | AO2: 0.045636799 | AP2: 0.063955834 | AQ2: 0.052150347 | AR2: 0.066197293 | AS2: 0.072959482 | AT2: 0.074747652 | AU2: 0.074345659 | AV2: 0.055688748 | AW2: 0.06165053 | AX2: 0.058095357 | AY2: 0.056166675 | AZ2: 0.046997512 | BA2: 0.063610903 | BB2: 0.093953035 | BC2: 0.069468615 | BD2: 0.068133568 | BE2: 0.10072659 | BF2: 0.065872729
A3: 10120 | AD3: 0.10203538 | AE3: 0.10777479 | AF3: 0.11877328 | AG3: 0.11164507 | AH3: 0.10658308 | AI3: 0.0963468 | AJ3: 0.11085744 | AK3: 0.086690043 | AL3: 0.093857836 | AM3: 0.09654273 | AN3: 0.10400685 | AO3: 0.083365909 | AP3: 0.10278033 | AQ3: 0.074265195 | AR3: 0.098188281 | AS3: 0.10325658 | AT3: 0.10760116 | AU3: 0.10489538 | AV3: 0.095932698 | AW3: 0.095640066 | AX3: 0.078553793 | AY3: 0.07951904 | AZ3: 0.077908112 | BA3: 0.094663324 | BB3: 0.095160056 | BC3: 0.083019975 | BD3: 0.083904178 | BE3: 0.086398922 | BF3: 0.082330124
A4: Privat
A5: REST | AD5: 0.089550877 | AE5: 0.095563278 | AF5: 0.093422145 | AG5: 0.094739862 | AH5: 0.091017427 | AI5: 0.087634851 | AJ5: 0.083132466 | AK5: 0.073182359 | AL5: 0.07897033 | AM5: 0.082359985 | AN5: 0.085365409 | AO5: 0.071647686 | AP5: 0.08076912 | AQ5: 0.066085404 | AR5: 0.081532434 | AS5: 0.098867346 | AT5: 0.098193075 | AU5: 0.090370048 | AV5: 0.080607895 | AW5: 0.085510326 | AX5: 0.08566152 | AY5: 0.081148775 | AZ5: 0.075072538 | BA5: 0.080983122 | BB5: 0.082669874 | BC5: 0.080932536 | BD5: 0.084380497 | BE5: 0.082775737 | BF5: 0.063257686

Sheet KL
A1: ANVENDELSE | B1: 1994 | C1: 1995 | D1: 1996 | E1: 1997 | F1: 1998 | G1: 1999 | H1: 2000 | I1: 2001 | J1: 2002 | K1: 2003 | L1: 2004 | M1: 2005 | N1: 2006 | O1: 2007 | P1: 2008 | Q1: 2009 | R1: 2010 | S1: 2011 | T1: 2012 | U1: 2013 | V1: 2014 | W1: 2015 | X1: 2016 | Y1: 2017 | Z1: 2018 | AA1: 2019 | AB1: 2020 | AC1: 2021 | AD1: 2022
A2: 01000 | B2: 52117.794 | C2: 50900.442 | D2: 49681.538 | E2: 48143.426 | F2: 47708.981 | G2: 46314.405 | H2: 45117.473 | I2: 44432.633 | J2: 44480.111 | K2: 42600.847 | L2: 42241.35 | M2: 40925.503 | N2: 39424.938 | O2: 39026.41 | P2: 38328.713 | Q2: 37355.83 | R2: 36543.067 | S2: 35879.711 | T2: 35222.069 | U2: 34756.946 | V2: 34683.366 | W2: 34775.854 | X2: 33362.229 | Y2: 33300.801 | Z2: 32593.134 | AA2: 31418.74 | AB2: 31265.505 | AC2: 31288.388 | AD2: 30691.04
A3: 10120 | B3: 41053.802 | C3: 41759.501 | D3: 41128.759 | E3: 40942.503 | F3: 40365.296 | G3: 40787.837 | H3: 41003.31 | I3: 41301.986 | J3: 41472.717 | K3: 40135.482 | L3: 39397.689 | M3: 37857.534 | N3: 36744.013 | O3: 35523.214 | P3: 35229.502 | Q3: 33872.477 | R3: 33070.653 | S3: 32127.489 | T3: 31029.396 | U3: 30326.43 | V3: 29083.172 | W3: 28650.367 | X3: 28823.509 | Y3: 29246.826 | Z3: 28738.801 | AA3: 28997.102 | AB3: 30557.868 | AC3: 30574.44 | AD3: 30523.704
A4: REST | B4: 1527969.9 | C4: 1546477.3 | D4: 1561291.6 | E4: 1596610.2 | F4: 1630908.7 | G4: 1664171.9 | H4: 1689272.5 | I4: 1715552.3 | J4: 1720985.9 | K4: 1719611.2 | L4: 1722950.2 | M4: 1745689.9 | N4: 1789467.5 | O4: 1815573.7 | P4: 1843060 | Q4: 1805786.2 | R4: 1790700.5 | S4: 1804084.2 | T4: 1787836.6 | U4: 1794529.7 | V4: 1796799.1 | W4: 1814378.2 | X4: 1848027 | Y4: 1868512.6 | Z4: 1878314 | AA4: 1901400.2 | AB4: 1862622.6 | AC4: 1949504.5 | AD4: 2016873.8

Sheet JKL
A1: ANVENDELSE | B1: 1994 | C1: 1995 | D1: 1996 | E1: 1997 | F1: 1998 | G1: 1999 | H1: 2000 | I1: 2001 | J1: 2002 | K1: 2003 | L1: 2004 | M1: 2005 | N1: 2006 | O1: 2007 | P1: 2008 | Q1: 2009 | R1: 2010 | S1: 2011 | T1: 2012 | U1: 2013 | V1: 2014 | W1: 2015 | X1: 2016 | Y1: 2017 | Z1: 2018 | AA1: 2019 | AB1: 2020 | AC1: 2021 | AD1: 2022
A2: 01000 | B2: 39615.423 | C2: 38703.353 | D2: 37843.795 | E2: 36756.849 | F2: 36466.9 | G2: 35429.093 | H2: 34504.781 | I2: 34006.56 | J2: 34046.776 | K2: 32626.197 | L2: 32344.644 | M2: 31282.764 | N2: 29799.95 | O2: 29463.372 | P2: 28938.182 | Q2: 28443.2 | R2: 27834.982 | S2: 27251.991 | T2: 26664.953 | U2: 26233.149 | V2: 26206.615 | W2: 26195.87 | X2: 25089.115 | Y2: 24975.354 | Z2: 24306.916 | AA2: 23237.553 | AB2: 23089.686 | AC2: 23204.748 | AD2: 22673.607
A3: 10120 | B3: 0 | C3: 0 | D3: 0 | E3: 0 | F3: 0 | G3: 0 | H3: 0 | I3: 0 | J3: 0 | K3: 0 | L3: 0 | M3: 0 | N3: 0 | O3: 0 | P3: 0 | Q3: 0 | R3: 0 | S3: 0 | T3: 0 | U3: 0 | V3: 0 | W3: 0 | X3: 0 | Y3: 0 | Z3: 0 | AA3: 0 | AB3: 0 | AC3: 0 | AD3: 0
A4: REST | B4: 0 | C4: 0 | D4: 0 | E4: 0 | F4: 0 | G4: 0 | H4: 0 | I4: 0 | J4: 0 | K4: 0 | L4: 0 | M4: 0 | N4: 0 | O4: 0 | P4: 0 | Q4: 0 | R4: 0 | S4: 0 | T4: 0 | U4: 0 | V4: 0 | W4: 0 | X4: 0 | Y4: 0 | Z4: 0 | AA4: 0 | AB4: 0 | AC4: 0 | AD4: 0

Sheet P_KL
A1: ANVENDELSE | B1: 1994 | C1: 1995 | D1: 1996 | E1: 1997 | F1: 1998 | G1: 1999 | H1: 2000 | I1: 2001 | J1: 2002 | K1: 2003 | L1: 2004 | M1: 2005 | N1: 2006 | O1: 2007 | P1: 2008 | Q1: 2009 | R1: 2010 | S1: 2011 | T1: 2012 | U1: 2013 | V1: 2014 | W1: 2015 | X1: 2016 | Y1: 2017 | Z1: 2018 | AA1: 2019 | AB1: 2020 | AC1: 2021 | AD1: 2022
A2: 01000 | B2: 0.5694121 | C2: 0.62035501 | D2: 0.71346775 | E2: 0.65078662 | F2: 0.64940884 | G2: 0.76888134 | H2: 0.63509005 | I2: 0.60434501 | J2: 0.64413311 | K2: 0.68386032 | L2: 0.74184557 | M2: 0.59880691 | N2: 0.7204948 | O2: 0.67093704 | P2: 0.77635834 | Q2: 0.83598365 | R2: 0.86793431 | S2: 0.87398331 | T2: 0.76017118 | U2: 0.80984611 | V2: 0.80380746 | W2: 0.84621455 | X2: 0.79660741 | Y2: 0.90949967 | Z2: 1.1242478 | AA2: 0.98676346 | AB2: 1 | AC2: 1.1984003 | AD2: 1.0173887
A3: 10120 | B3: 0.63115103 | C3: 0.64443612 | D3: 0.6816428 | E3: 0.68202981 | F3: 0.70220843 | G3: 0.67554531 | H3: 0.7184454 | I3: 0.68647991 | J3: 0.72568847 | K3: 0.76404035 | L3: 0.79923661 | M3: 0.77670287 | N3: 0.8516072 | O3: 0.81207128 | P3: 0.89659224 | Q3: 0.92442524 | R3: 0.96034766 | S3: 0.94828548 | T3: 0.93424129 | U3: 0.94465941 | V3: 0.8967559 | W3: 0.90316668 | X3: 0.93621212 | Y3: 1.0050415 | Z3: 1.0293892 | AA3: 1.0030241 | AB3: 1 | AC3: 1.0358694 | AD3: 1.0386862
A4: REST | B4: 0.64426937 | C4: 0.67373434 | D4: 0.68326909 | E4: 0.69286435 | F4: 0.69199508 | G4: 0.69138756 | H4: 0.68846437 | I4: 0.67004359 | J4: 0.708581 | K4: 0.73646721 | L4: 0.76056082 | M4: 0.72857669 | N4: 0.77409188 | O4: 0.74840172 | P4: 0.82122482 | Q4: 0.90265454 | R4: 0.91516668 | S4: 0.88942961 | T4: 0.86843753 | U4: 0.89470878 | V4: 0.90871245 | W4: 0.90639536 | X4: 0.88728105 | Y4: 0.92198246 | Z4: 0.94896591 | AA4: 0.95423242 | AB4: 1 | AC4: 0.99393303 | AD4: 0.94007068

Sheet P_JKL
A1: ANVENDELSE | B1: 1994 | C1: 1995 | D1: 1996 | E1: 1997 | F1: 1998 | G1: 1999 | H1: 2000 | I1: 2001 | J1: 2002 | K1: 2003 | L1: 2004 | M1: 2005 | N1: 2006 | O1: 2007 | P1: 2008 | Q1: 2009 | R1: 2010 | S1: 2011 | T1: 2012 | U1: 2013 | V1: 2014 | W1: 2015 | X1: 2016 | Y1: 2017 | Z1: 2018 | AA1: 2019 | AB1: 2020 | AC1: 2021 | AD1: 2022
A2: 01000 | B2: 0.78955065 | C2: 0.86603523 | D2: 0.98633788 | E2: 0.89070213 | F2: 0.87230866 | G2: 1.0602147 | H2: 0.89728176 | I2: 0.81573364 | J2: 0.85435782 | K2: 0.85378233 | L2: 0.9207597 | M2: 0.6713107 | N2: 0.89180965 | O2: 0.92796618 | P2: 1.1712725 | Q2: 1.1292171 | R2: 1.0266244 | S2: 1.0203331 | T2: 0.76705998 | U2: 0.81458429 | V2: 0.82163463 | W2: 0.86560481 | X2: 0.78623653 | Y2: 0.93580081 | Z2: 1.1852182 | AA2: 0.99639826 | AB2: 1 | AC2: 1.2943497 | AD2: 1.1943897
A3: 10120 | B3: 0.91204468 | C3: 0.94214976 | D3: 0.99038459 | E3: 0.97438183 | F3: 0.98142971 | G3: 0.98264568 | H3: 1.0548166 | I3: 0.96482557 | J3: 1.0033153 | K3: 0.99748008 | L3: 1.035665 | M3: 0.93453306 | N3: 1.1041385 | O3: 1.1661255 | P3: 1.4004694 | Q3: 1.3002981 | R3: 1.1830881 | S3: 1.1499318 | T3: 1.0084345 | U3: 1.0009334 | V3: 0.95270531 | W3: 0.94581899 | X3: 0.97567968 | Y3: 1.0703929 | Z3: 1.0588539 | AA3: 1.0189032 | AB3: 1 | AC3: 1.0764477 | AD3: 1.2266574
A4: REST | B4: 0.64831935 | C4: 0.67816131 | D4: 0.68769376 | E4: 0.69702119 | F4: 0.69577508 | G4: 0.69584333 | H4: 0.69315252 | I4: 0.67381809 | J4: 0.71227713 | K4: 0.73929888 | L4: 0.76334433 | M4: 0.73008331 | N4: 0.77681478 | O4: 0.75266041 | P4: 0.8274733 | Q4: 0.90737988 | R4: 0.91769339 | S4: 0.89161937 | T4: 0.86898565 | U4: 0.89511152 | V4: 0.9094009 | W4: 0.90689417 | X4: 0.8875119 | Y4: 0.92235433 | Z4: 0.94895569 | AA4: 0.95420896 | AB4: 1 | AC4: 0.9942285 | AD4: 0.94178693

Sheet P_O
A1: ANVENDELSE | B1: 1967 | C1: 1968 | D1: 1969 | E1: 1970 | F1: 1971 | G1: 1972 | H1: 1973 | I1: 1974 | J1: 1975 | K1: 1976 | L1: 1977 | M1: 1978 | N1: 1979 | O1: 1980 | P1: 1981 | Q1: 1982 | R1: 1983 | S1: 1984 | T1: 1985 | U1: 1986 | V1: 1987 | W1: 1988 | X1: 1989 | Y1: 1990 | Z1: 1991 | AA1: 1992 | AB1: 1993 | AC1: 1994 | AD1: 1995 | AE1: 1996 | AF1: 1997 | AG1: 1998 | AH1: 1999 | AI1: 2000 | AJ1: 2001 | AK1: 2002 | AL1: 2003 | AM1: 2004 | AN1: 2005 | AO1: 2006 | AP1: 2007 | AQ1: 2008 | AR1: 2009 | AS1: 2010 | AT1: 2011 | AU1: 2012 | AV1: 2013 | AW1: 2014 | AX1: 2015 | AY1: 2016 | AZ1: 2017 | BA1: 2018 | BB1: 2019 | BC1: 2020 | BD1: 2021 | BE1: 2022
A2: 01000 | AC2: 1.0481703 | AD2: 1.0702537 | AE2: 1.1255544 | AF2: 1.0597685 | AG2: 1.0145974 | AH2: 1.1044605 | AI2: 1.0185723 | AJ2: 0.99001938 | AK2: 0.99229024 | AL2: 0.95947773 | AM2: 0.98414178 | AN2: 0.86876256 | AO2: 0.94142877 | AP2: 0.97556454 | AQ2: 1.2341753 | AR2: 1.1697522 | AS2: 1.0623945 | AT2: 1.1609966 | AU2: 1.0550088 | AV2: 1.0976547 | AW2: 1.0181562 | AX2: 1.0744671 | AY2: 1.0431754 | AZ2: 1.0623164 | BA2: 1.1647028 | BB2: 1.086338 | BC2: 1.0668641 | BD2: 1.1916317 | BE2: 1.3759215
A3: 10120 | AC3: 1.0008822 | AD3: 1.0085012 | AE3: 1.0559933 | AF3: 1.0566874 | AG3: 0.98781958 | AH3: 0.94038916 | AI3: 1.0204709 | AJ3: 1.0599885 | AK3: 1.0446186 | AL3: 1.0304986 | AM3: 1.0454927 | AN3: 1.0123571 | AO3: 1.0603867 | AP3: 1.0926712 | AQ3: 1.2060375 | AR3: 1.1257863 | AS3: 1.2011039 | AT3: 1.2726798 | AU3: 1.3227445 | AV3: 1.3384965 | AW3: 1.2777617 | AX3: 1.2150675 | AY3: 1.2074075 | AZ3: 1.2764247 | BA3: 1.244958 | BB3: 1.2747509 | BC3: 1.2944683 | BD3: 1.2843866 | BE3: 1.4906053
A4: Privat
A5: REST | AC5: 0.70001894 | AD5: 0.72001034 | AE5: 0.71972554 | AF5: 0.72717973 | AG5: 0.72753329 | AH5: 0.7230466 | AI5: 0.71500177 | AJ5: 0.71204119 | AK5: 0.73670825 | AL5: 0.75014391 | AM5: 0.75986266 | AN5: 0.74465426 | AO5: 0.7698258 | AP5: 0.76550124 | AQ5: 0.82315055 | AR5: 0.87517631 | AS5: 0.88223278 | AT5: 0.87102648 | AU5: 0.86297282 | AV5: 0.87426604 | AW5: 0.87674347 | AX5: 0.86800637 | AY5: 0.84721538 | AZ5: 0.86648764 | BA5: 0.88173345 | BB5: 0.8873298 | BC5: 0.91450732 | BD5: 0.92524633 | BE5: 0.96484612

Sheet mu_Y_Mtot
A1: ANVENDELSE | B1: 1967 | C1: 1968 | D1: 1969 | E1: 1970 | F1: 1971 | G1: 1972 | H1: 1973 | I1: 1974 | J1: 1975 | K1: 1976 | L1: 1977 | M1: 1978 | N1: 1979 | O1: 1980 | P1: 1981 | Q1: 1982 | R1: 1983 | S1: 1984 | T1: 1985 | U1: 1986 | V1: 1987 | W1: 1988 | X1: 1989 | Y1: 1990 | Z1: 1991 | AA1: 1992 | AB1: 1993 | AC1: 1994 | AD1: 1995 | AE1: 1996 | AF1: 1997 | AG1: 1998 | AH1: 1999 | AI1: 2000 | AJ1: 2001 | AK1: 2002 | AL1: 2003 | AM1: 2004 | AN1: 2005 | AO1: 2006 | AP1: 2007 | AQ1: 2008 | AR1: 2009 | AS1: 2010 | AT1: 2011 | AU1: 2012 | AV1: 2013 | AW1: 2014 | AX1: 2015 | AY1: 2016 | AZ1: 2017 | BA1: 2018 | BB1: 2019 | BC1: 2020 | BD1: 2021 | BE1: 2022
A2: 01000 | AC2: 0.48608435 | AD2: 0.47033694 | AE2: 0.44652322 | AF2: 0.4971519 | AG2: 0.4938984 | AH2: 0.44860399 | AI2: 0.51869323 | AJ2: 0.55300826 | AK2: 0.54980135 | AL2: 0.56149101 | AM2: 0.55015161 | AN2: 0.64574064 | AO2: 0.5892595 | AP2: 0.62243119 | AQ2: 0.57924719 | AR2: 0.57753376 | AS2: 0.6231667 | AT2: 0.65303766 | AU2: 0.7446747 | AV2: 0.73388333 | AW2: 0.73555756 | AX2: 0.71746974 | AY2: 0.73645887 | AZ2: 0.70822481 | BA2: 0.65861919 | BB2: 0.71437305 | BC2: 0.7198016 | BD2: 0.67593882 | BE2: 0.74462835
A3: 10120 | AC3: 0.76992307 | AD3: 0.76550052 | AE3: 0.75243245 | AF3: 0.75887245 | AG3: 0.74551999 | AH3: 0.74287998 | AI3: 0.74596958 | AJ3: 0.76909459 | AK3: 0.74168954 | AL3: 0.72967119 | AM3: 0.73307809 | AN3: 0.75887897 | AO3: 0.74834995 | AP3: 0.76609168 | AQ3: 0.76449214 | AR3: 0.74690179 | AS3: 0.74768245 | AT3: 0.7700835 | AU3: 0.78461889 | AV3: 0.78948896 | AW3: 0.79748332 | AX3: 0.78665553 | AY3: 0.78323096 | AZ3: 0.78755508 | BA3: 0.7795091 | BB3: 0.79123377 | BC3: 0.7911389 | BD3: 0.79228311 | BE3: 0.82863163
A4: Privat
A5: REST | AC5: 0.35998307 | AD5: 0.36547929 | AE5: 0.37419991 | AF5: 0.38002212 | AG5: 0.38790611 | AH5: 0.40182327 | AI5: 0.42607985 | AJ5: 0.44970617 | AK5: 0.43865642 | AL5: 0.4271346 | AM5: 0.42873591 | AN5: 0.4723839 | AO5: 0.47374126 | AP5: 0.50352539 | AQ5: 0.48665148 | AR5: 0.43096092 | AS5: 0.43585668 | AT5: 0.46207051 | AU5: 0.48409611 | AV5: 0.47137486 | AW5: 0.47476998 | AX5: 0.47958174 | AY5: 0.49076778 | AZ5: 0.49001903 | BA5: 0.49201318 | BB5: 0.4948973 | BC5: 0.47799602 | BD5: 0.50306139 | BE5: 0.56083653

Sheet mu_Y_KL
A1: ANVENDELSE | B1: 1967 | C1: 1968 | D1: 1969 | E1: 1970 | F1: 1971 | G1: 1972 | H1: 1973 | I1: 1974 | J1: 1975 | K1: 1976 | L1: 1977 | M1: 1978 | N1: 1979 | O1: 1980 | P1: 1981 | Q1: 1982 | R1: 1983 | S1: 1984 | T1: 1985 | U1: 1986 | V1: 1987 | W1: 1988 | X1: 1989 | Y1: 1990 | Z1: 1991 | AA1: 1992 | AB1: 1993 | AC1: 1994 | AD1: 1995 | AE1: 1996 | AF1: 1997 | AG1: 1998 | AH1: 1999 | AI1: 2000 | AJ1: 2001 | AK1: 2002 | AL1: 2003 | AM1: 2004 | AN1: 2005 | AO1: 2006 | AP1: 2007 | AQ1: 2008 | AR1: 2009 | AS1: 2010 | AT1: 2011 | AU1: 2012 | AV1: 2013 | AW1: 2014 | AX1: 2015 | AY1: 2016 | AZ1: 2017 | BA1: 2018 | BB1: 2019 | BC1: 2020 | BD1: 2021 | BE1: 2022
A2: 01000 | AC2: 0.34239896 | AD2: 0.35921735 | AE2: 0.39081312 | AF2: 0.35385853 | AG2: 0.36511436 | AH2: 0.39526057 | AI2: 0.32786396 | AJ2: 0.31803018 | AK2: 0.34004633 | AL2: 0.3671127 | AM2: 0.38684896 | AN2: 0.34002793 | AO2: 0.36824488 | AP2: 0.303045 | AQ2: 0.28690695 | AR2: 0.32865169 | AS2: 0.36332189 | AT2: 0.32692888 | AU2: 0.29635153 | AV2: 0.30560992 | AW2: 0.31735155 | AX2: 0.32186088 | AY2: 0.30521466 | AZ2: 0.3371717 | BA2: 0.39045867 | BB2: 0.35369206 | BC2: 0.35703337 | BD2: 0.38123107 | BE2: 0.25439958
A3: 10120 | AC3: 0.14852343 | AD3: 0.1543401 | AE3: 0.1610648 | AF3: 0.15867378 | AG3: 0.17260895 | AH3: 0.1771121 | AI3: 0.1732567 | AJ3: 0.15355914 | AK3: 0.16573496 | AL3: 0.1728528 | AM3: 0.17379501 | AN3: 0.16375993 | AO3: 0.17038002 | AP3: 0.15088298 | AQ3: 0.15153803 | AR3: 0.17379315 | AS3: 0.1708575 | AT3: 0.15037844 | AU3: 0.13848095 | AV3: 0.13343435 | AW3: 0.12619127 | AX3: 0.13268506 | AY3: 0.13982115 | AZ3: 0.13964197 | BA3: 0.14607183 | BB3: 0.13645507 | BC3: 0.1353818 | BD3: 0.13988775 | BE3: 0.11305953
A4: Privat
A5: REST | AC5: 0.6131777 | AD5: 0.6108843 | AE5: 0.60682608 | AF5: 0.60373095 | AG5: 0.59767547 | AH5: 0.58740794 | AI5: 0.57143835 | AJ5: 0.54905484 | AK5: 0.56047457 | AL5: 0.57417099 | AM5: 0.57627291 | AN5: 0.53644777 | AO5: 0.53872982 | AP5: 0.51101375 | AQ5: 0.52662905 | AR5: 0.57734677 | AS5: 0.57592598 | AT5: 0.55343604 | AU5: 0.53344951 | AV5: 0.54656134 | AW5: 0.54495432 | AX5: 0.54142826 | AY5: 0.53303627 | AZ5: 0.53651577 | BA5: 0.53676153 | BB5: 0.53421831 | BC5: 0.54859527 | BD5: 0.52641561 | BE5: 0.46638277

Sheet mu_Y_JKL
A1: ANVENDELSE | B1: 1967 | C1: 1968 | D1: 1969 | E1: 1970 | F1: 1971 | G1: 1972 | H1: 1973 | I1: 1974 | J1: 1975 | K1: 1976 | L1: 1977 | M1: 1978 | N1: 1979 | O1: 1980 | P1: 1981 | Q1: 1982 | R1: 1983 | S1: 1984 | T1: 1985 | U1: 1986 | V1: 1987 | W1: 1988 | X1: 1989 | Y1: 1990 | Z1: 1991 | AA1: 1992 | AB1: 1993 | AC1: 1994 | AD1: 1995 | AE1: 1996 | AF1: 1997 | AG1: 1998 | AH1: 1999 | AI1: 2000 | AJ1: 2001 | AK1: 2002 | AL1: 2003 | AM1: 2004 | AN1: 2005 | AO1: 2006 | AP1: 2007 | AQ1: 2008 | AR1: 2009 | AS1: 2010 | AT1: 2011 | AU1: 2012 | AV1: 2013 | AW1: 2014 | AX1: 2015 | AY1: 2016 | AZ1: 2017 | BA1: 2018 | BB1: 2019 | BC1: 2020 | BD1: 2021 | BE1: 2022
A2: 01000 | AC2: 0.39806134 | AD2: 0.42145207 | AE2: 0.45353996 | AF2: 0.40626836 | AG2: 0.40956723 | AH2: 0.45911584 | AI2: 0.3929613 | AJ2: 0.35947727 | AK2: 0.37576095 | AL2: 0.37518141 | AM2: 0.39227322 | AN2: 0.30154594 | AO2: 0.36729494 | AP2: 0.34876786 | AQ2: 0.36971113 | AR2: 0.36992142 | AS2: 0.34425454 | AT2: 0.30367782 | AU2: 0.22700031 | AV2: 0.23241805 | AW2: 0.24672606 | AX2: 0.24969747 | AY2: 0.22565098 | AZ2: 0.26242379 | BA2: 0.31188607 | BB2: 0.26491882 | BC2: 0.26367041 | BD2: 0.31251191 | BE2: 0.23151668
A3: 10120 | AC3: 0.14852343 | AD3: 0.1543401 | AE3: 0.1610648 | AF3: 0.15867378 | AG3: 0.17260895 | AH3: 0.1771121 | AI3: 0.1732567 | AJ3: 0.15355914 | AK3: 0.16573496 | AL3: 0.1728528 | AM3: 0.17379501 | AN3: 0.16375993 | AO3: 0.17038002 | AP3: 0.15088298 | AQ3: 0.15153803 | AR3: 0.17379315 | AS3: 0.1708575 | AT3: 0.15037844 | AU3: 0.13848095 | AV3: 0.13343435 | AW3: 0.12619127 | AX3: 0.13268506 | AY3: 0.13982115 | AZ3: 0.13964197 | BA3: 0.14607183 | BB3: 0.13645507 | BC3: 0.1353818 | BD3: 0.13988775 | BE3: 0.11305953
A4: Privat
A5: REST | AC5: 0.6131777 | AD5: 0.6108843 | AE5: 0.60682608 | AF5: 0.60373095 | AG5: 0.59767547 | AH5: 0.58740794 | AI5: 0.57143835 | AJ5: 0.54905484 | AK5: 0.56047457 | AL5: 0.57417099 | AM5: 0.57627291 | AN5: 0.53644777 | AO5: 0.53872982 | AP5: 0.51101375 | AQ5: 0.52662905 | AR5: 0.57734677 | AS5: 0.57592598 | AT5: 0.55343604 | AU5: 0.53344951 | AV5: 0.54656134 | AW5: 0.54495432 | AX5: 0.54142826 | AY5: 0.53303627 | AZ5: 0.53651577 | BA5: 0.53676153 | BB5: 0.53421831 | BC5: 0.54859527 | BD5: 0.52641561 | BE5: 0.46638277

Sheet mu_JKL_J
A1: ANVENDELSE | B1: 1966 | C1: 1967 | D1: 1968 | E1: 1969 | F1: 1970 | G1: 1971 | H1: 1972 | I1: 1973 | J1: 1974 | K1: 1975 | L1: 1976 | M1: 1977 | N1: 1978 | O1: 1979 | P1: 1980 | Q1: 1981 | R1: 1982 | S1: 1983 | T1: 1984 | U1: 1985 | V1: 1986 | W1: 1987 | X1: 1988 | Y1: 1989 | Z1: 1990 | AA1: 1991 | AB1: 1992 | AC1: 1993 | AD1: 1994 | AE1: 1995 | AF1: 1996 | AG1: 1997 | AH1: 1998 | AI1: 1999 | AJ1: 2000 | AK1: 2001 | AL1: 2002 | AM1: 2003 | AN1: 2004 | AO1: 2005 | AP1: 2006 | AQ1: 2007 | AR1: 2008 | AS1: 2009 | AT1: 2010 | AU1: 2011 | AV1: 2012 | AW1: 2013 | AX1: 2014 | AY1: 2015 | AZ1: 2016 | BA1: 2017 | BB1: 2018 | BC1: 2019 | BD1: 2020 | BE1: 2021 | BF1: 2022 | BG1: 2023 | BH1: 2024 | BI1: 2025
A2: 01000 | AD2: 5.8735534e-05 | AE2: 5.9108212e-05 | AF2: 6.0816363e-05 | AG2: 6.3457071e-05 | AH2: 6.5073094e-05 | AI2: 6.700849e-05 | AJ2: 6.6700467e-05 | AK2: 6.7322393e-05 | AL2: 6.7554414e-05 | AM2: 6.9981801e-05 | AN2: 7.0289164e-05 | AO2: 7.2749006e-05 | AP2: 7.8479193e-05 | AQ2: 7.9940849e-05 | AR2: 8.003737e-05 | AS2: 8.4884999e-05 | AT2: 8.602294e-05 | AU2: 8.8499993e-05 | AV2: 9.1064702e-05 | AW2: 9.2236316e-05 | AX2: 9.1812468e-05 | AY2: 9.3053829e-05 | AZ2: 9.3731124e-05 | BA2: 9.4714855e-05 | BB2: 9.7064804e-05 | BC2: 0.0001008462 | BD2: 0.00010144196 | BE2: 9.980091e-05 | BF2: 0.00010175029

Sheet mu_JKL_KL
A1: ANVENDELSE | B1: 1994 | C1: 1995 | D1: 1996 | E1: 1997 | F1: 1998 | G1: 1999 | H1: 2000 | I1: 2001 | J1: 2002 | K1: 2003 | L1: 2004 | M1: 2005 | N1: 2006 | O1: 2007 | P1: 2008 | Q1: 2009 | R1: 2010 | S1: 2011 | T1: 2012 | U1: 2013 | V1: 2014 | W1: 2015 | X1: 2016 | Y1: 2017 | Z1: 2018 | AA1: 2019 | AB1: 2020 | AC1: 2021 | AD1: 2022
A2: 01000 | B2: 1.3155935 | C2: 1.315143 | D2: 1.3128054 | E2: 1.3097811 | F2: 1.3082818 | G2: 1.3072422 | H2: 1.3075716 | I2: 1.3065901 | J2: 1.3064412 | K2: 1.3057252 | L2: 1.3059766 | M2: 1.3082445 | N2: 1.3229867 | O2: 1.3245738 | P2: 1.3245031 | Q2: 1.3133484 | R2: 1.3128468 | S2: 1.3165905 | T2: 1.3209125 | U2: 1.3249247 | V2: 1.3234584 | W2: 1.3275319 | X2: 1.3297491 | Y2: 1.3333465 | Z2: 1.3408996 | AA2: 1.3520675 | AB2: 1.3540897 | AC2: 1.3483615 | AD2: 1.353602

Sheet mu_KL_K
A1: ANVENDELSE | B1: 1966 | C1: 1967 | D1: 1968 | E1: 1969 | F1: 1970 | G1: 1971 | H1: 1972 | I1: 1973 | J1: 1974 | K1: 1975 | L1: 1976 | M1: 1977 | N1: 1978 | O1: 1979 | P1: 1980 | Q1: 1981 | R1: 1982 | S1: 1983 | T1: 1984 | U1: 1985 | V1: 1986 | W1: 1987 | X1: 1988 | Y1: 1989 | Z1: 1990 | AA1: 1991 | AB1: 1992 | AC1: 1993 | AD1: 1994 | AE1: 1995 | AF1: 1996 | AG1: 1997 | AH1: 1998 | AI1: 1999 | AJ1: 2000 | AK1: 2001 | AL1: 2002 | AM1: 2003 | AN1: 2004 | AO1: 2005 | AP1: 2006 | AQ1: 2007 | AR1: 2008 | AS1: 2009 | AT1: 2010 | AU1: 2011 | AV1: 2012 | AW1: 2013 | AX1: 2014 | AY1: 2015 | AZ1: 2016 | BA1: 2017 | BB1: 2018 | BC1: 2019 | BD1: 2020 | BE1: 2021 | BF1: 2022 | BG1: 2023 | BH1: 2024
A2: 01000 | AD2: 2.0786514 | AE2: 2.1431597 | AF2: 2.2249409 | AG2: 2.1817657 | AH2: 2.1527425 | AI2: 2.2853422 | AJ2: 2.1359542 | AK2: 2.1053013 | AL2: 2.1047164 | AM2: 2.1806131 | AN2: 2.2034878 | AO2: 2.0601139 | AP2: 2.2595281 | AQ2: 2.1751952 | AR2: 2.3322984 | AS2: 2.4448275 | AT2: 2.4529054 | AU2: 2.4343705 | AV2: 2.2864322 | AW2: 2.3116832 | AX2: 2.2379934 | AY2: 2.1228886 | AZ2: 2.0799679 | BA2: 2.1893327 | BB2: 2.3677551 | BC2: 2.249139 | BD2: 2.1922124 | BE2: 2.3325298 | BF2: 2.1199641
A3: 10120 | AD3: 0.93358685 | AE3: 0.93881639 | AF3: 0.97753754 | AG3: 0.98758595 | AH3: 0.97637337 | AI3: 0.95140168 | AJ3: 0.97609962 | AK3: 0.91921148 | AL3: 0.94530791 | AM3: 0.98638043 | AN3: 1.0447321 | AO3: 1.035009 | AP3: 1.1202589 | AQ3: 1.0366637 | AR3: 1.1321903 | AS3: 1.2238458 | AT3: 1.2858097 | AU3: 1.288928 | AV3: 1.2783099 | AW3: 1.31196 | AX3: 1.2868946 | AY3: 1.3049166 | AZ3: 1.2598013 | BA3: 1.3005854 | BB3: 1.31747 | BC3: 1.2772013 | BD3: 1.2329037 | BE3: 1.2277121 | BF3: 1.2106351
A4: Privat
A5: REST | AD5: 1.5838077 | AE5: 1.5852989 | AF5: 1.5613515 | AG5: 1.5436366 | AH5: 1.5065771 | AI5: 1.4761943 | AJ5: 1.443981 | AK5: 1.3878397 | AL5: 1.4137161 | AM5: 1.4328275 | AN5: 1.447282 | AO5: 1.3696933 | AP5: 1.387709 | AQ5: 1.3082482 | AR5: 1.377364 | AS5: 1.4831445 | AT5: 1.4940458 | AU5: 1.4547914 | AV5: 1.4197178 | AW5: 1.4378626 | AX5: 1.4364254 | AY5: 1.4058212 | AZ5: 1.3639809 | BA5: 1.3898938 | BB5: 1.4010078 | BC5: 1.3931886 | BD5: 1.4396686 | BE5: 1.3902705 | BF5: 1.2614449

Sheet mu_KL_L
A1: ANVENDELSE | B1: 1966 | C1: 1967 | D1: 1968 | E1: 1969 | F1: 1970 | G1: 1971 | H1: 1972 | I1: 1973 | J1: 1974 | K1: 1975 | L1: 1976 | M1: 1977 | N1: 1978 | O1: 1979 | P1: 1980 | Q1: 1981 | R1: 1982 | S1: 1983 | T1: 1984 | U1: 1985 | V1: 1986 | W1: 1987 | X1: 1988 | Y1: 1989 | Z1: 1990 | AA1: 1991 | AB1: 1992 | AC1: 1993 | AD1: 1994 | AE1: 1995 | AF1: 1996 | AG1: 1997 | AH1: 1998 | AI1: 1999 | AJ1: 2000 | AK1: 2001 | AL1: 2002 | AM1: 2003 | AN1: 2004 | AO1: 2005 | AP1: 2006 | AQ1: 2007 | AR1: 2008 | AS1: 2009 | AT1: 2010 | AU1: 2011 | AV1: 2012 | AW1: 2013 | AX1: 2014 | AY1: 2015 | AZ1: 2016 | BA1: 2017 | BB1: 2018 | BC1: 2019 | BD1: 2020 | BE1: 2021 | BF1: 2022
A2: 01000 | AD2: 0.024962906 | AE2: 0.024018563 | AF2: 0.022728751 | AG2: 0.023348268 | AH2: 0.023757764 | AI2: 0.021833095 | AJ2: 0.023974389 | AK2: 0.024342285 | AL2: 0.024349192 | AM2: 0.023449102 | AN2: 0.023172616 | AO2: 0.024632275 | AP2: 0.022642114 | AQ2: 0.023486954 | AR2: 0.021936036 | AS2: 0.020726069 | AT2: 0.020635373 | AU2: 0.020835592 | AV2: 0.022282684 | AW2: 0.022051458 | AX2: 0.022722762 | AY2: 0.023701255 | AZ2: 0.023998196 | BA2: 0.023129336 | BB2: 0.021472654 | BC2: 0.022543853 | BD2: 0.023021444 | BE2: 0.021677675 | BF2: 0.023555633
A3: 10120 | AD3: 0.026146995 | AE3: 0.026077894 | AF3: 0.025565342 | AG3: 0.025418804 | AH3: 0.02555044 | AI3: 0.025843364 | AJ3: 0.025549659 | AK3: 0.026168696 | AL3: 0.02589909 | AM3: 0.025466833 | AN3: 0.024864383 | AO3: 0.024898599 | AP3: 0.024111405 | AQ3: 0.024808922 | AR3: 0.024011331 | AS3: 0.02317616 | AT3: 0.022602044 | AU3: 0.02257271 | AV3: 0.022658492 | AW3: 0.022369264 | AX3: 0.022541711 | AY3: 0.022407295 | AZ3: 0.022740091 | BA3: 0.022424362 | BB3: 0.022289741 | BC3: 0.022583264 | BD3: 0.022897371 | BE3: 0.022934582 | BF3: 0.023052867
A4: Privat
A5: REST | AD5: 0.019617635 | AE5: 0.019582384 | AF5: 0.019824639 | AG5: 0.019991882 | AH5: 0.020342551 | AI5: 0.020613827 | AJ5: 0.020906191 | AK5: 0.021394063 | AL5: 0.021144718 | AM5: 0.020959631 | AN5: 0.020815042 | AO5: 0.021470654 | AP5: 0.021309581 | AQ5: 0.021917215 | AR5: 0.021379136 | AS5: 0.020485285 | AT5: 0.020383275 | AU5: 0.020718787 | AV5: 0.020992603 | AW5: 0.020851987 | AX5: 0.020861349 | AY5: 0.021090324 | AZ5: 0.021391633 | BA5: 0.021202945 | BB5: 0.021118884 | BC5: 0.021171451 | BD5: 0.020842421 | BE5: 0.021188418 | BF5: 0.022017563

Sheet markup
A1: ANVENDELSE | B1: 1966 | C1: 1967 | D1: 1968 | E1: 1969 | F1: 1970 | G1: 1971 | H1: 1972 | I1: 1973 | J1: 1974 | K1: 1975 | L1: 1976 | M1: 1977 | N1: 1978 | O1: 1979 | P1: 1980 | Q1: 1981 | R1: 1982 | S1: 1983 | T1: 1984 | U1: 1985 | V1: 1986 | W1: 1987 | X1: 1988 | Y1: 1989 | Z1: 1990 | AA1: 1991 | AB1: 1992 | AC1: 1993 | AD1: 1994 | AE1: 1995 | AF1: 1996 | AG1: 1997 | AH1: 1998 | AI1: 1999 | AJ1: 2000 | AK1: 2001 | AL1: 2002 | AM1: 2003 | AN1: 2004 | AO1: 2005 | AP1: 2006 | AQ1: 2007 | AR1: 2008 | AS1: 2009 | AT1: 2010 | AU1: 2011 | AV1: 2012 | AW1: 2013 | AX1: 2014 | AY1: 2015 | AZ1: 2016 | BA1: 2017 | BB1: 2018 | BC1: 2019 | BD1: 2020 | BE1: 2021 | BF1: 2022
A2: 01000 | AD2: -0.21886022 | AE2: -0.20511718 | AF2: -0.23157808 | AG2: -0.18764222 | AH2: -0.24873654 | AI2: -0.32263535 | AJ2: -0.19924693 | AK2: -0.11993927 | AL2: -0.19714816 | AM2: -0.1898521 | AN2: -0.18782171 | AO2: -0.17593556 | AP2: -0.21657991 | AQ2: -0.21311905 | AR2: -0.32476423 | AS2: -0.30683595 | AT2: -0.20033201 | AU2: -0.17606056 | AV2: -0.022590822 | AW2: -0.1032409 | AX2: -0.069556225 | AY2: -0.17852141 | AZ2: -0.14649833 | BA2: -0.091412013 | BB2: -0.20473721 | BC2: -0.080889231 | BD2: -0.043245158 | BE2: -0.15874973 | BF2: -0.1315978
