Workbook

Sheet 01000
A1: Mængder | C1: 1993 | D1: 1994 | E1: 1995 | F1: 1996 | G1: 1997 | H1: 1998 | I1: 1999 | J1: 2000 | K1: 2001 | L1: 2002 | M1: 2003 | N1: 2004 | O1: 2005 | P1: 2006 | Q1: 2007 | R1: 2008 | S1: 2009 | T1: 2010 | U1: 2011 | V1: 2012 | W1: 2013 | X1: 2014 | Y1: 2015 | Z1: 2016 | AA1: 2017 | AB1: 2018 | AC1: 2019 | AD1: 2020 | AE1: 2021 | AF1: 2022
A2: Y | C2: =Y!AB4 -> 69638.69 | D2: =Y!AC4 -> 68856.807 | E2: =Y!AD4 -> 69737.096 | F2: =Y!AE4 -> 70280.702 | G2: =Y!AF4 -> 72177.731 | H2: =Y!AG4 -> 73158.199 | I2: =Y!AH4 -> 73173.611 | J2: =Y!AI4 -> 74464.21 | ... AF2: =Y!BE4 -> 81481.018
A3: Mtot | C3: =M_tot!AB4 -> 58815.855 | D3: =M_tot!AC4 -> 57920.723 | E3: =M_tot!AD4 -> 58130.609 | F3: =M_tot!AE4 -> 59331.138 | G3: =M_tot!AF4 -> 62338.487 | H3: =M_tot!AG4 -> 64918.017 | I3: =M_tot!AH4 -> 66099.123 | J3: =M_tot!AI4 -> 65171.865 | ... AF3: =M_tot!BE4 -> 52153.994
A4: MDtot | C4: =MDtot!AB4 -> 40169.914 | D4: =MDtot!AC4 -> 39171.124 | E4: =MDtot!AD4 -> 38654.183 | F4: =MDtot!AE4 -> 38488.072 | G4: =MDtot!AF4 -> 39980.752 | H4: =MDtot!AG4 -> 40065.075 | I4: =MDtot!AH4 -> 41213.409 | J4: =MDtot!AI4 -> 39869.067 | ... AF4: =MDtot!BE4 -> 42512.469
A5: MFtot | C5: =MFtot!AB4 -> 12232.502 | D5: =MFtot!AC4 -> 11218.161 | E5: =MFtot!AD4 -> 10511.072 | F5: =MFtot!AE4 -> 9836.3247 | G5: =MFtot!AF4 -> 10011.355 | H5: =MFtot!AG4 -> 11135.292 | I5: =MFtot!AH4 -> 10713.711 | J5: =MFtot!AI4 -> 10401.888 | ... AF5: =MFtot!BE4 -> 10684.743
A6: JKL | C6: =JKL!B4 -> 64494.017 | D6: =JKL!C4 -> 61394.762 | E6: =JKL!D4 -> 60299.504 | F6: =JKL!E4 -> 59681.765 | G6: =JKL!F4 -> 58957.258 | H6: =JKL!G4 -> 58903.895 | I6: =JKL!H4 -> 58150.047 | J6: =JKL!I4 -> 56506.64 | ... AF6: =JKL!AE4 -> 47162.558
A7: KL | C7: =KL!B4 -> 49999.608 | D7: =KL!C4 -> 48351.425 | E7: =KL!D4 -> 47471.354 | F7: =KL!E4 -> 46680.113 | G7: =KL!F4 -> 45637.233 | H7: =KL!G4 -> 45231.472 | I7: =KL!H4 -> 44372.399 | J7: =KL!I4 -> 43165.21 | ... AF7: =KL!AE4 -> 32114.78
A8: MD | B8: 01000 | C8: =M_D!AC4 -> 10515.091 | D8: =M_D!AD4 -> 10348.109 | E8: =M_D!AE4 -> 10887.235 | F8: =M_D!AF4 -> 11408.106 | G8: =M_D!AG4 -> 11468.928 | H8: =M_D!AH4 -> 11366.961 | I8: =M_D!AI4 -> 12541.535 | J8: =M_D!AJ4 -> 12348.996 | ... AF8: =M_D!BF4 -> 11377.674
B9: 10120 | C9: =M_D!AC5 -> 4022.3888 | D9: =M_D!AD5 -> 3945.5878 | E9: =M_D!AE5 -> 4071.0425 | F9: =M_D!AF5 -> 3479.085 | G9: =M_D!AG5 -> 3723.5773 | H9: =M_D!AH5 -> 3696.5954 | I9: =M_D!AI5 -> 3468.9447 | J9: =M_D!AJ5 -> 3150.118 | ... AF9: =M_D!BF5 -> 10400.685
B10: REST | C10: =M_D!AC6 -> 26470.824 | D10: =M_D!AD6 -> 25674.114 | E10: =M_D!AE6 -> 24362.444 | F10: =M_D!AF6 -> 24081.286 | G10: =M_D!AG6 -> 25366.734 | H10: =M_D!AH6 -> 25601.393 | I10: =M_D!AI6 -> 25678.757 | J10: =M_D!AJ6 -> 24772.285 | ... AF10: =M_D!BF6 -> 20752.792
A11: M_F | B11: 01000 | C11: =M_F!AC4 -> 684.61314 | D11: =M_F!AD4 -> 539.41007 | E11: =M_F!AE4 -> 551.38119 | F11: =M_F!AF4 -> 526.29729 | G11: =M_F!AG4 -> 514.50158 | H11: =M_F!AH4 -> 750.44625 | I11: =M_F!AI4 -> 742.33836 | J11: =M_F!AJ4 -> 807.85043 | ... AF11: =M_F!BF4 -> 904.15457
B12: 10120 | C12: =M_F!AC5 -> 6475.2934 | D12: =M_F!AD5 -> 6417.0224 | E12: =M_F!AE5 -> 5809.5681 | F12: =M_F!AF5 -> 5207.4533 | G12: =M_F!AG5 -> 5169.0392 | H12: =M_F!AH5 -> 5769.2418 | I12: =M_F!AI5 -> 5155.4147 | J12: =M_F!AJ5 -> 5390.7143 | ... AF12: =M_F!BF5 -> 5832.7793
B13: REST | C13: =M_F!AC6 -> 5095.0533 | D13: =M_F!AD6 -> 4224.9361 | E13: =M_F!AE6 -> 4123.1343 | F13: =M_F!AF6 -> 4100.3871 | G13: =M_F!AG6 -> 4400.2278 | H13: =M_F!AH6 -> 4513.1561 | I13: =M_F!AI6 -> 4785.3657 | J13: =M_F!AJ6 -> 4078.6806 | ... AF13: =M_F!BF6 -> 3971.3521
A14: L | C14: =L!AC4/1000 -> 205.929 | D14: =L!AD4/1000 -> 187.306 | E14: =L!AE4/1000 -> 180.889 | F14: =L!AF4/1000 -> 173.049 | G14: =L!AG4/1000 -> 162.332 | H14: =L!AH4/1000 -> 160.81 | I14: =L!AI4/1000 -> 152.28 | J14: =L!AJ4/1000 -> 149.02 | ... AF14: =L!BF4/1000 -> 84.49
A15: J | C15: =J!M4 -> 303379.47 | D15: =J!N4 -> 298275.36 | E15: =J!O4 -> 300079.34 | F15: =J!P4 -> 304116 | G15: =J!Q4 -> 309400.68 | H15: =J!R4 -> 309535.76 | I15: =J!S4 -> 300074.52 | J15: =J!T4 -> 298499.23 | ... AF15: =J!AP4 -> 298554.25
A16: K | C16: =K!AB4 -> 265264.85 | D16: =K!AC4 -> 261502.44 | E16: =K!AD4 -> 258943.47 | F16: =K!AE4 -> 255818.3 | G16: =K!AF4 -> 253576.45 | H16: =K!AG4 -> 250997.48 | I16: =K!AH4 -> 243846.79 | J16: =K!AI4 -> 242189.17 | ... AF16: =K!BE4 -> 190721.79
A18: Priser | C18: 1993 | D18: 1994 | E18: 1995 | F18: 1996 | G18: 1997 | H18: 1998 | I18: 1999 | J18: 2000 | K18: 2001 | L18: 2002 | M18: 2003 | N18: 2004 | O18: 2005 | P18: 2006 | Q18: 2007 | R18: 2008 | S18: 2009 | T18: 2010 | U18: 2011 | V18: 2012 | W18: 2013 | X18: 2014 | Y18: 2015 | Z18: 2016 | AA18: 2017 | AB18: 2018 | AC18: 2019 | AD18: 2020 | AE18: 2021 | AF18: 2022
A19: Y | C19: =P!AB4 -> 0.80025435 | D19: =P!AC4 -> 0.80089488 | E19: =P!AD4 -> 0.83564746 | F19: =P!AE4 -> 0.84700116 | G19: =P!AF4 -> 0.84671658 | H19: =P!AG4 -> 0.75191861 | I19: =P!AH4 -> 0.73512719 | J19: =P!AI4 -> 0.80247949 | ... AF19: =P!BE4 -> 1.1755229
A20: Mtot | C20: =P_Mtot!AB4 -> 0.57109878 | D20: =P_Mtot!AC4 -> 0.5600206 | E20: =P_Mtot!AD4 -> 0.54846327 | F20: =P_Mtot!AE4 -> 0.54271973 | G20: =P_Mtot!AF4 -> 0.54973262 | H20: =P_Mtot!AG4 -> 0.50941847 | I20: =P_Mtot!AH4 -> 0.49982297 | J20: =P_Mtot!AI4 -> 0.52682465 | ... AF20: =P_Mtot!BE4 -> 1.3658065
A21: MDtot | C21: =P_MDtot!AB4 -> 0.68497098 | D21: =P_MDtot!AC4 -> 0.69705886 | E21: =P_MDtot!AD4 -> 0.7120465 | F21: =P_MDtot!AE4 -> 0.71632009 | G21: =P_MDtot!AF4 -> 0.72380161 | H21: =P_MDtot!AG4 -> 0.70846055 | I21: =P_MDtot!AH4 -> 0.70268461 | J21: =P_MDtot!AI4 -> 0.73851085 | ... AF21: =P_MDtot!BE4 -> 1.2425342
A22: MFtot | C22: =P_MFtot!AB4 -> 0.63213063 | D22: =P_MFtot!AC4 -> 0.60712074 | E22: =P_MFtot!AD4 -> 0.58800651 | F22: =P_MFtot!AE4 -> 0.65350272 | G22: =P_MFtot!AF4 -> 0.69064185 | H22: =P_MFtot!AG4 -> 0.58331786 | I22: =P_MFtot!AH4 -> 0.55339807 | J22: =P_MFtot!AI4 -> 0.63945187 | ... AF22: =P_MFtot!BE4 -> 1.5966176
A23: JKL | C23: =P_JKL!B4 -> 0.43713453 | D23: =P_JKL!C4 -> 0.4565416 | E23: =P_JKL!D4 -> 0.48186045 | F23: =P_JKL!E4 -> 0.49752944 | G23: =P_JKL!F4 -> 0.54638688 | H23: =P_JKL!G4 -> 0.57864629 | I23: =P_JKL!H4 -> 0.64634956 | J23: =P_JKL!I4 -> 0.62647965 | ... AF23: =P_JKL!AE4 -> 1.087387
A24: KL | C24: =P_KL!B4 -> 0.40621427 | D24: =P_KL!C4 -> 0.42737516 | E24: =P_KL!D4 -> 0.43899956 | F24: =P_KL!E4 -> 0.45480608 | G24: =P_KL!F4 -> 0.49126852 | H24: =P_KL!G4 -> 0.51329255 | I24: =P_KL!H4 -> 0.58092135 | J24: =P_KL!I4 -> 0.5375887 | ... AF24: =P_KL!AE4 -> 1.0666988
A25: MD | B25: 01000 | C25: =P_D!AC4 -> 0.78233354 | D25: =P_D!AD4 -> 0.78251869 | E25: =P_D!AE4 -> 0.81311562 | F25: =P_D!AF4 -> 0.80405777 | G25: =P_D!AG4 -> 0.79597314 | H25: =P_D!AH4 -> 0.77210326 | I25: =P_D!AI4 -> 0.76788256 | J25: =P_D!AJ4 -> 0.79735022 | ... AF25: =P_D!BF4 -> 1.116501
B26: 10120 | C26: =P_D!AC5 -> 0.61099514 | D26: =P_D!AD5 -> 0.60867407 | E26: =P_D!AE5 -> 0.59880142 | F26: =P_D!AF5 -> 0.6517136 | G26: =P_D!AG5 -> 0.66829819 | H26: =P_D!AH5 -> 0.63895281 | I26: =P_D!AI5 -> 0.58286198 | J26: =P_D!AJ5 -> 0.71429928 | ... AF26: =P_D!BF5 -> 1.3235891
B27: REST | C27: =P_D!AC6 -> 0.63584182 | D27: =P_D!AD6 -> 0.65456644 | E27: =P_D!AE6 -> 0.66632269 | F27: =P_D!AF6 -> 0.66979962 | G27: =P_D!AG6 -> 0.68281213 | H27: =P_D!AH6 -> 0.67363939 | I27: =P_D!AI6 -> 0.67400794 | J27: =P_D!AJ6 -> 0.7002639 | ... AF27: =P_D!BF6 -> 1.2698908
A28: M_F | B28: 01000 | C28: =P_F!AC4 -> 1.137717 | D28: =P_F!AD4 -> 1.0301458 | E28: =P_F!AE4 -> 1.0179437 | F28: =P_F!AF4 -> 1.0375809 | G28: =P_F!AG4 -> 1.0236256 | H28: =P_F!AH4 -> 0.95326881 | I28: =P_F!AI4 -> 0.95818975 | J28: =P_F!AJ4 -> 1.0059399 | ... AF28: =P_F!BF4 -> 1.2994625
B29: 10120 | C29: =P_F!AC5 -> 0.67922204 | D29: =P_F!AD5 -> 0.6424006 | E29: =P_F!AE5 -> 0.59681149 | F29: =P_F!AF5 -> 0.72397845 | G29: =P_F!AG5 -> 0.79305222 | H29: =P_F!AH5 -> 0.61011639 | I29: =P_F!AI5 -> 0.53699618 | J29: =P_F!AJ5 -> 0.66140419 | ... AF29: =P_F!BF5 -> 1.4071021
B30: REST | C30: =P_F!AC6 -> 0.50156119 | D30: =P_F!AD6 -> 0.50481426 | E30: =P_F!AE6 -> 0.52195413 | F30: =P_F!AF6 -> 0.51505015 | G30: =P_F!AG6 -> 0.52003808 | H30: =P_F!AH6 -> 0.5007868 | I30: =P_F!AI6 -> 0.51181208 | J30: =P_F!AJ6 -> 0.5573903 | ... AF30: =P_F!BF6 -> 1.9331497
A31: L | C31: =w!AC4 -> 20.647432 | D31: =w!AD4 -> 22.079768 | E31: =w!AE4 -> 23.628678 | F31: =w!AF4 -> 25.27435 | G31: =w!AG4 -> 28.771524 | H31: =w!AH4 -> 29.709266 | I31: =w!AI4 -> 30.675946 | J31: =w!AJ4 -> 32.824487 | ... AF31: =w!BF4 -> 127.31765
A32: J | C32: =P_Jord!M2 -> 0.02372188 | D32: =P_Jord!N2 -> 0.024276743 | E32: =P_Jord!O2 -> 0.027545159 | F32: =P_Jord!P2 -> 0.028202661 | G32: =P_Jord!Q2 -> 0.032202635 | H32: =P_Jord!R2 -> 0.035124494 | I32: =P_Jord!S2 -> 0.038148688 | J32: =P_Jord!T2 -> 0.040640339 | ... AF32: =P_Jord!AP2 -> 0.056606306
A33: K | C33: =P_K!AB2 -> 0.059463781 | D33: =P_K!AC2 -> 0.062309517 | E33: =P_K!AD2 -> 0.063348304 | F33: =P_K!AE2 -> 0.065097984 | G33: =P_K!AF2 -> 0.06938361 | H33: =P_K!AG2 -> 0.072717441 | I33: =P_K!AH2 -> 0.084086664 | J33: =P_K!AI2 -> 0.075102996 | ... AF33: =P_K!BE2 -> 0.12079438

Sheet 10120
A2: Mængder | C2: 1993 | D2: 1994 | E2: 1995 | F2: 1996 | G2: 1997 | H2: 1998 | I2: 1999 | J2: 2000 | K2: 2001 | L2: 2002 | M2: 2003 | N2: 2004 | O2: 2005 | P2: 2006 | Q2: 2007 | R2: 2008 | S2: 2009 | T2: 2010 | U2: 2011 | V2: 2012 | W2: 2013 | X2: 2014 | Y2: 2015 | Z2: 2016 | AA2: 2017 | AB2: 2018 | AC2: 2019 | AD2: 2020 | AE2: 2021 | AF2: 2022
A3: Y | C3: =Y!AB5 -> 150359.82 | D3: =Y!AC5 -> 151786.73 | E3: =Y!AD5 -> 151157.95 | F3: =Y!AE5 -> 144547.1 | G3: =Y!AF5 -> 146043.78 | H3: =Y!AG5 -> 150061.67 | I3: =Y!AH5 -> 149807.44 | J3: =Y!AI5 -> 149968.46 | ... AF3: =Y!BE5 -> 168806.14
A4: Mtot | C4: =M_tot!AB5 -> 130572.26 | D4: =M_tot!AC5 -> 132987.96 | E4: =M_tot!AD5 -> 129295.44 | F4: =M_tot!AE5 -> 125463.49 | G4: =M_tot!AF5 -> 122208.94 | H4: =M_tot!AG5 -> 123079 | I4: =M_tot!AH5 -> 121389.7 | J4: =M_tot!AI5 -> 123225.67 | ... AF4: =M_tot!BE5 -> 128980.71
A5: MDtot | C5: =MDtot!AB5 -> 99002.458 | D5: =MDtot!AC5 -> 98515.248 | E5: =MDtot!AD5 -> 94913.352 | F5: =MDtot!AE5 -> 89306.466 | G5: =MDtot!AF5 -> 87818.068 | H5: =MDtot!AG5 -> 91349.28 | I5: =MDtot!AH5 -> 89368.694 | J5: =MDtot!AI5 -> 88151.946 | ... AF5: =MDtot!BE5 -> 94115.541
A6: MFtot | C6: =MFtot!AB5 -> 16461.391 | D6: =MFtot!AC5 -> 18321.557 | E6: =MFtot!AD5 -> 19482.96 | F6: =MFtot!AE5 -> 20617.97 | G6: =MFtot!AF5 -> 21007.964 | H6: =MFtot!AG5 -> 21431.735 | I6: =MFtot!AH5 -> 21626.279 | J6: =MFtot!AI5 -> 24106.921 | ... AF6: =MFtot!BE5 -> 34477.997
A7: JKL | C7: =JKL!B5 -> 0 | D7: =JKL!C5 -> 0 | E7: =JKL!D5 -> 0 | F7: =JKL!E5 -> 0 | G7: =JKL!F5 -> 0 | H7: =JKL!G5 -> 0 | I7: =JKL!H5 -> 0 | J7: =JKL!I5 -> 0 | ... AF7: =JKL!AE5 -> 0
A8: KL | C8: =KL!B5 -> 46040.827 | D8: =KL!C5 -> 45387.876 | E8: =KL!D5 -> 46164.598 | F8: =KL!E5 -> 45462.042 | G8: =KL!F5 -> 45193.503 | H8: =KL!G5 -> 44559.239 | I8: =KL!H5 -> 45024.582 | J8: =KL!I5 -> 45246.877 | ... AF8: =KL!AE5 -> 35094.697
A9: MD | B9: 01000 | C9: =M_D!AC7 -> 41769.774 | D9: =M_D!AD7 -> 42524.839 | E9: =M_D!AE7 -> 41604.931 | F9: =M_D!AF7 -> 42107.744 | G9: =M_D!AG7 -> 42549.732 | H9: =M_D!AH7 -> 43778.572 | I9: =M_D!AI7 -> 43967.402 | J9: =M_D!AJ7 -> 43435.648 | ... AF9: =M_D!BF7 -> 46362.37
B10: 10120 | C10: =M_D!AC8 -> 27108.113 | D10: =M_D!AD8 -> 24901.839 | E10: =M_D!AE8 -> 23958.066 | F10: =M_D!AF8 -> 17972.843 | G10: =M_D!AG8 -> 16094.457 | H10: =M_D!AH8 -> 18083.047 | I10: =M_D!AI8 -> 15499.507 | J10: =M_D!AJ8 -> 15288.445 | ... AF10: =M_D!BF8 -> 18504.41
B11: REST | C11: =M_D!AC9 -> 31002.432 | D11: =M_D!AD9 -> 31964.265 | E11: =M_D!AE9 -> 30045.843 | F11: =M_D!AF9 -> 29658.81 | G11: =M_D!AG9 -> 29476.623 | H11: =M_D!AH9 -> 29795.786 | I11: =M_D!AI9 -> 30166.104 | J11: =M_D!AJ9 -> 29688.454 | ... AF11: =M_D!BF9 -> 29253.513
A12: M_F | B12: 01000 | C12: =M_F!AC7 -> 1610.9445 | D12: =M_F!AD7 -> 1910.1649 | E12: =M_F!AE7 -> 2203.4458 | F12: =M_F!AF7 -> 2081.5888 | G12: =M_F!AG7 -> 2187.8589 | H12: =M_F!AH7 -> 2330.1157 | I12: =M_F!AI7 -> 2396.8691 | J12: =M_F!AJ7 -> 2457.6181 | ... AF12: =M_F!BF7 -> 1786.8999
B13: 10120 | C13: =M_F!AC8 -> 7576.074 | D13: =M_F!AD8 -> 8563.1006 | E13: =M_F!AE8 -> 9656.6831 | F13: =M_F!AF8 -> 10371.872 | G13: =M_F!AG8 -> 10626.931 | H13: =M_F!AH8 -> 10573.136 | I13: =M_F!AI8 -> 10253.346 | J13: =M_F!AJ8 -> 11984.549 | ... AF13: =M_F!BF8 -> 16713.948
B14: REST | C14: =M_F!AC9 -> 7166.392 | D14: =M_F!AD9 -> 7716.5238 | E14: =M_F!AE9 -> 7486.4984 | F14: =M_F!AF9 -> 8045.9162 | G14: =M_F!AG9 -> 8069.0476 | H14: =M_F!AH9 -> 8369.1873 | I14: =M_F!AI9 -> 8781.4741 | J14: =M_F!AJ9 -> 9521.8058 | ... AF14: =M_F!BF9 -> 15977.698
A15: L | C15: =L!AC5/1000 -> 124.695 | D15: =L!AD5/1000 -> 121.438 | E15: =L!AE5/1000 -> 123.972 | F15: =L!AF5/1000 -> 120.697 | G15: =L!AG5/1000 -> 117.906 | H15: =L!AH5/1000 -> 115.14 | I15: =L!AI5/1000 -> 116.399 | J15: =L!AJ5/1000 -> 117.301 | ... AF15: =L!BF5/1000 -> 69.952
A16: J | C16: =J!M5 -> 0 | D16: =J!N5 -> 0 | E16: =J!O5 -> 0 | F16: =J!P5 -> 0 | G16: =J!Q5 -> 0 | H16: =J!R5 -> 0 | I16: =J!S5 -> 0 | J16: =J!T5 -> 0 | ... AF16: =J!AP5 -> 0
A17: K | C17: =K!AB5 -> 79445.567 | D17: =K!AC5 -> 80169.581 | E17: =K!AD5 -> 80876.595 | F17: =K!AE5 -> 83395.645 | G17: =K!AF5 -> 83780.653 | H17: =K!AG5 -> 84572.668 | I17: =K!AH5 -> 84522.667 | J17: =K!AI5 -> 86867.714 | ... AF17: =K!BE5 -> 102662.03
A19: Priser | C19: 1993 | D19: 1994 | E19: 1995 | F19: 1996 | G19: 1997 | H19: 1998 | I19: 1999 | J19: 2000 | K19: 2001 | L19: 2002 | M19: 2003 | N19: 2004 | O19: 2005 | P19: 2006 | Q19: 2007 | R19: 2008 | S19: 2009 | T19: 2010 | U19: 2011 | V19: 2012 | W19: 2013 | X19: 2014 | Y19: 2015 | Z19: 2016 | AA19: 2017 | AB19: 2018 | AC19: 2019 | AD19: 2020 | AE19: 2021 | AF19: 2022
A20: Y | C20: =P!AB5 -> 0.75479964 | D20: =P!AC5 -> 0.76114401 | E20: =P!AD5 -> 0.76856146 | F20: =P!AE5 -> 0.78565486 | G20: =P!AF5 -> 0.79803586 | H20: =P!AG5 -> 0.75402237 | I20: =P!AH5 -> 0.73069725 | J20: =P!AI5 -> 0.78026275 | ... AF20: =P!BE5 -> 1.1472759
A21: Mtot | C21: =P_Mtot!AB5 -> 0.66428391 | D21: =P_Mtot!AC5 -> 0.67151116 | E21: =P_Mtot!AD5 -> 0.68547191 | F21: =P_Mtot!AE5 -> 0.68816405 | G21: =P_Mtot!AF5 -> 0.71202651 | H21: =P_Mtot!AG5 -> 0.68796997 | I21: =P_Mtot!AH5 -> 0.65869187 | J21: =P_Mtot!AI5 -> 0.70101809 | ... AF21: =P_Mtot!BE5 -> 1.2481187
A22: MDtot | C22: =P_MDtot!AB5 -> 0.75104999 | D22: =P_MDtot!AC5 -> 0.7640817 | E22: =P_MDtot!AD5 -> 0.77928862 | F22: =P_MDtot!AE5 -> 0.79798993 | G22: =P_MDtot!AF5 -> 0.80896638 | H22: =P_MDtot!AG5 -> 0.74492247 | I22: =P_MDtot!AH5 -> 0.71497377 | J22: =P_MDtot!AI5 -> 0.77068319 | ... AF22: =P_MDtot!BE5 -> 1.2233192
A23: MFtot | C23: =P_MFtot!AB5 -> 0.76616485 | D23: =P_MFtot!AC5 -> 0.76683139 | E23: =P_MFtot!AD5 -> 0.7615809 | F23: =P_MFtot!AE5 -> 0.74053591 | G23: =P_MFtot!AF5 -> 0.7689577 | H23: =P_MFtot!AG5 -> 0.77715848 | I23: =P_MFtot!AH5 -> 0.73415437 | J23: =P_MFtot!AI5 -> 0.75273372 | ... AF23: =P_MFtot!BE5 -> 1.3026351
A24: JKL | C24: =P_JKL!B5 -> 0.53550069 | D24: =P_JKL!C5 -> 0.55605246 | E24: =P_JKL!D5 -> 0.57488307 | F24: =P_JKL!E5 -> 0.58886902 | G24: =P_JKL!F5 -> 0.6298813 | H24: =P_JKL!G5 -> 0.66864897 | I24: =P_JKL!H5 -> 0.68522348 | J24: =P_JKL!I5 -> 0.70817867 | ... AF24: =P_JKL!AE5 -> 1.0913175
A25: KL | C25: =P_KL!B5 -> 0.53548001 | D25: =P_KL!C5 -> 0.55840753 | E25: =P_KL!D5 -> 0.56151211 | F25: =P_KL!E5 -> 0.57525612 | G25: =P_KL!F5 -> 0.60162117 | H25: =P_KL!G5 -> 0.63212348 | I25: =P_KL!H5 -> 0.63298749 | J25: =P_KL!I5 -> 0.64614385 | ... AF25: =P_KL!AE5 -> 1.0738184
A26: MD | B26: 01000 | C26: =P_D!AC7 -> 0.82714961 | D26: =P_D!AD7 -> 0.82764052 | E26: =P_D!AE7 -> 0.84765913 | F26: =P_D!AF7 -> 0.87256809 | G26: =P_D!AG7 -> 0.88260937 | H26: =P_D!AH7 -> 0.7591156 | I26: =P_D!AI7 -> 0.71849389 | J26: =P_D!AJ7 -> 0.81148917 | ... AF26: =P_D!BF7 -> 1.2233984
B27: 10120 | C27: =P_D!AC8 -> 0.73029776 | D27: =P_D!AD8 -> 0.75279775 | E27: =P_D!AE8 -> 0.75698535 | F27: =P_D!AF8 -> 0.76998452 | G27: =P_D!AG8 -> 0.77685036 | H27: =P_D!AH8 -> 0.73049109 | I27: =P_D!AI8 -> 0.6884031 | J27: =P_D!AJ8 -> 0.72073491 | ... AF27: =P_D!BF8 -> 1.1846814
B28: REST | C28: =P_D!AC9 -> 0.64539932 | D28: =P_D!AD9 -> 0.66738184 | E28: =P_D!AE9 -> 0.68436056 | F28: =P_D!AF9 -> 0.69743108 | G28: =P_D!AG9 -> 0.71188911 | H28: =P_D!AH9 -> 0.72512364 | I28: =P_D!AI9 -> 0.71723061 | J28: =P_D!AJ9 -> 0.72993861 | ... AF28: =P_D!BF9 -> 1.2474354
A29: M_F | B29: 01000 | C29: =P_F!AC7 -> 0.92127385 | D29: =P_F!AD7 -> 0.90174988 | E29: =P_F!AE7 -> 0.83643128 | F29: =P_F!AF7 -> 0.83515485 | G29: =P_F!AG7 -> 0.93918212 | H29: =P_F!AH7 -> 0.93972802 | I29: =P_F!AI7 -> 0.83135455 | J29: =P_F!AJ7 -> 0.86370051 | ... AF29: =P_F!BF7 -> 1.3950183
B30: 10120 | C30: =P_F!AC8 -> 0.7282904 | D30: =P_F!AD8 -> 0.7366285 | E30: =P_F!AE8 -> 0.7339254 | F30: =P_F!AF8 -> 0.71547974 | G30: =P_F!AG8 -> 0.73971816 | H30: =P_F!AH8 -> 0.74249633 | I30: =P_F!AI8 -> 0.69236714 | J30: =P_F!AJ8 -> 0.70158542 | ... AF30: =P_F!BF8 -> 1.3089871
B31: REST | C31: =P_F!AC9 -> 0.78288154 | D31: =P_F!AD9 -> 0.78004425 | E31: =P_F!AE9 -> 0.78909174 | F31: =P_F!AF9 -> 0.75927139 | G31: =P_F!AG9 -> 0.77314007 | H31: =P_F!AH9 -> 0.79047879 | I31: =P_F!AI9 -> 0.77268337 | J31: =P_F!AJ9 -> 0.79977067 | ... AF31: =P_F!BF9 -> 1.2856138
A32: L | C32: =w!AC5 -> 137.34957 | D32: =w!AD5 -> 142.05217 | E32: =w!AE5 -> 142.6408 | F32: =w!AF5 -> 147.93775 | G32: =w!AG5 -> 153.19007 | H32: =w!AH5 -> 163.48697 | I32: =w!AI5 -> 162.29581 | J32: =w!AJ5 -> 166.99432 | ... AF32: =w!BF5 -> 327.89005
A33: J | C33: =P_Jord!M3 -> 0 | D33: =P_Jord!N3 -> 0 | E33: =P_Jord!O3 -> 0 | F33: =P_Jord!P3 -> 0 | G33: =P_Jord!Q3 -> 0 | H33: =P_Jord!R3 -> 0 | I33: =P_Jord!S3 -> 0 | J33: =P_Jord!T3 -> 0 | ... AF33: =P_Jord!AP3 -> 0
A34: K | C34: =P_K!AB3 -> 0.095975689 | D34: =P_K!AC3 -> 0.10188612 | E34: =P_K!AD3 -> 0.10276361 | F34: =P_K!AE3 -> 0.10258437 | G34: =P_K!AF3 -> 0.10944624 | H34: =P_K!AG3 -> 0.11151801 | I34: =P_K!AH3 -> 0.11361741 | J34: =P_K!AI3 -> 0.11413968 | ... AF34: =P_K!BE3 -> 0.14478596

Sheet Y
B1: Xt
A2: TID | B2: 1967 | C2: 1968 | D2: 1969 | E2: 1970 | F2: 1971 | G2: 1972 | H2: 1973 | I2: 1974 | J2: 1975 | K2: 1976 | L2: 1977 | M2: 1978 | N2: 1979 | O2: 1980 | P2: 1981 | Q2: 1982 | R2: 1983 | S2: 1984 | T2: 1985 | U2: 1986 | V2: 1987 | W2: 1988 | X2: 1989 | Y2: 1990 | Z2: 1991 | AA2: 1992 | AB2: 1993 | AC2: 1994 | AD2: 1995 | AE2: 1996 | AF2: 1997 | AG2: 1998 | AH2: 1999 | AI2: 2000 | AJ2: 2001 | AK2: 2002 | AL2: 2003 | AM2: 2004 | AN2: 2005 | AO2: 2006 | AP2: 2007 | AQ2: 2008 | AR2: 2009 | AS2: 2010 | AT2: 2011 | AU2: 2012 | AV2: 2013 | AW2: 2014 | AX2: 2015 | AY2: 2016 | AZ2: 2017 | BA2: 2018 | BB2: 2019 | BC2: 2020 | BD2: 2021 | BE2: 2022
A3: ANVENDELSE
A4: 01000 | B4: 44352.253 | C4: 44088.474 | D4: 44065.485 | E4: 41076.955 | F4: 44428.588 | G4: 45125.516 | H4: 45687.594 | I4: 47792.366 | J4: 45353.08 | K4: 45360.614 | L4: 48300.748 | M4: 50462.618 | N4: 51681.032 | O4: 51506.404 | P4: 52624.818 | Q4: 55228.202 | R4: 53482.361 | S4: 58750.744 | T4: 58588.026 | U4: 58742.299 | V4: 56961.097 | W4: 56075.446 | X4: 58852.663 | Y4: 62263.479 | Z4: 60786.475 | AA4: 60399.718 | AB4: 69638.69 | AC4: 68856.807 | AD4: 69737.096 | AE4: 70280.702 | AF4: 72177.731 | AG4: 73158.199 | AH4: 73173.611 | AI4: 74464.21 | AJ4: 73547.402 | AK4: 74587.448 | AL4: 74719.005 | AM4: 75618.655 | AN4: 74196.06 | AO4: 75618.96 | AP4: 79159.854 | AQ4: 73126.391 | AR4: 73444.22 | AS4: 77334.77 | AT4: 75869.896 | AU4: 77617.493 | AV4: 76593.51 | AW4: 80374.732 | AX4: 79210.579 | AY4: 76984.41 | AZ4: 80708.048 | BA4: 79724.539 | BB4: 78394.569 | BC4: 80503.511 | BD4: 82678.533 | BE4: 81481.018
A5: 10120 | B5: 83186.189 | C5: 86476.234 | D5: 85557.501 | E5: 89270.716 | F5: 92244.747 | G5: 94861.982 | H5: 96469.273 | I5: 98731.17 | J5: 96574.474 | K5: 100366.04 | L5: 105550.69 | M5: 108622.24 | N5: 118817.66 | O5: 124261.63 | P5: 125155.28 | Q5: 121655.97 | R5: 119434.54 | S5: 120350.92 | T5: 126590.8 | U5: 133131.09 | V5: 131489.29 | W5: 131466.32 | X5: 131914.27 | Y5: 138076.58 | Z5: 139256.11 | AA5: 142823.72 | AB5: 150359.82 | AC5: 151786.73 | AD5: 151157.95 | AE5: 144547.1 | AF5: 146043.78 | AG5: 150061.67 | AH5: 149807.44 | AI5: 149968.46 | AJ5: 152904.38 | AK5: 155839.87 | AL5: 157377.12 | AM5: 159879.98 | AN5: 163810.69 | AO5: 162171.86 | AP5: 160069.3 | AQ5: 158120.91 | AR5: 150853.33 | AS5: 144714.15 | AT5: 145739.45 | AU5: 142580.88 | AV5: 144480.44 | AW5: 145446.79 | AX5: 146833.77 | AY5: 148098.44 | AZ5: 153499.94 | BA5: 153657.79 | BB5: 155602.57 | BC5: 161377.86 | BD5: 165261.18 | BE5: 168806.14
A6: REST | B6: 1109665.2 | C6: 1150467.2 | D6: 1244272.4 | E6: 1296967.3 | F6: 1323255.2 | G6: 1389078.8 | H6: 1455464.8 | I6: 1429114.2 | J6: 1395556.7 | K6: 1504518.1 | L6: 1524849.3 | M6: 1565128.5 | N6: 1624837 | O6: 1610111.2 | P6: 1578283.4 | Q6: 1618114.6 | R6: 1656904 | S6: 1747167.8 | T6: 1838273 | U6: 1959928.8 | V6: 1995809.2 | W6: 2024259.3 | X6: 2032213.7 | Y6: 2061376.4 | Z6: 2081193.2 | AA6: 2112919.2 | AB6: 2121405.3 | AC6: 2237038.4 | AD6: 2322092.6 | AE6: 2404762 | AF6: 2483498.2 | AG6: 2556756.6 | AH6: 2672884.8 | AI6: 2814342.7 | AJ6: 2887124.9 | AK6: 2919063.6 | AL6: 2924155.7 | AM6: 2993388 | AN6: 3163125.6 | AO6: 3345591.2 | AP6: 3450061.6 | AQ6: 3489091 | AR6: 3255992.7 | AS6: 3260982 | AT6: 3349605.6 | AU6: 3379079.5 | AV6: 3383461.5 | AW6: 3454296 | AX6: 3545031.5 | AY6: 3681621.6 | AZ6: 3775390.8 | BA6: 3850118.5 | BB6: 3911961.7 | BC6: 3813550.3 | BD6: 4064668.8 | BE6: 4180703.9

Sheet M_tot
B1: Xt
A2: TID | B2: 1967 | C2: 1968 | D2: 1969 | E2: 1970 | F2: 1971 | G2: 1972 | H2: 1973 | I2: 1974 | J2: 1975 | K2: 1976 | L2: 1977 | M2: 1978 | N2: 1979 | O2: 1980 | P2: 1981 | Q2: 1982 | R2: 1983 | S2: 1984 | T2: 1985 | U2: 1986 | V2: 1987 | W2: 1988 | X2: 1989 | Y2: 1990 | Z2: 1991 | AA2: 1992 | AB2: 1993 | AC2: 1994 | AD2: 1995 | AE2: 1996 | AF2: 1997 | AG2: 1998 | AH2: 1999 | AI2: 2000 | AJ2: 2001 | AK2: 2002 | AL2: 2003 | AM2: 2004 | AN2: 2005 | AO2: 2006 | AP2: 2007 | AQ2: 2008 | AR2: 2009 | AS2: 2010 | AT2: 2011 | AU2: 2012 | AV2: 2013 | AW2: 2014 | AX2: 2015 | AY2: 2016 | AZ2: 2017 | BA2: 2018 | BB2: 2019 | BC2: 2020 | BD2: 2021 | BE2: 2022
A3: ANVENDELSE
A4: 01000 | B4: 36286.068 | C4: 35648.365 | D4: 35411.44 | E4: 36831.743 | F4: 36581.647 | G4: 36337.603 | H4: 38932.19 | I4: 37915.618 | J4: 38386.534 | K4: 42245.594 | L4: 43231.703 | M4: 47371.118 | N4: 51396.739 | O4: 50520.803 | P4: 49904.905 | Q4: 50707.483 | R4: 50978.938 | S4: 51240.812 | T4: 53708.663 | U4: 52495.873 | V4: 54808.035 | W4: 52067.454 | X4: 50222.42 | Y4: 51620.02 | Z4: 49891.226 | AA4: 52221.712 | AB4: 58815.855 | AC4: 57920.723 | AD4: 58130.609 | AE4: 59331.138 | AF4: 62338.487 | AG4: 64918.017 | AH4: 66099.123 | AI4: 65171.865 | AJ4: 63252.997 | AK4: 67487.135 | AL4: 64683.309 | AM4: 64431.452 | AN4: 63687.737 | AO4: 62401.498 | AP4: 60544.132 | AQ4: 59998.917 | AR4: 61009.714 | AS4: 59831.101 | AT4: 60233.089 | AU4: 59147.607 | AV4: 59127.63 | AW4: 57258.392 | AX4: 58279.704 | AY4: 58501.307 | AZ4: 57482.406 | BA4: 56699.817 | BB4: 52681.075 | BC4: 53402.835 | BD4: 51862.639 | BE4: 52153.994
A5: 10120 | B5: 57424.459 | C5: 60414.069 | D5: 62522.3 | E5: 67746.779 | F5: 73500.745 | G5: 78564.212 | H5: 82192.116 | I5: 85685.212 | J5: 84789.959 | K5: 89629.126 | L5: 92939.84 | M5: 96261.409 | N5: 105690.94 | O5: 110097.16 | P5: 107517.47 | Q5: 103062.6 | R5: 99139.719 | S5: 101401.48 | T5: 107339.59 | U5: 114713.18 | V5: 115238.85 | W5: 112540.82 | X5: 111155.12 | Y5: 116914.67 | Z5: 116466.86 | AA5: 122116.89 | AB5: 130572.26 | AC5: 132987.96 | AD5: 129295.44 | AE5: 125463.49 | AF5: 122208.94 | AG5: 123079 | AH5: 121389.7 | AI5: 123225.67 | AJ5: 124433.72 | AK5: 131672.92 | AL5: 137330.07 | AM5: 138898.36 | AN5: 143560.35 | AO5: 143736.48 | AP5: 141485.12 | AQ5: 138585.67 | AR5: 131190.5 | AS5: 124018.68 | AT5: 124229.51 | AU5: 121432.56 | AV5: 122478.53 | AW5: 121298.97 | AX5: 124499.62 | AY5: 124509.59 | AZ5: 127029.86 | BA5: 128793.89 | BB5: 126939.79 | BC5: 130185.31 | BD5: 130100.96 | BE5: 128980.71
A6: REST | B6: 429425.77 | C6: 438104.29 | D6: 481460.68 | E6: 508854.09 | F6: 510244.46 | G6: 540634.97 | H6: 570883.72 | I6: 556252.43 | J6: 535578.38 | K6: 583106.24 | L6: 591924.48 | M6: 608211.11 | N6: 628418.8 | O6: 618325.33 | P6: 593573.52 | Q6: 593445.7 | R6: 609143.43 | S6: 667096.98 | T6: 710926.28 | U6: 775663.24 | V6: 789733.13 | W6: 796441.78 | X6: 793487.58 | Y6: 800866.82 | Z6: 801200.15 | AA6: 809276.4 | AB6: 814819.29 | AC6: 864082.93 | AD6: 912068.8 | AE6: 951107.78 | AF6: 981114.47 | AG6: 1017067.6 | AH6: 1081882.8 | AI6: 1133494 | AJ6: 1185092.3 | AK6: 1205063.8 | AL6: 1191577.4 | AM6: 1223673.4 | AN6: 1342970 | AO6: 1437216.6 | AP6: 1499775.9 | AQ6: 1517743.2 | AR6: 1379351.6 | AS6: 1364739.9 | AT6: 1400676.1 | AU6: 1427973.9 | AV6: 1417020.8 | AW6: 1463315.3 | AX6: 1517724.4 | AY6: 1581461.1 | AZ6: 1617080.5 | BA6: 1650726.9 | BB6: 1681786.2 | BC6: 1658028.6 | BD6: 1767698.2 | BE6: 1864350.3

Sheet JKL
B1: Xt
A2: TID | B2: 1993 | C2: 1994 | D2: 1995 | E2: 1996 | F2: 1997 | G2: 1998 | H2: 1999 | I2: 2000 | J2: 2001 | K2: 2002 | L2: 2003 | M2: 2004 | N2: 2005 | O2: 2006 | P2: 2007 | Q2: 2008 | R2: 2009 | S2: 2010 | T2: 2011 | U2: 2012 | V2: 2013 | W2: 2014 | X2: 2015 | Y2: 2016 | Z2: 2017 | AA2: 2018 | AB2: 2019 | AC2: 2020 | AD2: 2021 | AE2: 2022
A3: ANVENDELSE
A4: 01000 | B4: 64494.017 | C4: 61394.762 | D4: 60299.504 | E4: 59681.765 | F4: 58957.258 | G4: 58903.895 | H4: 58150.047 | I4: 56506.64 | J4: 56013.075 | K4: 56125.378 | L4: 55149.51 | M4: 54759.451 | N4: 54115.741 | O4: 54107.868 | P4: 54223.968 | Q4: 53844.429 | R4: 54840.115 | S4: 54108.149 | T4: 53665.503 | U4: 53118.874 | V4: 52521.227 | W4: 52149.568 | X4: 52156.474 | Y4: 50571.911 | Z4: 50311.579 | AA4: 49657.182 | AB4: 48531.675 | AC4: 48195.839 | AD4: 47743.073 | AE4: 47162.558
A5: 10120 | B5: 0 | C5: 0 | D5: 0 | E5: 0 | F5: 0 | G5: 0 | H5: 0 | I5: 0 | J5: 0 | K5: 0 | L5: 0 | M5: 0 | N5: 0 | O5: 0 | P5: 0 | Q5: 0 | R5: 0 | S5: 0 | T5: 0 | U5: 0 | V5: 0 | W5: 0 | X5: 0 | Y5: 0 | Z5: 0 | AA5: 0 | AB5: 0 | AC5: 0 | AD5: 0 | AE5: 0
A6: REST | B6: 0 | C6: 0 | D6: 0 | E6: 0 | F6: 0 | G6: 0 | H6: 0 | I6: 0 | J6: 0 | K6: 0 | L6: 0 | M6: 0 | N6: 0 | O6: 0 | P6: 0 | Q6: 0 | R6: 0 | S6: 0 | T6: 0 | U6: 0 | V6: 0 | W6: 0 | X6: 0 | Y6: 0 | Z6: 0 | AA6: 0 | AB6: 0 | AC6: 0 | AD6: 0 | AE6: 0

Sheet KL
B1: Xt
A2: TID | B2: 1993 | C2: 1994 | D2: 1995 | E2: 1996 | F2: 1997 | G2: 1998 | H2: 1999 | I2: 2000 | J2: 2001 | K2: 2002 | L2: 2003 | M2: 2004 | N2: 2005 | O2: 2006 | P2: 2007 | Q2: 2008 | R2: 2009 | S2: 2010 | T2: 2011 | U2: 2012 | V2: 2013 | W2: 2014 | X2: 2015 | Y2: 2016 | Z2: 2017 | AA2: 2018 | AB2: 2019 | AC2: 2020 | AD2: 2021 | AE2: 2022
A3: ANVENDELSE
A4: 01000 | B4: 49999.608 | C4: 48351.425 | D4: 47471.354 | E4: 46680.113 | F4: 45637.233 | G4: 45231.472 | H4: 44372.399 | I4: 43165.21 | J4: 42709.122 | K4: 42731.772 | L4: 41751.239 | M4: 41392.295 | N4: 40590.304 | O4: 39865.44 | P4: 39792.767 | Q4: 39868.113 | R4: 39638.817 | S4: 38930.087 | T4: 38180.14 | U4: 37433.231 | V4: 36854.717 | W4: 36567.46 | X4: 36327.128 | Y4: 35323.086 | Z4: 34946.067 | AA4: 34313.443 | AB4: 33260.791 | AC4: 32926.275 | AD4: 32645.667 | AE4: 32114.78
A5: 10120 | B5: 46040.827 | C5: 45387.876 | D5: 46164.598 | E5: 45462.042 | F5: 45193.503 | G5: 44559.239 | H5: 45024.582 | I5: 45246.877 | J5: 45592.635 | K5: 45860.824 | L5: 44577.479 | M5: 43921.297 | N5: 42388.125 | O5: 41318.564 | P5: 40055.498 | Q5: 39833.141 | R5: 38584.438 | S5: 37825.136 | T5: 36763.992 | U5: 35566.534 | V5: 34882.766 | W5: 33599.144 | X5: 33170.008 | Y5: 33297.543 | Z5: 33684.521 | AA5: 33176.523 | AB5: 33525.108 | AC5: 35112.307 | AD5: 35122.106 | AE5: 35094.697
A6: REST | B6: 1662485.9 | C6: 1662705.2 | D6: 1682993.6 | E6: 1699048.9 | F6: 1738002.6 | G6: 1775587.6 | H6: 1811803.4 | I6: 1839087.6 | J6: 1867997.1 | K6: 1876549.7 | L6: 1877573.1 | M6: 1882917.7 | N6: 1907517.3 | O6: 1952564 | P6: 1983042.3 | Q6: 2015048 | R6: 1984433.5 | S6: 1969763.3 | T6: 1983831.6 | U6: 1968424.8 | V6: 1976095.9 | W6: 1979783.7 | X6: 1998987.7 | Y6: 2033891.7 | Z6: 2057918.6 | AA6: 2072342.5 | AB6: 2099495.3 | AC6: 2068520.8 | AD6: 2155264.9 | AE6: 2225307.8

Sheet M_D
C1: Xt
B2: TID | C2: 1967 | D2: 1968 | E2: 1969 | F2: 1970 | G2: 1971 | H2: 1972 | I2: 1973 | J2: 1974 | K2: 1975 | L2: 1976 | M2: 1977 | N2: 1978 | O2: 1979 | P2: 1980 | Q2: 1981 | R2: 1982 | S2: 1983 | T2: 1984 | U2: 1985 | V2: 1986 | W2: 1987 | X2: 1988 | Y2: 1989 | Z2: 1990 | AA2: 1991 | AB2: 1992 | AC2: 1993 | AD2: 1994 | AE2: 1995 | AF2: 1996 | AG2: 1997 | AH2: 1998 | AI2: 1999 | AJ2: 2000 | AK2: 2001 | AL2: 2002 | AM2: 2003 | AN2: 2004 | AO2: 2005 | AP2: 2006 | AQ2: 2007 | AR2: 2008 | AS2: 2009 | AT2: 2010 | AU2: 2011 | AV2: 2012 | AW2: 2013 | AX2: 2014 | AY2: 2015 | AZ2: 2016 | BA2: 2017 | BB2: 2018 | BC2: 2019 | BD2: 2020 | BE2: 2021 | BF2: 2022
A3: ANVENDELSE | B3: TILGANG2
A4: 01000 | B4: 01000 | C4: 7473.8564 | D4: 8474.7709 | E4: 7976.3547 | F4: 8707.4791 | G4: 8465.4449 | H4: 8160.6701 | I4: 9724.2357 | J4: 8941.0765 | K4: 9192.6092 | L4: 9342.6889 | M4: 9361.2423 | N4: 9698.8514 | O4: 10430.262 | P4: 10516.181 | Q4: 10466.779 | R4: 9892.048 | S4: 9146.8457 | T4: 9320.8876 | U4: 9769.195 | V4: 8679.9126 | W4: 9117.8395 | X4: 7612.8913 | Y4: 7506.7628 | Z4: 7755.5907 | AA4: 7081.5689 | AB4: 7280.8855 | AC4: 10515.091 | AD4: 10348.109 | AE4: 10887.235 | AF4: 11408.106 | AG4: 11468.928 | AH4: 11366.961 | AI4: 12541.535 | AJ4: 12348.996 | AK4: 12041.646 | AL4: 9058.2665 | AM4: 8867.1233 | AN4: 8841.9753 | AO4: 8334.1393 | AP4: 7874.4491 | AQ4: 8006.3573 | AR4: 7154.7644 | AS4: 8391.9214 | AT4: 7695.7332 | AU4: 8802.5664 | AV4: 8841.3276 | AW4: 8488.2364 | AX4: 8629.9499 | AY4: 8966.4674 | AZ4: 8806.0513 | BA4: 9287.7124 | BB4: 9343.7468 | BC4: 8965.86 | BD4: 8830.27 | BE4: 9818.222 | BF4: 11377.674
B5: 10120 | C5: 4794.089 | D5: 4739.5013 | E5: 4807.6146 | F5: 4684.0342 | G5: 4443.9087 | H5: 4392.4554 | I5: 4835.6982 | J5: 4824.535 | K5: 5454.1157 | L5: 5747.4953 | M5: 5274.5595 | N5: 5970.7523 | O5: 6274.3192 | P5: 5367.4966 | Q5: 4527.6758 | R5: 4929.7452 | S5: 5336.8939 | T5: 4941.2977 | U5: 4601.8296 | V5: 4433.9173 | W5: 4212.954 | X5: 3806.6959 | Y5: 3910.9838 | Z5: 4240.8778 | AA5: 3945.9918 | AB5: 3570.1965 | AC5: 4022.3888 | AD5: 3945.5878 | AE5: 4071.0425 | AF5: 3479.085 | AG5: 3723.5773 | AH5: 3696.5954 | AI5: 3468.9447 | AJ5: 3150.118 | AK5: 2925.0541 | AL5: 7723.5767 | AM5: 9250.5902 | AN5: 9358.6789 | AO5: 8730.8613 | AP5: 8588.9048 | AQ5: 9280.9699 | AR5: 9647.1932 | AS5: 9308.3263 | AT5: 8671.6647 | AU5: 8675.7415 | AV5: 7860.067 | AW5: 8389.3668 | AX5: 8210.2737 | AY5: 8831.8807 | AZ5: 9983.1781 | BA5: 10094.135 | BB5: 10343.587 | BC5: 9856.1879 | BD5: 10904.267 | BE5: 9897.179 | BF5: 10400.685
B6: REST | C6: 19892.138 | D6: 19938.007 | E6: 19724.739 | F6: 19842.252 | G6: 20239.981 | H6: 20856.439 | I6: 21426.841 | J6: 19820.198 | K6: 18734.601 | L6: 20734.088 | M6: 20386.471 | N6: 22082.434 | O6: 22083.162 | P6: 21609.608 | Q6: 20560.139 | R6: 21386.234 | S6: 21429.444 | T6: 22311.646 | U6: 22753.458 | V6: 23355.624 | W6: 25509.112 | X6: 26566.356 | Y6: 24580.17 | Z6: 25331.938 | AA6: 24493.236 | AB6: 25263.854 | AC6: 26470.824 | AD6: 25674.114 | AE6: 24362.444 | AF6: 24081.286 | AG6: 25366.734 | AH6: 25601.393 | AI6: 25678.757 | AJ6: 24772.285 | AK6: 23547.768 | AL6: 22871.63 | AM6: 21340.025 | AN6: 20833.181 | AO6: 21822.553 | AP6: 22678.799 | AQ6: 21891.43 | AR6: 22131.588 | AS6: 21808.301 | AT6: 21820.354 | AU6: 20950.088 | AV6: 21332.074 | AW6: 22353.224 | AX6: 21675.51 | AY6: 22278.093 | AZ6: 21824.046 | BA6: 22278.978 | BB6: 21721.157 | BC6: 20558.772 | BD6: 22008.078 | BE6: 21872.132 | BF6: 20752.792
A7: 10120 | B7: 01000 | C7: 27835.022 | D7: 27219.87 | E7: 26461.123 | F7: 27272.892 | G7: 27531.641 | H7: 27020.692 | I7: 28171.552 | J7: 27913.626 | K7: 28644.502 | L7: 28830.025 | M7: 29468.096 | N7: 30813.772 | O7: 31877.865 | P7: 32888.912 | Q7: 33114.192 | R7: 33534.638 | S7: 35294.405 | T7: 35209.663 | U7: 35334.613 | V7: 36993.021 | W7: 36107.156 | X7: 35099.305 | Y7: 35222.516 | Z7: 35886.58 | AA7: 36420.538 | AB7: 38737.309 | AC7: 41769.774 | AD7: 42524.839 | AE7: 41604.931 | AF7: 42107.744 | AG7: 42549.732 | AH7: 43778.572 | AI7: 43967.402 | AJ7: 43435.648 | AK7: 43658.463 | AL7: 47326.307 | AM7: 48866.522 | AN7: 49799.925 | AO7: 48713.703 | AP7: 47657.591 | AQ7: 48628.72 | AR7: 46716.989 | AS7: 43179.007 | AT7: 44504.297 | AU7: 44613.893 | AV7: 43452.911 | AW7: 43774.776 | AX7: 44891.162 | AY7: 45404.165 | AZ7: 44194.535 | BA7: 43823.163 | BB7: 44104.309 | BC7: 44220.576 | BD7: 46091.117 | BE7: 47540.042 | BF7: 46362.37
B8: 10120 | C8: 11966.038 | D8: 14169.818 | E8: 14176.878 | F8: 14904.633 | G8: 16358.845 | H8: 17623.509 | I8: 16348.217 | J8: 17531.982 | K8: 16701.419 | L8: 17959.241 | M8: 19591.577 | N8: 20455.462 | O8: 25235.314 | P8: 27252.616 | Q8: 27451.603 | R8: 22991.637 | S8: 18006.201 | T8: 18580.597 | U8: 22610.504 | V8: 24619.229 | W8: 24281.079 | X8: 23767.474 | Y8: 22046.489 | Z8: 24183.95 | AA8: 22353.716 | AB8: 23906.809 | AC8: 27108.113 | AD8: 24901.839 | AE8: 23958.066 | AF8: 17972.843 | AG8: 16094.457 | AH8: 18083.047 | AI8: 15499.507 | AJ8: 15288.445 | AK8: 15619.436 | AL8: 15632.038 | AM8: 16451.079 | AN8: 16678.729 | AO8: 17540.739 | AP8: 17200.727 | AQ8: 16816.205 | AR8: 16461.763 | AS8: 17566.911 | AT8: 15287.566 | AU8: 15381.635 | AV8: 15710.984 | AW8: 15518.266 | AX8: 14810.448 | AY8: 15546.58 | AZ8: 15082.171 | BA8: 15833.974 | BB8: 15566.613 | BC8: 16445.299 | BD8: 17236.153 | BE8: 17750.585 | BF8: 18504.41
B9: REST | C9: 14332.51 | D9: 16154.196 | E9: 16347.926 | F9: 17202.042 | G9: 19070.955 | H9: 20086.546 | I9: 18914.996 | J9: 20369.669 | K9: 19959.211 | L9: 21244.828 | M9: 20733.547 | N9: 21002.751 | O9: 21988.366 | P9: 23624.42 | Q9: 23541.221 | R9: 24185.288 | S9: 24076.64 | T9: 25436.646 | U9: 25473.443 | V9: 27027.625 | W9: 28413.354 | X9: 28119.194 | Y9: 28140.018 | Z9: 29573.615 | AA9: 30007.484 | AB9: 31121.884 | AC9: 31002.432 | AD9: 31964.265 | AE9: 30045.843 | AF9: 29658.81 | AG9: 29476.623 | AH9: 29795.786 | AI9: 30166.104 | AJ9: 29688.454 | AK9: 29239.703 | AL9: 30154.242 | AM9: 29446.712 | AN9: 28811.295 | AO9: 30996.958 | AP9: 31086.807 | AQ9: 29565.587 | AR9: 28853.672 | AS9: 28442.757 | AT9: 25380.877 | AU9: 26772.849 | AV9: 24871.109 | AW9: 25666.94 | AX9: 25556.318 | AY9: 26832.453 | AZ9: 28840.182 | BA9: 30414.555 | BB9: 30944.364 | BC9: 28660.484 | BD9: 30573.137 | BE9: 30115.972 | BF9: 29253.513
A10: REST | B10: 01000 | C10: 527.30157 | D10: 563.72886 | E10: 554.02337 | F10: 548.67149 | G10: 571.02486 | H10: 574.27012 | I10: 520.89475 | J10: 479.87263 | K10: 580.4761 | L10: 587.39843 | M10: 684.26265 | N10: 784.08783 | O10: 747.67328 | P10: 856.79001 | Q10: 938.85299 | R10: 972.92185 | S10: 1028.8828 | T10: 923.02622 | U10: 927.55878 | V10: 948.45836 | W10: 899.49033 | X10: 920.68986 | Y10: 1051.3266 | Z10: 1031.3524 | AA10: 1099.3721 | AB10: 1297.735 | AC10: 1502.9073 | AD10: 1271.9154 | AE10: 1398.9025 | AF10: 1309.8655 | AG10: 1325.2813 | AH10: 1532.6027 | AI10: 1547.5327 | AJ10: 1519.7997 | AK10: 1466.4489 | AL10: 1785.8032 | AM10: 1865.8704 | AN10: 1723.215 | AO10: 1652.5607 | AP10: 1697.2144 | AQ10: 1680.7417 | AR10: 1862.3401 | AS10: 1957.0009 | AT10: 1707.3692 | AU10: 1368.351 | AV10: 1405.08 | AW10: 1369.9664 | AX10: 1551.3942 | AY10: 1765.8833 | AZ10: 1798.8387 | BA10: 1918.7739 | BB10: 1823.4507 | BC10: 1855.9086 | BD10: 1874.14 | BE10: 2720.23 | BF10: 2545.7664
B11: 10120 | C11: 7191.1218 | D11: 7192.8482 | E11: 7909.7397 | F11: 8092.6549 | G11: 8086.7784 | H11: 9246.5354 | I11: 8969.8133 | J11: 8732.2239 | K11: 9110.2166 | L11: 9396.2957 | M11: 9509.9358 | N11: 9684.7295 | O11: 9975.1602 | P11: 10392.75 | Q11: 9939.5637 | R11: 10020.484 | S11: 11286.372 | T11: 11328.528 | U11: 11918.965 | V11: 12968.725 | W11: 12714.435 | X11: 13543.102 | Y11: 13091.874 | Z11: 13362.504 | AA11: 13141.52 | AB11: 13650.136 | AC11: 13540.814 | AD11: 13880.974 | AE11: 14127.465 | AF11: 12912.806 | AG11: 12840.65 | AH11: 13797.94 | AI11: 14298.441 | AJ11: 13826.129 | AK11: 14173.828 | AL11: 13209.383 | AM11: 13027.49 | AN11: 13879.796 | AO11: 14105.683 | AP11: 13945.429 | AQ11: 14976.831 | AR11: 12942.492 | AS11: 13371.73 | AT11: 11108.652 | AU11: 10496.514 | AV11: 10484.394 | AW11: 11085.415 | AX11: 13313.886 | AY11: 12468.965 | AZ11: 11596.237 | BA11: 12325.725 | BB11: 12922.92 | BC11: 13797.306 | BD11: 12844.096 | BE11: 12504.297 | BF11: 14326.272
B12: REST | C12: 333549.59 | D12: 333773.79 | E12: 359668.1 | F12: 379483.98 | G12: 377403.11 | H12: 398810.74 | I12: 415064.17 | J12: 402824.75 | K12: 397272.6 | L12: 426907.13 | M12: 434251.61 | N12: 449440.5 | O12: 463650.64 | P12: 456559.96 | Q12: 438308.64 | R12: 440985.7 | S12: 453851.08 | T12: 504015.05 | U12: 538217.35 | V12: 600442.98 | W12: 614779.18 | X12: 610583.43 | Y12: 605776.45 | Z12: 611075.01 | AA12: 606718.03 | AB12: 614055.57 | AC12: 621828.32 | AD12: 654904.5 | AE12: 690788.55 | AF12: 721533.29 | AG12: 743617.42 | AH12: 764770.04 | AI12: 817626.87 | AJ12: 846818.31 | AK12: 889083.43 | AL12: 898570.42 | AM12: 893683.09 | AN12: 916546.36 | AO12: 992247.12 | AP12: 1050071.9 | AQ12: 1096477 | AR12: 1089560.6 | AS12: 1006372.8 | AT12: 991991.13 | AU12: 1008549.8 | AV12: 1019064 | AW12: 1002258.4 | AX12: 1038958 | AY12: 1064136.1 | AZ12: 1105830.3 | BA12: 1129390.8 | BB12: 1136519 | BC12: 1140806.9 | BD12: 1123718.2 | BE12: 1197372.2 | BF12: 1247270.7

Sheet M_F
C1: Xt
B2: TID | C2: 1967 | D2: 1968 | E2: 1969 | F2: 1970 | G2: 1971 | H2: 1972 | I2: 1973 | J2: 1974 | K2: 1975 | L2: 1976 | M2: 1977 | N2: 1978 | O2: 1979 | P2: 1980 | Q2: 1981 | R2: 1982 | S2: 1983 | T2: 1984 | U2: 1985 | V2: 1986 | W2: 1987 | X2: 1988 | Y2: 1989 | Z2: 1990 | AA2: 1991 | AB2: 1992 | AC2: 1993 | AD2: 1994 | AE2: 1995 | AF2: 1996 | AG2: 1997 | AH2: 1998 | AI2: 1999 | AJ2: 2000 | AK2: 2001 | AL2: 2002 | AM2: 2003 | AN2: 2004 | AO2: 2005 | AP2: 2006 | AQ2: 2007 | AR2: 2008 | AS2: 2009 | AT2: 2010 | AU2: 2011 | AV2: 2012 | AW2: 2013 | AX2: 2014 | AY2: 2015 | AZ2: 2016 | BA2: 2017 | BB2: 2018 | BC2: 2019 | BD2: 2020 | BE2: 2021 | BF2: 2022
A3: ANVENDELSE | B3: TILGANG2
A4: 01000 | B4: 01000 | C4: 1690.1296 | D4: 836.04564 | E4: 440.81167 | F4: 873.55584 | G4: 1302.4235 | H4: 831.6776 | I4: 874.87238 | J4: 873.70529 | K4: 678.54148 | L4: 1252.8444 | M4: 1016.423 | N4: 684.98779 | O4: 714.29588 | P4: 719.97087 | Q4: 1007.6512 | R4: 700.59393 | S4: 1198.8942 | T4: 694.34775 | U4: 649.37536 | V4: 794.32986 | W4: 620.69345 | X4: 427.76107 | Y4: 294.63769 | Z4: 225.93967 | AA4: 360.03148 | AB4: 1432.4552 | AC4: 684.61314 | AD4: 539.41007 | AE4: 551.38119 | AF4: 526.29729 | AG4: 514.50158 | AH4: 750.44625 | AI4: 742.33836 | AJ4: 807.85043 | AK4: 936.87106 | AL4: 1153.7083 | AM4: 892.66811 | AN4: 604.07993 | AO4: 568.78487 | AP4: 817.82957 | AQ4: 504.61421 | AR4: 928.55543 | AS4: 755.58596 | AT4: 809.23189 | AU4: 1254.8328 | AV4: 1026.9569 | AW4: 945.74862 | AX4: 735.05974 | AY4: 823.81966 | AZ4: 1006.4774 | BA4: 1160.8751 | BB4: 1403.3293 | BC4: 1214.0151 | BD4: 641.172 | BE4: 625.623 | BF4: 904.15457
B5: 10120 | C5: 1808.5867 | D5: 1695.5769 | E5: 1857.6892 | F5: 1918.2905 | G5: 1810.5278 | H5: 2101.0082 | I5: 2131.2433 | J5: 2035.3535 | K5: 2648.2907 | L5: 3230.3575 | M5: 3500.0378 | N5: 4078.4241 | O5: 4422.1909 | P5: 4563.7538 | Q5: 4798.9579 | R5: 5526.7012 | S5: 5308.4012 | T5: 5109.2839 | U5: 5516.0013 | V5: 5695.1304 | W5: 6009.697 | X5: 5304.0217 | Y5: 5456.8415 | Z5: 5701.5584 | AA5: 5826.7514 | AB5: 5965.9644 | AC5: 6475.2934 | AD5: 6417.0224 | AE5: 5809.5681 | AF5: 5207.4533 | AG5: 5169.0392 | AH5: 5769.2418 | AI5: 5155.4147 | AJ5: 5390.7143 | AK5: 5443.3871 | AL5: 5467.7064 | AM5: 4225.1593 | AN5: 5074.096 | AO5: 5122.7998 | AP5: 5026.744 | AQ5: 5279.7919 | AR5: 4539.176 | AS5: 5732.2929 | AT5: 6456.8448 | AU5: 6082.5204 | AV5: 6347.9549 | AW5: 5790.7775 | AX5: 6275.7085 | AY5: 7055.2104 | AZ5: 6522.5277 | BA5: 5927.5189 | BB5: 6157.9672 | BC5: 5987.4999 | BD5: 6014.407 | BE5: 6132.786 | BF5: 5832.7793
B6: REST | C6: 3196.3322 | D6: 3479.4806 | E6: 3504.4378 | F6: 3793.2402 | G6: 4049.5634 | H6: 4212.6719 | I6: 4753.3053 | J6: 4598.4729 | K6: 4332.1899 | L6: 4163.6208 | M6: 4406.9778 | N6: 4563.509 | O6: 5569.957 | P6: 5127.1688 | Q6: 5048.4421 | R6: 5166.2665 | S6: 5897.7149 | T6: 6275.1314 | U6: 5956.6889 | V6: 5410.8908 | W6: 5212.9973 | X6: 4735.0566 | Y6: 5573.4848 | Z6: 5802.0963 | AA6: 5700.3099 | AB6: 4901.3514 | AC6: 5095.0533 | AD6: 4224.9361 | AE6: 4123.1343 | AF6: 4100.3871 | AG6: 4400.2278 | AH6: 4513.1561 | AI6: 4785.3657 | AJ6: 4078.6806 | AK6: 3763.8222 | AL6: 4239.89 | AM6: 4447.9457 | AN6: 4791.1331 | AO6: 4341.8032 | AP6: 4250.3685 | AQ6: 4437.2198 | AR6: 5481.2312 | AS6: 4967.5869 | AT6: 4538.0229 | AU6: 5135.1022 | AV6: 4796.5123 | AW6: 5005.5484 | AX6: 4747.1803 | AY6: 4803.2977 | AZ6: 4803.4723 | BA6: 4678.8394 | BB6: 4212.8434 | BC6: 3920.8933 | BD6: 3864.642 | BE6: 4160.433 | BF6: 3971.3521
A7: 10120 | B7: 01000 | C7: 2238.2665 | D7: 1580.3695 | E7: 1604.6795 | F7: 1921.5579 | G7: 1851.5508 | H7: 1593.389 | I7: 2040.6372 | J7: 1795.9876 | K7: 1596.1719 | L7: 1839.2101 | M7: 1550.8672 | N7: 2051.5293 | O7: 2051.6348 | P7: 1776.8474 | Q7: 1477.8576 | R7: 1470.2066 | S7: 1417.1813 | T7: 1249.5458 | U7: 1342.0862 | V7: 1412.9147 | W7: 1208.5646 | X7: 1065.2477 | Y7: 1015.7947 | Z7: 1372.4748 | AA7: 1584.5199 | AB7: 1456.2147 | AC7: 1610.9445 | AD7: 1910.1649 | AE7: 2203.4458 | AF7: 2081.5888 | AG7: 2187.8589 | AH7: 2330.1157 | AI7: 2396.8691 | AJ7: 2457.6181 | AK7: 2499.4127 | AL7: 3374.8661 | AM7: 3695.4959 | AN7: 3269.605 | AO7: 2901.358 | AP7: 3587.9201 | AQ7: 3380.6759 | AR7: 4376.7085 | AS7: 2814.6438 | AT7: 2482.9682 | AU7: 2205.8295 | AV7: 2126.849 | AW7: 2306.6478 | AX7: 2138.1439 | AY7: 2352.7391 | AZ7: 2119.7414 | BA7: 2526.9213 | BB7: 2599.8442 | BC7: 2862.9786 | BD7: 2317.639 | BE7: 1652.062 | BF7: 1786.8999
B8: 10120 | C8: 863.93225 | D8: 1068.9073 | E8: 1172.7549 | F8: 1474.0914 | G8: 1454.1805 | H8: 1498.7768 | I8: 1569.2633 | J8: 1745.7509 | K8: 1860.9781 | L8: 2348.9862 | M8: 2427.5024 | N8: 2299.4517 | O8: 2620.5183 | P8: 2706.4329 | Q8: 3077.7134 | R8: 2869.6795 | S8: 2949.4592 | T8: 3399.365 | U8: 3816.2216 | V8: 4027.9348 | W8: 4481.6602 | X8: 4981.4929 | Y8: 5603.4576 | Z8: 6123.5024 | AA8: 7030.9376 | AB8: 7723.0478 | AC8: 7576.074 | AD8: 8563.1006 | AE8: 9656.6831 | AF8: 10371.872 | AG8: 10626.931 | AH8: 10573.136 | AI8: 10253.346 | AJ8: 11984.549 | AK8: 12631.721 | AL8: 12457.473 | AM8: 13977.083 | AN8: 14482.957 | AO8: 15490.407 | AP8: 16975.117 | AQ8: 17575.419 | AR8: 17301.019 | AS8: 16043.328 | AT8: 15050.058 | AU8: 15061.087 | AV8: 15230.716 | AW8: 16344.2 | AX8: 17290.555 | AY8: 17964.441 | AZ8: 16320.649 | BA8: 16603.618 | BB8: 17489.573 | BC8: 17510.782 | BD8: 17608.054 | BE8: 17224.302 | BF8: 16713.948
B9: REST | C9: 1523.96 | D9: 1989.2237 | E9: 2139.2612 | F9: 2394.9454 | G9: 2780.7959 | H9: 2877.3771 | I9: 3188.2714 | J9: 3492.527 | K9: 3152.679 | L9: 3584.8736 | M9: 3862.5333 | N9: 3976.4048 | O9: 4463.7019 | P9: 4935.2472 | Q9: 5164.1108 | R9: 5516.3521 | S9: 5221.5034 | T9: 5664.9839 | U9: 5619.1929 | V9: 6268.4287 | W9: 6781.4966 | X9: 6509.696 | Y9: 6847.787 | Z9: 7439.8702 | AA9: 8015.8016 | AB9: 7191.1609 | AC9: 7166.392 | AD9: 7716.5238 | AE9: 7486.4984 | AF9: 8045.9162 | AG9: 8069.0476 | AH9: 8369.1873 | AI9: 8781.4741 | AJ9: 9521.8058 | AK9: 10093.035 | AL9: 10911.344 | AM9: 11473.828 | AN9: 11818.42 | AO9: 12144.625 | AP9: 12650.939 | AQ9: 12377.723 | AR9: 13868.983 | AS9: 12940.226 | AT9: 12215.763 | AU9: 12251.269 | AV9: 12458.749 | AW9: 11897.881 | AX9: 11429.625 | AY9: 11959.656 | AZ9: 13442.009 | BA9: 13718.229 | BB9: 13881.505 | BC9: 14422.813 | BD9: 15722.832 | BE9: 15320.421 | BF9: 15977.698
A10: REST | B10: 01000 | C10: 1606.7363 | D10: 1112.4872 | E10: 1211.0029 | F10: 1353.0031 | G10: 1408.3857 | H10: 1212.2626 | I10: 1374.7267 | J10: 1458.814 | K10: 1299.8894 | L10: 1575.6389 | M10: 1696.5177 | N10: 1538.9704 | O10: 1294.9979 | P10: 1365.9934 | Q10: 1310.8899 | R10: 1335.7478 | S10: 1082.1583 | T10: 1164.4903 | U10: 1250.0508 | V10: 1360.6943 | W10: 1357.3567 | X10: 1405.0717 | Y10: 1782.4327 | Z10: 1157.707 | AA10: 1498.6089 | AB10: 1322.2734 | AC10: 1912.5961 | AD10: 1959.3416 | AE10: 1534.6985 | AF10: 1818.4474 | AG10: 1177.6252 | AH10: 1493.9998 | AI10: 1626.7723 | AJ10: 1690.2551 | AK10: 1818.9021 | AL10: 1757.9691 | AM10: 1843.7174 | AN10: 1653.0656 | AO10: 1517.0846 | AP10: 1438.7239 | AQ10: 1626.4628 | AR10: 1630.6657 | AS10: 1449.5427 | AT10: 1374.6631 | AU10: 1072.3798 | AV10: 1147.5523 | AW10: 1334.0245 | AX10: 1232.7325 | AY10: 1567.7594 | AZ10: 1513.5177 | BA10: 1508.9768 | BB10: 1752.4484 | BC10: 1661.9689 | BD10: 1441.883 | BE10: 1858.472 | BF10: 1659.9134
B11: 10120 | C11: 870.29763 | D11: 919.30271 | E11: 1090.9077 | F11: 1280.0421 | G11: 1357.706 | H11: 1448.4415 | I11: 1722.8689 | J11: 1735.5686 | K11: 1659.0814 | L11: 1928.7904 | M11: 1959.6021 | N11: 2114.4261 | O11: 2367.8062 | P11: 2620.5468 | Q11: 2879.7337 | R11: 2508.68 | S11: 2803.104 | T11: 2974.121 | U11: 3288.8463 | V11: 3256.072 | W11: 3657.268 | X11: 3598.4272 | Y11: 4200.2177 | Z11: 3930.9687 | AA11: 4945.8858 | AB11: 6080.3459 | AC11: 6800.8736 | AD11: 6710.0035 | AE11: 7582.3263 | AF11: 8001.1695 | AG11: 8220.0005 | AH11: 9002.0673 | AI11: 9153.5242 | AJ11: 10070.911 | AK11: 10230.342 | AL11: 10985.586 | AM11: 9998.2745 | AN11: 10942.537 | AO11: 11489.482 | AP11: 11927.65 | AQ11: 12587.344 | AR11: 11245.009 | AS11: 9532.1791 | AT11: 10113.435 | AU11: 10266.15 | AV11: 10521.311 | AW11: 11179.205 | AX11: 11781.036 | AY11: 12588.628 | AZ11: 12406.634 | BA11: 12515.551 | BB11: 13214.243 | BC11: 13826.532 | BD11: 13238.154 | BE11: 13000.797 | BF11: 13798.438
B12: REST | C12: 68531.702 | D12: 75112.534 | E12: 87341.768 | F12: 92818.6 | G12: 95092.378 | H12: 101271.64 | I12: 111936.75 | J12: 110075.25 | K12: 99147.896 | L12: 112118.6 | M12: 112960.4 | N12: 113945.33 | O12: 118654.73 | P12: 115409.54 | Q12: 110415.95 | R12: 108748.27 | S12: 110149.04 | T12: 117126.31 | U12: 124199.8 | V12: 127151.78 | W12: 127158.13 | X12: 134953.99 | Y12: 135812.48 | Z12: 138114.79 | AA12: 140991.26 | AB12: 140112.21 | AC12: 137051.05 | AD12: 150568.14 | AE12: 159922.35 | AF12: 167299.68 | AG12: 174431.69 | AH12: 184998.26 | AI12: 193714.85 | AJ12: 213185.9 | AK12: 220054.6 | AL12: 229394.42 | AM12: 222436.48 | AN12: 228916.04 | AO12: 266377.49 | AP12: 297904.06 | AQ12: 309674.12 | AR12: 335438.2 | AS12: 288376.54 | AT12: 290805.67 | AU12: 309567.93 | AV12: 324466.72 | AW12: 329211.11 | AX12: 333859.73 | AY12: 360388.77 | AZ12: 380905.28 | BA12: 390514.83 | BB12: 414717.04 | BC12: 439165.49 | BD12: 435257.59 | BE12: 466048.48 | BF12: 506674.67

Sheet L
B1: Xt
A2: TID | B2: 1966 | C2: 1967 | D2: 1968 | E2: 1969 | F2: 1970 | G2: 1971 | H2: 1972 | I2: 1973 | J2: 1974 | K2: 1975 | L2: 1976 | M2: 1977 | N2: 1978 | O2: 1979 | P2: 1980 | Q2: 1981 | R2: 1982 | S2: 1983 | T2: 1984 | U2: 1985 | V2: 1986 | W2: 1987 | X2: 1988 | Y2: 1989 | Z2: 1990 | AA2: 1991 | AB2: 1992 | AC2: 1993 | AD2: 1994 | AE2: 1995 | AF2: 1996 | AG2: 1997 | AH2: 1998 | AI2: 1999 | AJ2: 2000 | AK2: 2001 | AL2: 2002 | AM2: 2003 | AN2: 2004 | AO2: 2005 | AP2: 2006 | AQ2: 2007 | AR2: 2008 | AS2: 2009 | AT2: 2010 | AU2: 2011 | AV2: 2012 | AW2: 2013 | AX2: 2014 | AY2: 2015 | AZ2: 2016 | BA2: 2017 | BB2: 2018 | BC2: 2019 | BD2: 2020 | BE2: 2021 | BF2: 2022
A3: ANVENDELSE
A4: 01000 | B4: 630077 | C4: 595974 | D4: 561953 | E4: 532920 | F4: 505492 | G4: 472538 | H4: 463150 | I4: 454509 | J4: 433263 | K4: 415440 | L4: 408086 | M4: 393844 | N4: 380021 | O4: 361600 | P4: 342439 | Q4: 325525 | R4: 314708 | S4: 305717 | T4: 297005 | U4: 286292 | V4: 277373 | W4: 272733 | X4: 247527 | Y4: 239832 | Z4: 229640 | AA4: 224577 | AB4: 216746 | AC4: 205929 | AD4: 187306 | AE4: 180889 | AF4: 173049 | AG4: 162332 | AH4: 160810 | AI4: 152280 | AJ4: 149020 | AK4: 145343 | AL4: 145637 | AM4: 134391 | AN4: 133301 | AO4: 125588 | AP4: 117953 | AQ4: 114771 | AR4: 109397 | AS4: 101938 | AT4: 98594 | AU4: 97135 | AV4: 95702 | AW4: 94814 | AX4: 95678 | AY4: 97467 | AZ4: 91694 | BA4: 92464 | BB4: 89982 | BC4: 85014 | BD4: 85490 | BE4: 86997 | BF4: 84490
A5: 10120 | B5: 232125 | C5: 220326 | D5: 210205 | E5: 204420 | F5: 202642 | G5: 194114 | H5: 187292 | I5: 179902 | J5: 174334 | K5: 156330 | L5: 155216 | M5: 152588 | N5: 149102 | O5: 150151 | P5: 147911 | Q5: 145985 | R5: 146121 | S5: 147457 | T5: 147552 | U5: 145082 | V5: 148494 | W5: 140336 | X5: 138844 | Y5: 133495 | Z5: 129957 | AA5: 129100 | AB5: 127466 | AC5: 124695 | AD5: 121438 | AE5: 123972 | AF5: 120697 | AG5: 117906 | AH5: 115140 | AI5: 116399 | AJ5: 117301 | AK5: 117036 | AL5: 116729 | AM5: 110661 | AN5: 106601 | AO5: 99250 | AP5: 95156 | AQ5: 90557 | AR5: 89332 | AS5: 83220 | AT5: 79289 | AU5: 76719 | AV5: 73253 | AW5: 70479 | AX5: 66267 | AY5: 64949 | AZ5: 65699 | BA5: 67126 | BB5: 65335 | BC5: 65519 | BD5: 70152 | BE5: 70240 | BF5: 69952
A6: REST | B6: 3742182 | C6: 3720867 | D6: 3695254 | E6: 3716009 | F6: 3741101 | G6: 3694889 | H6: 3653882 | I6: 3614336 | J6: 3566698 | K6: 3379346 | L6: 3472797 | M6: 3418194 | N6: 3410781 | O6: 3444395 | P6: 3477283 | Q6: 3356998 | R6: 3400968 | S6: 3394252 | T6: 3445565 | U6: 3514700 | V6: 3625889 | W6: 3568130 | X6: 3517672 | Y6: 3475337 | Z6: 3434810 | AA6: 3395609 | AB6: 3413744 | AC6: 3357281 | AD6: 3342697 | AE6: 3401971 | AF6: 3431762 | AG6: 3539072 | AH6: 3632582 | AI6: 3714509 | AJ6: 3772557 | AK6: 3824171 | AL6: 3809762 | AM6: 3776588 | AN6: 3761275 | AO6: 3814540 | AP6: 3929729 | AQ6: 3967488 | AR6: 4018058 | AS6: 3861885 | AT6: 3790107 | AU6: 3830075 | AV6: 3769454 | AW6: 3781533 | AX6: 3776795 | AY6: 3815080 | AZ6: 3899913 | BA6: 3935591 | BB6: 3934302 | BC6: 3972380 | BD6: 3827066 | BE6: 4062261 | BF6: 4225398

Sheet J
B1: Xt
A2: TID | B2: 1982 | C2: 1983 | D2: 1984 | E2: 1985 | F2: 1986 | G2: 1987 | H2: 1988 | I2: 1989 | J2: 1990 | K2: 1991 | L2: 1992 | M2: 1993 | N2: 1994 | O2: 1995 | P2: 1996 | Q2: 1997 | R2: 1998 | S2: 1999 | T2: 2000 | U2: 2001 | V2: 2002 | W2: 2003 | X2: 2004 | Y2: 2005 | Z2: 2006 | AA2: 2007 | AB2: 2008 | AC2: 2009 | AD2: 2010 | AE2: 2011 | AF2: 2012 | AG2: 2013 | AH2: 2014 | AI2: 2015 | AJ2: 2016 | AK2: 2017 | AL2: 2018 | AM2: 2019 | AN2: 2020 | AO2: 2021 | AP2: 2022 | AQ2: 2023 | AR2: 2024
A3: ANVENDELSE
A4: 01000 | B4: 341929.03 | C4: 340285.55 | D4: 342435.3 | E4: 340760.66 | F4: 339577.83 | G4: 337332.5 | H4: 335061.88 | I4: 333134.17 | J4: 335220.04 | K4: 333471.08 | L4: 332267.39 | M4: 303379.47 | N4: 298275.36 | O4: 300079.34 | P4: 304116 | Q4: 309400.68 | R4: 309535.76 | S4: 300074.52 | T4: 298499.23 | U4: 299882.2 | V4: 297695.68 | W4: 296422.88 | X4: 296724.33 | Y4: 304923.59 | Z4: 307094.6 | AA4: 301984.76 | AB4: 314796.85 | AC4: 312195.18 | AD4: 314457.85 | AE4: 316600.69 | AF4: 315481.1 | AG4: 313713.75 | AH4: 317824.99 | AI4: 306612.7 | AJ4: 308425.81 | AK4: 307618.61 | AL4: 305542 | AM4: 305391.28 | AN4: 301948.12 | AO4: 300799.58 | AP4: 298554.25 | AQ4: 290344.04 | AR4: 285270.31
A5: 10120 | B5: 0 | C5: 0 | D5: 0 | E5: 0 | F5: 0 | G5: 0 | H5: 0 | I5: 0 | J5: 0 | K5: 0 | L5: 0 | M5: 0 | N5: 0 | O5: 0 | P5: 0 | Q5: 0 | R5: 0 | S5: 0 | T5: 0 | U5: 0 | V5: 0 | W5: 0 | X5: 0 | Y5: 0 | Z5: 0 | AA5: 0 | AB5: 0 | AC5: 0 | AD5: 0 | AE5: 0 | AF5: 0 | AG5: 0 | AH5: 0 | AI5: 0 | AJ5: 0 | AK5: 0 | AL5: 0 | AM5: 0 | AN5: 0 | AO5: 0 | AP5: 0 | AQ5: 0 | AR5: 0
A6: REST | B6: 0 | C6: 0 | D6: 0 | E6: 0 | F6: 0 | G6: 0 | H6: 0 | I6: 0 | J6: 0 | K6: 0 | L6: 0 | M6: 0 | N6: 0 | O6: 0 | P6: 0 | Q6: 0 | R6: 0 | S6: 0 | T6: 0 | U6: 0 | V6: 0 | W6: 0 | X6: 0 | Y6: 0 | Z6: 0 | AA6: 0 | AB6: 0 | AC6: 0 | AD6: 0 | AE6: 0 | AF6: 0 | AG6: 0 | AH6: 0 | AI6: 0 | AJ6: 0 | AK6: 0 | AL6: 0 | AM6: 0 | AN6: 0 | AO6: 0 | AP6: 0 | AQ6: 0 | AR6: 0

Sheet K
B1: Xt
A2: TID | B2: 1967 | C2: 1968 | D2: 1969 | E2: 1970 | F2: 1971 | G2: 1972 | H2: 1973 | I2: 1974 | J2: 1975 | K2: 1976 | L2: 1977 | M2: 1978 | N2: 1979 | O2: 1980 | P2: 1981 | Q2: 1982 | R2: 1983 | S2: 1984 | T2: 1985 | U2: 1986 | V2: 1987 | W2: 1988 | X2: 1989 | Y2: 1990 | Z2: 1991 | AA2: 1992 | AB2: 1993 | AC2: 1994 | AD2: 1995 | AE2: 1996 | AF2: 1997 | AG2: 1998 | AH2: 1999 | AI2: 2000 | AJ2: 2001 | AK2: 2002 | AL2: 2003 | AM2: 2004 | AN2: 2005 | AO2: 2006 | AP2: 2007 | AQ2: 2008 | AR2: 2009 | AS2: 2010 | AT2: 2011 | AU2: 2012 | AV2: 2013 | AW2: 2014 | AX2: 2015 | AY2: 2016 | AZ2: 2017 | BA2: 2018 | BB2: 2019 | BC2: 2020 | BD2: 2021 | BE2: 2022 | BF2: 2023 | BG2: 2024
A3: ANVENDELSE
A4: 01000 | B4: 224514.51 | C4: 224366.46 | D4: 225176.76 | E4: 225616.93 | F4: 226470.25 | G4: 229355.33 | H4: 235259.56 | I4: 240569.56 | J4: 244107.89 | K4: 250017.11 | L4: 257639.98 | M4: 265809.06 | N4: 274053.16 | O4: 274942.49 | P4: 271676.26 | Q4: 269273.36 | R4: 265486.94 | S4: 264809.68 | T4: 266326.25 | U4: 266985.5 | V4: 266210.21 | W4: 264402.53 | X4: 267324.63 | Y4: 270872.96 | Z4: 271079.04 | AA4: 270057.66 | AB4: 265264.85 | AC4: 261502.44 | AD4: 258943.47 | AE4: 255818.3 | AF4: 253576.45 | AG4: 250997.48 | AH4: 243846.79 | AI4: 242189.17 | AJ4: 242222.18 | AK4: 240251.44 | AL4: 238152.65 | AM4: 236176.9 | AN4: 234775.37 | AO4: 235933.81 | AP4: 239420.12 | AQ4: 242335.22 | AR4: 239114.01 | AS4: 234152.14 | AT4: 229189.27 | AU4: 225174.76 | AV4: 222099.6 | AW4: 218559.27 | AX4: 215349.06 | AY4: 211367.56 | AZ4: 208356.43 | BA4: 204332.92 | BB4: 200801.59 | BC4: 196588 | BD4: 194543.23 | BE4: 190721.79 | BF4: 187463.57 | BG4: 184659.51
A5: 10120 | B5: 36904.728 | C5: 38025.75 | D5: 39447.778 | E5: 40346.796 | F5: 41710.823 | G5: 42921.847 | H5: 44127.87 | I5: 46869.925 | J5: 48514.957 | K5: 50580.998 | L5: 52445.035 | M5: 54644.078 | N5: 57093.126 | O5: 58319.15 | P5: 59086.166 | Q5: 59217.168 | R5: 59269.169 | S5: 60352.191 | T5: 61830.22 | U5: 63941.261 | V5: 66179.305 | W5: 68824.358 | X5: 71029.401 | Y5: 72699.434 | Z5: 75679.493 | AA5: 78427.547 | AB5: 79445.567 | AC5: 80169.581 | AD5: 80876.595 | AE5: 83395.645 | AF5: 83780.653 | AG5: 84572.668 | AH5: 84522.667 | AI5: 86867.714 | AJ5: 88849.753 | AK5: 90560.786 | AL5: 93052.836 | AM5: 95677.887 | AN5: 95905.892 | AO5: 95869.891 | AP5: 96615.906 | AQ5: 99623.965 | AR5: 102064.01 | AS5: 99904.971 | AT5: 98585.945 | AU5: 99449.962 | AV5: 99127.955 | AW5: 98818.949 | AX5: 98168.937 | AY5: 97864.931 | AZ5: 98144.936 | BA5: 100339.98 | BB5: 101519 | BC5: 101387 | BD5: 101866.01 | BE5: 102662.03 | BF5: 103488.04 | BG5: 104609.06
A6: REST | B6: 2649638.3 | C6: 2759368.2 | D6: 2886580.6 | E6: 3015208.8 | F6: 3138405.5 | G6: 3280526.9 | H6: 3428105.1 | I6: 3542953.7 | J6: 3632246.8 | K6: 3761136.1 | L6: 3879000.1 | M6: 3996137.1 | N6: 4110011.6 | O6: 4195908.6 | P6: 4231481.6 | Q6: 4280161.2 | R6: 4335621.6 | S6: 4406211.8 | T6: 4504274.4 | U6: 4649803.9 | V6: 4790087 | W6: 4891882.6 | X6: 4981504.3 | Y6: 5072787.9 | Z6: 5129425.3 | AA6: 5174500.6 | AB6: 5201875.4 | AC6: 5232337.6 | AD6: 5287123.2 | AE6: 5353696.3 | AF6: 5437468.8 | AG6: 5533345.6 | AH6: 5612669 | AI6: 5715695.6 | AJ6: 5803091.1 | AK6: 5874688.6 | AL6: 5943074.3 | AM6: 6012449.4 | AN6: 6103124.5 | AO6: 6247179.6 | AP6: 6376010.8 | AQ6: 6474294.7 | AR6: 6522656.8 | AS6: 6540181.6 | AT6: 6557790.1 | AU6: 6589190.1 | AV6: 6628205.8 | AW6: 6688660.6 | AX6: 6762598 | AY6: 6866765.9 | AZ6: 6983072.4 | BA6: 7106985 | BB6: 7209887.2 | BC6: 7326042 | BD6: 7489112.7 | BE6: 7648995.4 | BF6: 7786056.3 | BG6: 7926877.2

Sheet MDtot
B1: Xt
A2: TID | B2: 1967 | C2: 1968 | D2: 1969 | E2: 1970 | F2: 1971 | G2: 1972 | H2: 1973 | I2: 1974 | J2: 1975 | K2: 1976 | L2: 1977 | M2: 1978 | N2: 1979 | O2: 1980 | P2: 1981 | Q2: 1982 | R2: 1983 | S2: 1984 | T2: 1985 | U2: 1986 | V2: 1987 | W2: 1988 | X2: 1989 | Y2: 1990 | Z2: 1991 | AA2: 1992 | AB2: 1993 | AC2: 1994 | AD2: 1995 | AE2: 1996 | AF2: 1997 | AG2: 1998 | AH2: 1999 | AI2: 2000 | AJ2: 2001 | AK2: 2002 | AL2: 2003 | AM2: 2004 | AN2: 2005 | AO2: 2006 | AP2: 2007 | AQ2: 2008 | AR2: 2009 | AS2: 2010 | AT2: 2011 | AU2: 2012 | AV2: 2013 | AW2: 2014 | AX2: 2015 | AY2: 2016 | AZ2: 2017 | BA2: 2018 | BB2: 2019 | BC2: 2020 | BD2: 2021 | BE2: 2022
A3: ANVENDELSE
A4: 01000 | B4: 31709.383 | C4: 32928.936 | D4: 32248.759 | E4: 33058.048 | F4: 32857.409 | G4: 33005.843 | H4: 35820.684 | I4: 33458.534 | J4: 33491.351 | K4: 35793.006 | L4: 35058.2 | M4: 37664.175 | N4: 38926.524 | O4: 37794.129 | P4: 36016.019 | Q4: 36373.867 | R4: 35806.567 | S4: 36438.996 | T4: 37083.241 | U4: 35965.965 | V4: 38219.755 | W4: 36463.258 | X4: 34728.876 | Y4: 36019.18 | Z4: 34155.68 | AA4: 34779.904 | AB4: 40169.914 | AC4: 39171.124 | AD4: 38654.183 | AE4: 38488.072 | AF4: 39980.752 | AG4: 40065.075 | AH4: 41213.409 | AI4: 39869.067 | AJ4: 38158.444 | AK4: 39526.432 | AL4: 39460.402 | AM4: 39049.542 | AN4: 38852.368 | AO4: 39206.53 | AP4: 39239.256 | AQ4: 39065.118 | AR4: 39561.728 | AS4: 38287.097 | AT4: 38369.71 | AU4: 37945.18 | AV4: 39183.116 | AW4: 38453.53 | AX4: 40043.646 | AY4: 40649.577 | AZ4: 41666.266 | BA4: 41402.993 | BB4: 39369.003 | BC4: 41742.615 | BD4: 41587.533 | BE4: 42512.469
A5: 10120 | B5: 55401.38 | C5: 58151.495 | D5: 57351.605 | E5: 59635.214 | F5: 62630.409 | G5: 63973.347 | H5: 63352.985 | I5: 65119.522 | J5: 64844.067 | K5: 67192.189 | L5: 69361.755 | M5: 72062.413 | N5: 78931.562 | O5: 83264.812 | P5: 83680.291 | Q5: 80229.553 | R5: 77401.508 | S5: 78812.251 | T5: 83060.992 | U5: 88172.476 | V5: 87778.049 | W5: 85861.172 | X5: 84341.679 | Y5: 88244.37 | Z5: 87425.119 | AA5: 92477.288 | AB5: 99002.458 | AC5: 98515.248 | AD5: 94913.352 | AE5: 89306.466 | AF5: 87818.068 | AG5: 91349.28 | AH5: 89368.694 | AI5: 88151.946 | AJ5: 88271.071 | AK5: 93055.729 | AL5: 94721.314 | AM5: 95199.176 | AN5: 97210.924 | AO5: 95959.612 | AP5: 94875.505 | AQ5: 91944.58 | AR5: 89199.15 | AS5: 84791.793 | AT5: 86469.949 | AU5: 83711.527 | AV5: 84645.013 | AW5: 84972.384 | AX5: 87502.725 | AY5: 88050.164 | AZ5: 90152.864 | BA5: 90695.094 | BB5: 89321.561 | BC5: 93900.407 | BD5: 95406.599 | BE5: 94115.541
A6: REST | B6: 341295.61 | C6: 341590.65 | D6: 368220.75 | E6: 388079.96 | F6: 386053.51 | G6: 408872.83 | H6: 424489.77 | I6: 411963.31 | J6: 407170.18 | K6: 436935.17 | L6: 444549.29 | M6: 460001.02 | N6: 474435.24 | O6: 468119.37 | P6: 449524.9 | Q6: 452335.86 | R6: 466829.42 | S6: 516617.18 | T6: 551364.61 | U6: 614591 | V6: 628473.36 | W6: 625338.04 | X6: 620161.94 | Y6: 625742.11 | Z6: 621218.52 | AA6: 629327.66 | AB6: 637161 | AC6: 670301.98 | AD6: 706513.39 | AE6: 735781.76 | AF6: 757765.77 | AG6: 780125.36 | AH6: 833471.28 | AI6: 862121.41 | AJ6: 904666.28 | AK6: 913448.14 | AL6: 908460.67 | AM6: 932042.58 | AN6: 1007843.2 | AO6: 1065521.4 | AP6: 1112934.1 | AQ6: 1104159.1 | AR6: 1021559.6 | AS6: 1004672.4 | AT6: 1020287.4 | AU6: 1030820.6 | AV6: 1014623.8 | AW6: 1053827.1 | AX6: 1078366.7 | AY6: 1119206.9 | AZ6: 1143627.1 | BA6: 1151259.5 | BB6: 1156450.1 | BC6: 1138436.5 | BD6: 1212596.7 | BE6: 1264111.7

Sheet MFtot
B1: Xt
A2: TID | B2: 1967 | C2: 1968 | D2: 1969 | E2: 1970 | F2: 1971 | G2: 1972 | H2: 1973 | I2: 1974 | J2: 1975 | K2: 1976 | L2: 1977 | M2: 1978 | N2: 1979 | O2: 1980 | P2: 1981 | Q2: 1982 | R2: 1983 | S2: 1984 | T2: 1985 | U2: 1986 | V2: 1987 | W2: 1988 | X2: 1989 | Y2: 1990 | Z2: 1991 | AA2: 1992 | AB2: 1993 | AC2: 1994 | AD2: 1995 | AE2: 1996 | AF2: 1997 | AG2: 1998 | AH2: 1999 | AI2: 2000 | AJ2: 2001 | AK2: 2002 | AL2: 2003 | AM2: 2004 | AN2: 2005 | AO2: 2006 | AP2: 2007 | AQ2: 2008 | AR2: 2009 | AS2: 2010 | AT2: 2011 | AU2: 2012 | AV2: 2013 | AW2: 2014 | AX2: 2015 | AY2: 2016 | AZ2: 2017 | BA2: 2018 | BB2: 2019 | BC2: 2020 | BD2: 2021 | BE2: 2022
A3: ANVENDELSE
