Workbook

Sheet Figurer
B2: Ratioer
B3: Kapital-output-ratio (K/Y) | C3: 1993 | D3: 1994 | E3: 1995 | F3: 1996 | G3: 1997 | H3: 1998 | I3: 1999 | J3: 2000 | K3: 2001 | L3: 2002 | M3: 2003 | N3: 2004 | O3: 2005 | P3: 2006 | Q3: 2007 | R3: 2008 | S3: 2009 | T3: 2010 | U3: 2011 | V3: 2012 | W3: 2013 | X3: 2014 | Y3: 2015 | Z3: 2016 | AA3: 2017 | AB3: 2018 | AC3: 2019 | AD3: 2020 | AE3: 2021 | AF3: 2022
B4: Landbrug | C4: =K!AC2/Y!AB2 | D4: =K!AD2/Y!AC2 | E4: =K!AE2/Y!AD2 | F4: =K!AF2/Y!AE2 | G4: =K!AG2/Y!AF2 | H4: =K!AH2/Y!AG2 | I4: =K!AI2/Y!AH2 | J4: =K!AJ2/Y!AI2 | ... AF4: =K!BF2/Y!BE2
B5: Slagterier | C5: =K!AC3/Y!AB3 | D5: =K!AD3/Y!AC3 | E5: =K!AE3/Y!AD3 | F5: =K!AF3/Y!AE3 | G5: =K!AG3/Y!AF3 | H5: =K!AH3/Y!AG3 | I5: =K!AI3/Y!AH3 | J5: =K!AJ3/Y!AI3 | ... AF5: =K!BF3/Y!BE3
B6: Mejerier | C6: =K!AC4/Y!AB4 | D6: =K!AD4/Y!AC4 | E6: =K!AE4/Y!AD4 | F6: =K!AF4/Y!AE4 | G6: =K!AG4/Y!AF4 | H6: =K!AH4/Y!AG4 | I6: =K!AI4/Y!AH4 | J6: =K!AJ4/Y!AI4 | ... AF6: =K!BF4/Y!BE4
B7: Anden fødevareindustri | C7: =K!AC5/Y!AB5 | D7: =K!AD5/Y!AC5 | E7: =K!AE5/Y!AD5 | F7: =K!AF5/Y!AE5 | G7: =K!AG5/Y!AF5 | H7: =K!AH5/Y!AG5 | I7: =K!AI5/Y!AH5 | J7: =K!AJ5/Y!AI5 | ... AF7: =K!BF5/Y!BE5
B8: Resten af økonomien | C8: =K!AC6/Y!AB6 | D8: =K!AD6/Y!AC6 | E8: =K!AE6/Y!AD6 | F8: =K!AF6/Y!AE6 | G8: =K!AG6/Y!AF6 | H8: =K!AH6/Y!AG6 | I8: =K!AI6/Y!AH6 | J8: =K!AJ6/Y!AI6 | ... AF8: =K!BF6/Y!BE6
B10: Arbejdskraft-output-ratio (L/Y) | C10: 1993 | D10: 1994 | E10: 1995 | F10: 1996 | G10: 1997 | H10: 1998 | I10: 1999 | J10: 2000 | K10: 2001 | L10: 2002 | M10: 2003 | N10: 2004 | O10: 2005 | P10: 2006 | Q10: 2007 | R10: 2008 | S10: 2009 | T10: 2010 | U10: 2011 | V10: 2012 | W10: 2013 | X10: 2014 | Y10: 2015 | Z10: 2016 | AA10: 2017 | AB10: 2018 | AC10: 2019 | AD10: 2020 | AE10: 2021 | AF10: 2022
B11: Landbrug | C11: =L!AC2/Y!AB2 | D11: =L!AD2/Y!AC2 | E11: =L!AE2/Y!AD2 | F11: =L!AF2/Y!AE2 | G11: =L!AG2/Y!AF2 | H11: =L!AH2/Y!AG2 | I11: =L!AI2/Y!AH2 | J11: =L!AJ2/Y!AI2 | ... AF11: =L!BF2/Y!BE2
B12: Slagterier | C12: =L!AC3/Y!AB3 | D12: =L!AD3/Y!AC3 | E12: =L!AE3/Y!AD3 | F12: =L!AF3/Y!AE3 | G12: =L!AG3/Y!AF3 | H12: =L!AH3/Y!AG3 | I12: =L!AI3/Y!AH3 | J12: =L!AJ3/Y!AI3 | ... AF12: =L!BF3/Y!BE3
B13: Mejerier | C13: =L!AC4/Y!AB4 | D13: =L!AD4/Y!AC4 | E13: =L!AE4/Y!AD4 | F13: =L!AF4/Y!AE4 | G13: =L!AG4/Y!AF4 | H13: =L!AH4/Y!AG4 | I13: =L!AI4/Y!AH4 | J13: =L!AJ4/Y!AI4 | ... AF13: =L!BF4/Y!BE4
B14: Anden fødevareindustri | C14: =L!AC5/Y!AB5 | D14: =L!AD5/Y!AC5 | E14: =L!AE5/Y!AD5 | F14: =L!AF5/Y!AE5 | G14: =L!AG5/Y!AF5 | H14: =L!AH5/Y!AG5 | I14: =L!AI5/Y!AH5 | J14: =L!AJ5/Y!AI5 | ... AF14: =L!BF5/Y!BE5
B15: Resten af økonomien | C15: =L!AC6/Y!AB6 | D15: =L!AD6/Y!AC6 | E15: =L!AE6/Y!AD6 | F15: =L!AF6/Y!AE6 | G15: =L!AG6/Y!AF6 | H15: =L!AH6/Y!AG6 | I15: =L!AI6/Y!AH6 | J15: =L!AJ6/Y!AI6 | ... AF15: =L!BF6/Y!BE6
B17: Materiale-output-ratio (Mtot/Y) | C17: 1993 | D17: 1994 | E17: 1995 | F17: 1996 | G17: 1997 | H17: 1998 | I17: 1999 | J17: 2000 | K17: 2001 | L17: 2002 | M17: 2003 | N17: 2004 | O17: 2005 | P17: 2006 | Q17: 2007 | R17: 2008 | S17: 2009 | T17: 2010 | U17: 2011 | V17: 2012 | W17: 2013 | X17: 2014 | Y17: 2015 | Z17: 2016 | AA17: 2017 | AB17: 2018 | AC17: 2019 | AD17: 2020 | AE17: 2021 | AF17: 2022
B18: Landbrug | C18: =Mtot!AB2/Y!AB2 | D18: =Mtot!AC2/Y!AC2 | E18: =Mtot!AD2/Y!AD2 | F18: =Mtot!AE2/Y!AE2 | G18: =Mtot!AF2/Y!AF2 | H18: =Mtot!AG2/Y!AG2 | I18: =Mtot!AH2/Y!AH2 | J18: =Mtot!AI2/Y!AI2 | ... AF18: =Mtot!BE2/Y!BE2
B19: Slagterier | C19: =Mtot!AB3/Y!AB3 | D19: =Mtot!AC3/Y!AC3 | E19: =Mtot!AD3/Y!AD3 | F19: =Mtot!AE3/Y!AE3 | G19: =Mtot!AF3/Y!AF3 | H19: =Mtot!AG3/Y!AG3 | I19: =Mtot!AH3/Y!AH3 | J19: =Mtot!AI3/Y!AI3 | ... AF19: =Mtot!BE3/Y!BE3
B20: Mejerier | C20: =Mtot!AB4/Y!AB4 | D20: =Mtot!AC4/Y!AC4 | E20: =Mtot!AD4/Y!AD4 | F20: =Mtot!AE4/Y!AE4 | G20: =Mtot!AF4/Y!AF4 | H20: =Mtot!AG4/Y!AG4 | I20: =Mtot!AH4/Y!AH4 | J20: =Mtot!AI4/Y!AI4 | ... AF20: =Mtot!BE4/Y!BE4
B21: Anden fødevareindustri | C21: =Mtot!AB5/Y!AB5 | D21: =Mtot!AC5/Y!AC5 | E21: =Mtot!AD5/Y!AD5 | F21: =Mtot!AE5/Y!AE5 | G21: =Mtot!AF5/Y!AF5 | H21: =Mtot!AG5/Y!AG5 | I21: =Mtot!AH5/Y!AH5 | J21: =Mtot!AI5/Y!AI5 | ... AF21: =Mtot!BE5/Y!BE5
B22: Resten af økonomien | C22: =Mtot!AB6/Y!AB6 | D22: =Mtot!AC6/Y!AC6 | E22: =Mtot!AD6/Y!AD6 | F22: =Mtot!AE6/Y!AE6 | G22: =Mtot!AF6/Y!AF6 | H22: =Mtot!AG6/Y!AG6 | I22: =Mtot!AH6/Y!AH6 | J22: =Mtot!AI6/Y!AI6 | ... AF22: =Mtot!BE6/Y!BE6
B24: Kapital pr arbejdstime (K/L) | C24: 1993 | D24: 1994 | E24: 1995 | F24: 1996 | G24: 1997 | H24: 1998 | I24: 1999 | J24: 2000 | K24: 2001 | L24: 2002 | M24: 2003 | N24: 2004 | O24: 2005 | P24: 2006 | Q24: 2007 | R24: 2008 | S24: 2009 | T24: 2010 | U24: 2011 | V24: 2012 | W24: 2013 | X24: 2014 | Y24: 2015 | Z24: 2016 | AA24: 2017 | AB24: 2018 | AC24: 2019 | AD24: 2020 | AE24: 2021 | AF24: 2022
B25: Landbrug | C25: =K!AC2/L!AC2 | D25: =K!AD2/L!AD2 | E25: =K!AE2/L!AE2 | F25: =K!AF2/L!AF2 | G25: =K!AG2/L!AG2 | H25: =K!AH2/L!AH2 | I25: =K!AI2/L!AI2 | J25: =K!AJ2/L!AJ2 | ... AF25: =K!BF2/L!BF2
B26: Slagterier | C26: =K!AC3/L!AC3 | D26: =K!AD3/L!AD3 | E26: =K!AE3/L!AE3 | F26: =K!AF3/L!AF3 | G26: =K!AG3/L!AG3 | H26: =K!AH3/L!AH3 | I26: =K!AI3/L!AI3 | J26: =K!AJ3/L!AJ3 | ... AF26: =K!BF3/L!BF3
B27: Mejerier | C27: =K!AC4/L!AC4 | D27: =K!AD4/L!AD4 | E27: =K!AE4/L!AE4 | F27: =K!AF4/L!AF4 | G27: =K!AG4/L!AG4 | H27: =K!AH4/L!AH4 | I27: =K!AI4/L!AI4 | J27: =K!AJ4/L!AJ4 | ... AF27: =K!BF4/L!BF4
B28: Anden fødevareindustri | C28: =K!AC5/L!AC5 | D28: =K!AD5/L!AD5 | E28: =K!AE5/L!AE5 | F28: =K!AF5/L!AF5 | G28: =K!AG5/L!AG5 | H28: =K!AH5/L!AH5 | I28: =K!AI5/L!AI5 | J28: =K!AJ5/L!AJ5 | ... AF28: =K!BF5/L!BF5
B29: Resten af økonomien | C29: =K!AC6/L!AC6 | D29: =K!AD6/L!AD6 | E29: =K!AE6/L!AE6 | F29: =K!AF6/L!AF6 | G29: =K!AG6/L!AG6 | H29: =K!AH6/L!AH6 | I29: =K!AI6/L!AI6 | J29: =K!AJ6/L!AJ6 | ... AF29: =K!BF6/L!BF6
B31: Produktionsværdi (mio.kr.) | C31: 1993 | D31: 1994 | E31: 1995 | F31: 1996 | G31: 1997 | H31: 1998 | I31: 1999 | J31: 2000 | K31: 2001 | L31: 2002 | M31: 2003 | N31: 2004 | O31: 2005 | P31: 2006 | Q31: 2007 | R31: 2008 | S31: 2009 | T31: 2010 | U31: 2011 | V31: 2012 | W31: 2013 | X31: 2014 | Y31: 2015 | Z31: 2016 | AA31: 2017 | AB31: 2018 | AC31: 2019 | AD31: 2020 | AE31: 2021 | AF31: 2022
B32: Landbrug | C32: =Y!AB2*P!AB2 | D32: =Y!AC2*P!AC2 | E32: =Y!AD2*P!AD2 | F32: =Y!AE2*P!AE2 | G32: =Y!AF2*P!AF2 | H32: =Y!AG2*P!AG2 | I32: =Y!AH2*P!AH2 | J32: =Y!AI2*P!AI2 | ... AF32: =Y!BE2*P!BE2
B33: Slagterier | C33: =Y!AB3*P!AB3 | D33: =Y!AC3*P!AC3 | E33: =Y!AD3*P!AD3 | F33: =Y!AE3*P!AE3 | G33: =Y!AF3*P!AF3 | H33: =Y!AG3*P!AG3 | I33: =Y!AH3*P!AH3 | J33: =Y!AI3*P!AI3 | ... AF33: =Y!BE3*P!BE3
B34: Mejerier | C34: =Y!AB4*P!AB4 | D34: =Y!AC4*P!AC4 | E34: =Y!AD4*P!AD4 | F34: =Y!AE4*P!AE4 | G34: =Y!AF4*P!AF4 | H34: =Y!AG4*P!AG4 | I34: =Y!AH4*P!AH4 | J34: =Y!AI4*P!AI4 | ... AF34: =Y!BE4*P!BE4
B35: Anden fødevareindustri | C35: =Y!AB5*P!AB5 | D35: =Y!AC5*P!AC5 | E35: =Y!AD5*P!AD5 | F35: =Y!AE5*P!AE5 | G35: =Y!AF5*P!AF5 | H35: =Y!AG5*P!AG5 | I35: =Y!AH5*P!AH5 | J35: =Y!AI5*P!AI5 | ... AF35: =Y!BE5*P!BE5
B36: Resten af økonomien | C36: =Y!AB6*P!AB6 | D36: =Y!AC6*P!AC6 | E36: =Y!AD6*P!AD6 | F36: =Y!AE6*P!AE6 | G36: =Y!AF6*P!AF6 | H36: =Y!AG6*P!AG6 | I36: =Y!AH6*P!AH6 | J36: =Y!AI6*P!AI6 | ... AF36: =Y!BE6*P!BE6
B38: Alt Kapital-output-ratio (K/Y) | C38: 1993 | D38: 1994 | E38: 1995 | F38: 1996 | G38: 1997 | H38: 1998 | I38: 1999 | J38: 2000 | K38: 2001 | L38: 2002 | M38: 2003 | N38: 2004 | O38: 2005 | P38: 2006 | Q38: 2007 | R38: 2008 | S38: 2009 | T38: 2010 | U38: 2011 | V38: 2012 | W38: 2013 | X38: 2014 | Y38: 2015 | Z38: 2016 | AA38: 2017 | AB38: 2018 | AC38: 2019 | AD38: 2020 | AE38: 2021 | AF38: 2022
B39: Landbrug | C39: =K_BVT!AC2/Y!AB2 | D39: =K_BVT!AD2/Y!AC2 | E39: =K_BVT!AE2/Y!AD2 | F39: =K_BVT!AF2/Y!AE2 | G39: =K_BVT!AG2/Y!AF2 | H39: =K_BVT!AH2/Y!AG2 | I39: =K_BVT!AI2/Y!AH2 | J39: =K_BVT!AJ2/Y!AI2 | ... AF39: =K_BVT!BF2/Y!BE2
B40: Ny Slagterier | C40: =K_BVT!AC3/Y!AB3 | D40: =K_BVT!AD3/Y!AC3 | E40: =K_BVT!AE3/Y!AD3 | F40: =K_BVT!AF3/Y!AE3 | G40: =K_BVT!AG3/Y!AF3 | H40: =K_BVT!AH3/Y!AG3 | I40: =K_BVT!AI3/Y!AH3 | J40: =K_BVT!AJ3/Y!AI3 | ... AF40: =K_BVT!BF3/Y!BE3
B41: Ny Mejerier | C41: =K_BVT!AC4/Y!AB4 | D41: =K_BVT!AD4/Y!AC4 | E41: =K_BVT!AE4/Y!AD4 | F41: =K_BVT!AF4/Y!AE4 | G41: =K_BVT!AG4/Y!AF4 | H41: =K_BVT!AH4/Y!AG4 | I41: =K_BVT!AI4/Y!AH4 | J41: =K_BVT!AJ4/Y!AI4 | ... AF41: =K_BVT!BF4/Y!BE4
B42: Ny Anden fødevareindustri | C42: =K_BVT!AC5/Y!AB5 | D42: =K_BVT!AD5/Y!AC5 | E42: =K_BVT!AE5/Y!AD5 | F42: =K_BVT!AF5/Y!AE5 | G42: =K_BVT!AG5/Y!AF5 | H42: =K_BVT!AH5/Y!AG5 | I42: =K_BVT!AI5/Y!AH5 | J42: =K_BVT!AJ5/Y!AI5 | ... AF42: =K_BVT!BF5/Y!BE5
B43: Resten af økonomien | C43: =K_BVT!AC6/Y!AB6 | D43: =K_BVT!AD6/Y!AC6 | E43: =K_BVT!AE6/Y!AD6 | F43: =K_BVT!AF6/Y!AE6 | G43: =K_BVT!AG6/Y!AF6 | H43: =K_BVT!AH6/Y!AG6 | I43: =K_BVT!AI6/Y!AH6 | J43: =K_BVT!AJ6/Y!AI6 | ... AF43: =K_BVT!BF6/Y!BE6
B45: Kapital-BVT-ratio | C45: 1993 | D45: 1994 | E45: 1995 | F45: 1996 | G45: 1997 | H45: 1998 | I45: 1999 | J45: 2000 | K45: 2001 | L45: 2002 | M45: 2003 | N45: 2004 | O45: 2005 | P45: 2006 | Q45: 2007 | R45: 2008 | S45: 2009 | T45: 2010 | U45: 2011 | V45: 2012 | W45: 2013 | X45: 2014 | Y45: 2015 | Z45: 2016 | AA45: 2017 | AB45: 2018 | AC45: 2019 | AD45: 2020 | AE45: 2021 | AF45: 2022
B46: Landbrug
B47: Ny Slagterier | C47: =K_BVT!AC3/BVT!AB3 | D47: =K_BVT!AD3/BVT!AC3 | E47: =K_BVT!AE3/BVT!AD3 | F47: =K_BVT!AF3/BVT!AE3 | G47: =K_BVT!AG3/BVT!AF3 | H47: =K_BVT!AH3/BVT!AG3 | I47: =K_BVT!AI3/BVT!AH3 | J47: =K_BVT!AJ3/BVT!AI3 | ... AF47: =K_BVT!BF3/BVT!BE3
...

Sheet Produktivitetsudvikling
A1: =theta_KL_L!A1 | B1: =theta_KL_L!AD1 | C1: =theta_KL_L!AE1 | D1: =theta_KL_L!AF1 | E1: =theta_KL_L!AG1 | F1: =theta_KL_L!AH1 | G1: =theta_KL_L!AI1 | H1: =theta_KL_L!AJ1 | I1: =theta_KL_L!AK1 | ... AD1: =theta_KL_L!BF1
A2: =theta_KL_L!A2 | B2: =theta_KL_L!AD2 | C2: =theta_KL_L!AE2 | D2: =theta_KL_L!AF2 | E2: =theta_KL_L!AG2 | F2: =theta_KL_L!AH2 | G2: =theta_KL_L!AI2 | H2: =theta_KL_L!AJ2 | I2: =theta_KL_L!AK2 | ... AD2: =theta_KL_L!BF2
A3: =theta_KL_L!A3 | B3: =theta_KL_L!AD3 | C3: =theta_KL_L!AE3 | D3: =theta_KL_L!AF3 | E3: =theta_KL_L!AG3 | F3: =theta_KL_L!AH3 | G3: =theta_KL_L!AI3 | H3: =theta_KL_L!AJ3 | I3: =theta_KL_L!AK3 | ... AD3: =theta_KL_L!BF3
A4: =theta_KL_L!A4 | B4: =theta_KL_L!AD4 | C4: =theta_KL_L!AE4 | D4: =theta_KL_L!AF4 | E4: =theta_KL_L!AG4 | F4: =theta_KL_L!AH4 | G4: =theta_KL_L!AI4 | H4: =theta_KL_L!AJ4 | I4: =theta_KL_L!AK4 | ... AD4: =theta_KL_L!BF4
A5: =theta_KL_L!A5 | B5: =theta_KL_L!AD5 | C5: =theta_KL_L!AE5 | D5: =theta_KL_L!AF5 | E5: =theta_KL_L!AG5 | F5: =theta_KL_L!AH5 | G5: =theta_KL_L!AI5 | H5: =theta_KL_L!AJ5 | I5: =theta_KL_L!AK5 | ... AD5: =theta_KL_L!BF5
A6: =theta_KL_L!A6 | B6: =theta_KL_L!AD6 | C6: =theta_KL_L!AE6 | D6: =theta_KL_L!AF6 | E6: =theta_KL_L!AG6 | F6: =theta_KL_L!AH6 | G6: =theta_KL_L!AI6 | H6: =theta_KL_L!AJ6 | I6: =theta_KL_L!AK6 | ... AD6: =theta_KL_L!BF6
A8: Indeks 1994=1 | B8: 1994 | C8: 1995 | D8: 1996 | E8: 1997 | F8: 1998 | G8: 1999 | H8: 2000 | I8: 2001 | J8: 2002 | K8: 2003 | L8: 2004 | M8: 2005 | N8: 2006 | O8: 2007 | P8: 2008 | Q8: 2009 | R8: 2010 | S8: 2011 | T8: 2012 | U8: 2013 | V8: 2014 | W8: 2015 | X8: 2016 | Y8: 2017 | Z8: 2018 | AA8: 2019 | AB8: 2020 | AC8: 2021 | AD8: 2022
A9: Landbrug (010000) | B9: =B2/$B2 | C9: =C2/$B2 | D9: =D2/$B2 | E9: =E2/$B2 | F9: =F2/$B2 | G9: =G2/$B2 | H9: =H2/$B2 | I9: =I2/$B2 | ... AD9: =AD2/$B2 | AF9: =(AC9/B9)^(1/28)-1
A10: Slagterier (100010) | B10: =B3/$B3 | C10: =C3/$B3 | D10: =D3/$B3 | E10: =E3/$B3 | F10: =F3/$B3 | G10: =G3/$B3 | H10: =H3/$B3 | I10: =I3/$B3 | ... AD10: =AD3/$B3 | AF10: =(AC10/B10)^(1/28)-1
A11: Mejerier (100030) | B11: =B4/$B4 | C11: =C4/$B4 | D11: =D4/$B4 | E11: =E4/$B4 | F11: =F4/$B4 | G11: =G4/$B4 | H11: =H4/$B4 | I11: =I4/$B4 | ... AD11: =AD4/$B4 | AF11: =(AC11/B11)^(1/28)-1
A12: Anden fødevareindustri (100040x100050) | B12: =B5/$B5 | C12: =C5/$B5 | D12: =D5/$B5 | E12: =E5/$B5 | F12: =F5/$B5 | G12: =G5/$B5 | H12: =H5/$B5 | I12: =I5/$B5 | ... AD12: =AD5/$B5 | AF12: =(AC12/B12)^(1/28)-1
A13: REST | B13: =B6/$B6 | C13: =C6/$B6 | D13: =D6/$B6 | E13: =E6/$B6 | F13: =F6/$B6 | G13: =G6/$B6 | H13: =H6/$B6 | I13: =I6/$B6 | ... AD13: =AD6/$B6 | AF13: =(AC13/B13)^(1/28)-1
A15: =theta_KL_K!A1 | B15: =theta_KL_K!AD1 | C15: =theta_KL_K!AE1 | D15: =theta_KL_K!AF1 | E15: =theta_KL_K!AG1 | F15: =theta_KL_K!AH1 | G15: =theta_KL_K!AI1 | H15: =theta_KL_K!AJ1 | I15: =theta_KL_K!AK1 | ... AD15: =theta_KL_K!BF1
A16: =theta_KL_K!A2 | B16: =theta_KL_K!AD2 | C16: =theta_KL_K!AE2 | D16: =theta_KL_K!AF2 | E16: =theta_KL_K!AG2 | F16: =theta_KL_K!AH2 | G16: =theta_KL_K!AI2 | H16: =theta_KL_K!AJ2 | I16: =theta_KL_K!AK2 | ... AD16: =theta_KL_K!BF2
A17: =theta_KL_K!A3 | B17: =theta_KL_K!AD3 | C17: =theta_KL_K!AE3 | D17: =theta_KL_K!AF3 | E17: =theta_KL_K!AG3 | F17: =theta_KL_K!AH3 | G17: =theta_KL_K!AI3 | H17: =theta_KL_K!AJ3 | I17: =theta_KL_K!AK3 | ... AD17: =theta_KL_K!BF3
A18: =theta_KL_K!A4 | B18: =theta_KL_K!AD4 | C18: =theta_KL_K!AE4 | D18: =theta_KL_K!AF4 | E18: =theta_KL_K!AG4 | F18: =theta_KL_K!AH4 | G18: =theta_KL_K!AI4 | H18: =theta_KL_K!AJ4 | I18: =theta_KL_K!AK4 | ... AD18: =theta_KL_K!BF4
A19: =theta_KL_K!A5 | B19: =theta_KL_K!AD5 | C19: =theta_KL_K!AE5 | D19: =theta_KL_K!AF5 | E19: =theta_KL_K!AG5 | F19: =theta_KL_K!AH5 | G19: =theta_KL_K!AI5 | H19: =theta_KL_K!AJ5 | I19: =theta_KL_K!AK5 | ... AD19: =theta_KL_K!BF5
A20: =theta_KL_K!A6 | B20: =theta_KL_K!AD6 | C20: =theta_KL_K!AE6 | D20: =theta_KL_K!AF6 | E20: =theta_KL_K!AG6 | F20: =theta_KL_K!AH6 | G20: =theta_KL_K!AI6 | H20: =theta_KL_K!AJ6 | I20: =theta_KL_K!AK6 | ... AD20: =theta_KL_K!BF6
A22: Indeks 1994=1 | B22: 1994 | C22: 1995 | D22: 1996 | E22: 1997 | F22: 1998 | G22: 1999 | H22: 2000 | I22: 2001 | J22: 2002 | K22: 2003 | L22: 2004 | M22: 2005 | N22: 2006 | O22: 2007 | P22: 2008 | Q22: 2009 | R22: 2010 | S22: 2011 | T22: 2012 | U22: 2013 | V22: 2014 | W22: 2015 | X22: 2016 | Y22: 2017 | Z22: 2018 | AA22: 2019 | AB22: 2020 | AC22: 2021 | AD22: 2022
A23: Landbrug (010000) | B23: =B16/$B16 | C23: =C16/$B16 | D23: =D16/$B16 | E23: =E16/$B16 | F23: =F16/$B16 | G23: =G16/$B16 | H23: =H16/$B16 | I23: =I16/$B16 | ... AD23: =AD16/$B16
A24: Slagterier (100010) | B24: =B17/$B17 | C24: =C17/$B17 | D24: =D17/$B17 | E24: =E17/$B17 | F24: =F17/$B17 | G24: =G17/$B17 | H24: =H17/$B17 | I24: =I17/$B17 | ... AD24: =AD17/$B17
A25: Mejerier (100030) | B25: =B18/$B18 | C25: =C18/$B18 | D25: =D18/$B18 | E25: =E18/$B18 | F25: =F18/$B18 | G25: =G18/$B18 | H25: =H18/$B18 | I25: =I18/$B18 | ... AD25: =AD18/$B18
A26: Anden fødevareindustri (100040x100050) | B26: =B19/$B19 | C26: =C19/$B19 | D26: =D19/$B19 | E26: =E19/$B19 | F26: =F19/$B19 | G26: =G19/$B19 | H26: =H19/$B19 | I26: =I19/$B19 | ... AD26: =AD19/$B19
A27: REST | B27: =B20/$B20 | C27: =C20/$B20 | D27: =D20/$B20 | E27: =E20/$B20 | F27: =F20/$B20 | G27: =G20/$B20 | H27: =H20/$B20 | I27: =I20/$B20 | ... AD27: =AD20/$B20
A47: =mu_KL_L!A1 | B47: =mu_KL_L!AD1 | C47: =mu_KL_L!AE1 | D47: =mu_KL_L!AF1 | E47: =mu_KL_L!AG1 | F47: =mu_KL_L!AH1 | G47: =mu_KL_L!AI1 | H47: =mu_KL_L!AJ1 | I47: =mu_KL_L!AK1 | ... AD47: =mu_KL_L!BF1
A48: =mu_KL_L!A2 | B48: =mu_KL_L!AD2 | C48: =mu_KL_L!AE2 | D48: =mu_KL_L!AF2 | E48: =mu_KL_L!AG2 | F48: =mu_KL_L!AH2 | G48: =mu_KL_L!AI2 | H48: =mu_KL_L!AJ2 | I48: =mu_KL_L!AK2 | ... AD48: =mu_KL_L!BF2
A49: =mu_KL_L!A3 | B49: =mu_KL_L!AD3 | C49: =mu_KL_L!AE3 | D49: =mu_KL_L!AF3 | E49: =mu_KL_L!AG3 | F49: =mu_KL_L!AH3 | G49: =mu_KL_L!AI3 | H49: =mu_KL_L!AJ3 | I49: =mu_KL_L!AK3 | ... AD49: =mu_KL_L!BF3
A50: =mu_KL_L!A4 | B50: =mu_KL_L!AD4 | C50: =mu_KL_L!AE4 | D50: =mu_KL_L!AF4 | E50: =mu_KL_L!AG4 | F50: =mu_KL_L!AH4 | G50: =mu_KL_L!AI4 | H50: =mu_KL_L!AJ4 | I50: =mu_KL_L!AK4 | ... AD50: =mu_KL_L!BF4
A51: =mu_KL_L!A5 | B51: =mu_KL_L!AD5 | C51: =mu_KL_L!AE5 | D51: =mu_KL_L!AF5 | E51: =mu_KL_L!AG5 | F51: =mu_KL_L!AH5 | G51: =mu_KL_L!AI5 | H51: =mu_KL_L!AJ5 | I51: =mu_KL_L!AK5 | ... AD51: =mu_KL_L!BF5
A52: =mu_KL_L!A6 | B52: =mu_KL_L!AD6 | C52: =mu_KL_L!AE6 | D52: =mu_KL_L!AF6 | E52: =mu_KL_L!AG6 | F52: =mu_KL_L!AH6 | G52: =mu_KL_L!AI6 | H52: =mu_KL_L!AJ6 | I52: =mu_KL_L!AK6 | ... AD52: =mu_KL_L!BF6
A54: Indeks 1994=1 | B54: 1994 | C54: 1995 | D54: 1996 | E54: 1997 | F54: 1998 | G54: 1999 | H54: 2000 | I54: 2001 | J54: 2002 | K54: 2003 | L54: 2004 | M54: 2005 | N54: 2006 | O54: 2007 | P54: 2008 | Q54: 2009 | R54: 2010 | S54: 2011 | T54: 2012 | U54: 2013 | V54: 2014 | W54: 2015 | X54: 2016 | Y54: 2017 | Z54: 2018 | AA54: 2019 | AB54: 2020 | AC54: 2021 | AD54: 2022
A55: Landbrug (010000) | B55: =B48/$B48 | C55: =C48/$B48 | D55: =D48/$B48 | E55: =E48/$B48 | F55: =F48/$B48 | G55: =G48/$B48 | H55: =H48/$B48 | I55: =I48/$B48 | ... AD55: =AD48/$B48
A56: Slagterier (100010) | B56: =B49/$B49 | C56: =C49/$B49 | D56: =D49/$B49 | E56: =E49/$B49 | F56: =F49/$B49 | G56: =G49/$B49 | H56: =H49/$B49 | I56: =I49/$B49 | ... AD56: =AD49/$B49
A57: Mejerier (100030) | B57: =B50/$B50 | C57: =C50/$B50 | D57: =D50/$B50 | E57: =E50/$B50 | F57: =F50/$B50 | G57: =G50/$B50 | H57: =H50/$B50 | I57: =I50/$B50 | ... AD57: =AD50/$B50
A58: Anden fødevareindustri (100040x100050) | B58: =B51/$B51 | C58: =C51/$B51 | D58: =D51/$B51 | E58: =E51/$B51 | F58: =F51/$B51 | G58: =G51/$B51 | H58: =H51/$B51 | I58: =I51/$B51 | ... AD58: =AD51/$B51
A59: REST | B59: =B52/$B52 | C59: =C52/$B52 | D59: =D52/$B52 | E59: =E52/$B52 | F59: =F52/$B52 | G59: =G52/$B52 | H59: =H52/$B52 | I59: =I52/$B52 | ... AD59: =AD52/$B52
A61: =mu_KL_K!A1 | B61: =mu_KL_K!AD1 | C61: =mu_KL_K!AE1 | D61: =mu_KL_K!AF1 | E61: =mu_KL_K!AG1 | F61: =mu_KL_K!AH1 | G61: =mu_KL_K!AI1 | H61: =mu_KL_K!AJ1 | I61: =mu_KL_K!AK1 | ... AD61: =mu_KL_K!BF1
A62: =mu_KL_K!A2 | B62: =mu_KL_K!AD2 | C62: =mu_KL_K!AE2 | D62: =mu_KL_K!AF2 | E62: =mu_KL_K!AG2 | F62: =mu_KL_K!AH2 | G62: =mu_KL_K!AI2 | H62: =mu_KL_K!AJ2 | I62: =mu_KL_K!AK2 | ... AD62: =mu_KL_K!BF2
A63: =mu_KL_K!A3 | B63: =mu_KL_K!AD3 | C63: =mu_KL_K!AE3 | D63: =mu_KL_K!AF3 | E63: =mu_KL_K!AG3 | F63: =mu_KL_K!AH3 | G63: =mu_KL_K!AI3 | H63: =mu_KL_K!AJ3 | I63: =mu_KL_K!AK3 | ... AD63: =mu_KL_K!BF3
A64: =mu_KL_K!A4 | B64: =mu_KL_K!AD4 | C64: =mu_KL_K!AE4 | D64: =mu_KL_K!AF4 | E64: =mu_KL_K!AG4 | F64: =mu_KL_K!AH4 | G64: =mu_KL_K!AI4 | H64: =mu_KL_K!AJ4 | I64: =mu_KL_K!AK4 | ... AD64: =mu_KL_K!BF4
...

Sheet Produktivitetsudvikling (2)
A1: =theta_KL_L!A1 | B1: =theta_KL_L!AD1 | C1: =theta_KL_L!AE1 | D1: =theta_KL_L!AF1 | E1: =theta_KL_L!AG1 | F1: =theta_KL_L!AH1 | G1: =theta_KL_L!AI1 | H1: =theta_KL_L!AJ1 | I1: =theta_KL_L!AK1 | ... AD1: =theta_KL_L!BF1
A2: =theta_KL_L!A2 | B2: =theta_Y_JKL!AC2 | C2: =theta_Y_JKL!AD2 | D2: =theta_Y_JKL!AE2 | E2: =theta_Y_JKL!AF2 | F2: =theta_Y_JKL!AG2 | G2: =theta_Y_JKL!AH2 | H2: =theta_Y_JKL!AI2 | I2: =theta_Y_JKL!AJ2 | ... AD2: =theta_Y_JKL!BE2
A3: =theta_KL_L!A3 | B3: =theta_Y_KL!AC3 | C3: =theta_Y_KL!AD3 | D3: =theta_Y_KL!AE3 | E3: =theta_Y_KL!AF3 | F3: =theta_Y_KL!AG3 | G3: =theta_Y_KL!AH3 | H3: =theta_Y_KL!AI3 | I3: =theta_Y_KL!AJ3 | ... AD3: =theta_Y_KL!BE3
A4: =theta_KL_L!A4 | B4: =theta_Y_KL!AC4 | C4: =theta_Y_KL!AD4 | D4: =theta_Y_KL!AE4 | E4: =theta_Y_KL!AF4 | F4: =theta_Y_KL!AG4 | G4: =theta_Y_KL!AH4 | H4: =theta_Y_KL!AI4 | I4: =theta_Y_KL!AJ4 | ... AD4: =theta_Y_KL!BE4
A5: =theta_KL_L!A5 | B5: =theta_Y_KL!AC5 | C5: =theta_Y_KL!AD5 | D5: =theta_Y_KL!AE5 | E5: =theta_Y_KL!AF5 | F5: =theta_Y_KL!AG5 | G5: =theta_Y_KL!AH5 | H5: =theta_Y_KL!AI5 | I5: =theta_Y_KL!AJ5 | ... AD5: =theta_Y_KL!BE5
A6: =theta_KL_L!A6 | B6: =theta_Y_KL!AC6 | C6: =theta_Y_KL!AD6 | D6: =theta_Y_KL!AE6 | E6: =theta_Y_KL!AF6 | F6: =theta_Y_KL!AG6 | G6: =theta_Y_KL!AH6 | H6: =theta_Y_KL!AI6 | I6: =theta_Y_KL!AJ6 | ... AD6: =theta_Y_KL!BE6
A8: Indeks 1994=1 | B8: 1994 | C8: 1995 | D8: 1996 | E8: 1997 | F8: 1998 | G8: 1999 | H8: 2000 | I8: 2001 | J8: 2002 | K8: 2003 | L8: 2004 | M8: 2005 | N8: 2006 | O8: 2007 | P8: 2008 | Q8: 2009 | R8: 2010 | S8: 2011 | T8: 2012 | U8: 2013 | V8: 2014 | W8: 2015 | X8: 2016 | Y8: 2017 | Z8: 2018 | AA8: 2019 | AB8: 2020 | AC8: 2021 | AD8: 2022
A9: Landbrug (010000) (JKL) | B9: =B2/$B2 | C9: =C2/$B2 | D9: =D2/$B2 | E9: =E2/$B2 | F9: =F2/$B2 | G9: =G2/$B2 | H9: =H2/$B2 | I9: =I2/$B2 | ... AD9: =AD2/$B2 | AF9: =(AC9/B9)^(1/28)-1
A10: Slagterier (100010) | B10: =B3/$B3 | C10: =C3/$B3 | D10: =D3/$B3 | E10: =E3/$B3 | F10: =F3/$B3 | G10: =G3/$B3 | H10: =H3/$B3 | I10: =I3/$B3 | ... AD10: =AD3/$B3 | AF10: =(AC10/B10)^(1/28)-1
A11: Mejerier (100030) | B11: =B4/$B4 | C11: =C4/$B4 | D11: =D4/$B4 | E11: =E4/$B4 | F11: =F4/$B4 | G11: =G4/$B4 | H11: =H4/$B4 | I11: =I4/$B4 | ... AD11: =AD4/$B4 | AF11: =(AC11/B11)^(1/28)-1
A12: Anden fødevareindustri (100040x100050) | B12: =B5/$B5 | C12: =C5/$B5 | D12: =D5/$B5 | E12: =E5/$B5 | F12: =F5/$B5 | G12: =G5/$B5 | H12: =H5/$B5 | I12: =I5/$B5 | ... AD12: =AD5/$B5 | AF12: =(AC12/B12)^(1/28)-1
A13: REST | B13: =B6/$B6 | C13: =C6/$B6 | D13: =D6/$B6 | E13: =E6/$B6 | F13: =F6/$B6 | G13: =G6/$B6 | H13: =H6/$B6 | I13: =I6/$B6 | ... AD13: =AD6/$B6 | AF13: =(AC13/B13)^(1/28)-1
A15: =theta_KL_K!A1 | B15: =theta_KL_K!AD1 | C15: =theta_KL_K!AE1 | D15: =theta_KL_K!AF1 | E15: =theta_KL_K!AG1 | F15: =theta_KL_K!AH1 | G15: =theta_KL_K!AI1 | H15: =theta_KL_K!AJ1 | I15: =theta_KL_K!AK1 | ... AD15: =theta_KL_K!BF1
A16: =theta_KL_K!A2 | B16: =theta_Y_Mtot!AC2 | C16: =theta_Y_Mtot!AD2 | D16: =theta_Y_Mtot!AE2 | E16: =theta_Y_Mtot!AF2 | F16: =theta_Y_Mtot!AG2 | G16: =theta_Y_Mtot!AH2 | H16: =theta_Y_Mtot!AI2 | I16: =theta_Y_Mtot!AJ2 | ... AD16: =theta_Y_Mtot!BE2
A17: =theta_KL_K!A3 | B17: =theta_Y_Mtot!AC3 | C17: =theta_Y_Mtot!AD3 | D17: =theta_Y_Mtot!AE3 | E17: =theta_Y_Mtot!AF3 | F17: =theta_Y_Mtot!AG3 | G17: =theta_Y_Mtot!AH3 | H17: =theta_Y_Mtot!AI3 | I17: =theta_Y_Mtot!AJ3 | ... AD17: =theta_Y_Mtot!BE3
A18: =theta_KL_K!A4 | B18: =theta_Y_Mtot!AC4 | C18: =theta_Y_Mtot!AD4 | D18: =theta_Y_Mtot!AE4 | E18: =theta_Y_Mtot!AF4 | F18: =theta_Y_Mtot!AG4 | G18: =theta_Y_Mtot!AH4 | H18: =theta_Y_Mtot!AI4 | I18: =theta_Y_Mtot!AJ4 | ... AD18: =theta_Y_Mtot!BE4
A19: =theta_KL_K!A5 | B19: =theta_Y_Mtot!AC5 | C19: =theta_Y_Mtot!AD5 | D19: =theta_Y_Mtot!AE5 | E19: =theta_Y_Mtot!AF5 | F19: =theta_Y_Mtot!AG5 | G19: =theta_Y_Mtot!AH5 | H19: =theta_Y_Mtot!AI5 | I19: =theta_Y_Mtot!AJ5 | ... AD19: =theta_Y_Mtot!BE5
A20: =theta_KL_K!A6 | B20: =theta_Y_Mtot!AC6 | C20: =theta_Y_Mtot!AD6 | D20: =theta_Y_Mtot!AE6 | E20: =theta_Y_Mtot!AF6 | F20: =theta_Y_Mtot!AG6 | G20: =theta_Y_Mtot!AH6 | H20: =theta_Y_Mtot!AI6 | I20: =theta_Y_Mtot!AJ6 | ... AD20: =theta_Y_Mtot!BE6
A22: Indeks 1994=1 | B22: 1994 | C22: 1995 | D22: 1996 | E22: 1997 | F22: 1998 | G22: 1999 | H22: 2000 | I22: 2001 | J22: 2002 | K22: 2003 | L22: 2004 | M22: 2005 | N22: 2006 | O22: 2007 | P22: 2008 | Q22: 2009 | R22: 2010 | S22: 2011 | T22: 2012 | U22: 2013 | V22: 2014 | W22: 2015 | X22: 2016 | Y22: 2017 | Z22: 2018 | AA22: 2019 | AB22: 2020 | AC22: 2021 | AD22: 2022
A23: Landbrug (010000) | B23: =B16/$B16 | C23: =C16/$B16 | D23: =D16/$B16 | E23: =E16/$B16 | F23: =F16/$B16 | G23: =G16/$B16 | H23: =H16/$B16 | I23: =I16/$B16 | ... AD23: =AD16/$B16
A24: Slagterier (100010) | B24: =B17/$B17 | C24: =C17/$B17 | D24: =D17/$B17 | E24: =E17/$B17 | F24: =F17/$B17 | G24: =G17/$B17 | H24: =H17/$B17 | I24: =I17/$B17 | ... AD24: =AD17/$B17
A25: Mejerier (100030) | B25: =B18/$B18 | C25: =C18/$B18 | D25: =D18/$B18 | E25: =E18/$B18 | F25: =F18/$B18 | G25: =G18/$B18 | H25: =H18/$B18 | I25: =I18/$B18 | ... AD25: =AD18/$B18
A26: Anden fødevareindustri (100040x100050) | B26: =B19/$B19 | C26: =C19/$B19 | D26: =D19/$B19 | E26: =E19/$B19 | F26: =F19/$B19 | G26: =G19/$B19 | H26: =H19/$B19 | I26: =I19/$B19 | ... AD26: =AD19/$B19
A27: REST | B27: =B20/$B20 | C27: =C20/$B20 | D27: =D20/$B20 | E27: =E20/$B20 | F27: =F20/$B20 | G27: =G20/$B20 | H27: =H20/$B20 | I27: =I20/$B20 | ... AD27: =AD20/$B20
A47: =mu_KL_L!A1 | B47: =mu_KL_L!AD1 | C47: =mu_KL_L!AE1 | D47: =mu_KL_L!AF1 | E47: =mu_KL_L!AG1 | F47: =mu_KL_L!AH1 | G47: =mu_KL_L!AI1 | H47: =mu_KL_L!AJ1 | I47: =mu_KL_L!AK1 | ... AD47: =mu_KL_L!BF1
A48: =mu_KL_L!A2 | B48: =mu_Y_JKL!AC2 | C48: =mu_Y_JKL!AD2 | D48: =mu_Y_JKL!AE2 | E48: =mu_Y_JKL!AF2 | F48: =mu_Y_JKL!AG2 | G48: =mu_Y_JKL!AH2 | H48: =mu_Y_JKL!AI2 | I48: =mu_Y_JKL!AJ2 | ... AD48: =mu_Y_JKL!BE2
A49: =mu_KL_L!A3 | B49: =mu_Y_KL!AC3 | C49: =mu_Y_KL!AD3 | D49: =mu_Y_KL!AE3 | E49: =mu_Y_KL!AF3 | F49: =mu_Y_KL!AG3 | G49: =mu_Y_KL!AH3 | H49: =mu_Y_KL!AI3 | I49: =mu_Y_KL!AJ3 | ... AD49: =mu_Y_KL!BE3
A50: =mu_KL_L!A4 | B50: =mu_Y_KL!AC4 | C50: =mu_Y_KL!AD4 | D50: =mu_Y_KL!AE4 | E50: =mu_Y_KL!AF4 | F50: =mu_Y_KL!AG4 | G50: =mu_Y_KL!AH4 | H50: =mu_Y_KL!AI4 | I50: =mu_Y_KL!AJ4 | ... AD50: =mu_Y_KL!BE4
A51: =mu_KL_L!A5 | B51: =mu_Y_KL!AC5 | C51: =mu_Y_KL!AD5 | D51: =mu_Y_KL!AE5 | E51: =mu_Y_KL!AF5 | F51: =mu_Y_KL!AG5 | G51: =mu_Y_KL!AH5 | H51: =mu_Y_KL!AI5 | I51: =mu_Y_KL!AJ5 | ... AD51: =mu_Y_KL!BE5
A52: =mu_KL_L!A6 | B52: =mu_Y_KL!AC6 | C52: =mu_Y_KL!AD6 | D52: =mu_Y_KL!AE6 | E52: =mu_Y_KL!AF6 | F52: =mu_Y_KL!AG6 | G52: =mu_Y_KL!AH6 | H52: =mu_Y_KL!AI6 | I52: =mu_Y_KL!AJ6 | ... AD52: =mu_Y_KL!BE6
A54: Indeks 1994=1 | B54: 1994 | C54: 1995 | D54: 1996 | E54: 1997 | F54: 1998 | G54: 1999 | H54: 2000 | I54: 2001 | J54: 2002 | K54: 2003 | L54: 2004 | M54: 2005 | N54: 2006 | O54: 2007 | P54: 2008 | Q54: 2009 | R54: 2010 | S54: 2011 | T54: 2012 | U54: 2013 | V54: 2014 | W54: 2015 | X54: 2016 | Y54: 2017 | Z54: 2018 | AA54: 2019 | AB54: 2020 | AC54: 2021 | AD54: 2022
A55: Landbrug (010000) | B55: =B48/$B48 | C55: =C48/$B48 | D55: =D48/$B48 | E55: =E48/$B48 | F55: =F48/$B48 | G55: =G48/$B48 | H55: =H48/$B48 | I55: =I48/$B48 | ... AD55: =AD48/$B48
A56: Slagterier (100010) | B56: =B49/$B49 | C56: =C49/$B49 | D56: =D49/$B49 | E56: =E49/$B49 | F56: =F49/$B49 | G56: =G49/$B49 | H56: =H49/$B49 | I56: =I49/$B49 | ... AD56: =AD49/$B49
A57: Mejerier (100030) | B57: =B50/$B50 | C57: =C50/$B50 | D57: =D50/$B50 | E57: =E50/$B50 | F57: =F50/$B50 | G57: =G50/$B50 | H57: =H50/$B50 | I57: =I50/$B50 | ... AD57: =AD50/$B50
A58: Anden fødevareindustri (100040x100050) | B58: =B51/$B51 | C58: =C51/$B51 | D58: =D51/$B51 | E58: =E51/$B51 | F58: =F51/$B51 | G58: =G51/$B51 | H58: =H51/$B51 | I58: =I51/$B51 | ... AD58: =AD51/$B51
A59: REST | B59: =B52/$B52 | C59: =C52/$B52 | D59: =D52/$B52 | E59: =E52/$B52 | F59: =F52/$B52 | G59: =G52/$B52 | H59: =H52/$B52 | I59: =I52/$B52 | ... AD59: =AD52/$B52
A61: =mu_KL_K!A1 | B61: =mu_KL_K!AD1 | C61: =mu_KL_K!AE1 | D61: =mu_KL_K!AF1 | E61: =mu_KL_K!AG1 | F61: =mu_KL_K!AH1 | G61: =mu_KL_K!AI1 | H61: =mu_KL_K!AJ1 | I61: =mu_KL_K!AK1 | ... AD61: =mu_KL_K!BF1
A62: =mu_KL_K!A2 | B62: =mu_Y_Mtot!AC2 | C62: =mu_Y_Mtot!AD2 | D62: =mu_Y_Mtot!AE2 | E62: =mu_Y_Mtot!AF2 | F62: =mu_Y_Mtot!AG2 | G62: =mu_Y_Mtot!AH2 | H62: =mu_Y_Mtot!AI2 | I62: =mu_Y_Mtot!AJ2 | ... AD62: =mu_Y_Mtot!BE2
A63: =mu_KL_K!A3 | B63: =mu_Y_Mtot!AC3 | C63: =mu_Y_Mtot!AD3 | D63: =mu_Y_Mtot!AE3 | E63: =mu_Y_Mtot!AF3 | F63: =mu_Y_Mtot!AG3 | G63: =mu_Y_Mtot!AH3 | H63: =mu_Y_Mtot!AI3 | I63: =mu_Y_Mtot!AJ3 | ... AD63: =mu_Y_Mtot!BE3
A64: =mu_KL_K!A4 | B64: =mu_Y_Mtot!AC4 | C64: =mu_Y_Mtot!AD4 | D64: =mu_Y_Mtot!AE4 | E64: =mu_Y_Mtot!AF4 | F64: =mu_Y_Mtot!AG4 | G64: =mu_Y_Mtot!AH4 | H64: =mu_Y_Mtot!AI4 | I64: =mu_Y_Mtot!AJ4 | ... AD64: =mu_Y_Mtot!BE4
...

Sheet 010000
A2: Mængder | B2: 1993 | C2: 1994 | D2: 1995 | E2: 1996 | F2: 1997 | G2: 1998 | H2: 1999 | I2: 2000 | J2: 2001 | K2: 2002 | L2: 2003 | M2: 2004 | N2: 2005 | O2: 2006 | P2: 2007 | Q2: 2008 | R2: 2009 | S2: 2010 | T2: 2011 | U2: 2012 | V2: 2013 | W2: 2014 | X2: 2015 | Y2: 2016 | Z2: 2017 | AA2: 2018 | AB2: 2019 | AC2: 2020 | AD2: 2021 | AE2: 2022 | AF2: 2023
A3: Y | B3: =Y!AB2 | C3: =Y!AC2 | D3: =Y!AD2 | E3: =Y!AE2 | F3: =Y!AF2 | G3: =Y!AG2 | H3: =Y!AH2 | I3: =Y!AI2 | ... AE3: =Y!BE2
A4: K | B4: =K!AC2 | C4: =K!AD2 | D4: =K!AE2 | E4: =K!AF2 | F4: =K!AG2 | G4: =K!AH2 | H4: =K!AI2 | I4: =K!AJ2 | ... AE4: =K!BF2
A5: L | B5: =L!AC2 | C5: =L!AD2 | D5: =L!AE2 | E5: =L!AF2 | F5: =L!AG2 | G5: =L!AH2 | H5: =L!AI2 | I5: =L!AJ2 | ... AE5: =L!BF2
A6: Mtot | B6: =Mtot!AB2 | C6: =Mtot!AC2 | D6: =Mtot!AD2 | E6: =Mtot!AE2 | F6: =Mtot!AF2 | G6: =Mtot!AG2 | H6: =Mtot!AH2 | I6: =Mtot!AI2 | ... AE6: =Mtot!BE2
A7: J | B7: =J!M2 | C7: =J!N2 | D7: =J!O2 | E7: =J!P2 | F7: =J!Q2 | G7: =J!R2 | H7: =J!S2 | I7: =J!T2 | ... AE7: =J!AP2
A8: I | B8: =I!AC2 | C8: =I!AD2 | D8: =I!AE2 | E8: =I!AF2 | F8: =I!AG2 | G8: =I!AH2 | H8: =I!AI2 | I8: =I!AJ2 | ... AE8: =I!BF2
A10: Priser
A11: p_Y | B11: =P!AB2 | C11: =P!AC2 | D11: =P!AD2 | E11: =P!AE2 | F11: =P!AF2 | G11: =P!AG2 | H11: =P!AH2 | I11: =P!AI2 | ... AE11: =P!BE2
A12: P_K | B12: =P_K!AC2 | C12: =P_K!AD2 | D12: =P_K!AE2 | E12: =P_K!AF2 | F12: =P_K!AG2 | G12: =P_K!AH2 | H12: =P_K!AI2 | I12: =P_K!AJ2 | ... AE12: =P_K!BF2
A13: w | B13: =w!AC2 | C13: =w!AD2 | D13: =w!AE2 | E13: =w!AF2 | F13: =w!AG2 | G13: =w!AH2 | H13: =w!AI2 | I13: =w!AJ2 | ... AE13: =w!BF2
A14: P_Mtot | B14: =P_Mtot!AB2 | C14: =P_Mtot!AC2 | D14: =P_Mtot!AD2 | E14: =P_Mtot!AE2 | F14: =P_Mtot!AF2 | G14: =P_Mtot!AG2 | H14: =P_Mtot!AH2 | I14: =P_Mtot!AI2 | ... AE14: =P_Mtot!BE2
A15: P_J | B15: =P_J!AC2 | C15: =P_J!AD2 | D15: =P_J!AE2 | E15: =P_J!AF2 | F15: =P_J!AG2 | G15: =P_J!AH2 | H15: =P_J!AI2 | I15: =P_J!AJ2 | ... AE15: =P_J!BF2
A16: P_I | B16: =P_I!C2 | C16: =P_I!D2 | D16: =P_I!E2 | E16: =P_I!F2 | F16: =P_I!G2 | G16: =P_I!H2 | H16: =P_I!I2 | I16: =P_I!J2 | ... AE16: =P_I!AF2
A17: P_Jord | B17: =P_Jord!M2 | C17: =P_Jord!N2 | D17: =P_Jord!O2 | E17: =P_Jord!P2 | F17: =P_Jord!Q2 | G17: =P_Jord!R2 | H17: =P_Jord!S2 | I17: =P_Jord!T2 | ... AE17: =P_Jord!AP2
A19: Andet
A20: Subsidiesats | B20: =tau_Y!AC2 | C20: =tau_Y!AD2 | D20: =tau_Y!AE2 | E20: =tau_Y!AF2 | F20: =tau_Y!AG2 | G20: =tau_Y!AH2 | H20: =tau_Y!AI2 | I20: =tau_Y!AJ2 | ... AE20: =tau_Y!BF2
A21: Afgift indenlandsk | B21: =tau_MD!AB2 | C21: =tau_MD!AC2 | D21: =tau_MD!AD2 | E21: =tau_MD!AE2 | F21: =tau_MD!AF2 | G21: =tau_MD!AG2 | H21: =tau_MD!AH2 | I21: =tau_MD!AI2 | ... AE21: =tau_MD!BE2
A22: Markup | B22: =markup!AC2 | C22: =markup!AD2 | D22: =markup!AE2 | E22: =markup!AF2 | F22: =markup!AG2 | G22: =markup!AH2 | H22: =markup!AI2 | I22: =markup!AJ2 | ... AE22: =markup!BF2

Sheet 100010
A2: Mængder | B2: 1993 | C2: 1994 | D2: 1995 | E2: 1996 | F2: 1997 | G2: 1998 | H2: 1999 | I2: 2000 | J2: 2001 | K2: 2002 | L2: 2003 | M2: 2004 | N2: 2005 | O2: 2006 | P2: 2007 | Q2: 2008 | R2: 2009 | S2: 2010 | T2: 2011 | U2: 2012 | V2: 2013 | W2: 2014 | X2: 2015 | Y2: 2016 | Z2: 2017 | AA2: 2018 | AB2: 2019 | AC2: 2020 | AD2: 2021 | AE2: 2022 | AF2: 2023
A3: Y | B3: =Y!AB3 | C3: =Y!AC3 | D3: =Y!AD3 | E3: =Y!AE3 | F3: =Y!AF3 | G3: =Y!AG3 | H3: =Y!AH3 | I3: =Y!AI3 | ... AE3: =Y!BE3
A4: K | B4: =K!AC3 | C4: =K!AD3 | D4: =K!AE3 | E4: =K!AF3 | F4: =K!AG3 | G4: =K!AH3 | H4: =K!AI3 | I4: =K!AJ3 | ... AE4: =K!BF3
A5: L | B5: =L!AC3 | C5: =L!AD3 | D5: =L!AE3 | E5: =L!AF3 | F5: =L!AG3 | G5: =L!AH3 | H5: =L!AI3 | I5: =L!AJ3 | ... AE5: =L!BF3
A6: Mtot | B6: =Mtot!AB3 | C6: =Mtot!AC3 | D6: =Mtot!AD3 | E6: =Mtot!AE3 | F6: =Mtot!AF3 | G6: =Mtot!AG3 | H6: =Mtot!AH3 | I6: =Mtot!AI3 | ... AE6: =Mtot!BE3
A7: J | B7: =J!M3 | C7: =J!N3 | D7: =J!O3 | E7: =J!P3 | F7: =J!Q3 | G7: =J!R3 | H7: =J!S3 | I7: =J!T3 | ... AE7: =J!AP3
A8: I | B8: =I!AC3 | C8: =I!AD3 | D8: =I!AE3 | E8: =I!AF3 | F8: =I!AG3 | G8: =I!AH3 | H8: =I!AI3 | I8: =I!AJ3 | ... AE8: =I!BF3
A10: Priser
A11: p_Y | B11: =P!AB3 | C11: =P!AC3 | D11: =P!AD3 | E11: =P!AE3 | F11: =P!AF3 | G11: =P!AG3 | H11: =P!AH3 | I11: =P!AI3 | ... AE11: =P!BE3
A12: P_K | B12: =P_K!AC3 | C12: =P_K!AD3 | D12: =P_K!AE3 | E12: =P_K!AF3 | F12: =P_K!AG3 | G12: =P_K!AH3 | H12: =P_K!AI3 | I12: =P_K!AJ3 | ... AE12: =P_K!BF3
A13: w | B13: =w!AC3 | C13: =w!AD3 | D13: =w!AE3 | E13: =w!AF3 | F13: =w!AG3 | G13: =w!AH3 | H13: =w!AI3 | I13: =w!AJ3 | ... AE13: =w!BF3
A14: P_Mtot | B14: =P_Mtot!AB3 | C14: =P_Mtot!AC3 | D14: =P_Mtot!AD3 | E14: =P_Mtot!AE3 | F14: =P_Mtot!AF3 | G14: =P_Mtot!AG3 | H14: =P_Mtot!AH3 | I14: =P_Mtot!AI3 | ... AE14: =P_Mtot!BE3
A15: P_J | B15: =P_J!AC3 | C15: =P_J!AD3 | D15: =P_J!AE3 | E15: =P_J!AF3 | F15: =P_J!AG3 | G15: =P_J!AH3 | H15: =P_J!AI3 | I15: =P_J!AJ3 | ... AE15: =P_J!BF3
A16: P_I | B16: =P_I!C3 | C16: =P_I!D3 | D16: =P_I!E3 | E16: =P_I!F3 | F16: =P_I!G3 | G16: =P_I!H3 | H16: =P_I!I3 | I16: =P_I!J3 | ... AE16: =P_I!AF3
A17: P_Jord | B17: =P_Jord!M3 | C17: =P_Jord!N3 | D17: =P_Jord!O3 | E17: =P_Jord!P3 | F17: =P_Jord!Q3 | G17: =P_Jord!R3 | H17: =P_Jord!S3 | I17: =P_Jord!T3 | ... AE17: =P_Jord!AP3
A19: Andet
A20: Subsidiesats | B20: =tau_Y!AC3 | C20: =tau_Y!AD3 | D20: =tau_Y!AE3 | E20: =tau_Y!AF3 | F20: =tau_Y!AG3 | G20: =tau_Y!AH3 | H20: =tau_Y!AI3 | I20: =tau_Y!AJ3 | ... AE20: =tau_Y!BF3
A21: Afgift indenlandsk | B21: =tau_MD!AB3 | C21: =tau_MD!AC3 | D21: =tau_MD!AD3 | E21: =tau_MD!AE3 | F21: =tau_MD!AF3 | G21: =tau_MD!AG3 | H21: =tau_MD!AH3 | I21: =tau_MD!AI3 | ... AE21: =tau_MD!BE3
A22: Markup | B22: =markup!AC3 | C22: =markup!AD3 | D22: =markup!AE3 | E22: =markup!AF3 | F22: =markup!AG3 | G22: =markup!AH3 | H22: =markup!AI3 | I22: =markup!AJ3 | ... AE22: =markup!BF3

Sheet 100030
A2: Mængder | B2: 1993 | C2: 1994 | D2: 1995 | E2: 1996 | F2: 1997 | G2: 1998 | H2: 1999 | I2: 2000 | J2: 2001 | K2: 2002 | L2: 2003 | M2: 2004 | N2: 2005 | O2: 2006 | P2: 2007 | Q2: 2008 | R2: 2009 | S2: 2010 | T2: 2011 | U2: 2012 | V2: 2013 | W2: 2014 | X2: 2015 | Y2: 2016 | Z2: 2017 | AA2: 2018 | AB2: 2019 | AC2: 2020 | AD2: 2021 | AE2: 2022 | AF2: 2023
A3: Y | B3: =Y!AB4 | C3: =Y!AC4 | D3: =Y!AD4 | E3: =Y!AE4 | F3: =Y!AF4 | G3: =Y!AG4 | H3: =Y!AH4 | I3: =Y!AI4 | ... AE3: =Y!BE4
A4: K | B4: =K!AC4 | C4: =K!AD4 | D4: =K!AE4 | E4: =K!AF4 | F4: =K!AG4 | G4: =K!AH4 | H4: =K!AI4 | I4: =K!AJ4 | ... AE4: =K!BF4
A5: L | B5: =L!AC4 | C5: =L!AD4 | D5: =L!AE4 | E5: =L!AF4 | F5: =L!AG4 | G5: =L!AH4 | H5: =L!AI4 | I5: =L!AJ4 | ... AE5: =L!BF4
A6: Mtot | B6: =Mtot!AB4 | C6: =Mtot!AC4 | D6: =Mtot!AD4 | E6: =Mtot!AE4 | F6: =Mtot!AF4 | G6: =Mtot!AG4 | H6: =Mtot!AH4 | I6: =Mtot!AI4 | ... AE6: =Mtot!BE4
A7: J | B7: =J!M4 | C7: =J!N4 | D7: =J!O4 | E7: =J!P4 | F7: =J!Q4 | G7: =J!R4 | H7: =J!S4 | I7: =J!T4 | ... AE7: =J!AP4
A8: I | B8: =I!AC4 | C8: =I!AD4 | D8: =I!AE4 | E8: =I!AF4 | F8: =I!AG4 | G8: =I!AH4 | H8: =I!AI4 | I8: =I!AJ4 | ... AE8: =I!BF4
A10: Priser
A11: p_Y | B11: =P!AB4 | C11: =P!AC4 | D11: =P!AD4 | E11: =P!AE4 | F11: =P!AF4 | G11: =P!AG4 | H11: =P!AH4 | I11: =P!AI4 | ... AE11: =P!BE4
A12: P_K | B12: =P_K!AC4 | C12: =P_K!AD4 | D12: =P_K!AE4 | E12: =P_K!AF4 | F12: =P_K!AG4 | G12: =P_K!AH4 | H12: =P_K!AI4 | I12: =P_K!AJ4 | ... AE12: =P_K!BF4
A13: w | B13: =w!AC4 | C13: =w!AD4 | D13: =w!AE4 | E13: =w!AF4 | F13: =w!AG4 | G13: =w!AH4 | H13: =w!AI4 | I13: =w!AJ4 | ... AE13: =w!BF4
A14: P_Mtot | B14: =P_Mtot!AB4 | C14: =P_Mtot!AC4 | D14: =P_Mtot!AD4 | E14: =P_Mtot!AE4 | F14: =P_Mtot!AF4 | G14: =P_Mtot!AG4 | H14: =P_Mtot!AH4 | I14: =P_Mtot!AI4 | ... AE14: =P_Mtot!BE4
A15: P_J | B15: =P_J!AC4 | C15: =P_J!AD4 | D15: =P_J!AE4 | E15: =P_J!AF4 | F15: =P_J!AG4 | G15: =P_J!AH4 | H15: =P_J!AI4 | I15: =P_J!AJ4 | ... AE15: =P_J!BF4
A16: P_I | B16: =P_I!C4 | C16: =P_I!D4 | D16: =P_I!E4 | E16: =P_I!F4 | F16: =P_I!G4 | G16: =P_I!H4 | H16: =P_I!I4 | I16: =P_I!J4 | ... AE16: =P_I!AF4
A17: P_Jord | B17: =P_Jord!M3 | C17: =P_Jord!N3 | D17: =P_Jord!O3 | E17: =P_Jord!P3 | F17: =P_Jord!Q3 | G17: =P_Jord!R3 | H17: =P_Jord!S3 | I17: =P_Jord!T3 | ... AE17: =P_Jord!AP3
A19: Andet
A20: Subsidiesats | B20: =tau_Y!AC4 | C20: =tau_Y!AD4 | D20: =tau_Y!AE4 | E20: =tau_Y!AF4 | F20: =tau_Y!AG4 | G20: =tau_Y!AH4 | H20: =tau_Y!AI4 | I20: =tau_Y!AJ4 | ... AE20: =tau_Y!BF4
A21: Afgift indenlandsk | B21: =tau_MD!AB4 | C21: =tau_MD!AC4 | D21: =tau_MD!AD4 | E21: =tau_MD!AE4 | F21: =tau_MD!AF4 | G21: =tau_MD!AG4 | H21: =tau_MD!AH4 | I21: =tau_MD!AI4 | ... AE21: =tau_MD!BE4
A22: Markup | B22: =markup!AC4 | C22: =markup!AD4 | D22: =markup!AE4 | E22: =markup!AF4 | F22: =markup!AG4 | G22: =markup!AH4 | H22: =markup!AI4 | I22: =markup!AJ4 | ... AE22: =markup!BF4

Sheet Anden fødevareindustri
A2: Mængder | B2: 1993 | C2: 1994 | D2: 1995 | E2: 1996 | F2: 1997 | G2: 1998 | H2: 1999 | I2: 2000 | J2: 2001 | K2: 2002 | L2: 2003 | M2: 2004 | N2: 2005 | O2: 2006 | P2: 2007 | Q2: 2008 | R2: 2009 | S2: 2010 | T2: 2011 | U2: 2012 | V2: 2013 | W2: 2014 | X2: 2015 | Y2: 2016 | Z2: 2017 | AA2: 2018 | AB2: 2019 | AC2: 2020 | AD2: 2021 | AE2: 2022 | AF2: 2023
A3: Y | B3: =Y!AB5 | C3: =Y!AC5 | D3: =Y!AD5 | E3: =Y!AE5 | F3: =Y!AF5 | G3: =Y!AG5 | H3: =Y!AH5 | I3: =Y!AI5 | ... AE3: =Y!BE5
A4: K | B4: =K!AC5 | C4: =K!AD5 | D4: =K!AE5 | E4: =K!AF5 | F4: =K!AG5 | G4: =K!AH5 | H4: =K!AI5 | I4: =K!AJ5 | ... AE4: =K!BF5
A5: L | B5: =L!AC5 | C5: =L!AD5 | D5: =L!AE5 | E5: =L!AF5 | F5: =L!AG5 | G5: =L!AH5 | H5: =L!AI5 | I5: =L!AJ5 | ... AE5: =L!BF5
A6: Mtot | B6: =Mtot!AB5 | C6: =Mtot!AC5 | D6: =Mtot!AD5 | E6: =Mtot!AE5 | F6: =Mtot!AF5 | G6: =Mtot!AG5 | H6: =Mtot!AH5 | I6: =Mtot!AI5 | ... AE6: =Mtot!BE5
A7: J | B7: =J!M5 | C7: =J!N5 | D7: =J!O5 | E7: =J!P5 | F7: =J!Q5 | G7: =J!R5 | H7: =J!S5 | I7: =J!T5 | ... AE7: =J!AP5
A8: I | B8: =I!AC5 | C8: =I!AD5 | D8: =I!AE5 | E8: =I!AF5 | F8: =I!AG5 | G8: =I!AH5 | H8: =I!AI5 | I8: =I!AJ5 | ... AE8: =I!BF5
A10: Priser
A11: p_Y | B11: =P!AB5 | C11: =P!AC5 | D11: =P!AD5 | E11: =P!AE5 | F11: =P!AF5 | G11: =P!AG5 | H11: =P!AH5 | I11: =P!AI5 | ... AE11: =P!BE5
A12: P_K | B12: =P_K!AC5 | C12: =P_K!AD5 | D12: =P_K!AE5 | E12: =P_K!AF5 | F12: =P_K!AG5 | G12: =P_K!AH5 | H12: =P_K!AI5 | I12: =P_K!AJ5 | ... AE12: =P_K!BF5
A13: w | B13: =w!AC5 | C13: =w!AD5 | D13: =w!AE5 | E13: =w!AF5 | F13: =w!AG5 | G13: =w!AH5 | H13: =w!AI5 | I13: =w!AJ5 | ... AE13: =w!BF5
A14: P_Mtot | B14: =P_Mtot!AB5 | C14: =P_Mtot!AC5 | D14: =P_Mtot!AD5 | E14: =P_Mtot!AE5 | F14: =P_Mtot!AF5 | G14: =P_Mtot!AG5 | H14: =P_Mtot!AH5 | I14: =P_Mtot!AI5 | ... AE14: =P_Mtot!BE5
A15: P_J | B15: =P_J!AC5 | C15: =P_J!AD5 | D15: =P_J!AE5 | E15: =P_J!AF5 | F15: =P_J!AG5 | G15: =P_J!AH5 | H15: =P_J!AI5 | I15: =P_J!AJ5 | ... AE15: =P_J!BF5
A16: P_I | B16: =P_I!C5 | C16: =P_I!D5 | D16: =P_I!E5 | E16: =P_I!F5 | F16: =P_I!G5 | G16: =P_I!H5 | H16: =P_I!I5 | I16: =P_I!J5 | ... AE16: =P_I!AF5
A17: P_Jord | B17: =P_Jord!M3 | C17: =P_Jord!N3 | D17: =P_Jord!O3 | E17: =P_Jord!P3 | F17: =P_Jord!Q3 | G17: =P_Jord!R3 | H17: =P_Jord!S3 | I17: =P_Jord!T3 | ... AE17: =P_Jord!AP3
A19: Andet
A20: Subsidiesats | B20: =tau_Y!AC5 | C20: =tau_Y!AD5 | D20: =tau_Y!AE5 | E20: =tau_Y!AF5 | F20: =tau_Y!AG5 | G20: =tau_Y!AH5 | H20: =tau_Y!AI5 | I20: =tau_Y!AJ5 | ... AE20: =tau_Y!BF5
A21: Afgift indenlandsk | B21: =tau_MD!AB5 | C21: =tau_MD!AC5 | D21: =tau_MD!AD5 | E21: =tau_MD!AE5 | F21: =tau_MD!AF5 | G21: =tau_MD!AG5 | H21: =tau_MD!AH5 | I21: =tau_MD!AI5 | ... AE21: =tau_MD!BE5
A22: Markup | B22: =markup!AC5 | C22: =markup!AD5 | D22: =markup!AE5 | E22: =markup!AF5 | F22: =markup!AG5 | G22: =markup!AH5 | H22: =markup!AI5 | I22: =markup!AJ5 | ... AE22: =markup!BF5

Sheet Resten
A2: Mængder | B2: 1993 | C2: 1994 | D2: 1995 | E2: 1996 | F2: 1997 | G2: 1998 | H2: 1999 | I2: 2000 | J2: 2001 | K2: 2002 | L2: 2003 | M2: 2004 | N2: 2005 | O2: 2006 | P2: 2007 | Q2: 2008 | R2: 2009 | S2: 2010 | T2: 2011 | U2: 2012 | V2: 2013 | W2: 2014 | X2: 2015 | Y2: 2016 | Z2: 2017 | AA2: 2018 | AB2: 2019 | AC2: 2020 | AD2: 2021 | AE2: 2022 | AF2: 2023
A3: Y | B3: =Y!AB6 | C3: =Y!AC6 | D3: =Y!AD6 | E3: =Y!AE6 | F3: =Y!AF6 | G3: =Y!AG6 | H3: =Y!AH6 | I3: =Y!AI6 | ... AE3: =Y!BE6
A4: K | B4: =K!AC6 | C4: =K!AD6 | D4: =K!AE6 | E4: =K!AF6 | F4: =K!AG6 | G4: =K!AH6 | H4: =K!AI6 | I4: =K!AJ6 | ... AE4: =K!BF6
A5: L | B5: =L!AC6 | C5: =L!AD6 | D5: =L!AE6 | E5: =L!AF6 | F5: =L!AG6 | G5: =L!AH6 | H5: =L!AI6 | I5: =L!AJ6 | ... AE5: =L!BF6
A6: Mtot | B6: =Mtot!AB6 | C6: =Mtot!AC6 | D6: =Mtot!AD6 | E6: =Mtot!AE6 | F6: =Mtot!AF6 | G6: =Mtot!AG6 | H6: =Mtot!AH6 | I6: =Mtot!AI6 | ... AE6: =Mtot!BE6
A7: J | B7: =J!M6 | C7: =J!N6 | D7: =J!O6 | E7: =J!P6 | F7: =J!Q6 | G7: =J!R6 | H7: =J!S6 | I7: =J!T6 | ... AE7: =J!AP6
A8: I | B8: =I!AC6 | C8: =I!AD6 | D8: =I!AE6 | E8: =I!AF6 | F8: =I!AG6 | G8: =I!AH6 | H8: =I!AI6 | I8: =I!AJ6 | ... AE8: =I!BF6
A10: Priser
A11: p_Y | B11: =P!AB6 | C11: =P!AC6 | D11: =P!AD6 | E11: =P!AE6 | F11: =P!AF6 | G11: =P!AG6 | H11: =P!AH6 | I11: =P!AI6 | ... AE11: =P!BE6
A12: P_K | B12: =P_K!AC6 | C12: =P_K!AD6 | D12: =P_K!AE6 | E12: =P_K!AF6 | F12: =P_K!AG6 | G12: =P_K!AH6 | H12: =P_K!AI6 | I12: =P_K!AJ6 | ... AE12: =P_K!BF6
A13: w | B13: =w!AC6 | C13: =w!AD6 | D13: =w!AE6 | E13: =w!AF6 | F13: =w!AG6 | G13: =w!AH6 | H13: =w!AI6 | I13: =w!AJ6 | ... AE13: =w!BF6
A14: P_Mtot | B14: =P_Mtot!AB6 | C14: =P_Mtot!AC6 | D14: =P_Mtot!AD6 | E14: =P_Mtot!AE6 | F14: =P_Mtot!AF6 | G14: =P_Mtot!AG6 | H14: =P_Mtot!AH6 | I14: =P_Mtot!AI6 | ... AE14: =P_Mtot!BE6
A15: P_J | B15: =P_J!AC6 | C15: =P_J!AD6 | D15: =P_J!AE6 | E15: =P_J!AF6 | F15: =P_J!AG6 | G15: =P_J!AH6 | H15: =P_J!AI6 | I15: =P_J!AJ6 | ... AE15: =P_J!BF6
A16: P_I | B16: =P_I!C6 | C16: =P_I!D6 | D16: =P_I!E6 | E16: =P_I!F6 | F16: =P_I!G6 | G16: =P_I!H6 | H16: =P_I!I6 | I16: =P_I!J6 | ... AE16: =P_I!AF6
A17: P_Jord | B17: =P_Jord!M6 | C17: =P_Jord!N6 | D17: =P_Jord!O6 | E17: =P_Jord!P6 | F17: =P_Jord!Q6 | G17: =P_Jord!R6 | H17: =P_Jord!S6 | I17: =P_Jord!T6 | ... AE17: =P_Jord!AP6
A19: Andet
A20: Subsidiesats | B20: =tau_Y!AC6 | C20: =tau_Y!AD6 | D20: =tau_Y!AE6 | E20: =tau_Y!AF6 | F20: =tau_Y!AG6 | G20: =tau_Y!AH6 | H20: =tau_Y!AI6 | I20: =tau_Y!AJ6 | ... AE20: =tau_Y!BF6
A21: Afgift indenlandsk | B21: =tau_MD!AB6 | C21: =tau_MD!AC6 | D21: =tau_MD!AD6 | E21: =tau_MD!AE6 | F21: =tau_MD!AF6 | G21: =tau_MD!AG6 | H21: =tau_MD!AH6 | I21: =tau_MD!AI6 | ... AE21: =tau_MD!BE6
A22: Markup | B22: =markup!AC6 | C22: =markup!AD6 | D22: =markup!AE6 | E22: =markup!AF6 | F22: =markup!AG6 | G22: =markup!AH6 | H22: =markup!AI6 | I22: =markup!AJ6 | ... AE22: =markup!BF6

Sheet Y
A1: ANVENDELSE | B1: 1967 | C1: 1968 | D1: 1969 | E1: 1970 | F1: 1971 | G1: 1972 | H1: 1973 | I1: 1974 | J1: 1975 | K1: 1976 | L1: 1977 | M1: 1978 | N1: 1979 | O1: 1980 | P1: 1981 | Q1: 1982 | R1: 1983 | S1: 1984 | T1: 1985 | U1: 1986 | V1: 1987 | W1: 1988 | X1: 1989 | Y1: 1990 | Z1: 1991 | AA1: 1992 | AB1: 1993 | AC1: 1994 | AD1: 1995 | AE1: 1996 | AF1: 1997 | AG1: 1998 | AH1: 1999 | AI1: 2000 | AJ1: 2001 | AK1: 2002 | AL1: 2003 | AM1: 2004 | AN1: 2005 | AO1: 2006 | AP1: 2007 | AQ1: 2008 | AR1: 2009 | AS1: 2010 | AT1: 2011 | AU1: 2012 | AV1: 2013 | AW1: 2014 | AX1: 2015 | AY1: 2016 | AZ1: 2017 | BA1: 2018 | BB1: 2019 | BC1: 2020 | BD1: 2021 | BE1: 2022
A2: 010000 | B2: 44352.253 | C2: 44088.474 | D2: 44065.485 | E2: 41076.955 | F2: 44428.588 | G2: 45125.516 | H2: 45687.594 | I2: 47792.366 | J2: 45353.08 | K2: 45360.614 | L2: 48300.748 | M2: 50462.618 | N2: 51681.032 | O2: 51506.404 | P2: 52624.818 | Q2: 55228.202 | R2: 53482.361 | S2: 58750.744 | T2: 58588.026 | U2: 58742.299 | V2: 56961.097 | W2: 56075.446 | X2: 58852.663 | Y2: 62263.479 | Z2: 60786.475 | AA2: 60399.718 | AB2: 69638.69 | AC2: 68856.807 | AD2: 69737.096 | AE2: 70280.702 | AF2: 72177.731 | AG2: 73158.199 | AH2: 73173.611 | AI2: 74464.21 | AJ2: 73547.402 | AK2: 74587.448 | AL2: 74719.005 | AM2: 75618.655 | AN2: 74196.06 | AO2: 75618.96 | AP2: 79159.854 | AQ2: 73126.391 | AR2: 73444.22 | AS2: 77334.77 | AT2: 75869.896 | AU2: 77617.493 | AV2: 76593.51 | AW2: 80374.732 | AX2: 79210.579 | AY2: 76984.41 | AZ2: 80708.048 | BA2: 79724.539 | BB2: 78394.569 | BC2: 80503.511 | BD2: 82678.533 | BE2: 81481.018
A3: 100010 | B3: 19603.637 | C3: 20162.552 | D3: 19600.349 | E3: 20860.731 | F3: 21652.481 | G3: 21811.726 | H3: 21771.594 | I3: 22881.54 | J3: 21700.694 | K3: 21738.23 | L3: 23706.522 | M3: 24543.494 | N3: 30503.414 | O3: 32114.066 | P3: 32819.62 | Q3: 29452.209 | R3: 26717.607 | S3: 27249.076 | T3: 30407.824 | U3: 33466.516 | V3: 33552.058 | W3: 33140.377 | X3: 31472.527 | Y3: 33958.43 | Z3: 33567.682 | AA3: 36548.965 | AB3: 41661.646 | AC3: 45997.897 | AD3: 38506.194 | AE3: 36861.103 | AF3: 38258.226 | AG3: 43120.781 | AH3: 42765.432 | AI3: 41046.325 | AJ3: 41829.729 | AK3: 40178.006 | AL3: 41397.664 | AM3: 41559.693 | AN3: 41156.783 | AO3: 40168.836 | AP3: 39629.858 | AQ3: 39535.454 | AR3: 41178.776 | AS3: 40912.159 | AT3: 41991.465 | AU3: 40441.434 | AV3: 40083.909 | AW3: 40146.462 | AX3: 40967.353 | AY3: 40700.138 | AZ3: 41359.72 | BA3: 41163.584 | BB3: 42404.428 | BC3: 45302.133 | BD3: 49544.273 | BE3: 47077.794
A4: 100030 | B4: 23308.218 | C4: 23349.031 | D4: 22452.475 | E4: 22045.546 | F4: 21902.4 | G4: 23446.451 | H4: 25018.051 | I4: 26029.253 | J4: 25974.336 | K4: 27360.29 | L4: 28510.653 | M4: 30345.834 | N4: 30337.185 | O4: 30745.601 | P4: 30305.228 | Q4: 31437.555 | R4: 32448.687 | S4: 31365.862 | T4: 30634.946 | U4: 30995.16 | V4: 30284.499 | W4: 30056.351 | X4: 30854.017 | Y4: 30976.745 | Z4: 30345.777 | AA4: 29933.086 | AB4: 30205.03 | AC4: 27872.967 | AD4: 29157.8 | AE4: 27898.946 | AF4: 28237.717 | AG4: 28196.69 | AH4: 27691.888 | AI4: 28237.449 | AJ4: 29226.309 | AK4: 28304.969 | AL4: 29583.592 | AM4: 29630.848 | AN4: 32097.647 | AO4: 33050.295 | AP4: 31604.092 | AQ4: 32137.717 | AR4: 31767.824 | AS4: 31699.519 | AT4: 34922.022 | AU4: 36078.324 | AV4: 35320.572 | AW4: 36124.205 | AX4: 35608.113 | AY4: 36399.12 | AZ4: 39447.426 | BA4: 37989.2 | BB4: 39920.752 | BC4: 41925.241 | BD4: 42596.809 | BE4: 46862.176
A5: 100040x100050 | B5: 24863.697 | C5: 25574.321 | D5: 26091.853 | E5: 27370.559 | F5: 28252.747 | G5: 28717.037 | H5: 29114.567 | I5: 29612.323 | J5: 28336.304 | K5: 30139.055 | L5: 31413.931 | M5: 32561.905 | N5: 32822.047 | O5: 33641.371 | P5: 33058.299 | Q5: 33832.921 | R5: 34708.71 | S5: 35106.024 | T5: 37091.976 | U5: 38043.297 | V5: 36666.074 | W5: 37337.592 | X5: 39058.838 | Y5: 40680.822 | Z5: 41036.673 | AA5: 41065.703 | AB5: 42926.619 | AC5: 41498.476 | AD5: 46373.218 | AE5: 44764.985 | AF5: 44235.122 | AG5: 44765.003 | AH5: 44976.291 | AI5: 45387.545 | AJ5: 46689.86 | AK5: 51898.162 | AL5: 50892.62 | AM5: 53832.517 | AN5: 55453.57 | AO5: 54361.675 | AP5: 55384.357 | AQ5: 54436.712 | AR5: 47572.699 | AS5: 44358.08 | AT5: 43377.988 | AU5: 41462.983 | AV5: 43634.444 | AW5: 43737.466 | AX5: 46185.736 | AY5: 48390.815 | AZ5: 49333.025 | BA5: 50453.61 | BB5: 51033.634 | BC5: 52160.771 | BD5: 50247.84 | BE5: 51593.742
A6: REST | B6: 1126140.7 | C6: 1169959.1 | D6: 1263696.3 | E6: 1317513.7 | F6: 1345389 | G6: 1412406.4 | H6: 1478856.3 | I6: 1450913.1 | J6: 1419212 | K6: 1529632.1 | L6: 1549707.3 | M6: 1588498.8 | N6: 1649089.1 | O6: 1637535 | P6: 1607018.2 | Q6: 1646652.4 | R6: 1685956.5 | S6: 1777204.3 | T6: 1868522 | U6: 1991395.7 | V6: 2027532.3 | W6: 2056059.7 | X6: 2064248.2 | Y6: 2094915.9 | Z6: 2117342.9 | AA6: 2149198.5 | AB6: 2156220.3 | AC6: 2272527.1 | AD6: 2359548.7 | AE6: 2440245.6 | AF6: 2519153.8 | AG6: 2589693.7 | AH6: 2706345.5 | AI6: 2848898.1 | AJ6: 2921460.3 | AK6: 2953824.1 | AL6: 2958892.8 | AM6: 3027295.7 | AN6: 3197352.5 | AO6: 3379596.8 | AP6: 3482958.5 | AQ6: 3520620.6 | AR6: 3286094.4 | AS6: 3288710.2 | AT6: 3375239.8 | AU6: 3404100 | AV6: 3409132.4 | AW6: 3480021 | AX6: 3569228.5 | AY6: 3704226.7 | AZ6: 3798775.1 | BA6: 3874168.7 | BB6: 3934204.8 | BC6: 3835540 | BD6: 4087541.1 | BE6: 4203685.8

Sheet BVT
A1: ANVENDELSE | B1: 1967 | C1: 1968 | D1: 1969 | E1: 1970 | F1: 1971 | G1: 1972 | H1: 1973 | I1: 1974 | J1: 1975 | K1: 1976 | L1: 1977 | M1: 1978 | N1: 1979 | O1: 1980 | P1: 1981 | Q1: 1982 | R1: 1983 | S1: 1984 | T1: 1985 | U1: 1986 | V1: 1987 | W1: 1988 | X1: 1989 | Y1: 1990 | Z1: 1991 | AA1: 1992 | AB1: 1993 | AC1: 1994 | AD1: 1995 | AE1: 1996 | AF1: 1997 | AG1: 1998 | AH1: 1999 | AI1: 2000 | AJ1: 2001 | AK1: 2002 | AL1: 2003 | AM1: 2004 | AN1: 2005 | AO1: 2006 | AP1: 2007 | AQ1: 2008 | AR1: 2009 | AS1: 2010 | AT1: 2011 | AU1: 2012 | AV1: 2013 | AW1: 2014 | AX1: 2015 | AY1: 2016 | AZ1: 2017 | BA1: 2018 | BB1: 2019 | BC1: 2020 | BD1: 2021 | BE1: 2022
A2: 010000
A3: 100010 | AB3: 4952 | AC3: 5232 | AD3: 4697 | AE3: 4445 | AF3: 4623 | AG3: 5792 | AH3: 6517 | AI3: 5228 | AJ3: 6208 | AK3: 4228 | AL3: 4634 | AM3: 5063 | AN3: 4437 | AO3: 4565 | AP3: 3695 | AQ3: 3846 | AR3: 4123 | AS3: 4204 | AT3: 4516 | AU3: 5518 | AV3: 4573 | AW3: 4150 | AX3: 4554 | AY3: 5025 | AZ3: 5227 | BA3: 4407 | BB3: 5959 | BC3: 7838 | BD3: 6937 | BE3: 5319
A4: 100030 | AB4: 6102 | AC4: 6452 | AD4: 8025 | AE4: 8198 | AF4: 9104 | AG4: 7515 | AH4: 7009 | AI4: 9066 | AJ4: 8496 | AK4: 8627 | AL4: 8145 | AM4: 7415 | AN4: 7294 | AO4: 6784 | AP4: 7179 | AQ4: 7822 | AR4: 5640 | AS4: 7133 | AT4: 7810 | AU4: 8030 | AV4: 7841 | AW4: 9238 | AX4: 6960 | AY4: 5964 | AZ4: 8153 | BA4: 5731 | BB4: 6505 | BC4: 4959 | BD4: 7505 | BE4: 12836
A5: 100040x100050
A6: REST

Sheet Mtot
A1: ANVENDELSE | B1: 1967 | C1: 1968 | D1: 1969 | E1: 1970 | F1: 1971 | G1: 1972 | H1: 1973 | I1: 1974 | J1: 1975 | K1: 1976 | L1: 1977 | M1: 1978 | N1: 1979 | O1: 1980 | P1: 1981 | Q1: 1982 | R1: 1983 | S1: 1984 | T1: 1985 | U1: 1986 | V1: 1987 | W1: 1988 | X1: 1989 | Y1: 1990 | Z1: 1991 | AA1: 1992 | AB1: 1993 | AC1: 1994 | AD1: 1995 | AE1: 1996 | AF1: 1997 | AG1: 1998 | AH1: 1999 | AI1: 2000 | AJ1: 2001 | AK1: 2002 | AL1: 2003 | AM1: 2004 | AN1: 2005 | AO1: 2006 | AP1: 2007 | AQ1: 2008 | AR1: 2009 | AS1: 2010 | AT1: 2011 | AU1: 2012 | AV1: 2013 | AW1: 2014 | AX1: 2015 | AY1: 2016 | AZ1: 2017 | BA1: 2018 | BB1: 2019 | BC1: 2020 | BD1: 2021 | BE1: 2022
A2: 010000 | B2: 39152.71 | C2: 38644.579 | D2: 37593.999 | E2: 39471.608 | F2: 39983.958 | G2: 39962.846 | H2: 43196.789 | I2: 40618.773 | J2: 41177.92 | K2: 45043.076 | L2: 44512.096 | M2: 47524.478 | N2: 49973.078 | O2: 48724.641 | P2: 47705.373 | Q2: 48742.204 | R2: 49273.52 | S2: 49171.629 | T2: 50048.249 | U2: 48849.048 | V2: 51120.164 | W2: 47929.284 | X2: 46710.236 | Y2: 48390.395 | Z2: 46706.776 | AA2: 48446.544 | AB2: 53349.784 | AC2: 51310.254 | AD2: 50096.221 | AE2: 49299.256 | AF2: 51004.663 | AG2: 52245.844 | AH2: 53060.676 | AI2: 51363.356 | AJ2: 49570.227 | AK2: 51730.597 | AL2: 50328.915 | AM2: 50586.449 | AN2: 49985.907 | AO2: 50474.454 | AP2: 50614.979 | AQ2: 51279.064 | AR2: 52129.893 | AS2: 51106.498 | AT2: 51930.226 | AU2: 51124.064 | AV2: 51953.221 | AW2: 51251.334 | AX2: 53805.736 | AY2: 54100.571 | AZ2: 54613.036 | BA2: 54309.946 | BB2: 51547.509 | BC2: 53402.835 | BD2: 53643.97 | BE2: 54314.097
A3: 100010 | B3: 22245.859 | C3: 22147.117 | D3: 21927.345 | E3: 23045.516 | F3: 23995.23 | G3: 23665.978 | H3: 23995.561 | I3: 24619.587 | J3: 23803.218 | K3: 23963.378 | L3: 24693.633 | M3: 25622.59 | N3: 30384.484 | O3: 31717.544 | P3: 32092.464 | Q3: 29702.348 | R3: 28215.907 | S3: 28835.556 | T3: 31262 | U3: 33801.573 | V3: 33828.649 | W3: 32523.397 | X3: 31250.427 | Y3: 33503.903 | Z3: 33988.966 | AA3: 36175.36 | AB3: 39564.103 | AC3: 44110.465 | AD3: 36319.247 | AE3: 34878.111 | AF3: 36226.755 | AG3: 39672.329 | AH3: 37871.494 | AI3: 38197.302 | AJ3: 37283.666 | AK3: 38605.626 | AL3: 39021.725 | AM3: 37944.451 | AN3: 38805.108 | AO3: 37366.99 | AP3: 38626.296 | AQ3: 38070.92 | AR3: 39359.608 | AS3: 38842.965 | AT3: 39453.525 | AU3: 36127.324 | AV3: 36821.821 | AW3: 37391.106 | AX3: 37725.578 | AY3: 36750.754 | AZ3: 37236.499 | BA3: 37888.95 | BB3: 36686.658 | BC3: 37462.228 | BD3: 42600.802 | BE3: 41846.374
A4: 100030 | B4: 19378.446 | C4: 19355.92 | D4: 18697.131 | E4: 18401.314 | F4: 18811.868 | G4: 20262.173 | H4: 19705.799 | I4: 20238.455 | J4: 20749.754 | K4: 22152.978 | L4: 22798.191 | M4: 23885.681 | N4: 23122.244 | O4: 23699.848 | P4: 23343.033 | Q4: 24081.601 | R4: 24928.726 | S4: 24551.527 | T4: 24082.933 | U4: 24969.687 | V4: 24654.438 | W4: 23146.864 | X4: 23586.394 | Y4: 24283.595 | Z4: 23721.271 | AA4: 23834.187 | AB4: 25015.624 | AC4: 22463.147 | AD4: 22813.121 | AE4: 21546.034 | AF4: 21414.547 | AG4: 22089.919 | AH4: 21918.002 | AI4: 21183.767 | AJ4: 22500.167 | AK4: 21590.979 | AL4: 23175.92 | AM4: 23727.677 | AN4: 26243.291 | AO4: 27668.716 | AP4: 25967.838 | AQ4: 25952.912 | AR4: 26984.534 | AS4: 25472.665 | AT4: 28128.78 | AU4: 29139.197 | AV4: 28530.33 | AW4: 28572.695 | AX4: 29250.296 | AY4: 31245.061 | AZ4: 31740.887 | BA4: 32045.887 | BB4: 33276.316 | BC4: 36964.21 | BD4: 35067.587 | BE4: 35380.457
A5: 100040x100050 | B5: 13022.936 | C5: 14197.977 | D5: 14374.392 | E5: 15654.831 | F5: 16809.348 | G5: 16870.364 | H5: 17348.585 | I5: 18064.479 | J5: 17137.557 | K5: 18638.217 | L5: 19461.333 | M5: 20984.634 | N5: 23195.649 | O5: 24429.862 | P5: 24123.49 | Q5: 22972.265 | R5: 20682.053 | S5: 21641.71 | T5: 24226.13 | U5: 25432.868 | V5: 25622.862 | W5: 25752.107 | X5: 26186.762 | Y5: 27812.237 | Z5: 27792.899 | AA5: 28969.842 | AB5: 31602.816 | AC5: 30113.873 | AD5: 35198.363 | AE5: 34193.47 | AF5: 32955.76 | AG5: 33550.432 | AH5: 33749.905 | AI5: 33636.408 | AJ5: 34180.106 | AK5: 40410.77 | AL5: 42356.254 | AM5: 43972.3 | AN5: 43787.429 | AO5: 43960.906 | AP5: 43802.42 | AQ5: 42681.134 | AR5: 36155.139 | AS5: 33223.023 | AT5: 32540.62 | AU5: 31749.452 | AV5: 32300.156 | AW5: 32888.892 | AX5: 36735.924 | AY5: 36539.698 | AZ5: 37433.905 | BA5: 37603.733 | BB5: 37522.547 | BC5: 39265.28 | BD5: 35523.965 | BE5: 36317.792
A6: REST | B6: 435006.82 | C6: 445661.89 | D6: 488689.46 | E6: 517331.61 | F6: 519754.32 | G6: 550298.55 | H6: 580193.47 | I6: 565766.78 | J6: 546636.82 | K6: 595138.53 | L6: 603640.04 | M6: 619729.76 | N6: 640453.08 | O6: 632434.32 | P6: 609080.01 | Q6: 608950.52 | R6: 624626.51 | S6: 683319.19 | T6: 726567.93 | U6: 792672.14 | V6: 807106.92 | W6: 814990.61 | X6: 811723.87 | Y6: 819999.6 | Z6: 821478.1 | AA6: 831164.17 | AB6: 835794.98 | AC6: 886447.6 | AD6: 933979.76 | AE6: 972040.63 | AF6: 1000645 | AG6: 1035613.4 | AH6: 1100098.8 | AI6: 1153633 | AJ6: 1205483.1 | AK6: 1225501.3 | AL6: 1211995.4 | AM6: 1243523.8 | AN6: 1362477.1 | AO6: 1457823.6 | AP6: 1520062.6 | AQ6: 1539294.7 | AR6: 1398743.9 | AS6: 1382803.4 | AT6: 1417628.3 | AU6: 1445341.4 | AV6: 1435473.5 | AW6: 1481115 | AX6: 1534527.7 | AY6: 1597497.7 | AZ6: 1634324.5 | BA6: 1668534.3 | BB6: 1698975.9 | BC6: 1674522.2 | BD6: 1784692.9 | BE6: 1879876.4

Sheet K
A1: ANVENDELSE | B1: 1966 | C1: 1967 | D1: 1968 | E1: 1969 | F1: 1970 | G1: 1971 | H1: 1972 | I1: 1973 | J1: 1974 | K1: 1975 | L1: 1976 | M1: 1977 | N1: 1978 | O1: 1979 | P1: 1980 | Q1: 1981 | R1: 1982 | S1: 1983 | T1: 1984 | U1: 1985 | V1: 1986 | W1: 1987 | X1: 1988 | Y1: 1989 | Z1: 1990 | AA1: 1991 | AB1: 1992 | AC1: 1993 | AD1: 1994 | AE1: 1995 | AF1: 1996 | AG1: 1997 | AH1: 1998 | AI1: 1999 | AJ1: 2000 | AK1: 2001 | AL1: 2002 | AM1: 2003 | AN1: 2004 | AO1: 2005 | AP1: 2006 | AQ1: 2007 | AR1: 2008 | AS1: 2009 | AT1: 2010 | AU1: 2011 | AV1: 2012 | AW1: 2013 | AX1: 2014 | AY1: 2015 | AZ1: 2016 | BA1: 2017 | BB1: 2018 | BC1: 2019 | BD1: 2020 | BE1: 2021 | BF1: 2022 | BG1: 2023 | BH1: 2024
A2: 010000 | B2: 222779 | C2: 224430 | D2: 224282 | E2: 225092 | F2: 225532 | G2: 226385 | H2: 229269 | I2: 235171 | J2: 240479 | K2: 244016 | L2: 249923 | M2: 257543 | N2: 265709 | O2: 273950 | P2: 274839 | Q2: 271574 | R2: 269172 | S2: 265387 | T2: 264710 | U2: 266226 | V2: 266885 | W2: 266110 | X2: 264303 | Y2: 267224 | Z2: 270771 | AA2: 270977 | AB2: 269956 | AC2: 265165 | AD2: 261404 | AE2: 258846 | AF2: 255722 | AG2: 253481 | AH2: 250903 | AI2: 243755 | AJ2: 242098 | AK2: 242131 | AL2: 240161 | AM2: 238063 | AN2: 236088 | AO2: 234687 | AP2: 235845 | AQ2: 239330 | AR2: 242244 | AS2: 239024 | AT2: 234064 | AU2: 229103 | AV2: 225090 | AW2: 222016 | AX2: 218477 | AY2: 215268 | AZ2: 211288 | BA2: 208278 | BB2: 204256 | BC2: 200726 | BD2: 196514 | BE2: 194470 | BF2: 190650 | BG2: 187393 | BH2: 184590
A3: 100010 | AB3: 20659.335 | AC3: 21072.522 | AD3: 21551.229 | AE3: 21742.316 | AF3: 22460.401 | AG3: 22568.393 | AH3: 22913.784 | AI3: 22988.021 | AJ3: 23592.776 | AK3: 24191.702 | AL3: 24611.737 | AM3: 25409.962 | AN3: 26129.686 | AO3: 26020.37 | AP3: 25899.864 | AQ3: 25988.255 | AR3: 26725.596 | AS3: 27361.265 | AT3: 26762.313 | AU3: 26324.033 | AV3: 26528.139 | AW3: 26364.293 | AX3: 26169.173 | AY3: 25905.465 | AZ3: 25721.654 | BA3: 25611.833 | BB3: 26158.64 | BC3: 26445.716 | BD3: 26503.103 | BE3: 26671.438 | BF3: 26893.946
A4: 100030 | AB4: 9519.2358 | AC4: 9709.6205 | AD4: 9788.8389 | AE4: 9928.4904 | AF4: 10279.873 | AG4: 10358.006 | AH4: 10458.014 | AI4: 10482.767 | AJ4: 11017.677 | AK4: 11384.866 | AL4: 11751.699 | AM4: 12266.585 | AN4: 12817.5 | AO4: 12995.031 | AP4: 13041.134 | AQ4: 13186.74 | AR4: 13720.145 | AS4: 14164.163 | AT4: 13980.592 | AU4: 13934.689 | AV4: 14395.724 | AW4: 14355.248 | AX4: 14392.773 | AY4: 14584.333 | AZ4: 14797.38 | BA4: 15013.94 | BB4: 15356.999 | BC4: 15778.213 | BD4: 15812.693 | BE4: 16061.663 | BF4: 16329.681
A5: 100040x100050 | AB5: 27478.908 | AC5: 28028.487 | AD5: 28422.088 | AE5: 28819.556 | AF5: 29949.559 | AG5: 30200.498 | AH5: 30590.829 | AI5: 30632.304 | AJ5: 31588.809 | AK5: 32452.564 | AL5: 33285.899 | AM5: 34147.781 | AN5: 35205.048 | AO5: 35380.877 | AP5: 35497.982 | AQ5: 35967.291 | AR5: 37455.371 | AS5: 38469.174 | AT5: 37685.915 | AU5: 37323.817 | AV5: 37588.007 | AW5: 37764.879 | AX5: 37827.609 | AY5: 37544.634 | AZ5: 37575.704 | BA5: 37941.154 | BB5: 39093.069 | BC5: 39652.161 | BD5: 39656.21 | BE5: 39906.398 | BF5: 40233.083
A6: REST | B6: 2618163 | C6: 2738303 | D6: 2867006 | E6: 3015495 | F6: 3161059 | G6: 3302298 | H6: 3467494 | I6: 3631240 | J6: 3755637 | K6: 3856260 | L6: 3992820 | M6: 4114787 | N6: 4233512 | O6: 4350333 | P6: 4435830 | Q6: 4471498 | R6: 4517509 | S6: 4564886 | T6: 4625448 | U6: 4710206 | V6: 4837386 | W6: 4962141 | X6: 5055391 | Y6: 5137935 | Z6: 5217291 | AA6: 5264800 | AB6: 5305384 | AC6: 5328639 | AD6: 5354683 | AE6: 5403081 | AF6: 5462484 | AG6: 5531111 | AH6: 5612542 | AI6: 5682056 | AJ6: 5773271 | AK6: 5852073 | AL6: 5918328 | AM6: 5980902 | AN6: 6046439 | AO6: 6132550 | AP6: 6270696 | AQ6: 6395005 | AR6: 6486901 | AS6: 6533631 | AT6: 6550770 | AU6: 6568622 | AV6: 6599838 | AW6: 6638025 | AX6: 6696875 | AY6: 6769376 | AZ6: 6870825 | BA6: 6985059 | BB6: 7107156 | BC6: 7209258 | BD6: 7324959 | BE6: 7488001 | BF6: 7648052 | BG6: 7786450 | BH6: 7930718

Sheet K_BVT
A1: ANVENDELSE | B1: 1966 | C1: 1967 | D1: 1968 | E1: 1969 | F1: 1970 | G1: 1971 | H1: 1972 | I1: 1973 | J1: 1974 | K1: 1975 | L1: 1976 | M1: 1977 | N1: 1978 | O1: 1979 | P1: 1980 | Q1: 1981 | R1: 1982 | S1: 1983 | T1: 1984 | U1: 1985 | V1: 1986 | W1: 1987 | X1: 1988 | Y1: 1989 | Z1: 1990 | AA1: 1991 | AB1: 1992 | AC1: 1993 | AD1: 1994 | AE1: 1995 | AF1: 1996 | AG1: 1997 | AH1: 1998 | AI1: 1999 | AJ1: 2000 | AK1: 2001 | AL1: 2002 | AM1: 2003 | AN1: 2004 | AO1: 2005 | AP1: 2006 | AQ1: 2007 | AR1: 2008 | AS1: 2009 | AT1: 2010 | AU1: 2011 | AV1: 2012 | AW1: 2013 | AX1: 2014 | AY1: 2015 | AZ1: 2016 | BA1: 2017 | BB1: 2018 | BC1: 2019 | BD1: 2020 | BE1: 2021 | BF1: 2022 | BG1: 2023 | BH1: 2024
A2: 010000 | B2: 222779 | C2: 224430 | D2: 224282 | E2: 225092 | F2: 225532 | G2: 226385 | H2: 229269 | I2: 235171 | J2: 240479 | K2: 244016 | L2: 249923 | M2: 257543 | N2: 265709 | O2: 273950 | P2: 274839 | Q2: 271574 | R2: 269172 | S2: 265387 | T2: 264710 | U2: 266226 | V2: 266885 | W2: 266110 | X2: 264303 | Y2: 267224 | Z2: 270771 | AA2: 270977 | AB2: 269956 | AC2: 265165 | AD2: 261404 | AE2: 258846 | AF2: 255722 | AG2: 253481 | AH2: 250903 | AI2: 243755 | AJ2: 242098 | AK2: 242131 | AL2: 240161 | AM2: 238063 | AN2: 236088 | AO2: 234687 | AP2: 235845 | AQ2: 239330 | AR2: 242244 | AS2: 239024 | AT2: 234064 | AU2: 229103 | AV2: 225090 | AW2: 222016 | AX2: 218477 | AY2: 215268 | AZ2: 211288 | BA2: 208278 | BB2: 204256 | BC2: 200726 | BD2: 196514 | BE2: 194470 | BF2: 190650 | BG2: 187393 | BH2: 184590
A3: 100010 | AB3: 20659.335 | AC3: 21072.522 | AD3: 21551.229 | AE3: 21742.316 | AF3: 22460.401 | AG3: 22568.393 | AH3: 22913.784 | AI3: 22988.021 | AJ3: 23592.776 | AK3: 24191.702 | AL3: 24611.737 | AM3: 25409.962 | AN3: 26129.686 | AO3: 26020.37 | AP3: 25899.864 | AQ3: 25988.255 | AR3: 26725.596 | AS3: 27361.265 | AT3: 26762.313 | AU3: 26324.033 | AV3: 26528.139 | AW3: 26364.293 | AX3: 26169.173 | AY3: 25905.465 | AZ3: 25721.654 | BA3: 25611.833 | BB3: 26158.64 | BC3: 26445.716 | BD3: 26503.103 | BE3: 26671.438 | BF3: 26893.946
